I0924 12:41:16.064396    6058 registry.go:154] Registering EvenPodsSpread predicate and priority function
I0924 12:41:16.064568    6058 registry.go:154] Registering EvenPodsSpread predicate and priority function
I0924 12:41:16.105580    6058 registry.go:154] Registering EvenPodsSpread predicate and priority function
I0924 12:41:16.105670    6058 registry.go:154] Registering EvenPodsSpread predicate and priority function
I0924 12:41:16.135917    6058 feature_gate.go:216] feature gates: &{map[AllAlpha:false BalanceAttachedNodeVolumes:false BoundServiceAccountTokenVolume:false CSIInlineVolume:false CSIMigration:false CSIMigrationAWS:false CSIMigrationAzureDisk:false CSIMigrationAzureFile:false CSIMigrationGCE:false CSIMigrationOpenStack:false CSINodeInfo:false CustomCPUCFSQuotaPeriod:false CustomResourceDefaulting:false DebugContainers:false DynamicAuditing:false ExpandCSIVolumes:false ExperimentalCriticalPodAnnotation:false HyperVContainer:false InPlacePodVerticalScaling:false LocalStorageCapacityIsolationFSQuotaMonitoring:false MandatoryArktosNetwork:true MountContainers:false NonPreemptingPriority:false PerNetworkServiceIPAlloc:false ProcMountType:false QOSReserved:false QPSDoubleGCController:false QPSDoubleRSController:false RemainingItemCount:false RemoveSelfLink:false RequestManagement:false ResourceLimitsPriorityFunction:false SCTPSupport:false ServerSideApply:false ServiceLoadBalancerFinalizer:false ServiceNodeExclusion:false TTLAfterFinished:false VolumePVCDataSource:false VolumeSnapshotDataSource:false WinDSR:false WinOverlay:false WindowsGMSA:false WorkloadInfoDefaulting:false]}
I0924 12:41:16.136138    6058 flags.go:33] FLAG: --add-dir-header="false"
I0924 12:41:16.136265    6058 flags.go:33] FLAG: --address="0.0.0.0"
I0924 12:41:16.136286    6058 flags.go:33] FLAG: --algorithm-provider=""
I0924 12:41:16.136301    6058 flags.go:33] FLAG: --alsologtostderr="false"
I0924 12:41:16.136312    6058 flags.go:33] FLAG: --application-metrics-count-limit="100"
I0924 12:41:16.136323    6058 flags.go:33] FLAG: --authentication-kubeconfig=""
I0924 12:41:16.136332    6058 flags.go:33] FLAG: --authentication-skip-lookup="false"
I0924 12:41:16.136345    6058 flags.go:33] FLAG: --authentication-token-webhook-cache-ttl="10s"
I0924 12:41:16.136358    6058 flags.go:33] FLAG: --authentication-tolerate-lookup-failure="true"
I0924 12:41:16.136368    6058 flags.go:33] FLAG: --authorization-always-allow-paths="[/healthz]"
I0924 12:41:16.136404    6058 flags.go:33] FLAG: --authorization-kubeconfig=""
I0924 12:41:16.136414    6058 flags.go:33] FLAG: --authorization-webhook-cache-authorized-ttl="10s"
I0924 12:41:16.136424    6058 flags.go:33] FLAG: --authorization-webhook-cache-unauthorized-ttl="10s"
I0924 12:41:16.136434    6058 flags.go:33] FLAG: --azure-container-registry-config=""
I0924 12:41:16.136443    6058 flags.go:33] FLAG: --bind-address="0.0.0.0"
I0924 12:41:16.136456    6058 flags.go:33] FLAG: --boot-id-file="/proc/sys/kernel/random/boot_id"
I0924 12:41:16.136467    6058 flags.go:33] FLAG: --cert-dir=""
I0924 12:41:16.136477    6058 flags.go:33] FLAG: --client-ca-file=""
I0924 12:41:16.136486    6058 flags.go:33] FLAG: --cloud-provider-gce-lb-src-cidrs="130.211.0.0/22,209.85.152.0/22,209.85.204.0/22,35.191.0.0/16"
I0924 12:41:16.136503    6058 flags.go:33] FLAG: --config=""
I0924 12:41:16.136512    6058 flags.go:33] FLAG: --container-hints="/etc/cadvisor/container_hints.json"
I0924 12:41:16.136523    6058 flags.go:33] FLAG: --containerd="/run/containerd/containerd.sock"
I0924 12:41:16.136543    6058 flags.go:33] FLAG: --containerd-namespace="k8s.io"
I0924 12:41:16.136558    6058 flags.go:33] FLAG: --contention-profiling="true"
I0924 12:41:16.136567    6058 flags.go:33] FLAG: --default-not-ready-toleration-seconds="300"
I0924 12:41:16.136578    6058 flags.go:33] FLAG: --default-unreachable-toleration-seconds="300"
I0924 12:41:16.136588    6058 flags.go:33] FLAG: --docker="unix:///var/run/docker.sock"
I0924 12:41:16.136598    6058 flags.go:33] FLAG: --docker-env-metadata-whitelist=""
I0924 12:41:16.136607    6058 flags.go:33] FLAG: --docker-only="false"
I0924 12:41:16.136638    6058 flags.go:33] FLAG: --docker-root="/var/lib/docker"
I0924 12:41:16.136648    6058 flags.go:33] FLAG: --docker-tls="false"
I0924 12:41:16.136658    6058 flags.go:33] FLAG: --docker-tls-ca="ca.pem"
I0924 12:41:16.136668    6058 flags.go:33] FLAG: --docker-tls-cert="cert.pem"
I0924 12:41:16.136677    6058 flags.go:33] FLAG: --docker-tls-key="key.pem"
I0924 12:41:16.136687    6058 flags.go:33] FLAG: --enable-load-reader="false"
I0924 12:41:16.136697    6058 flags.go:33] FLAG: --event-storage-age-limit="default=0"
I0924 12:41:16.136706    6058 flags.go:33] FLAG: --event-storage-event-limit="default=0"
I0924 12:41:16.136716    6058 flags.go:33] FLAG: --feature-gates="AllAlpha=false,BalanceAttachedNodeVolumes=false,BoundServiceAccountTokenVolume=false,CSIInlineVolume=false,CSIMigration=false,CSIMigrationAWS=false,CSIMigrationAzureDisk=false,CSIMigrationAzureFile=false,CSIMigrationGCE=false,CSIMigrationOpenStack=false,CSINodeInfo=false,CustomCPUCFSQuotaPeriod=false,CustomResourceDefaulting=false,DebugContainers=false,DynamicAuditing=false,ExpandCSIVolumes=false,ExperimentalCriticalPodAnnotation=false,HyperVContainer=false,InPlacePodVerticalScaling=false,LocalStorageCapacityIsolationFSQuotaMonitoring=false,MandatoryArktosNetwork=true,MountContainers=false,NonPreemptingPriority=false,PerNetworkServiceIPAlloc=false,ProcMountType=false,QOSReserved=false,QPSDoubleGCController=false,QPSDoubleRSController=false,RemainingItemCount=false,RemoveSelfLink=false,RequestManagement=false,ResourceLimitsPriorityFunction=false,SCTPSupport=false,ServerSideApply=false,ServiceLoadBalancerFinalizer=false,ServiceNodeExclusion=false,TTLAfterFinished=false,VolumePVCDataSource=false,VolumeSnapshotDataSource=false,WinDSR=false,WinOverlay=false,WindowsGMSA=false,WorkloadInfoDefaulting=false"
I0924 12:41:16.136851    6058 flags.go:33] FLAG: --global-housekeeping-interval="1m0s"
I0924 12:41:16.136864    6058 flags.go:33] FLAG: --hard-pod-affinity-symmetric-weight="1"
I0924 12:41:16.136876    6058 flags.go:33] FLAG: --help="false"
I0924 12:41:16.136892    6058 flags.go:33] FLAG: --housekeeping-interval="10s"
I0924 12:41:16.136903    6058 flags.go:33] FLAG: --http2-max-streams-per-connection="0"
I0924 12:41:16.136915    6058 flags.go:33] FLAG: --kube-api-burst="100"
I0924 12:41:16.136925    6058 flags.go:33] FLAG: --kube-api-content-type="application/vnd.kubernetes.protobuf"
I0924 12:41:16.136936    6058 flags.go:33] FLAG: --kube-api-qps="50"
I0924 12:41:16.136951    6058 flags.go:33] FLAG: --kubeconfig="/var/run/kubernetes/scheduler.kubeconfig"
I0924 12:41:16.136962    6058 flags.go:33] FLAG: --leader-elect="false"
I0924 12:41:16.136972    6058 flags.go:33] FLAG: --leader-elect-lease-duration="15s"
I0924 12:41:16.136982    6058 flags.go:33] FLAG: --leader-elect-renew-deadline="10s"
I0924 12:41:16.136991    6058 flags.go:33] FLAG: --leader-elect-resource-lock="endpointsleases"
I0924 12:41:16.137001    6058 flags.go:33] FLAG: --leader-elect-resource-name="kube-scheduler"
I0924 12:41:16.137011    6058 flags.go:33] FLAG: --leader-elect-resource-namespace="kube-system"
I0924 12:41:16.137021    6058 flags.go:33] FLAG: --leader-elect-retry-period="2s"
I0924 12:41:16.137030    6058 flags.go:33] FLAG: --lock-object-name="kube-scheduler"
I0924 12:41:16.137040    6058 flags.go:33] FLAG: --lock-object-namespace="kube-system"
I0924 12:41:16.137049    6058 flags.go:33] FLAG: --log-backtrace-at=":0"
I0924 12:41:16.137061    6058 flags.go:33] FLAG: --log-cadvisor-usage="false"
I0924 12:41:16.137070    6058 flags.go:33] FLAG: --log-dir=""
I0924 12:41:16.137079    6058 flags.go:33] FLAG: --log-file=""
I0924 12:41:16.137095    6058 flags.go:33] FLAG: --log-file-max-size="1800"
I0924 12:41:16.137106    6058 flags.go:33] FLAG: --log-flush-frequency="5s"
I0924 12:41:16.137116    6058 flags.go:33] FLAG: --logtostderr="true"
I0924 12:41:16.137125    6058 flags.go:33] FLAG: --machine-id-file="/etc/machine-id,/var/lib/dbus/machine-id"
I0924 12:41:16.137137    6058 flags.go:33] FLAG: --master=""
I0924 12:41:16.137146    6058 flags.go:33] FLAG: --policy-config-file=""
I0924 12:41:16.137162    6058 flags.go:33] FLAG: --policy-configmap=""
I0924 12:41:16.137171    6058 flags.go:33] FLAG: --policy-configmap-namespace="kube-system"
I0924 12:41:16.137181    6058 flags.go:33] FLAG: --port="10251"
I0924 12:41:16.137191    6058 flags.go:33] FLAG: --profiling="true"
I0924 12:41:16.137201    6058 flags.go:33] FLAG: --requestheader-allowed-names="[]"
I0924 12:41:16.137217    6058 flags.go:33] FLAG: --requestheader-client-ca-file=""
I0924 12:41:16.137226    6058 flags.go:33] FLAG: --requestheader-extra-headers-prefix="[x-remote-extra-]"
I0924 12:41:16.137246    6058 flags.go:33] FLAG: --requestheader-group-headers="[x-remote-group]"
I0924 12:41:16.137262    6058 flags.go:33] FLAG: --requestheader-username-headers="[x-remote-user]"
I0924 12:41:16.137281    6058 flags.go:33] FLAG: --resource-providers=""
I0924 12:41:16.137290    6058 flags.go:33] FLAG: --scheduler-name="default-scheduler"
I0924 12:41:16.137300    6058 flags.go:33] FLAG: --secure-port="10259"
I0924 12:41:16.137310    6058 flags.go:33] FLAG: --show-hidden-metrics-for-version=""
I0924 12:41:16.137319    6058 flags.go:33] FLAG: --skip-headers="false"
I0924 12:41:16.137332    6058 flags.go:33] FLAG: --skip-log-headers="false"
I0924 12:41:16.137342    6058 flags.go:33] FLAG: --stderrthreshold="2"
I0924 12:41:16.137352    6058 flags.go:33] FLAG: --storage-driver-buffer-duration="1m0s"
I0924 12:41:16.137362    6058 flags.go:33] FLAG: --storage-driver-db="cadvisor"
I0924 12:41:16.137372    6058 flags.go:33] FLAG: --storage-driver-host="localhost:8086"
I0924 12:41:16.137381    6058 flags.go:33] FLAG: --storage-driver-password="root"
I0924 12:41:16.137391    6058 flags.go:33] FLAG: --storage-driver-secure="false"
I0924 12:41:16.137400    6058 flags.go:33] FLAG: --storage-driver-table="stats"
I0924 12:41:16.137410    6058 flags.go:33] FLAG: --storage-driver-user="root"
I0924 12:41:16.137419    6058 flags.go:33] FLAG: --tls-cert-file=""
I0924 12:41:16.137428    6058 flags.go:33] FLAG: --tls-cipher-suites="[]"
I0924 12:41:16.137442    6058 flags.go:33] FLAG: --tls-min-version=""
I0924 12:41:16.137452    6058 flags.go:33] FLAG: --tls-private-key-file=""
I0924 12:41:16.137461    6058 flags.go:33] FLAG: --tls-sni-cert-key="[]"
I0924 12:41:16.137477    6058 flags.go:33] FLAG: --update-machine-info-interval="5m0s"
I0924 12:41:16.137487    6058 flags.go:33] FLAG: --use-legacy-policy-config="false"
I0924 12:41:16.137497    6058 flags.go:33] FLAG: --v="3"
I0924 12:41:16.137507    6058 flags.go:33] FLAG: --version="false"
I0924 12:41:16.137521    6058 flags.go:33] FLAG: --vmodule=""
I0924 12:41:16.137539    6058 flags.go:33] FLAG: --write-config-to=""
I0924 12:41:17.073124    6058 serving.go:319] Generated self-signed cert in-memory
W0924 12:41:17.972014    6058 authentication.go:250] No authentication-kubeconfig provided in order to lookup client-ca-file in configmap/extension-apiserver-authentication in kube-system, so client certificate authentication won't work.
W0924 12:41:17.972409    6058 authentication.go:253] No authentication-kubeconfig provided in order to lookup requestheader-client-ca-file in configmap/extension-apiserver-authentication in kube-system, so request-header client certificate authentication won't work.
W0924 12:41:17.972825    6058 authorization.go:147] No authorization-kubeconfig provided, so SubjectAccessReview of authorization tokens won't work.
I0924 12:41:18.003879    6058 options.go:286] ResourceProvider kubeConfig is not set. default to local cluster client
I0924 12:41:18.004218    6058 server.go:171] Starting Kubernetes Scheduler version v0.0.0-master+$Format:%h$. QPS 50
I0924 12:41:18.069469    6058 factory.go:228] Creating scheduler from algorithm provider 'DefaultProvider'
I0924 12:41:18.080830    6058 registry.go:154] Registering EvenPodsSpread predicate and priority function
I0924 12:41:18.081213    6058 registry.go:154] Registering EvenPodsSpread predicate and priority function
I0924 12:41:18.144000    6058 eventhandlers.go:456] Add event handler to node informer tp 0xc00076c630
W0924 12:41:18.154054    6058 authorization.go:48] Authorization is disabled
W0924 12:41:18.154139    6058 authentication.go:56] Authentication is disabled
I0924 12:41:18.154162    6058 deprecated_insecure_serving.go:52] Serving healthz insecurely on [::]:10251
I0924 12:41:18.156895    6058 secure_serving.go:123] Serving securely on [::]:10259
I0924 12:41:18.156984    6058 server.go:243] Scheduler started with resource provider number=1
I0924 12:41:18.158145    6058 reflector.go:218] Starting reflector *v1.Pod (0s) from k8s.io/kubernetes/cmd/kube-scheduler/app/server.go:239
I0924 12:41:18.158386    6058 reflector.go:218] Starting reflector *v1.PersistentVolume (0s) from k8s.io/client-go/informers/factory.go:145
I0924 12:41:18.162087    6058 reflector.go:218] Starting reflector *v1.PersistentVolumeClaim (0s) from k8s.io/client-go/informers/factory.go:145
I0924 12:41:18.163014    6058 reflector.go:293] ListAndWatch *v1.PersistentVolume. filter bounds []. name k8s.io/client-go/informers/factory.go:145. Watch page size 0. resync period 0s
I0924 12:41:18.163143    6058 reflector.go:218] Starting reflector *v1.StorageClass (0s) from k8s.io/client-go/informers/factory.go:145
I0924 12:41:18.163909    6058 reflector.go:293] ListAndWatch *v1.Pod. filter bounds []. name k8s.io/kubernetes/cmd/kube-scheduler/app/server.go:239. Watch page size 0. resync period 0s
I0924 12:41:18.163972    6058 reflector.go:218] Starting reflector *v1beta1.PodDisruptionBudget (0s) from k8s.io/client-go/informers/factory.go:145
I0924 12:41:18.164431    6058 reflector.go:218] Starting reflector *v1.Node (0s) from k8s.io/client-go/informers/factory.go:145
I0924 12:41:18.164564    6058 reflector.go:293] ListAndWatch *v1.Node. filter bounds []. name k8s.io/client-go/informers/factory.go:145. Watch page size 0. resync period 0s
I0924 12:41:18.166493    6058 reflector.go:293] ListAndWatch *v1.StorageClass. filter bounds []. name k8s.io/client-go/informers/factory.go:145. Watch page size 0. resync period 0s
I0924 12:41:18.166673    6058 reflector.go:293] ListAndWatch *v1beta1.PodDisruptionBudget. filter bounds []. name k8s.io/client-go/informers/factory.go:145. Watch page size 0. resync period 0s
I0924 12:41:18.166869    6058 reflector.go:293] ListAndWatch *v1.PersistentVolumeClaim. filter bounds []. name k8s.io/client-go/informers/factory.go:145. Watch page size 0. resync period 0s
I0924 12:41:18.167830    6058 reflector.go:218] Starting reflector *v1.Service (0s) from k8s.io/client-go/informers/factory.go:145
I0924 12:41:18.168220    6058 reflector.go:293] ListAndWatch *v1.Service. filter bounds []. name k8s.io/client-go/informers/factory.go:145. Watch page size 0. resync period 0s
I0924 12:41:32.854195    6058 eventhandlers.go:183] add event for unscheduled pod system/kube-system/kube-dns-7f4bf79dc-pvldq
I0924 12:41:32.854395    6058 scheduler.go:576] Attempting to schedule pod: system/kube-system/kube-dns-7f4bf79dc-pvldq
I0924 12:41:32.854391    6058 eventhandlers.go:183] add event for unscheduled pod system/default/mizar-operator-6985d77546-pxgk5
I0924 12:41:32.854615    6058 eventhandlers.go:183] add event for unscheduled pod system/kube-system/coredns-default-6cfd6c6766-cqfm7
I0924 12:41:32.854555    6058 factory.go:467] Unable to schedule system/kube-system/kube-dns-7f4bf79dc-pvldq: no nodes are registered to the cluster; waiting
I0924 12:41:32.854757    6058 scheduler.go:787] Updating pod condition for system/kube-system/kube-dns-7f4bf79dc-pvldq to (PodScheduled==False, Reason=Unschedulable)
I0924 12:41:32.885495    6058 scheduler.go:576] Attempting to schedule pod: system/kube-system/coredns-default-6cfd6c6766-cqfm7
I0924 12:41:32.885810    6058 factory.go:467] Unable to schedule system/kube-system/coredns-default-6cfd6c6766-cqfm7: no nodes are registered to the cluster; waiting
I0924 12:41:32.885944    6058 scheduler.go:787] Updating pod condition for system/kube-system/coredns-default-6cfd6c6766-cqfm7 to (PodScheduled==False, Reason=Unschedulable)
E0924 12:41:32.944231    6058 factory.go:512] pod: system/kube-system/kube-dns-7f4bf79dc-pvldq is already present in the active queue
I0924 12:41:32.974780    6058 scheduler.go:576] Attempting to schedule pod: system/kube-system/kube-dns-7f4bf79dc-pvldq
I0924 12:41:32.976127    6058 factory.go:467] Unable to schedule system/kube-system/kube-dns-7f4bf79dc-pvldq: no nodes are registered to the cluster; waiting
I0924 12:41:32.976248    6058 scheduler.go:787] Updating pod condition for system/kube-system/kube-dns-7f4bf79dc-pvldq to (PodScheduled==False, Reason=Unschedulable)
I0924 12:41:32.976499    6058 scheduler.go:576] Attempting to schedule pod: system/default/mizar-operator-6985d77546-pxgk5
I0924 12:41:32.977357    6058 factory.go:467] Unable to schedule system/default/mizar-operator-6985d77546-pxgk5: no nodes are registered to the cluster; waiting
I0924 12:41:32.980219    6058 scheduler.go:787] Updating pod condition for system/default/mizar-operator-6985d77546-pxgk5 to (PodScheduled==False, Reason=Unschedulable)
E0924 12:41:32.987705    6058 factory.go:512] pod: system/kube-system/coredns-default-6cfd6c6766-cqfm7 is already present in the active queue
I0924 12:41:33.092668    6058 scheduler.go:576] Attempting to schedule pod: system/kube-system/coredns-default-6cfd6c6766-cqfm7
I0924 12:41:33.093152    6058 factory.go:467] Unable to schedule system/kube-system/coredns-default-6cfd6c6766-cqfm7: no nodes are registered to the cluster; waiting
I0924 12:41:33.093215    6058 scheduler.go:787] Updating pod condition for system/kube-system/coredns-default-6cfd6c6766-cqfm7 to (PodScheduled==False, Reason=Unschedulable)
I0924 12:41:38.815777    6058 node_tree.go:88] Added node "master" in group "" to NodeTree
I0924 12:41:38.815866    6058 eventhandlers.go:114] Add node to cache. node [master], rpId [tp]. error <nil>
I0924 12:41:38.815994    6058 scheduler.go:576] Attempting to schedule pod: system/kube-system/kube-dns-7f4bf79dc-pvldq
I0924 12:41:38.832450    6058 eventhandlers.go:183] add event for unscheduled pod system/default/mizar-daemon-lxpzq
I0924 12:41:38.833889    6058 generic_scheduler.go:1052] Node master is a potential node for preemption.
I0924 12:41:38.834643    6058 factory.go:470] Unable to schedule system/kube-system/kube-dns-7f4bf79dc-pvldq: no fit: 0/1 nodes are available: 1 node(s) runtime is not ready.; waiting
I0924 12:41:38.834771    6058 scheduler.go:787] Updating pod condition for system/kube-system/kube-dns-7f4bf79dc-pvldq to (PodScheduled==False, Reason=Unschedulable)
I0924 12:41:38.858715    6058 scheduler.go:576] Attempting to schedule pod: system/kube-system/coredns-default-6cfd6c6766-cqfm7
I0924 12:41:38.873535    6058 generic_scheduler.go:1052] Node master is a potential node for preemption.
I0924 12:41:38.883400    6058 factory.go:470] Unable to schedule system/kube-system/coredns-default-6cfd6c6766-cqfm7: no fit: 0/1 nodes are available: 1 node(s) runtime is not ready.; waiting
I0924 12:41:38.883506    6058 scheduler.go:787] Updating pod condition for system/kube-system/coredns-default-6cfd6c6766-cqfm7 to (PodScheduled==False, Reason=Unschedulable)
I0924 12:41:38.904024    6058 scheduler.go:576] Attempting to schedule pod: system/kube-system/kube-dns-7f4bf79dc-pvldq
I0924 12:41:38.924784    6058 generic_scheduler.go:1052] Node master is a potential node for preemption.
I0924 12:41:38.925060    6058 factory.go:470] Unable to schedule system/kube-system/kube-dns-7f4bf79dc-pvldq: no fit: 0/1 nodes are available: 1 node(s) runtime is not ready.; waiting
I0924 12:41:38.929548    6058 scheduler.go:787] Updating pod condition for system/kube-system/kube-dns-7f4bf79dc-pvldq to (PodScheduled==False, Reason=Unschedulable)
I0924 12:41:38.930484    6058 scheduler.go:576] Attempting to schedule pod: system/default/mizar-operator-6985d77546-pxgk5
I0924 12:41:38.933151    6058 default_binder.go:53] Attempting to bind system/default/mizar-operator-6985d77546-pxgk5 to master
I0924 12:41:38.933365    6058 scheduler.go:576] Attempting to schedule pod: system/default/mizar-daemon-lxpzq
I0924 12:41:38.935186    6058 default_binder.go:53] Attempting to bind system/default/mizar-daemon-lxpzq to master
I0924 12:41:38.945856    6058 eventhandlers.go:215] delete event for unscheduled pod system/default/mizar-daemon-lxpzq
I0924 12:41:38.946114    6058 eventhandlers.go:239] add event for scheduled pod system/default/mizar-daemon-lxpzq 
I0924 12:41:38.946272    6058 scheduler.go:741] pod system/default/mizar-daemon-lxpzq is bound successfully on node "master", 1 nodes evaluated, 1 nodes were found feasible.
I0924 12:41:38.949664    6058 scheduler.go:741] pod system/default/mizar-operator-6985d77546-pxgk5 is bound successfully on node "master", 1 nodes evaluated, 1 nodes were found feasible.
I0924 12:41:38.951885    6058 eventhandlers.go:215] delete event for unscheduled pod system/default/mizar-operator-6985d77546-pxgk5
I0924 12:41:38.951952    6058 eventhandlers.go:239] add event for scheduled pod system/default/mizar-operator-6985d77546-pxgk5 
I0924 12:41:43.493103    6058 scheduler.go:576] Attempting to schedule pod: system/kube-system/coredns-default-6cfd6c6766-cqfm7
I0924 12:41:43.644712    6058 generic_scheduler.go:1052] Node master is a potential node for preemption.
I0924 12:41:43.645192    6058 factory.go:470] Unable to schedule system/kube-system/coredns-default-6cfd6c6766-cqfm7: no fit: 0/1 nodes are available: 1 node(s) runtime is not ready.; waiting
I0924 12:41:43.645271    6058 scheduler.go:787] Updating pod condition for system/kube-system/coredns-default-6cfd6c6766-cqfm7 to (PodScheduled==False, Reason=Unschedulable)
I0924 12:41:43.645352    6058 scheduler.go:576] Attempting to schedule pod: system/kube-system/kube-dns-7f4bf79dc-pvldq
I0924 12:41:43.651895    6058 generic_scheduler.go:1052] Node master is a potential node for preemption.
I0924 12:41:43.652290    6058 factory.go:470] Unable to schedule system/kube-system/kube-dns-7f4bf79dc-pvldq: no fit: 0/1 nodes are available: 1 node(s) runtime is not ready.; waiting
I0924 12:41:43.652397    6058 scheduler.go:787] Updating pod condition for system/kube-system/kube-dns-7f4bf79dc-pvldq to (PodScheduled==False, Reason=Unschedulable)
I0924 12:41:46.090613    6058 scheduler.go:576] Attempting to schedule pod: system/kube-system/kube-dns-7f4bf79dc-pvldq
I0924 12:41:46.104057    6058 generic_scheduler.go:1052] Node master is a potential node for preemption.
I0924 12:41:46.104793    6058 factory.go:470] Unable to schedule system/kube-system/kube-dns-7f4bf79dc-pvldq: no fit: 0/1 nodes are available: 1 node(s) runtime is not ready.; waiting
I0924 12:41:46.104874    6058 scheduler.go:787] Updating pod condition for system/kube-system/kube-dns-7f4bf79dc-pvldq to (PodScheduled==False, Reason=Unschedulable)
I0924 12:41:46.105440    6058 scheduler.go:576] Attempting to schedule pod: system/kube-system/coredns-default-6cfd6c6766-cqfm7
I0924 12:41:46.155651    6058 generic_scheduler.go:1052] Node master is a potential node for preemption.
I0924 12:41:46.155963    6058 factory.go:470] Unable to schedule system/kube-system/coredns-default-6cfd6c6766-cqfm7: no fit: 0/1 nodes are available: 1 node(s) runtime is not ready.; waiting
I0924 12:41:46.156025    6058 scheduler.go:787] Updating pod condition for system/kube-system/coredns-default-6cfd6c6766-cqfm7 to (PodScheduled==False, Reason=Unschedulable)
I0924 12:41:46.791062    6058 scheduler.go:576] Attempting to schedule pod: system/kube-system/coredns-default-6cfd6c6766-cqfm7
I0924 12:41:46.806501    6058 generic_scheduler.go:1052] Node master is a potential node for preemption.
I0924 12:41:46.806879    6058 factory.go:470] Unable to schedule system/kube-system/coredns-default-6cfd6c6766-cqfm7: no fit: 0/1 nodes are available: 1 node(s) runtime is not ready.; waiting
I0924 12:41:46.806997    6058 scheduler.go:787] Updating pod condition for system/kube-system/coredns-default-6cfd6c6766-cqfm7 to (PodScheduled==False, Reason=Unschedulable)
I0924 12:41:46.807550    6058 scheduler.go:576] Attempting to schedule pod: system/kube-system/kube-dns-7f4bf79dc-pvldq
I0924 12:41:46.830526    6058 generic_scheduler.go:1052] Node master is a potential node for preemption.
I0924 12:41:46.831511    6058 factory.go:470] Unable to schedule system/kube-system/kube-dns-7f4bf79dc-pvldq: no fit: 0/1 nodes are available: 1 node(s) runtime is not ready.; waiting
I0924 12:41:46.831721    6058 scheduler.go:787] Updating pod condition for system/kube-system/kube-dns-7f4bf79dc-pvldq to (PodScheduled==False, Reason=Unschedulable)
I0924 12:41:56.893808    6058 scheduler.go:576] Attempting to schedule pod: system/kube-system/coredns-default-6cfd6c6766-cqfm7
I0924 12:41:56.904648    6058 generic_scheduler.go:1052] Node master is a potential node for preemption.
I0924 12:41:56.905204    6058 factory.go:470] Unable to schedule system/kube-system/coredns-default-6cfd6c6766-cqfm7: no fit: 0/1 nodes are available: 1 node(s) runtime is not ready.; waiting
I0924 12:41:56.905336    6058 scheduler.go:787] Updating pod condition for system/kube-system/coredns-default-6cfd6c6766-cqfm7 to (PodScheduled==False, Reason=Unschedulable)
I0924 12:41:56.905859    6058 scheduler.go:576] Attempting to schedule pod: system/kube-system/kube-dns-7f4bf79dc-pvldq
I0924 12:41:56.916360    6058 generic_scheduler.go:1052] Node master is a potential node for preemption.
I0924 12:41:56.916795    6058 factory.go:470] Unable to schedule system/kube-system/kube-dns-7f4bf79dc-pvldq: no fit: 0/1 nodes are available: 1 node(s) runtime is not ready.; waiting
I0924 12:41:56.916862    6058 scheduler.go:787] Updating pod condition for system/kube-system/kube-dns-7f4bf79dc-pvldq to (PodScheduled==False, Reason=Unschedulable)
I0924 12:42:07.909517    6058 scheduler.go:576] Attempting to schedule pod: system/kube-system/coredns-default-6cfd6c6766-cqfm7
I0924 12:42:09.783880    6058 generic_scheduler.go:1052] Node master is a potential node for preemption.
I0924 12:42:09.784357    6058 factory.go:470] Unable to schedule system/kube-system/coredns-default-6cfd6c6766-cqfm7: no fit: 0/1 nodes are available: 1 node(s) runtime is not ready.; waiting
I0924 12:42:09.784431    6058 scheduler.go:787] Updating pod condition for system/kube-system/coredns-default-6cfd6c6766-cqfm7 to (PodScheduled==False, Reason=Unschedulable)
I0924 12:42:09.784629    6058 scheduler.go:576] Attempting to schedule pod: system/kube-system/kube-dns-7f4bf79dc-pvldq
E0924 12:42:09.844336    6058 factory.go:512] pod: system/kube-system/coredns-default-6cfd6c6766-cqfm7 is already present in the active queue
I0924 12:42:09.844831    6058 generic_scheduler.go:1052] Node master is a potential node for preemption.
I0924 12:42:09.845846    6058 factory.go:470] Unable to schedule system/kube-system/kube-dns-7f4bf79dc-pvldq: no fit: 0/1 nodes are available: 1 node(s) runtime is not ready.; waiting
I0924 12:42:09.846017    6058 scheduler.go:787] Updating pod condition for system/kube-system/kube-dns-7f4bf79dc-pvldq to (PodScheduled==False, Reason=Unschedulable)
I0924 12:42:09.846349    6058 scheduler.go:576] Attempting to schedule pod: system/kube-system/coredns-default-6cfd6c6766-cqfm7
I0924 12:42:09.853382    6058 generic_scheduler.go:1052] Node master is a potential node for preemption.
I0924 12:42:09.854011    6058 factory.go:470] Unable to schedule system/kube-system/coredns-default-6cfd6c6766-cqfm7: no fit: 0/1 nodes are available: 1 node(s) runtime is not ready.; waiting
I0924 12:42:09.854136    6058 scheduler.go:787] Updating pod condition for system/kube-system/coredns-default-6cfd6c6766-cqfm7 to (PodScheduled==False, Reason=Unschedulable)
I0924 12:42:10.875875    6058 scheduler.go:576] Attempting to schedule pod: system/kube-system/coredns-default-6cfd6c6766-cqfm7
I0924 12:42:19.131389    6058 generic_scheduler.go:1052] Node master is a potential node for preemption.
I0924 12:42:19.131683    6058 factory.go:470] Unable to schedule system/kube-system/coredns-default-6cfd6c6766-cqfm7: no fit: 0/1 nodes are available: 1 node(s) runtime is not ready.; waiting
I0924 12:42:19.131786    6058 scheduler.go:787] Updating pod condition for system/kube-system/coredns-default-6cfd6c6766-cqfm7 to (PodScheduled==False, Reason=Unschedulable)
I0924 12:42:19.132067    6058 scheduler.go:576] Attempting to schedule pod: system/kube-system/kube-dns-7f4bf79dc-pvldq
I0924 12:42:19.151997    6058 generic_scheduler.go:1052] Node master is a potential node for preemption.
I0924 12:42:19.152377    6058 factory.go:470] Unable to schedule system/kube-system/kube-dns-7f4bf79dc-pvldq: no fit: 0/1 nodes are available: 1 node(s) runtime is not ready.; waiting
I0924 12:42:19.152442    6058 scheduler.go:787] Updating pod condition for system/kube-system/kube-dns-7f4bf79dc-pvldq to (PodScheduled==False, Reason=Unschedulable)
I0924 12:42:21.915433    6058 scheduler.go:576] Attempting to schedule pod: system/kube-system/coredns-default-6cfd6c6766-cqfm7
I0924 12:42:21.924170    6058 generic_scheduler.go:1052] Node master is a potential node for preemption.
I0924 12:42:21.924528    6058 factory.go:470] Unable to schedule system/kube-system/coredns-default-6cfd6c6766-cqfm7: no fit: 0/1 nodes are available: 1 node(s) runtime is not ready.; waiting
I0924 12:42:21.924595    6058 scheduler.go:787] Updating pod condition for system/kube-system/coredns-default-6cfd6c6766-cqfm7 to (PodScheduled==False, Reason=Unschedulable)
I0924 12:42:26.917320    6058 scheduler.go:576] Attempting to schedule pod: system/kube-system/coredns-default-6cfd6c6766-cqfm7
I0924 12:42:26.925329    6058 generic_scheduler.go:1052] Node master is a potential node for preemption.
I0924 12:42:26.925663    6058 factory.go:470] Unable to schedule system/kube-system/coredns-default-6cfd6c6766-cqfm7: no fit: 0/1 nodes are available: 1 node(s) runtime is not ready.; waiting
I0924 12:42:26.925720    6058 scheduler.go:787] Updating pod condition for system/kube-system/coredns-default-6cfd6c6766-cqfm7 to (PodScheduled==False, Reason=Unschedulable)
I0924 12:42:31.101392    6058 scheduler.go:576] Attempting to schedule pod: system/kube-system/kube-dns-7f4bf79dc-pvldq
I0924 12:42:31.766554    6058 generic_scheduler.go:1052] Node master is a potential node for preemption.
I0924 12:42:31.767210    6058 factory.go:470] Unable to schedule system/kube-system/kube-dns-7f4bf79dc-pvldq: no fit: 0/1 nodes are available: 1 node(s) runtime is not ready.; waiting
I0924 12:42:31.767297    6058 scheduler.go:787] Updating pod condition for system/kube-system/kube-dns-7f4bf79dc-pvldq to (PodScheduled==False, Reason=Unschedulable)
I0924 12:42:34.782608    6058 scheduler.go:576] Attempting to schedule pod: system/kube-system/coredns-default-6cfd6c6766-cqfm7
I0924 12:42:35.417195    6058 generic_scheduler.go:1052] Node master is a potential node for preemption.
I0924 12:42:35.417500    6058 factory.go:470] Unable to schedule system/kube-system/coredns-default-6cfd6c6766-cqfm7: no fit: 0/1 nodes are available: 1 node(s) runtime is not ready.; waiting
I0924 12:42:35.417558    6058 scheduler.go:787] Updating pod condition for system/kube-system/coredns-default-6cfd6c6766-cqfm7 to (PodScheduled==False, Reason=Unschedulable)
I0924 12:42:35.483172    6058 scheduler.go:576] Attempting to schedule pod: system/kube-system/kube-dns-7f4bf79dc-pvldq
I0924 12:42:35.941613    6058 generic_scheduler.go:1052] Node master is a potential node for preemption.
I0924 12:42:35.941984    6058 factory.go:470] Unable to schedule system/kube-system/kube-dns-7f4bf79dc-pvldq: no fit: 0/1 nodes are available: 1 node(s) runtime is not ready.; waiting
I0924 12:42:35.942044    6058 scheduler.go:787] Updating pod condition for system/kube-system/kube-dns-7f4bf79dc-pvldq to (PodScheduled==False, Reason=Unschedulable)
I0924 12:42:39.434976    6058 scheduler.go:576] Attempting to schedule pod: system/kube-system/coredns-default-6cfd6c6766-cqfm7
I0924 12:42:42.869049    6058 generic_scheduler.go:1052] Node master is a potential node for preemption.
I0924 12:42:42.869542    6058 factory.go:470] Unable to schedule system/kube-system/coredns-default-6cfd6c6766-cqfm7: no fit: 0/1 nodes are available: 1 node(s) runtime is not ready.; waiting
I0924 12:42:42.869630    6058 scheduler.go:787] Updating pod condition for system/kube-system/coredns-default-6cfd6c6766-cqfm7 to (PodScheduled==False, Reason=Unschedulable)
I0924 12:42:45.619461    6058 scheduler.go:576] Attempting to schedule pod: system/kube-system/kube-dns-7f4bf79dc-pvldq
I0924 12:42:46.899301    6058 generic_scheduler.go:1052] Node master is a potential node for preemption.
I0924 12:42:46.899653    6058 factory.go:470] Unable to schedule system/kube-system/kube-dns-7f4bf79dc-pvldq: no fit: 0/1 nodes are available: 1 node(s) runtime is not ready.; waiting
I0924 12:42:46.899723    6058 scheduler.go:787] Updating pod condition for system/kube-system/kube-dns-7f4bf79dc-pvldq to (PodScheduled==False, Reason=Unschedulable)
I0924 12:42:56.165819    6058 scheduler.go:576] Attempting to schedule pod: system/kube-system/coredns-default-6cfd6c6766-cqfm7
I0924 12:42:56.186570    6058 generic_scheduler.go:1052] Node master is a potential node for preemption.
I0924 12:42:56.186918    6058 factory.go:470] Unable to schedule system/kube-system/coredns-default-6cfd6c6766-cqfm7: no fit: 0/1 nodes are available: 1 node(s) runtime is not ready.; waiting
I0924 12:42:56.186984    6058 scheduler.go:787] Updating pod condition for system/kube-system/coredns-default-6cfd6c6766-cqfm7 to (PodScheduled==False, Reason=Unschedulable)
I0924 12:42:58.330768    6058 scheduler.go:576] Attempting to schedule pod: system/kube-system/kube-dns-7f4bf79dc-pvldq
I0924 12:42:58.364116    6058 generic_scheduler.go:1052] Node master is a potential node for preemption.
I0924 12:42:58.364471    6058 factory.go:470] Unable to schedule system/kube-system/kube-dns-7f4bf79dc-pvldq: no fit: 0/1 nodes are available: 1 node(s) runtime is not ready.; waiting
I0924 12:42:58.364625    6058 scheduler.go:787] Updating pod condition for system/kube-system/kube-dns-7f4bf79dc-pvldq to (PodScheduled==False, Reason=Unschedulable)
I0924 12:42:59.370373    6058 scheduler.go:576] Attempting to schedule pod: system/kube-system/coredns-default-6cfd6c6766-cqfm7
I0924 12:42:59.426334    6058 generic_scheduler.go:1052] Node master is a potential node for preemption.
I0924 12:42:59.426706    6058 factory.go:470] Unable to schedule system/kube-system/coredns-default-6cfd6c6766-cqfm7: no fit: 0/1 nodes are available: 1 node(s) runtime is not ready.; waiting
I0924 12:42:59.426764    6058 scheduler.go:787] Updating pod condition for system/kube-system/coredns-default-6cfd6c6766-cqfm7 to (PodScheduled==False, Reason=Unschedulable)
I0924 12:43:04.550003    6058 scheduler.go:576] Attempting to schedule pod: system/kube-system/coredns-default-6cfd6c6766-cqfm7
I0924 12:43:05.059536    6058 generic_scheduler.go:1052] Node master is a potential node for preemption.
I0924 12:43:05.059857    6058 factory.go:470] Unable to schedule system/kube-system/coredns-default-6cfd6c6766-cqfm7: no fit: 0/1 nodes are available: 1 node(s) runtime is not ready.; waiting
I0924 12:43:05.059914    6058 scheduler.go:787] Updating pod condition for system/kube-system/coredns-default-6cfd6c6766-cqfm7 to (PodScheduled==False, Reason=Unschedulable)
I0924 12:43:05.060367    6058 scheduler.go:576] Attempting to schedule pod: system/kube-system/kube-dns-7f4bf79dc-pvldq
I0924 12:43:05.131329    6058 generic_scheduler.go:1052] Node master is a potential node for preemption.
I0924 12:43:05.131795    6058 factory.go:470] Unable to schedule system/kube-system/kube-dns-7f4bf79dc-pvldq: no fit: 0/1 nodes are available: 1 node(s) runtime is not ready.; waiting
I0924 12:43:05.131892    6058 scheduler.go:787] Updating pod condition for system/kube-system/kube-dns-7f4bf79dc-pvldq to (PodScheduled==False, Reason=Unschedulable)
I0924 12:43:08.676454    6058 scheduler.go:576] Attempting to schedule pod: system/kube-system/kube-dns-7f4bf79dc-pvldq
I0924 12:43:08.877846    6058 generic_scheduler.go:1052] Node master is a potential node for preemption.
I0924 12:43:08.878820    6058 factory.go:470] Unable to schedule system/kube-system/kube-dns-7f4bf79dc-pvldq: no fit: 0/1 nodes are available: 1 node(s) runtime is not ready.; waiting
I0924 12:43:08.878960    6058 scheduler.go:787] Updating pod condition for system/kube-system/kube-dns-7f4bf79dc-pvldq to (PodScheduled==False, Reason=Unschedulable)
I0924 12:43:15.179319    6058 scheduler.go:576] Attempting to schedule pod: system/kube-system/coredns-default-6cfd6c6766-cqfm7
I0924 12:43:15.264823    6058 generic_scheduler.go:1052] Node master is a potential node for preemption.
I0924 12:43:15.265159    6058 factory.go:470] Unable to schedule system/kube-system/coredns-default-6cfd6c6766-cqfm7: no fit: 0/1 nodes are available: 1 node(s) runtime is not ready.; waiting
I0924 12:43:15.265227    6058 scheduler.go:787] Updating pod condition for system/kube-system/coredns-default-6cfd6c6766-cqfm7 to (PodScheduled==False, Reason=Unschedulable)
I0924 12:43:19.370389    6058 scheduler.go:576] Attempting to schedule pod: system/kube-system/kube-dns-7f4bf79dc-pvldq
I0924 12:43:19.377243    6058 generic_scheduler.go:1052] Node master is a potential node for preemption.
I0924 12:43:19.377594    6058 factory.go:470] Unable to schedule system/kube-system/kube-dns-7f4bf79dc-pvldq: no fit: 0/1 nodes are available: 1 node(s) runtime is not ready.; waiting
I0924 12:43:19.377658    6058 scheduler.go:787] Updating pod condition for system/kube-system/kube-dns-7f4bf79dc-pvldq to (PodScheduled==False, Reason=Unschedulable)
I0924 12:43:24.278355    6058 scheduler.go:576] Attempting to schedule pod: system/kube-system/coredns-default-6cfd6c6766-cqfm7
I0924 12:43:24.558452    6058 generic_scheduler.go:1052] Node master is a potential node for preemption.
I0924 12:43:24.558737    6058 factory.go:470] Unable to schedule system/kube-system/coredns-default-6cfd6c6766-cqfm7: no fit: 0/1 nodes are available: 1 node(s) runtime is not ready.; waiting
I0924 12:43:24.558849    6058 scheduler.go:787] Updating pod condition for system/kube-system/coredns-default-6cfd6c6766-cqfm7 to (PodScheduled==False, Reason=Unschedulable)
I0924 12:43:28.015526    6058 scheduler.go:576] Attempting to schedule pod: system/kube-system/coredns-default-6cfd6c6766-cqfm7
I0924 12:43:28.295629    6058 generic_scheduler.go:1052] Node master is a potential node for preemption.
I0924 12:43:28.381048    6058 factory.go:470] Unable to schedule system/kube-system/coredns-default-6cfd6c6766-cqfm7: no fit: 0/1 nodes are available: 1 node(s) runtime is not ready.; waiting
I0924 12:43:28.381146    6058 scheduler.go:787] Updating pod condition for system/kube-system/coredns-default-6cfd6c6766-cqfm7 to (PodScheduled==False, Reason=Unschedulable)
I0924 12:43:28.432786    6058 scheduler.go:576] Attempting to schedule pod: system/kube-system/kube-dns-7f4bf79dc-pvldq
I0924 12:43:28.688675    6058 generic_scheduler.go:1052] Node master is a potential node for preemption.
I0924 12:43:28.693669    6058 factory.go:470] Unable to schedule system/kube-system/kube-dns-7f4bf79dc-pvldq: no fit: 0/1 nodes are available: 1 node(s) runtime is not ready.; waiting
I0924 12:43:28.693802    6058 scheduler.go:787] Updating pod condition for system/kube-system/kube-dns-7f4bf79dc-pvldq to (PodScheduled==False, Reason=Unschedulable)
I0924 12:43:31.317503    6058 scheduler.go:576] Attempting to schedule pod: system/kube-system/kube-dns-7f4bf79dc-pvldq
I0924 12:43:31.655743    6058 generic_scheduler.go:1052] Node master is a potential node for preemption.
I0924 12:43:31.656362    6058 factory.go:470] Unable to schedule system/kube-system/kube-dns-7f4bf79dc-pvldq: no fit: 0/1 nodes are available: 1 node(s) runtime is not ready.; waiting
I0924 12:43:31.656428    6058 scheduler.go:787] Updating pod condition for system/kube-system/kube-dns-7f4bf79dc-pvldq to (PodScheduled==False, Reason=Unschedulable)
I0924 12:43:39.054935    6058 scheduler.go:576] Attempting to schedule pod: system/kube-system/coredns-default-6cfd6c6766-cqfm7
I0924 12:43:39.534464    6058 generic_scheduler.go:1052] Node master is a potential node for preemption.
I0924 12:43:39.534812    6058 factory.go:470] Unable to schedule system/kube-system/coredns-default-6cfd6c6766-cqfm7: no fit: 0/1 nodes are available: 1 node(s) runtime is not ready.; waiting
I0924 12:43:39.534879    6058 scheduler.go:787] Updating pod condition for system/kube-system/coredns-default-6cfd6c6766-cqfm7 to (PodScheduled==False, Reason=Unschedulable)
I0924 12:43:42.282870    6058 scheduler.go:576] Attempting to schedule pod: system/kube-system/kube-dns-7f4bf79dc-pvldq
I0924 12:43:42.450852    6058 generic_scheduler.go:1052] Node master is a potential node for preemption.
I0924 12:43:42.451250    6058 factory.go:470] Unable to schedule system/kube-system/kube-dns-7f4bf79dc-pvldq: no fit: 0/1 nodes are available: 1 node(s) runtime is not ready.; waiting
I0924 12:43:42.451322    6058 scheduler.go:787] Updating pod condition for system/kube-system/kube-dns-7f4bf79dc-pvldq to (PodScheduled==False, Reason=Unschedulable)
I0924 12:43:47.938625    6058 scheduler.go:576] Attempting to schedule pod: system/kube-system/coredns-default-6cfd6c6766-cqfm7
I0924 12:43:49.069276    6058 generic_scheduler.go:1052] Node master is a potential node for preemption.
I0924 12:43:49.091478    6058 factory.go:470] Unable to schedule system/kube-system/coredns-default-6cfd6c6766-cqfm7: no fit: 0/1 nodes are available: 1 node(s) runtime is not ready.; waiting
I0924 12:43:49.091580    6058 scheduler.go:787] Updating pod condition for system/kube-system/coredns-default-6cfd6c6766-cqfm7 to (PodScheduled==False, Reason=Unschedulable)
I0924 12:43:52.294919    6058 scheduler.go:576] Attempting to schedule pod: system/kube-system/coredns-default-6cfd6c6766-cqfm7
I0924 12:43:52.768970    6058 generic_scheduler.go:1052] Node master is a potential node for preemption.
I0924 12:43:52.769380    6058 factory.go:470] Unable to schedule system/kube-system/coredns-default-6cfd6c6766-cqfm7: no fit: 0/1 nodes are available: 1 node(s) runtime is not ready.; waiting
I0924 12:43:52.769448    6058 scheduler.go:787] Updating pod condition for system/kube-system/coredns-default-6cfd6c6766-cqfm7 to (PodScheduled==False, Reason=Unschedulable)
I0924 12:43:52.980745    6058 scheduler.go:576] Attempting to schedule pod: system/kube-system/kube-dns-7f4bf79dc-pvldq
I0924 12:43:53.879210    6058 generic_scheduler.go:1052] Node master is a potential node for preemption.
I0924 12:43:53.879516    6058 factory.go:470] Unable to schedule system/kube-system/kube-dns-7f4bf79dc-pvldq: no fit: 0/1 nodes are available: 1 node(s) runtime is not ready.; waiting
I0924 12:43:53.879570    6058 scheduler.go:787] Updating pod condition for system/kube-system/kube-dns-7f4bf79dc-pvldq to (PodScheduled==False, Reason=Unschedulable)
I0924 12:43:56.557882    6058 scheduler.go:576] Attempting to schedule pod: system/kube-system/kube-dns-7f4bf79dc-pvldq
I0924 12:43:57.843008    6058 generic_scheduler.go:1052] Node master is a potential node for preemption.
I0924 12:43:57.843377    6058 factory.go:470] Unable to schedule system/kube-system/kube-dns-7f4bf79dc-pvldq: no fit: 0/1 nodes are available: 1 node(s) runtime is not ready.; waiting
I0924 12:43:57.843437    6058 scheduler.go:787] Updating pod condition for system/kube-system/kube-dns-7f4bf79dc-pvldq to (PodScheduled==False, Reason=Unschedulable)
I0924 12:44:03.202013    6058 scheduler.go:576] Attempting to schedule pod: system/kube-system/coredns-default-6cfd6c6766-cqfm7
I0924 12:44:04.536352    6058 generic_scheduler.go:1052] Node master is a potential node for preemption.
I0924 12:44:04.536700    6058 factory.go:470] Unable to schedule system/kube-system/coredns-default-6cfd6c6766-cqfm7: no fit: 0/1 nodes are available: 1 node(s) runtime is not ready.; waiting
I0924 12:44:04.536767    6058 scheduler.go:787] Updating pod condition for system/kube-system/coredns-default-6cfd6c6766-cqfm7 to (PodScheduled==False, Reason=Unschedulable)
I0924 12:44:09.757149    6058 scheduler.go:576] Attempting to schedule pod: system/kube-system/kube-dns-7f4bf79dc-pvldq
I0924 12:44:09.846104    6058 generic_scheduler.go:1052] Node master is a potential node for preemption.
I0924 12:44:09.846410    6058 factory.go:470] Unable to schedule system/kube-system/kube-dns-7f4bf79dc-pvldq: no fit: 0/1 nodes are available: 1 node(s) runtime is not ready.; waiting
I0924 12:44:09.846464    6058 scheduler.go:787] Updating pod condition for system/kube-system/kube-dns-7f4bf79dc-pvldq to (PodScheduled==False, Reason=Unschedulable)
I0924 12:44:12.159745    6058 scheduler.go:576] Attempting to schedule pod: system/kube-system/coredns-default-6cfd6c6766-cqfm7
I0924 12:44:12.381986    6058 generic_scheduler.go:1052] Node master is a potential node for preemption.
I0924 12:44:12.382238    6058 factory.go:470] Unable to schedule system/kube-system/coredns-default-6cfd6c6766-cqfm7: no fit: 0/1 nodes are available: 1 node(s) runtime is not ready.; waiting
I0924 12:44:12.382286    6058 scheduler.go:787] Updating pod condition for system/kube-system/coredns-default-6cfd6c6766-cqfm7 to (PodScheduled==False, Reason=Unschedulable)
I0924 12:44:15.328165    6058 scheduler.go:576] Attempting to schedule pod: system/kube-system/coredns-default-6cfd6c6766-cqfm7
I0924 12:44:15.378586    6058 generic_scheduler.go:1052] Node master is a potential node for preemption.
I0924 12:44:15.378883    6058 factory.go:470] Unable to schedule system/kube-system/coredns-default-6cfd6c6766-cqfm7: no fit: 0/1 nodes are available: 1 node(s) runtime is not ready.; waiting
I0924 12:44:15.378937    6058 scheduler.go:787] Updating pod condition for system/kube-system/coredns-default-6cfd6c6766-cqfm7 to (PodScheduled==False, Reason=Unschedulable)
I0924 12:44:20.946221    6058 scheduler.go:576] Attempting to schedule pod: system/kube-system/kube-dns-7f4bf79dc-pvldq
I0924 12:44:21.895247    6058 generic_scheduler.go:1052] Node master is a potential node for preemption.
I0924 12:44:21.895524    6058 factory.go:470] Unable to schedule system/kube-system/kube-dns-7f4bf79dc-pvldq: no fit: 0/1 nodes are available: 1 node(s) runtime is not ready.; waiting
I0924 12:44:21.895572    6058 scheduler.go:787] Updating pod condition for system/kube-system/kube-dns-7f4bf79dc-pvldq to (PodScheduled==False, Reason=Unschedulable)
I0924 12:44:21.895979    6058 scheduler.go:576] Attempting to schedule pod: system/kube-system/kube-dns-7f4bf79dc-pvldq
I0924 12:44:21.992758    6058 generic_scheduler.go:1052] Node master is a potential node for preemption.
I0924 12:44:21.993097    6058 factory.go:470] Unable to schedule system/kube-system/kube-dns-7f4bf79dc-pvldq: no fit: 0/1 nodes are available: 1 node(s) runtime is not ready.; waiting
I0924 12:44:21.993169    6058 scheduler.go:787] Updating pod condition for system/kube-system/kube-dns-7f4bf79dc-pvldq to (PodScheduled==False, Reason=Unschedulable)
E0924 12:44:22.099177    6058 factory.go:512] pod system/kube-system/kube-dns-7f4bf79dc-pvldq is already present in the backoff queue
I0924 12:44:25.496513    6058 scheduler.go:576] Attempting to schedule pod: system/kube-system/kube-dns-7f4bf79dc-pvldq
I0924 12:44:25.525236    6058 generic_scheduler.go:1052] Node master is a potential node for preemption.
I0924 12:44:25.525605    6058 factory.go:470] Unable to schedule system/kube-system/kube-dns-7f4bf79dc-pvldq: no fit: 0/1 nodes are available: 1 node(s) runtime is not ready.; waiting
I0924 12:44:25.525666    6058 scheduler.go:787] Updating pod condition for system/kube-system/kube-dns-7f4bf79dc-pvldq to (PodScheduled==False, Reason=Unschedulable)
I0924 12:44:26.030154    6058 scheduler.go:576] Attempting to schedule pod: system/kube-system/coredns-default-6cfd6c6766-cqfm7
I0924 12:44:26.181625    6058 generic_scheduler.go:1052] Node master is a potential node for preemption.
I0924 12:44:26.182166    6058 factory.go:470] Unable to schedule system/kube-system/coredns-default-6cfd6c6766-cqfm7: no fit: 0/1 nodes are available: 1 node(s) runtime is not ready.; waiting
I0924 12:44:26.182247    6058 scheduler.go:787] Updating pod condition for system/kube-system/coredns-default-6cfd6c6766-cqfm7 to (PodScheduled==False, Reason=Unschedulable)
I0924 12:44:35.628616    6058 scheduler.go:576] Attempting to schedule pod: system/kube-system/coredns-default-6cfd6c6766-cqfm7
I0924 12:44:35.801534    6058 generic_scheduler.go:1052] Node master is a potential node for preemption.
I0924 12:44:35.808376    6058 factory.go:470] Unable to schedule system/kube-system/coredns-default-6cfd6c6766-cqfm7: no fit: 0/1 nodes are available: 1 node(s) runtime is not ready.; waiting
I0924 12:44:35.808524    6058 scheduler.go:787] Updating pod condition for system/kube-system/coredns-default-6cfd6c6766-cqfm7 to (PodScheduled==False, Reason=Unschedulable)
I0924 12:44:36.478191    6058 scheduler.go:576] Attempting to schedule pod: system/kube-system/kube-dns-7f4bf79dc-pvldq
I0924 12:44:36.795558    6058 generic_scheduler.go:1052] Node master is a potential node for preemption.
I0924 12:44:36.795974    6058 factory.go:470] Unable to schedule system/kube-system/kube-dns-7f4bf79dc-pvldq: no fit: 0/1 nodes are available: 1 node(s) runtime is not ready.; waiting
I0924 12:44:36.796059    6058 scheduler.go:787] Updating pod condition for system/kube-system/kube-dns-7f4bf79dc-pvldq to (PodScheduled==False, Reason=Unschedulable)
I0924 12:44:39.377983    6058 scheduler.go:576] Attempting to schedule pod: system/kube-system/coredns-default-6cfd6c6766-cqfm7
I0924 12:44:39.689798    6058 generic_scheduler.go:1052] Node master is a potential node for preemption.
I0924 12:44:39.699872    6058 factory.go:470] Unable to schedule system/kube-system/coredns-default-6cfd6c6766-cqfm7: no fit: 0/1 nodes are available: 1 node(s) runtime is not ready.; waiting
I0924 12:44:39.700047    6058 scheduler.go:787] Updating pod condition for system/kube-system/coredns-default-6cfd6c6766-cqfm7 to (PodScheduled==False, Reason=Unschedulable)
I0924 12:44:43.357352    6058 scheduler.go:576] Attempting to schedule pod: system/kube-system/kube-dns-7f4bf79dc-pvldq
I0924 12:44:43.778726    6058 generic_scheduler.go:1052] Node master is a potential node for preemption.
I0924 12:44:43.779270    6058 factory.go:470] Unable to schedule system/kube-system/kube-dns-7f4bf79dc-pvldq: no fit: 0/1 nodes are available: 1 node(s) runtime is not ready.; waiting
I0924 12:44:43.779390    6058 scheduler.go:787] Updating pod condition for system/kube-system/kube-dns-7f4bf79dc-pvldq to (PodScheduled==False, Reason=Unschedulable)
I0924 12:44:46.347998    6058 scheduler.go:576] Attempting to schedule pod: system/kube-system/kube-dns-7f4bf79dc-pvldq
I0924 12:44:47.236489    6058 generic_scheduler.go:1052] Node master is a potential node for preemption.
I0924 12:44:47.237104    6058 factory.go:470] Unable to schedule system/kube-system/kube-dns-7f4bf79dc-pvldq: no fit: 0/1 nodes are available: 1 node(s) runtime is not ready.; waiting
I0924 12:44:47.237179    6058 scheduler.go:787] Updating pod condition for system/kube-system/kube-dns-7f4bf79dc-pvldq to (PodScheduled==False, Reason=Unschedulable)
I0924 12:44:50.273649    6058 scheduler.go:576] Attempting to schedule pod: system/kube-system/coredns-default-6cfd6c6766-cqfm7
I0924 12:44:50.387150    6058 generic_scheduler.go:1052] Node master is a potential node for preemption.
I0924 12:44:50.387489    6058 factory.go:470] Unable to schedule system/kube-system/coredns-default-6cfd6c6766-cqfm7: no fit: 0/1 nodes are available: 1 node(s) runtime is not ready.; waiting
I0924 12:44:50.387666    6058 scheduler.go:787] Updating pod condition for system/kube-system/coredns-default-6cfd6c6766-cqfm7 to (PodScheduled==False, Reason=Unschedulable)
I0924 12:44:58.075136    6058 scheduler.go:576] Attempting to schedule pod: system/kube-system/kube-dns-7f4bf79dc-pvldq
I0924 12:44:58.125762    6058 generic_scheduler.go:1052] Node master is a potential node for preemption.
I0924 12:44:58.147875    6058 factory.go:470] Unable to schedule system/kube-system/kube-dns-7f4bf79dc-pvldq: no fit: 0/1 nodes are available: 1 node(s) runtime is not ready.; waiting
I0924 12:44:58.148012    6058 scheduler.go:787] Updating pod condition for system/kube-system/kube-dns-7f4bf79dc-pvldq to (PodScheduled==False, Reason=Unschedulable)
I0924 12:44:59.191051    6058 scheduler.go:576] Attempting to schedule pod: system/kube-system/coredns-default-6cfd6c6766-cqfm7
I0924 12:44:59.290864    6058 generic_scheduler.go:1052] Node master is a potential node for preemption.
I0924 12:44:59.291195    6058 factory.go:470] Unable to schedule system/kube-system/coredns-default-6cfd6c6766-cqfm7: no fit: 0/1 nodes are available: 1 node(s) runtime is not ready.; waiting
I0924 12:44:59.291270    6058 scheduler.go:787] Updating pod condition for system/kube-system/coredns-default-6cfd6c6766-cqfm7 to (PodScheduled==False, Reason=Unschedulable)
I0924 12:45:02.687113    6058 scheduler.go:576] Attempting to schedule pod: system/kube-system/coredns-default-6cfd6c6766-cqfm7
I0924 12:45:02.919411    6058 generic_scheduler.go:1052] Node master is a potential node for preemption.
I0924 12:45:02.920059    6058 factory.go:470] Unable to schedule system/kube-system/coredns-default-6cfd6c6766-cqfm7: no fit: 0/1 nodes are available: 1 node(s) runtime is not ready.; waiting
I0924 12:45:02.920171    6058 scheduler.go:787] Updating pod condition for system/kube-system/coredns-default-6cfd6c6766-cqfm7 to (PodScheduled==False, Reason=Unschedulable)
I0924 12:45:08.969569    6058 scheduler.go:576] Attempting to schedule pod: system/kube-system/kube-dns-7f4bf79dc-pvldq
I0924 12:45:09.057238    6058 generic_scheduler.go:1052] Node master is a potential node for preemption.
I0924 12:45:09.057579    6058 factory.go:470] Unable to schedule system/kube-system/kube-dns-7f4bf79dc-pvldq: no fit: 0/1 nodes are available: 1 node(s) runtime is not ready.; waiting
I0924 12:45:09.057634    6058 scheduler.go:787] Updating pod condition for system/kube-system/kube-dns-7f4bf79dc-pvldq to (PodScheduled==False, Reason=Unschedulable)
I0924 12:45:10.242832    6058 scheduler.go:576] Attempting to schedule pod: system/kube-system/kube-dns-7f4bf79dc-pvldq
I0924 12:45:12.632839    6058 generic_scheduler.go:1052] Node master is a potential node for preemption.
I0924 12:45:12.634489    6058 factory.go:470] Unable to schedule system/kube-system/kube-dns-7f4bf79dc-pvldq: no fit: 0/1 nodes are available: 1 node(s) runtime is not ready.; waiting
I0924 12:45:12.637596    6058 scheduler.go:787] Updating pod condition for system/kube-system/kube-dns-7f4bf79dc-pvldq to (PodScheduled==False, Reason=Unschedulable)
I0924 12:45:14.666356    6058 scheduler.go:576] Attempting to schedule pod: system/kube-system/coredns-default-6cfd6c6766-cqfm7
I0924 12:45:14.899725    6058 generic_scheduler.go:1052] Node master is a potential node for preemption.
I0924 12:45:14.900236    6058 factory.go:470] Unable to schedule system/kube-system/coredns-default-6cfd6c6766-cqfm7: no fit: 0/1 nodes are available: 1 node(s) runtime is not ready.; waiting
I0924 12:45:14.900324    6058 scheduler.go:787] Updating pod condition for system/kube-system/coredns-default-6cfd6c6766-cqfm7 to (PodScheduled==False, Reason=Unschedulable)
I0924 12:45:22.511501    6058 scheduler.go:576] Attempting to schedule pod: system/kube-system/coredns-default-6cfd6c6766-cqfm7
I0924 12:45:22.526674    6058 generic_scheduler.go:1052] Node master is a potential node for preemption.
I0924 12:45:22.527051    6058 factory.go:470] Unable to schedule system/kube-system/coredns-default-6cfd6c6766-cqfm7: no fit: 0/1 nodes are available: 1 node(s) runtime is not ready.; waiting
I0924 12:45:22.527118    6058 scheduler.go:787] Updating pod condition for system/kube-system/coredns-default-6cfd6c6766-cqfm7 to (PodScheduled==False, Reason=Unschedulable)
I0924 12:45:23.277120    6058 scheduler.go:576] Attempting to schedule pod: system/kube-system/kube-dns-7f4bf79dc-pvldq
I0924 12:45:24.423246    6058 generic_scheduler.go:1052] Node master is a potential node for preemption.
I0924 12:45:24.423600    6058 factory.go:470] Unable to schedule system/kube-system/kube-dns-7f4bf79dc-pvldq: no fit: 0/1 nodes are available: 1 node(s) runtime is not ready.; waiting
I0924 12:45:24.423664    6058 scheduler.go:787] Updating pod condition for system/kube-system/kube-dns-7f4bf79dc-pvldq to (PodScheduled==False, Reason=Unschedulable)
I0924 12:45:26.357288    6058 scheduler.go:576] Attempting to schedule pod: system/kube-system/coredns-default-6cfd6c6766-cqfm7
I0924 12:45:27.717918    6058 generic_scheduler.go:1052] Node master is a potential node for preemption.
I0924 12:45:27.718917    6058 factory.go:470] Unable to schedule system/kube-system/coredns-default-6cfd6c6766-cqfm7: no fit: 0/1 nodes are available: 1 node(s) runtime is not ready.; waiting
I0924 12:45:27.719178    6058 scheduler.go:787] Updating pod condition for system/kube-system/coredns-default-6cfd6c6766-cqfm7 to (PodScheduled==False, Reason=Unschedulable)
I0924 12:45:33.413157    6058 scheduler.go:576] Attempting to schedule pod: system/kube-system/kube-dns-7f4bf79dc-pvldq
I0924 12:45:33.707731    6058 generic_scheduler.go:1052] Node master is a potential node for preemption.
I0924 12:45:33.708590    6058 factory.go:470] Unable to schedule system/kube-system/kube-dns-7f4bf79dc-pvldq: no fit: 0/1 nodes are available: 1 node(s) runtime is not ready.; waiting
I0924 12:45:33.708665    6058 scheduler.go:787] Updating pod condition for system/kube-system/kube-dns-7f4bf79dc-pvldq to (PodScheduled==False, Reason=Unschedulable)
I0924 12:45:36.216052    6058 scheduler.go:576] Attempting to schedule pod: system/kube-system/kube-dns-7f4bf79dc-pvldq
I0924 12:45:36.375366    6058 generic_scheduler.go:1052] Node master is a potential node for preemption.
I0924 12:45:36.375694    6058 factory.go:470] Unable to schedule system/kube-system/kube-dns-7f4bf79dc-pvldq: no fit: 0/1 nodes are available: 1 node(s) runtime is not ready.; waiting
I0924 12:45:36.375752    6058 scheduler.go:787] Updating pod condition for system/kube-system/kube-dns-7f4bf79dc-pvldq to (PodScheduled==False, Reason=Unschedulable)
I0924 12:45:38.598327    6058 scheduler.go:576] Attempting to schedule pod: system/kube-system/coredns-default-6cfd6c6766-cqfm7
I0924 12:45:38.762942    6058 generic_scheduler.go:1052] Node master is a potential node for preemption.
I0924 12:45:38.763305    6058 factory.go:470] Unable to schedule system/kube-system/coredns-default-6cfd6c6766-cqfm7: no fit: 0/1 nodes are available: 1 node(s) runtime is not ready.; waiting
I0924 12:45:38.763371    6058 scheduler.go:787] Updating pod condition for system/kube-system/coredns-default-6cfd6c6766-cqfm7 to (PodScheduled==False, Reason=Unschedulable)
I0924 12:45:44.456532    6058 scheduler.go:576] Attempting to schedule pod: system/kube-system/coredns-default-6cfd6c6766-cqfm7
I0924 12:45:45.011671    6058 generic_scheduler.go:1052] Node master is a potential node for preemption.
I0924 12:45:45.012190    6058 factory.go:470] Unable to schedule system/kube-system/coredns-default-6cfd6c6766-cqfm7: no fit: 0/1 nodes are available: 1 node(s) runtime is not ready.; waiting
I0924 12:45:45.012305    6058 scheduler.go:787] Updating pod condition for system/kube-system/coredns-default-6cfd6c6766-cqfm7 to (PodScheduled==False, Reason=Unschedulable)
I0924 12:45:47.158933    6058 scheduler.go:576] Attempting to schedule pod: system/kube-system/coredns-default-6cfd6c6766-cqfm7
I0924 12:45:47.534844    6058 generic_scheduler.go:1052] Node master is a potential node for preemption.
I0924 12:45:47.535194    6058 factory.go:470] Unable to schedule system/kube-system/coredns-default-6cfd6c6766-cqfm7: no fit: 0/1 nodes are available: 1 node(s) runtime is not ready.; waiting
I0924 12:45:47.535272    6058 scheduler.go:787] Updating pod condition for system/kube-system/coredns-default-6cfd6c6766-cqfm7 to (PodScheduled==False, Reason=Unschedulable)
I0924 12:45:47.537078    6058 scheduler.go:576] Attempting to schedule pod: system/kube-system/kube-dns-7f4bf79dc-pvldq
I0924 12:45:47.885182    6058 generic_scheduler.go:1052] Node master is a potential node for preemption.
I0924 12:45:47.978392    6058 factory.go:470] Unable to schedule system/kube-system/kube-dns-7f4bf79dc-pvldq: no fit: 0/1 nodes are available: 1 node(s) runtime is not ready.; waiting
I0924 12:45:47.978586    6058 scheduler.go:787] Updating pod condition for system/kube-system/kube-dns-7f4bf79dc-pvldq to (PodScheduled==False, Reason=Unschedulable)
I0924 12:45:57.838784    6058 scheduler.go:576] Attempting to schedule pod: system/kube-system/kube-dns-7f4bf79dc-pvldq
I0924 12:45:59.167589    6058 generic_scheduler.go:1052] Node master is a potential node for preemption.
I0924 12:45:59.168154    6058 factory.go:470] Unable to schedule system/kube-system/kube-dns-7f4bf79dc-pvldq: no fit: 0/1 nodes are available: 1 node(s) runtime is not ready.; waiting
I0924 12:45:59.168268    6058 scheduler.go:787] Updating pod condition for system/kube-system/kube-dns-7f4bf79dc-pvldq to (PodScheduled==False, Reason=Unschedulable)
I0924 12:45:59.219138    6058 scheduler.go:576] Attempting to schedule pod: system/kube-system/coredns-default-6cfd6c6766-cqfm7
I0924 12:45:59.593093    6058 generic_scheduler.go:1052] Node master is a potential node for preemption.
I0924 12:45:59.593441    6058 factory.go:470] Unable to schedule system/kube-system/coredns-default-6cfd6c6766-cqfm7: no fit: 0/1 nodes are available: 1 node(s) runtime is not ready.; waiting
I0924 12:45:59.593507    6058 scheduler.go:787] Updating pod condition for system/kube-system/coredns-default-6cfd6c6766-cqfm7 to (PodScheduled==False, Reason=Unschedulable)
I0924 12:46:00.545391    6058 scheduler.go:576] Attempting to schedule pod: system/kube-system/kube-dns-7f4bf79dc-pvldq
I0924 12:46:00.590339    6058 generic_scheduler.go:1052] Node master is a potential node for preemption.
I0924 12:46:00.590667    6058 factory.go:470] Unable to schedule system/kube-system/kube-dns-7f4bf79dc-pvldq: no fit: 0/1 nodes are available: 1 node(s) runtime is not ready.; waiting
I0924 12:46:00.590721    6058 scheduler.go:787] Updating pod condition for system/kube-system/kube-dns-7f4bf79dc-pvldq to (PodScheduled==False, Reason=Unschedulable)
I0924 12:46:07.988445    6058 scheduler.go:576] Attempting to schedule pod: system/kube-system/coredns-default-6cfd6c6766-cqfm7
I0924 12:46:08.932361    6058 generic_scheduler.go:1052] Node master is a potential node for preemption.
I0924 12:46:08.932710    6058 factory.go:470] Unable to schedule system/kube-system/coredns-default-6cfd6c6766-cqfm7: no fit: 0/1 nodes are available: 1 node(s) runtime is not ready.; waiting
I0924 12:46:08.932779    6058 scheduler.go:787] Updating pod condition for system/kube-system/coredns-default-6cfd6c6766-cqfm7 to (PodScheduled==False, Reason=Unschedulable)
I0924 12:46:12.512538    6058 scheduler.go:576] Attempting to schedule pod: system/kube-system/kube-dns-7f4bf79dc-pvldq
I0924 12:46:16.146871    6058 generic_scheduler.go:1052] Node master is a potential node for preemption.
I0924 12:46:16.147464    6058 factory.go:470] Unable to schedule system/kube-system/kube-dns-7f4bf79dc-pvldq: no fit: 0/1 nodes are available: 1 node(s) runtime is not ready.; waiting
I0924 12:46:16.147597    6058 scheduler.go:787] Updating pod condition for system/kube-system/kube-dns-7f4bf79dc-pvldq to (PodScheduled==False, Reason=Unschedulable)
I0924 12:46:16.147734    6058 scheduler.go:576] Attempting to schedule pod: system/kube-system/coredns-default-6cfd6c6766-cqfm7
I0924 12:46:16.499458    6058 generic_scheduler.go:1052] Node master is a potential node for preemption.
I0924 12:46:16.499753    6058 factory.go:470] Unable to schedule system/kube-system/coredns-default-6cfd6c6766-cqfm7: no fit: 0/1 nodes are available: 1 node(s) runtime is not ready.; waiting
I0924 12:46:16.499806    6058 scheduler.go:787] Updating pod condition for system/kube-system/coredns-default-6cfd6c6766-cqfm7 to (PodScheduled==False, Reason=Unschedulable)
I0924 12:46:22.540432    6058 scheduler.go:576] Attempting to schedule pod: system/kube-system/kube-dns-7f4bf79dc-pvldq
I0924 12:46:23.090378    6058 generic_scheduler.go:1052] Node master is a potential node for preemption.
I0924 12:46:23.090716    6058 factory.go:470] Unable to schedule system/kube-system/kube-dns-7f4bf79dc-pvldq: no fit: 0/1 nodes are available: 1 node(s) runtime is not ready.; waiting
I0924 12:46:23.090784    6058 scheduler.go:787] Updating pod condition for system/kube-system/kube-dns-7f4bf79dc-pvldq to (PodScheduled==False, Reason=Unschedulable)
I0924 12:46:25.214799    6058 scheduler.go:576] Attempting to schedule pod: system/kube-system/kube-dns-7f4bf79dc-pvldq
I0924 12:46:25.304189    6058 generic_scheduler.go:1052] Node master is a potential node for preemption.
I0924 12:46:25.304739    6058 factory.go:470] Unable to schedule system/kube-system/kube-dns-7f4bf79dc-pvldq: no fit: 0/1 nodes are available: 1 node(s) runtime is not ready.; waiting
I0924 12:46:25.304833    6058 scheduler.go:787] Updating pod condition for system/kube-system/kube-dns-7f4bf79dc-pvldq to (PodScheduled==False, Reason=Unschedulable)
I0924 12:46:27.218472    6058 scheduler.go:576] Attempting to schedule pod: system/kube-system/coredns-default-6cfd6c6766-cqfm7
I0924 12:46:27.346878    6058 generic_scheduler.go:1052] Node master is a potential node for preemption.
I0924 12:46:27.347948    6058 factory.go:470] Unable to schedule system/kube-system/coredns-default-6cfd6c6766-cqfm7: no fit: 0/1 nodes are available: 1 node(s) runtime is not ready.; waiting
I0924 12:46:27.348044    6058 scheduler.go:787] Updating pod condition for system/kube-system/coredns-default-6cfd6c6766-cqfm7 to (PodScheduled==False, Reason=Unschedulable)
I0924 12:46:33.282545    6058 scheduler.go:576] Attempting to schedule pod: system/kube-system/coredns-default-6cfd6c6766-cqfm7
I0924 12:46:33.440687    6058 generic_scheduler.go:1052] Node master is a potential node for preemption.
I0924 12:46:33.441108    6058 factory.go:470] Unable to schedule system/kube-system/coredns-default-6cfd6c6766-cqfm7: no fit: 0/1 nodes are available: 1 node(s) runtime is not ready.; waiting
I0924 12:46:33.441178    6058 scheduler.go:787] Updating pod condition for system/kube-system/coredns-default-6cfd6c6766-cqfm7 to (PodScheduled==False, Reason=Unschedulable)
I0924 12:46:36.368249    6058 scheduler.go:576] Attempting to schedule pod: system/kube-system/kube-dns-7f4bf79dc-pvldq
I0924 12:46:36.533507    6058 generic_scheduler.go:1052] Node master is a potential node for preemption.
I0924 12:46:36.534176    6058 factory.go:470] Unable to schedule system/kube-system/kube-dns-7f4bf79dc-pvldq: no fit: 0/1 nodes are available: 1 node(s) runtime is not ready.; waiting
I0924 12:46:36.534321    6058 scheduler.go:787] Updating pod condition for system/kube-system/kube-dns-7f4bf79dc-pvldq to (PodScheduled==False, Reason=Unschedulable)
I0924 12:46:38.208065    6058 scheduler.go:576] Attempting to schedule pod: system/kube-system/coredns-default-6cfd6c6766-cqfm7
I0924 12:46:38.458515    6058 generic_scheduler.go:1052] Node master is a potential node for preemption.
I0924 12:46:38.458855    6058 factory.go:470] Unable to schedule system/kube-system/coredns-default-6cfd6c6766-cqfm7: no fit: 0/1 nodes are available: 1 node(s) runtime is not ready.; waiting
I0924 12:46:38.458924    6058 scheduler.go:787] Updating pod condition for system/kube-system/coredns-default-6cfd6c6766-cqfm7 to (PodScheduled==False, Reason=Unschedulable)
I0924 12:46:45.140209    6058 scheduler.go:576] Attempting to schedule pod: system/kube-system/kube-dns-7f4bf79dc-pvldq
I0924 12:46:46.134145    6058 generic_scheduler.go:1052] Node master is a potential node for preemption.
I0924 12:46:46.134531    6058 factory.go:470] Unable to schedule system/kube-system/kube-dns-7f4bf79dc-pvldq: no fit: 0/1 nodes are available: 1 node(s) runtime is not ready.; waiting
I0924 12:46:46.134606    6058 scheduler.go:787] Updating pod condition for system/kube-system/kube-dns-7f4bf79dc-pvldq to (PodScheduled==False, Reason=Unschedulable)
I0924 12:46:46.138309    6058 eventhandlers.go:183] add event for unscheduled pod system/default/mizar-operator-6985d77546-2nd82
I0924 12:46:46.138449    6058 scheduler.go:576] Attempting to schedule pod: system/default/mizar-operator-6985d77546-2nd82
I0924 12:46:46.138875    6058 default_binder.go:53] Attempting to bind system/default/mizar-operator-6985d77546-2nd82 to master
I0924 12:46:46.437919    6058 eventhandlers.go:215] delete event for unscheduled pod system/default/mizar-operator-6985d77546-2nd82
I0924 12:46:46.438057    6058 eventhandlers.go:239] add event for scheduled pod system/default/mizar-operator-6985d77546-2nd82 
I0924 12:46:46.802877    6058 scheduler.go:741] pod system/default/mizar-operator-6985d77546-2nd82 is bound successfully on node "master", 1 nodes evaluated, 1 nodes were found feasible.
I0924 12:46:48.594096    6058 eventhandlers.go:308] delete event for scheduled pod system/default/mizar-operator-6985d77546-pxgk5 
I0924 12:46:49.228886    6058 scheduler.go:576] Attempting to schedule pod: system/kube-system/coredns-default-6cfd6c6766-cqfm7
I0924 12:46:49.493274    6058 generic_scheduler.go:1052] Node master is a potential node for preemption.
I0924 12:46:49.655289    6058 factory.go:470] Unable to schedule system/kube-system/coredns-default-6cfd6c6766-cqfm7: no fit: 0/1 nodes are available: 1 node(s) runtime is not ready.; waiting
I0924 12:46:49.655478    6058 scheduler.go:787] Updating pod condition for system/kube-system/coredns-default-6cfd6c6766-cqfm7 to (PodScheduled==False, Reason=Unschedulable)
I0924 12:46:56.816773    6058 scheduler.go:576] Attempting to schedule pod: system/kube-system/kube-dns-7f4bf79dc-pvldq
I0924 12:46:56.843177    6058 generic_scheduler.go:1052] Node master is a potential node for preemption.
I0924 12:46:56.843634    6058 factory.go:470] Unable to schedule system/kube-system/kube-dns-7f4bf79dc-pvldq: no fit: 0/1 nodes are available: 1 node(s) runtime is not ready.; waiting
I0924 12:46:56.843702    6058 scheduler.go:787] Updating pod condition for system/kube-system/kube-dns-7f4bf79dc-pvldq to (PodScheduled==False, Reason=Unschedulable)
I0924 12:47:00.428493    6058 scheduler.go:576] Attempting to schedule pod: system/kube-system/coredns-default-6cfd6c6766-cqfm7
I0924 12:47:00.486549    6058 generic_scheduler.go:1052] Node master is a potential node for preemption.
I0924 12:47:00.798093    6058 factory.go:470] Unable to schedule system/kube-system/coredns-default-6cfd6c6766-cqfm7: no fit: 0/1 nodes are available: 1 node(s) runtime is not ready.; waiting
I0924 12:47:00.798299    6058 scheduler.go:787] Updating pod condition for system/kube-system/coredns-default-6cfd6c6766-cqfm7 to (PodScheduled==False, Reason=Unschedulable)
I0924 12:47:07.817492    6058 scheduler.go:576] Attempting to schedule pod: system/kube-system/kube-dns-7f4bf79dc-pvldq
I0924 12:47:08.078655    6058 generic_scheduler.go:1052] Node master is a potential node for preemption.
I0924 12:47:08.079082    6058 factory.go:470] Unable to schedule system/kube-system/kube-dns-7f4bf79dc-pvldq: no fit: 0/1 nodes are available: 1 node(s) runtime is not ready.; waiting
I0924 12:47:08.079139    6058 scheduler.go:787] Updating pod condition for system/kube-system/kube-dns-7f4bf79dc-pvldq to (PodScheduled==False, Reason=Unschedulable)
I0924 12:47:12.073896    6058 scheduler.go:576] Attempting to schedule pod: system/kube-system/coredns-default-6cfd6c6766-cqfm7
I0924 12:47:12.745672    6058 generic_scheduler.go:1052] Node master is a potential node for preemption.
I0924 12:47:12.746018    6058 factory.go:470] Unable to schedule system/kube-system/coredns-default-6cfd6c6766-cqfm7: no fit: 0/1 nodes are available: 1 node(s) runtime is not ready.; waiting
I0924 12:47:12.746074    6058 scheduler.go:787] Updating pod condition for system/kube-system/coredns-default-6cfd6c6766-cqfm7 to (PodScheduled==False, Reason=Unschedulable)
I0924 12:47:19.458904    6058 scheduler.go:576] Attempting to schedule pod: system/kube-system/kube-dns-7f4bf79dc-pvldq
I0924 12:47:19.471330    6058 generic_scheduler.go:1052] Node master is a potential node for preemption.
I0924 12:47:19.471675    6058 factory.go:470] Unable to schedule system/kube-system/kube-dns-7f4bf79dc-pvldq: no fit: 0/1 nodes are available: 1 node(s) runtime is not ready.; waiting
I0924 12:47:19.471738    6058 scheduler.go:787] Updating pod condition for system/kube-system/kube-dns-7f4bf79dc-pvldq to (PodScheduled==False, Reason=Unschedulable)
I0924 12:47:22.807589    6058 scheduler.go:576] Attempting to schedule pod: system/kube-system/coredns-default-6cfd6c6766-cqfm7
I0924 12:47:22.961311    6058 generic_scheduler.go:1052] Node master is a potential node for preemption.
I0924 12:47:22.961676    6058 factory.go:470] Unable to schedule system/kube-system/coredns-default-6cfd6c6766-cqfm7: no fit: 0/1 nodes are available: 1 node(s) runtime is not ready.; waiting
I0924 12:47:22.961775    6058 scheduler.go:787] Updating pod condition for system/kube-system/coredns-default-6cfd6c6766-cqfm7 to (PodScheduled==False, Reason=Unschedulable)
I0924 12:47:29.738029    6058 scheduler.go:576] Attempting to schedule pod: system/kube-system/kube-dns-7f4bf79dc-pvldq
I0924 12:47:30.371444    6058 generic_scheduler.go:1052] Node master is a potential node for preemption.
I0924 12:47:30.371996    6058 factory.go:470] Unable to schedule system/kube-system/kube-dns-7f4bf79dc-pvldq: no fit: 0/1 nodes are available: 1 node(s) runtime is not ready.; waiting
I0924 12:47:30.372067    6058 scheduler.go:787] Updating pod condition for system/kube-system/kube-dns-7f4bf79dc-pvldq to (PodScheduled==False, Reason=Unschedulable)
I0924 12:47:34.066750    6058 scheduler.go:576] Attempting to schedule pod: system/kube-system/coredns-default-6cfd6c6766-cqfm7
I0924 12:47:34.455256    6058 generic_scheduler.go:1052] Node master is a potential node for preemption.
I0924 12:47:34.455712    6058 factory.go:470] Unable to schedule system/kube-system/coredns-default-6cfd6c6766-cqfm7: no fit: 0/1 nodes are available: 1 node(s) runtime is not ready.; waiting
I0924 12:47:34.455785    6058 scheduler.go:787] Updating pod condition for system/kube-system/coredns-default-6cfd6c6766-cqfm7 to (PodScheduled==False, Reason=Unschedulable)
I0924 12:47:41.289558    6058 scheduler.go:576] Attempting to schedule pod: system/kube-system/kube-dns-7f4bf79dc-pvldq
I0924 12:47:41.417589    6058 generic_scheduler.go:1052] Node master is a potential node for preemption.
I0924 12:47:41.418768    6058 factory.go:470] Unable to schedule system/kube-system/kube-dns-7f4bf79dc-pvldq: no fit: 0/1 nodes are available: 1 node(s) runtime is not ready.; waiting
I0924 12:47:41.418894    6058 scheduler.go:787] Updating pod condition for system/kube-system/kube-dns-7f4bf79dc-pvldq to (PodScheduled==False, Reason=Unschedulable)
I0924 12:47:45.645967    6058 scheduler.go:576] Attempting to schedule pod: system/kube-system/coredns-default-6cfd6c6766-cqfm7
I0924 12:47:45.882513    6058 generic_scheduler.go:1052] Node master is a potential node for preemption.
I0924 12:47:45.882827    6058 factory.go:470] Unable to schedule system/kube-system/coredns-default-6cfd6c6766-cqfm7: no fit: 0/1 nodes are available: 1 node(s) runtime is not ready.; waiting
I0924 12:47:45.882885    6058 scheduler.go:787] Updating pod condition for system/kube-system/coredns-default-6cfd6c6766-cqfm7 to (PodScheduled==False, Reason=Unschedulable)
I0924 12:47:51.678506    6058 scheduler.go:576] Attempting to schedule pod: system/kube-system/kube-dns-7f4bf79dc-pvldq
I0924 12:47:51.872643    6058 generic_scheduler.go:1052] Node master is a potential node for preemption.
I0924 12:47:51.873125    6058 factory.go:470] Unable to schedule system/kube-system/kube-dns-7f4bf79dc-pvldq: no fit: 0/1 nodes are available: 1 node(s) runtime is not ready.; waiting
I0924 12:47:51.880613    6058 scheduler.go:787] Updating pod condition for system/kube-system/kube-dns-7f4bf79dc-pvldq to (PodScheduled==False, Reason=Unschedulable)
I0924 12:47:56.331216    6058 scheduler.go:576] Attempting to schedule pod: system/kube-system/coredns-default-6cfd6c6766-cqfm7
I0924 12:47:56.692733    6058 generic_scheduler.go:1052] Node master is a potential node for preemption.
I0924 12:47:56.693030    6058 factory.go:470] Unable to schedule system/kube-system/coredns-default-6cfd6c6766-cqfm7: no fit: 0/1 nodes are available: 1 node(s) runtime is not ready.; waiting
I0924 12:47:56.693079    6058 scheduler.go:787] Updating pod condition for system/kube-system/coredns-default-6cfd6c6766-cqfm7 to (PodScheduled==False, Reason=Unschedulable)
I0924 12:48:03.448091    6058 scheduler.go:576] Attempting to schedule pod: system/kube-system/kube-dns-7f4bf79dc-pvldq
I0924 12:48:03.870378    6058 generic_scheduler.go:1052] Node master is a potential node for preemption.
I0924 12:48:03.870698    6058 factory.go:470] Unable to schedule system/kube-system/kube-dns-7f4bf79dc-pvldq: no fit: 0/1 nodes are available: 1 node(s) runtime is not ready.; waiting
I0924 12:48:03.870757    6058 scheduler.go:787] Updating pod condition for system/kube-system/kube-dns-7f4bf79dc-pvldq to (PodScheduled==False, Reason=Unschedulable)
I0924 12:48:06.961863    6058 scheduler.go:576] Attempting to schedule pod: system/kube-system/coredns-default-6cfd6c6766-cqfm7
I0924 12:48:07.949362    6058 generic_scheduler.go:1052] Node master is a potential node for preemption.
I0924 12:48:07.949673    6058 factory.go:470] Unable to schedule system/kube-system/coredns-default-6cfd6c6766-cqfm7: no fit: 0/1 nodes are available: 1 node(s) runtime is not ready.; waiting
I0924 12:48:07.949764    6058 scheduler.go:787] Updating pod condition for system/kube-system/coredns-default-6cfd6c6766-cqfm7 to (PodScheduled==False, Reason=Unschedulable)
I0924 12:48:14.342309    6058 scheduler.go:576] Attempting to schedule pod: system/kube-system/kube-dns-7f4bf79dc-pvldq
I0924 12:48:14.540430    6058 generic_scheduler.go:1052] Node master is a potential node for preemption.
I0924 12:48:14.541482    6058 factory.go:470] Unable to schedule system/kube-system/kube-dns-7f4bf79dc-pvldq: no fit: 0/1 nodes are available: 1 node(s) runtime is not ready.; waiting
I0924 12:48:14.543339    6058 scheduler.go:787] Updating pod condition for system/kube-system/kube-dns-7f4bf79dc-pvldq to (PodScheduled==False, Reason=Unschedulable)
I0924 12:48:19.239545    6058 scheduler.go:576] Attempting to schedule pod: system/kube-system/coredns-default-6cfd6c6766-cqfm7
I0924 12:48:19.358542    6058 generic_scheduler.go:1052] Node master is a potential node for preemption.
I0924 12:48:19.358874    6058 factory.go:470] Unable to schedule system/kube-system/coredns-default-6cfd6c6766-cqfm7: no fit: 0/1 nodes are available: 1 node(s) runtime is not ready.; waiting
I0924 12:48:19.358931    6058 scheduler.go:787] Updating pod condition for system/kube-system/coredns-default-6cfd6c6766-cqfm7 to (PodScheduled==False, Reason=Unschedulable)
I0924 12:48:25.543046    6058 scheduler.go:576] Attempting to schedule pod: system/kube-system/kube-dns-7f4bf79dc-pvldq
I0924 12:48:26.409502    6058 generic_scheduler.go:1052] Node master is a potential node for preemption.
I0924 12:48:26.409898    6058 factory.go:470] Unable to schedule system/kube-system/kube-dns-7f4bf79dc-pvldq: no fit: 0/1 nodes are available: 1 node(s) runtime is not ready.; waiting
I0924 12:48:26.409962    6058 scheduler.go:787] Updating pod condition for system/kube-system/kube-dns-7f4bf79dc-pvldq to (PodScheduled==False, Reason=Unschedulable)
I0924 12:48:30.973395    6058 scheduler.go:576] Attempting to schedule pod: system/kube-system/coredns-default-6cfd6c6766-cqfm7
I0924 12:48:31.298373    6058 generic_scheduler.go:1052] Node master is a potential node for preemption.
I0924 12:48:31.298685    6058 factory.go:470] Unable to schedule system/kube-system/coredns-default-6cfd6c6766-cqfm7: no fit: 0/1 nodes are available: 1 node(s) runtime is not ready.; waiting
I0924 12:48:31.298740    6058 scheduler.go:787] Updating pod condition for system/kube-system/coredns-default-6cfd6c6766-cqfm7 to (PodScheduled==False, Reason=Unschedulable)
I0924 12:48:35.972084    6058 scheduler.go:576] Attempting to schedule pod: system/kube-system/coredns-default-6cfd6c6766-cqfm7
I0924 12:48:36.595539    6058 trace.go:81] Trace[1889866052]: "Scheduling system/kube-system/coredns-default-6cfd6c6766-cqfm7" (started: 2021-09-24 12:48:35.972152601 +0000 UTC m=+440.105591855) (total time: 623.27245ms):
Trace[1889866052]: [623.177667ms] [623.155336ms] Running prefilter plugins done
I0924 12:48:36.645637    6058 generic_scheduler.go:1052] Node master is a potential node for preemption.
I0924 12:48:36.663992    6058 factory.go:470] Unable to schedule system/kube-system/coredns-default-6cfd6c6766-cqfm7: no fit: 0/1 nodes are available: 1 node(s) runtime is not ready.; waiting
I0924 12:48:36.664169    6058 scheduler.go:787] Updating pod condition for system/kube-system/coredns-default-6cfd6c6766-cqfm7 to (PodScheduled==False, Reason=Unschedulable)
I0924 12:48:36.884755    6058 scheduler.go:576] Attempting to schedule pod: system/kube-system/kube-dns-7f4bf79dc-pvldq
I0924 12:48:37.040038    6058 generic_scheduler.go:1052] Node master is a potential node for preemption.
I0924 12:48:37.040348    6058 factory.go:470] Unable to schedule system/kube-system/kube-dns-7f4bf79dc-pvldq: no fit: 0/1 nodes are available: 1 node(s) runtime is not ready.; waiting
I0924 12:48:37.040433    6058 scheduler.go:787] Updating pod condition for system/kube-system/kube-dns-7f4bf79dc-pvldq to (PodScheduled==False, Reason=Unschedulable)
I0924 12:48:43.398518    6058 scheduler.go:576] Attempting to schedule pod: system/kube-system/coredns-default-6cfd6c6766-cqfm7
I0924 12:48:43.645622    6058 generic_scheduler.go:1052] Node master is a potential node for preemption.
I0924 12:48:43.653140    6058 factory.go:470] Unable to schedule system/kube-system/coredns-default-6cfd6c6766-cqfm7: no fit: 0/1 nodes are available: 1 node(s) runtime is not ready.; waiting
I0924 12:48:43.653362    6058 scheduler.go:787] Updating pod condition for system/kube-system/coredns-default-6cfd6c6766-cqfm7 to (PodScheduled==False, Reason=Unschedulable)
I0924 12:48:45.347875    6058 scheduler.go:576] Attempting to schedule pod: system/kube-system/kube-dns-7f4bf79dc-pvldq
I0924 12:48:45.571451    6058 generic_scheduler.go:1052] Node master is a potential node for preemption.
I0924 12:48:45.571847    6058 factory.go:470] Unable to schedule system/kube-system/kube-dns-7f4bf79dc-pvldq: no fit: 0/1 nodes are available: 1 node(s) runtime is not ready.; waiting
I0924 12:48:45.571916    6058 scheduler.go:787] Updating pod condition for system/kube-system/kube-dns-7f4bf79dc-pvldq to (PodScheduled==False, Reason=Unschedulable)
I0924 12:48:47.930845    6058 scheduler.go:576] Attempting to schedule pod: system/kube-system/coredns-default-6cfd6c6766-cqfm7
I0924 12:48:48.170727    6058 generic_scheduler.go:1052] Node master is a potential node for preemption.
I0924 12:48:48.171087    6058 factory.go:470] Unable to schedule system/kube-system/coredns-default-6cfd6c6766-cqfm7: no fit: 0/1 nodes are available: 1 node(s) runtime is not ready.; waiting
I0924 12:48:48.171160    6058 scheduler.go:787] Updating pod condition for system/kube-system/coredns-default-6cfd6c6766-cqfm7 to (PodScheduled==False, Reason=Unschedulable)
I0924 12:48:51.708573    6058 scheduler.go:576] Attempting to schedule pod: system/kube-system/kube-dns-7f4bf79dc-pvldq
I0924 12:48:51.989926    6058 generic_scheduler.go:1052] Node master is a potential node for preemption.
I0924 12:48:51.990282    6058 factory.go:470] Unable to schedule system/kube-system/kube-dns-7f4bf79dc-pvldq: no fit: 0/1 nodes are available: 1 node(s) runtime is not ready.; waiting
I0924 12:48:51.990352    6058 scheduler.go:787] Updating pod condition for system/kube-system/kube-dns-7f4bf79dc-pvldq to (PodScheduled==False, Reason=Unschedulable)
I0924 12:48:58.750450    6058 scheduler.go:576] Attempting to schedule pod: system/kube-system/coredns-default-6cfd6c6766-cqfm7
I0924 12:49:00.576928    6058 generic_scheduler.go:1052] Node master is a potential node for preemption.
I0924 12:49:00.577262    6058 factory.go:470] Unable to schedule system/kube-system/coredns-default-6cfd6c6766-cqfm7: no fit: 0/1 nodes are available: 1 node(s) runtime is not ready.; waiting
I0924 12:49:00.577325    6058 scheduler.go:787] Updating pod condition for system/kube-system/coredns-default-6cfd6c6766-cqfm7 to (PodScheduled==False, Reason=Unschedulable)
I0924 12:49:02.941130    6058 scheduler.go:576] Attempting to schedule pod: system/kube-system/kube-dns-7f4bf79dc-pvldq
I0924 12:49:03.842048    6058 generic_scheduler.go:1052] Node master is a potential node for preemption.
I0924 12:49:03.844870    6058 factory.go:470] Unable to schedule system/kube-system/kube-dns-7f4bf79dc-pvldq: no fit: 0/1 nodes are available: 1 node(s) runtime is not ready.; waiting
I0924 12:49:03.844947    6058 scheduler.go:787] Updating pod condition for system/kube-system/kube-dns-7f4bf79dc-pvldq to (PodScheduled==False, Reason=Unschedulable)
I0924 12:49:07.629755    6058 scheduler.go:576] Attempting to schedule pod: system/kube-system/coredns-default-6cfd6c6766-cqfm7
I0924 12:49:08.288348    6058 generic_scheduler.go:1052] Node master is a potential node for preemption.
I0924 12:49:08.290057    6058 factory.go:470] Unable to schedule system/kube-system/coredns-default-6cfd6c6766-cqfm7: no fit: 0/1 nodes are available: 1 node(s) runtime is not ready.; waiting
I0924 12:49:08.290238    6058 scheduler.go:787] Updating pod condition for system/kube-system/coredns-default-6cfd6c6766-cqfm7 to (PodScheduled==False, Reason=Unschedulable)
I0924 12:49:09.951440    6058 scheduler.go:576] Attempting to schedule pod: system/kube-system/coredns-default-6cfd6c6766-cqfm7
I0924 12:49:10.759648    6058 generic_scheduler.go:1052] Node master is a potential node for preemption.
I0924 12:49:10.759921    6058 factory.go:470] Unable to schedule system/kube-system/coredns-default-6cfd6c6766-cqfm7: no fit: 0/1 nodes are available: 1 node(s) runtime is not ready.; waiting
I0924 12:49:10.759980    6058 scheduler.go:787] Updating pod condition for system/kube-system/coredns-default-6cfd6c6766-cqfm7 to (PodScheduled==False, Reason=Unschedulable)
I0924 12:49:12.929892    6058 scheduler.go:576] Attempting to schedule pod: system/kube-system/kube-dns-7f4bf79dc-pvldq
I0924 12:49:14.308758    6058 generic_scheduler.go:1052] Node master is a potential node for preemption.
I0924 12:49:14.309022    6058 factory.go:470] Unable to schedule system/kube-system/kube-dns-7f4bf79dc-pvldq: no fit: 0/1 nodes are available: 1 node(s) runtime is not ready.; waiting
I0924 12:49:14.309074    6058 scheduler.go:787] Updating pod condition for system/kube-system/kube-dns-7f4bf79dc-pvldq to (PodScheduled==False, Reason=Unschedulable)
I0924 12:49:15.552269    6058 scheduler.go:576] Attempting to schedule pod: system/kube-system/kube-dns-7f4bf79dc-pvldq
I0924 12:49:15.803467    6058 generic_scheduler.go:1052] Node master is a potential node for preemption.
I0924 12:49:15.804308    6058 factory.go:470] Unable to schedule system/kube-system/kube-dns-7f4bf79dc-pvldq: no fit: 0/1 nodes are available: 1 node(s) runtime is not ready.; waiting
I0924 12:49:15.804438    6058 scheduler.go:787] Updating pod condition for system/kube-system/kube-dns-7f4bf79dc-pvldq to (PodScheduled==False, Reason=Unschedulable)
I0924 12:49:21.755652    6058 scheduler.go:576] Attempting to schedule pod: system/kube-system/coredns-default-6cfd6c6766-cqfm7
I0924 12:49:21.978699    6058 generic_scheduler.go:1052] Node master is a potential node for preemption.
I0924 12:49:21.979204    6058 factory.go:470] Unable to schedule system/kube-system/coredns-default-6cfd6c6766-cqfm7: no fit: 0/1 nodes are available: 1 node(s) runtime is not ready.; waiting
I0924 12:49:21.979309    6058 scheduler.go:787] Updating pod condition for system/kube-system/coredns-default-6cfd6c6766-cqfm7 to (PodScheduled==False, Reason=Unschedulable)
I0924 12:49:26.543249    6058 scheduler.go:576] Attempting to schedule pod: system/kube-system/kube-dns-7f4bf79dc-pvldq
I0924 12:49:27.184902    6058 generic_scheduler.go:1052] Node master is a potential node for preemption.
I0924 12:49:27.185445    6058 factory.go:470] Unable to schedule system/kube-system/kube-dns-7f4bf79dc-pvldq: no fit: 0/1 nodes are available: 1 node(s) runtime is not ready.; waiting
I0924 12:49:27.185619    6058 scheduler.go:787] Updating pod condition for system/kube-system/kube-dns-7f4bf79dc-pvldq to (PodScheduled==False, Reason=Unschedulable)
I0924 12:49:33.090207    6058 scheduler.go:576] Attempting to schedule pod: system/kube-system/coredns-default-6cfd6c6766-cqfm7
I0924 12:49:33.243968    6058 generic_scheduler.go:1052] Node master is a potential node for preemption.
I0924 12:49:33.244365    6058 factory.go:470] Unable to schedule system/kube-system/coredns-default-6cfd6c6766-cqfm7: no fit: 0/1 nodes are available: 1 node(s) runtime is not ready.; waiting
I0924 12:49:33.244440    6058 scheduler.go:787] Updating pod condition for system/kube-system/coredns-default-6cfd6c6766-cqfm7 to (PodScheduled==False, Reason=Unschedulable)
I0924 12:49:35.533689    6058 scheduler.go:576] Attempting to schedule pod: system/kube-system/kube-dns-7f4bf79dc-pvldq
I0924 12:49:36.069047    6058 generic_scheduler.go:1052] Node master is a potential node for preemption.
I0924 12:49:36.069360    6058 factory.go:470] Unable to schedule system/kube-system/kube-dns-7f4bf79dc-pvldq: no fit: 0/1 nodes are available: 1 node(s) runtime is not ready.; waiting
I0924 12:49:36.069451    6058 scheduler.go:787] Updating pod condition for system/kube-system/kube-dns-7f4bf79dc-pvldq to (PodScheduled==False, Reason=Unschedulable)
I0924 12:49:37.900671    6058 scheduler.go:576] Attempting to schedule pod: system/kube-system/kube-dns-7f4bf79dc-pvldq
I0924 12:49:38.460048    6058 generic_scheduler.go:1052] Node master is a potential node for preemption.
I0924 12:49:38.460624    6058 factory.go:470] Unable to schedule system/kube-system/kube-dns-7f4bf79dc-pvldq: no fit: 0/1 nodes are available: 1 node(s) runtime is not ready.; waiting
I0924 12:49:38.460735    6058 scheduler.go:787] Updating pod condition for system/kube-system/kube-dns-7f4bf79dc-pvldq to (PodScheduled==False, Reason=Unschedulable)
I0924 12:49:44.280610    6058 scheduler.go:576] Attempting to schedule pod: system/kube-system/coredns-default-6cfd6c6766-cqfm7
I0924 12:49:44.782790    6058 generic_scheduler.go:1052] Node master is a potential node for preemption.
I0924 12:49:44.799876    6058 factory.go:470] Unable to schedule system/kube-system/coredns-default-6cfd6c6766-cqfm7: no fit: 0/1 nodes are available: 1 node(s) runtime is not ready.; waiting
I0924 12:49:44.799981    6058 scheduler.go:787] Updating pod condition for system/kube-system/coredns-default-6cfd6c6766-cqfm7 to (PodScheduled==False, Reason=Unschedulable)
I0924 12:49:49.047959    6058 scheduler.go:576] Attempting to schedule pod: system/kube-system/kube-dns-7f4bf79dc-pvldq
I0924 12:49:49.471540    6058 generic_scheduler.go:1052] Node master is a potential node for preemption.
I0924 12:49:49.472380    6058 factory.go:470] Unable to schedule system/kube-system/kube-dns-7f4bf79dc-pvldq: no fit: 0/1 nodes are available: 1 node(s) runtime is not ready.; waiting
I0924 12:49:49.472517    6058 scheduler.go:787] Updating pod condition for system/kube-system/kube-dns-7f4bf79dc-pvldq to (PodScheduled==False, Reason=Unschedulable)
I0924 12:49:55.768039    6058 scheduler.go:576] Attempting to schedule pod: system/kube-system/coredns-default-6cfd6c6766-cqfm7
I0924 12:49:55.810821    6058 generic_scheduler.go:1052] Node master is a potential node for preemption.
I0924 12:49:55.811346    6058 factory.go:470] Unable to schedule system/kube-system/coredns-default-6cfd6c6766-cqfm7: no fit: 0/1 nodes are available: 1 node(s) runtime is not ready.; waiting
I0924 12:49:55.811528    6058 scheduler.go:787] Updating pod condition for system/kube-system/coredns-default-6cfd6c6766-cqfm7 to (PodScheduled==False, Reason=Unschedulable)
I0924 12:50:00.366029    6058 scheduler.go:576] Attempting to schedule pod: system/kube-system/kube-dns-7f4bf79dc-pvldq
I0924 12:50:01.234741    6058 generic_scheduler.go:1052] Node master is a potential node for preemption.
I0924 12:50:01.235102    6058 factory.go:470] Unable to schedule system/kube-system/kube-dns-7f4bf79dc-pvldq: no fit: 0/1 nodes are available: 1 node(s) runtime is not ready.; waiting
I0924 12:50:01.235169    6058 scheduler.go:787] Updating pod condition for system/kube-system/kube-dns-7f4bf79dc-pvldq to (PodScheduled==False, Reason=Unschedulable)
I0924 12:50:06.307552    6058 scheduler.go:576] Attempting to schedule pod: system/kube-system/coredns-default-6cfd6c6766-cqfm7
I0924 12:50:06.387930    6058 generic_scheduler.go:1052] Node master is a potential node for preemption.
I0924 12:50:06.388258    6058 factory.go:470] Unable to schedule system/kube-system/coredns-default-6cfd6c6766-cqfm7: no fit: 0/1 nodes are available: 1 node(s) runtime is not ready.; waiting
I0924 12:50:06.388329    6058 scheduler.go:787] Updating pod condition for system/kube-system/coredns-default-6cfd6c6766-cqfm7 to (PodScheduled==False, Reason=Unschedulable)
I0924 12:50:12.166006    6058 scheduler.go:576] Attempting to schedule pod: system/kube-system/kube-dns-7f4bf79dc-pvldq
I0924 12:50:12.311709    6058 generic_scheduler.go:1052] Node master is a potential node for preemption.
I0924 12:50:12.312048    6058 factory.go:470] Unable to schedule system/kube-system/kube-dns-7f4bf79dc-pvldq: no fit: 0/1 nodes are available: 1 node(s) runtime is not ready.; waiting
I0924 12:50:12.312127    6058 scheduler.go:787] Updating pod condition for system/kube-system/kube-dns-7f4bf79dc-pvldq to (PodScheduled==False, Reason=Unschedulable)
I0924 12:50:17.442030    6058 scheduler.go:576] Attempting to schedule pod: system/kube-system/coredns-default-6cfd6c6766-cqfm7
I0924 12:50:17.723687    6058 generic_scheduler.go:1052] Node master is a potential node for preemption.
I0924 12:50:17.723988    6058 factory.go:470] Unable to schedule system/kube-system/coredns-default-6cfd6c6766-cqfm7: no fit: 0/1 nodes are available: 1 node(s) runtime is not ready.; waiting
I0924 12:50:17.724047    6058 scheduler.go:787] Updating pod condition for system/kube-system/coredns-default-6cfd6c6766-cqfm7 to (PodScheduled==False, Reason=Unschedulable)
I0924 12:50:22.773447    6058 scheduler.go:576] Attempting to schedule pod: system/kube-system/kube-dns-7f4bf79dc-pvldq
I0924 12:50:22.867429    6058 generic_scheduler.go:1052] Node master is a potential node for preemption.
I0924 12:50:22.867746    6058 factory.go:470] Unable to schedule system/kube-system/kube-dns-7f4bf79dc-pvldq: no fit: 0/1 nodes are available: 1 node(s) runtime is not ready.; waiting
I0924 12:50:22.867800    6058 scheduler.go:787] Updating pod condition for system/kube-system/kube-dns-7f4bf79dc-pvldq to (PodScheduled==False, Reason=Unschedulable)
I0924 12:50:28.570567    6058 scheduler.go:576] Attempting to schedule pod: system/kube-system/coredns-default-6cfd6c6766-cqfm7
I0924 12:50:28.852715    6058 generic_scheduler.go:1052] Node master is a potential node for preemption.
I0924 12:50:28.853010    6058 factory.go:470] Unable to schedule system/kube-system/coredns-default-6cfd6c6766-cqfm7: no fit: 0/1 nodes are available: 1 node(s) runtime is not ready.; waiting
I0924 12:50:28.853067    6058 scheduler.go:787] Updating pod condition for system/kube-system/coredns-default-6cfd6c6766-cqfm7 to (PodScheduled==False, Reason=Unschedulable)
I0924 12:50:33.290398    6058 scheduler.go:576] Attempting to schedule pod: system/kube-system/kube-dns-7f4bf79dc-pvldq
I0924 12:50:34.207993    6058 generic_scheduler.go:1052] Node master is a potential node for preemption.
I0924 12:50:34.208398    6058 factory.go:470] Unable to schedule system/kube-system/kube-dns-7f4bf79dc-pvldq: no fit: 0/1 nodes are available: 1 node(s) runtime is not ready.; waiting
I0924 12:50:34.208458    6058 scheduler.go:787] Updating pod condition for system/kube-system/kube-dns-7f4bf79dc-pvldq to (PodScheduled==False, Reason=Unschedulable)
I0924 12:50:39.283560    6058 scheduler.go:576] Attempting to schedule pod: system/kube-system/coredns-default-6cfd6c6766-cqfm7
I0924 12:50:39.327696    6058 generic_scheduler.go:1052] Node master is a potential node for preemption.
I0924 12:50:39.328256    6058 factory.go:470] Unable to schedule system/kube-system/coredns-default-6cfd6c6766-cqfm7: no fit: 0/1 nodes are available: 1 node(s) runtime is not ready.; waiting
I0924 12:50:39.344661    6058 scheduler.go:787] Updating pod condition for system/kube-system/coredns-default-6cfd6c6766-cqfm7 to (PodScheduled==False, Reason=Unschedulable)
I0924 12:50:47.149574    6058 scheduler.go:576] Attempting to schedule pod: system/kube-system/kube-dns-7f4bf79dc-pvldq
I0924 12:50:47.281098    6058 generic_scheduler.go:1052] Node master is a potential node for preemption.
I0924 12:50:47.281439    6058 factory.go:470] Unable to schedule system/kube-system/kube-dns-7f4bf79dc-pvldq: no fit: 0/1 nodes are available: 1 node(s) runtime is not ready.; waiting
I0924 12:50:47.281507    6058 scheduler.go:787] Updating pod condition for system/kube-system/kube-dns-7f4bf79dc-pvldq to (PodScheduled==False, Reason=Unschedulable)
I0924 12:50:50.280128    6058 scheduler.go:576] Attempting to schedule pod: system/kube-system/coredns-default-6cfd6c6766-cqfm7
I0924 12:50:50.366775    6058 generic_scheduler.go:1052] Node master is a potential node for preemption.
I0924 12:50:50.367061    6058 factory.go:470] Unable to schedule system/kube-system/coredns-default-6cfd6c6766-cqfm7: no fit: 0/1 nodes are available: 1 node(s) runtime is not ready.; waiting
I0924 12:50:50.367147    6058 scheduler.go:787] Updating pod condition for system/kube-system/coredns-default-6cfd6c6766-cqfm7 to (PodScheduled==False, Reason=Unschedulable)
I0924 12:50:58.470938    6058 scheduler.go:576] Attempting to schedule pod: system/kube-system/kube-dns-7f4bf79dc-pvldq
I0924 12:50:58.716481    6058 generic_scheduler.go:1052] Node master is a potential node for preemption.
I0924 12:50:58.716952    6058 factory.go:470] Unable to schedule system/kube-system/kube-dns-7f4bf79dc-pvldq: no fit: 0/1 nodes are available: 1 node(s) runtime is not ready.; waiting
I0924 12:50:58.717021    6058 scheduler.go:787] Updating pod condition for system/kube-system/kube-dns-7f4bf79dc-pvldq to (PodScheduled==False, Reason=Unschedulable)
I0924 12:51:00.843006    6058 scheduler.go:576] Attempting to schedule pod: system/kube-system/coredns-default-6cfd6c6766-cqfm7
I0924 12:51:00.902685    6058 generic_scheduler.go:1052] Node master is a potential node for preemption.
I0924 12:51:00.903040    6058 factory.go:470] Unable to schedule system/kube-system/coredns-default-6cfd6c6766-cqfm7: no fit: 0/1 nodes are available: 1 node(s) runtime is not ready.; waiting
I0924 12:51:00.903098    6058 scheduler.go:787] Updating pod condition for system/kube-system/coredns-default-6cfd6c6766-cqfm7 to (PodScheduled==False, Reason=Unschedulable)
I0924 12:51:09.844636    6058 scheduler.go:576] Attempting to schedule pod: system/kube-system/kube-dns-7f4bf79dc-pvldq
I0924 12:51:09.985282    6058 generic_scheduler.go:1052] Node master is a potential node for preemption.
I0924 12:51:09.985590    6058 factory.go:470] Unable to schedule system/kube-system/kube-dns-7f4bf79dc-pvldq: no fit: 0/1 nodes are available: 1 node(s) runtime is not ready.; waiting
I0924 12:51:10.376336    6058 scheduler.go:787] Updating pod condition for system/kube-system/kube-dns-7f4bf79dc-pvldq to (PodScheduled==False, Reason=Unschedulable)
I0924 12:51:11.085617    6058 scheduler.go:576] Attempting to schedule pod: system/kube-system/coredns-default-6cfd6c6766-cqfm7
I0924 12:51:11.257357    6058 generic_scheduler.go:1052] Node master is a potential node for preemption.
I0924 12:51:11.257968    6058 factory.go:470] Unable to schedule system/kube-system/coredns-default-6cfd6c6766-cqfm7: no fit: 0/1 nodes are available: 1 node(s) runtime is not ready.; waiting
I0924 12:51:11.258071    6058 scheduler.go:787] Updating pod condition for system/kube-system/coredns-default-6cfd6c6766-cqfm7 to (PodScheduled==False, Reason=Unschedulable)
I0924 12:51:21.935315    6058 scheduler.go:576] Attempting to schedule pod: system/kube-system/kube-dns-7f4bf79dc-pvldq
I0924 12:51:22.288748    6058 generic_scheduler.go:1052] Node master is a potential node for preemption.
I0924 12:51:22.289096    6058 factory.go:470] Unable to schedule system/kube-system/kube-dns-7f4bf79dc-pvldq: no fit: 0/1 nodes are available: 1 node(s) runtime is not ready.; waiting
I0924 12:51:22.289161    6058 scheduler.go:787] Updating pod condition for system/kube-system/kube-dns-7f4bf79dc-pvldq to (PodScheduled==False, Reason=Unschedulable)
I0924 12:51:22.289233    6058 scheduler.go:576] Attempting to schedule pod: system/kube-system/coredns-default-6cfd6c6766-cqfm7
I0924 12:51:22.346955    6058 generic_scheduler.go:1052] Node master is a potential node for preemption.
I0924 12:51:22.347291    6058 factory.go:470] Unable to schedule system/kube-system/coredns-default-6cfd6c6766-cqfm7: no fit: 0/1 nodes are available: 1 node(s) runtime is not ready.; waiting
I0924 12:51:22.348816    6058 scheduler.go:787] Updating pod condition for system/kube-system/coredns-default-6cfd6c6766-cqfm7 to (PodScheduled==False, Reason=Unschedulable)
I0924 12:51:32.724056    6058 scheduler.go:576] Attempting to schedule pod: system/kube-system/kube-dns-7f4bf79dc-pvldq
I0924 12:51:32.777322    6058 generic_scheduler.go:1052] Node master is a potential node for preemption.
I0924 12:51:32.777587    6058 factory.go:470] Unable to schedule system/kube-system/kube-dns-7f4bf79dc-pvldq: no fit: 0/1 nodes are available: 1 node(s) runtime is not ready.; waiting
I0924 12:51:32.777669    6058 scheduler.go:787] Updating pod condition for system/kube-system/kube-dns-7f4bf79dc-pvldq to (PodScheduled==False, Reason=Unschedulable)
I0924 12:51:32.816237    6058 scheduler.go:576] Attempting to schedule pod: system/kube-system/coredns-default-6cfd6c6766-cqfm7
I0924 12:51:32.835972    6058 generic_scheduler.go:1052] Node master is a potential node for preemption.
I0924 12:51:32.836264    6058 factory.go:470] Unable to schedule system/kube-system/coredns-default-6cfd6c6766-cqfm7: no fit: 0/1 nodes are available: 1 node(s) runtime is not ready.; waiting
I0924 12:51:32.836318    6058 scheduler.go:787] Updating pod condition for system/kube-system/coredns-default-6cfd6c6766-cqfm7 to (PodScheduled==False, Reason=Unschedulable)
I0924 12:51:43.560913    6058 scheduler.go:576] Attempting to schedule pod: system/kube-system/kube-dns-7f4bf79dc-pvldq
I0924 12:51:45.410186    6058 generic_scheduler.go:1052] Node master is a potential node for preemption.
I0924 12:51:45.410711    6058 factory.go:470] Unable to schedule system/kube-system/kube-dns-7f4bf79dc-pvldq: no fit: 0/1 nodes are available: 1 node(s) runtime is not ready.; waiting
I0924 12:51:45.410932    6058 scheduler.go:787] Updating pod condition for system/kube-system/kube-dns-7f4bf79dc-pvldq to (PodScheduled==False, Reason=Unschedulable)
I0924 12:51:45.419591    6058 scheduler.go:576] Attempting to schedule pod: system/kube-system/coredns-default-6cfd6c6766-cqfm7
I0924 12:51:46.025511    6058 generic_scheduler.go:1052] Node master is a potential node for preemption.
I0924 12:51:46.025830    6058 factory.go:470] Unable to schedule system/kube-system/coredns-default-6cfd6c6766-cqfm7: no fit: 0/1 nodes are available: 1 node(s) runtime is not ready.; waiting
I0924 12:51:46.025886    6058 scheduler.go:787] Updating pod condition for system/kube-system/coredns-default-6cfd6c6766-cqfm7 to (PodScheduled==False, Reason=Unschedulable)
I0924 12:51:47.418961    6058 eventhandlers.go:183] add event for unscheduled pod system/default/mizar-operator-6985d77546-n8jsm
I0924 12:51:47.421801    6058 scheduler.go:576] Attempting to schedule pod: system/default/mizar-operator-6985d77546-n8jsm
I0924 12:51:47.422300    6058 default_binder.go:53] Attempting to bind system/default/mizar-operator-6985d77546-n8jsm to master
I0924 12:51:47.665131    6058 eventhandlers.go:215] delete event for unscheduled pod system/default/mizar-operator-6985d77546-n8jsm
I0924 12:51:47.665490    6058 eventhandlers.go:239] add event for scheduled pod system/default/mizar-operator-6985d77546-n8jsm 
I0924 12:51:47.706497    6058 scheduler.go:741] pod system/default/mizar-operator-6985d77546-n8jsm is bound successfully on node "master", 1 nodes evaluated, 1 nodes were found feasible.
I0924 12:51:56.578251    6058 scheduler.go:576] Attempting to schedule pod: system/kube-system/kube-dns-7f4bf79dc-pvldq
I0924 12:51:57.474615    6058 generic_scheduler.go:1052] Node master is a potential node for preemption.
I0924 12:51:57.475010    6058 factory.go:470] Unable to schedule system/kube-system/kube-dns-7f4bf79dc-pvldq: no fit: 0/1 nodes are available: 1 node(s) runtime is not ready.; waiting
I0924 12:51:57.475081    6058 scheduler.go:787] Updating pod condition for system/kube-system/kube-dns-7f4bf79dc-pvldq to (PodScheduled==False, Reason=Unschedulable)
I0924 12:51:57.502132    6058 scheduler.go:576] Attempting to schedule pod: system/kube-system/coredns-default-6cfd6c6766-cqfm7
I0924 12:51:57.996723    6058 generic_scheduler.go:1052] Node master is a potential node for preemption.
I0924 12:51:57.997127    6058 factory.go:470] Unable to schedule system/kube-system/coredns-default-6cfd6c6766-cqfm7: no fit: 0/1 nodes are available: 1 node(s) runtime is not ready.; waiting
I0924 12:51:57.997191    6058 scheduler.go:787] Updating pod condition for system/kube-system/coredns-default-6cfd6c6766-cqfm7 to (PodScheduled==False, Reason=Unschedulable)
I0924 12:52:08.525954    6058 scheduler.go:576] Attempting to schedule pod: system/kube-system/kube-dns-7f4bf79dc-pvldq
I0924 12:52:08.743772    6058 generic_scheduler.go:1052] Node master is a potential node for preemption.
I0924 12:52:08.744092    6058 factory.go:470] Unable to schedule system/kube-system/kube-dns-7f4bf79dc-pvldq: no fit: 0/1 nodes are available: 1 node(s) runtime is not ready.; waiting
I0924 12:52:08.744145    6058 scheduler.go:787] Updating pod condition for system/kube-system/kube-dns-7f4bf79dc-pvldq to (PodScheduled==False, Reason=Unschedulable)
I0924 12:52:08.754257    6058 scheduler.go:576] Attempting to schedule pod: system/kube-system/coredns-default-6cfd6c6766-cqfm7
I0924 12:52:08.851003    6058 generic_scheduler.go:1052] Node master is a potential node for preemption.
I0924 12:52:08.851513    6058 factory.go:470] Unable to schedule system/kube-system/coredns-default-6cfd6c6766-cqfm7: no fit: 0/1 nodes are available: 1 node(s) runtime is not ready.; waiting
I0924 12:52:08.851583    6058 scheduler.go:787] Updating pod condition for system/kube-system/coredns-default-6cfd6c6766-cqfm7 to (PodScheduled==False, Reason=Unschedulable)
I0924 12:52:21.312901    6058 scheduler.go:576] Attempting to schedule pod: system/kube-system/kube-dns-7f4bf79dc-pvldq
I0924 12:52:21.450877    6058 generic_scheduler.go:1052] Node master is a potential node for preemption.
I0924 12:52:21.451461    6058 factory.go:470] Unable to schedule system/kube-system/kube-dns-7f4bf79dc-pvldq: no fit: 0/1 nodes are available: 1 node(s) runtime is not ready.; waiting
I0924 12:52:21.451573    6058 scheduler.go:787] Updating pod condition for system/kube-system/kube-dns-7f4bf79dc-pvldq to (PodScheduled==False, Reason=Unschedulable)
I0924 12:52:21.451763    6058 scheduler.go:576] Attempting to schedule pod: system/kube-system/coredns-default-6cfd6c6766-cqfm7
I0924 12:52:21.768163    6058 generic_scheduler.go:1052] Node master is a potential node for preemption.
I0924 12:52:21.782792    6058 factory.go:470] Unable to schedule system/kube-system/coredns-default-6cfd6c6766-cqfm7: no fit: 0/1 nodes are available: 1 node(s) runtime is not ready.; waiting
I0924 12:52:21.782906    6058 scheduler.go:787] Updating pod condition for system/kube-system/coredns-default-6cfd6c6766-cqfm7 to (PodScheduled==False, Reason=Unschedulable)
I0924 12:52:32.265029    6058 scheduler.go:576] Attempting to schedule pod: system/kube-system/coredns-default-6cfd6c6766-cqfm7
I0924 12:52:32.906517    6058 generic_scheduler.go:1052] Node master is a potential node for preemption.
I0924 12:52:32.909850    6058 factory.go:470] Unable to schedule system/kube-system/coredns-default-6cfd6c6766-cqfm7: no fit: 0/1 nodes are available: 1 node(s) runtime is not ready.; waiting
I0924 12:52:32.909976    6058 scheduler.go:787] Updating pod condition for system/kube-system/coredns-default-6cfd6c6766-cqfm7 to (PodScheduled==False, Reason=Unschedulable)
I0924 12:52:33.690512    6058 scheduler.go:576] Attempting to schedule pod: system/kube-system/kube-dns-7f4bf79dc-pvldq
I0924 12:52:34.170874    6058 generic_scheduler.go:1052] Node master is a potential node for preemption.
I0924 12:52:34.171224    6058 factory.go:470] Unable to schedule system/kube-system/kube-dns-7f4bf79dc-pvldq: no fit: 0/1 nodes are available: 1 node(s) runtime is not ready.; waiting
I0924 12:52:34.171494    6058 scheduler.go:787] Updating pod condition for system/kube-system/kube-dns-7f4bf79dc-pvldq to (PodScheduled==False, Reason=Unschedulable)
I0924 12:52:43.815884    6058 scheduler.go:576] Attempting to schedule pod: system/kube-system/coredns-default-6cfd6c6766-cqfm7
I0924 12:52:44.119908    6058 generic_scheduler.go:1052] Node master is a potential node for preemption.
I0924 12:52:44.120226    6058 factory.go:470] Unable to schedule system/kube-system/coredns-default-6cfd6c6766-cqfm7: no fit: 0/1 nodes are available: 1 node(s) runtime is not ready.; waiting
I0924 12:52:44.120300    6058 scheduler.go:787] Updating pod condition for system/kube-system/coredns-default-6cfd6c6766-cqfm7 to (PodScheduled==False, Reason=Unschedulable)
I0924 12:52:44.893486    6058 scheduler.go:576] Attempting to schedule pod: system/kube-system/kube-dns-7f4bf79dc-pvldq
I0924 12:52:45.085332    6058 generic_scheduler.go:1052] Node master is a potential node for preemption.
I0924 12:52:45.085703    6058 factory.go:470] Unable to schedule system/kube-system/kube-dns-7f4bf79dc-pvldq: no fit: 0/1 nodes are available: 1 node(s) runtime is not ready.; waiting
I0924 12:52:45.085837    6058 scheduler.go:787] Updating pod condition for system/kube-system/kube-dns-7f4bf79dc-pvldq to (PodScheduled==False, Reason=Unschedulable)
I0924 12:52:55.224746    6058 scheduler.go:576] Attempting to schedule pod: system/kube-system/coredns-default-6cfd6c6766-cqfm7
I0924 12:52:55.283839    6058 generic_scheduler.go:1052] Node master is a potential node for preemption.
I0924 12:52:55.316965    6058 factory.go:470] Unable to schedule system/kube-system/coredns-default-6cfd6c6766-cqfm7: no fit: 0/1 nodes are available: 1 node(s) runtime is not ready.; waiting
I0924 12:52:55.317851    6058 scheduler.go:787] Updating pod condition for system/kube-system/coredns-default-6cfd6c6766-cqfm7 to (PodScheduled==False, Reason=Unschedulable)
I0924 12:52:56.261133    6058 scheduler.go:576] Attempting to schedule pod: system/kube-system/kube-dns-7f4bf79dc-pvldq
I0924 12:52:56.366800    6058 generic_scheduler.go:1052] Node master is a potential node for preemption.
I0924 12:52:56.367272    6058 factory.go:470] Unable to schedule system/kube-system/kube-dns-7f4bf79dc-pvldq: no fit: 0/1 nodes are available: 1 node(s) runtime is not ready.; waiting
I0924 12:52:56.367623    6058 scheduler.go:787] Updating pod condition for system/kube-system/kube-dns-7f4bf79dc-pvldq to (PodScheduled==False, Reason=Unschedulable)
I0924 12:53:06.837302    6058 scheduler.go:576] Attempting to schedule pod: system/kube-system/coredns-default-6cfd6c6766-cqfm7
I0924 12:53:07.380451    6058 generic_scheduler.go:1052] Node master is a potential node for preemption.
I0924 12:53:07.381130    6058 factory.go:470] Unable to schedule system/kube-system/coredns-default-6cfd6c6766-cqfm7: no fit: 0/1 nodes are available: 1 node(s) runtime is not ready.; waiting
I0924 12:53:07.381352    6058 scheduler.go:787] Updating pod condition for system/kube-system/coredns-default-6cfd6c6766-cqfm7 to (PodScheduled==False, Reason=Unschedulable)
I0924 12:53:07.386297    6058 scheduler.go:576] Attempting to schedule pod: system/kube-system/kube-dns-7f4bf79dc-pvldq
I0924 12:53:07.468444    6058 generic_scheduler.go:1052] Node master is a potential node for preemption.
I0924 12:53:07.468827    6058 factory.go:470] Unable to schedule system/kube-system/kube-dns-7f4bf79dc-pvldq: no fit: 0/1 nodes are available: 1 node(s) runtime is not ready.; waiting
I0924 12:53:07.468894    6058 scheduler.go:787] Updating pod condition for system/kube-system/kube-dns-7f4bf79dc-pvldq to (PodScheduled==False, Reason=Unschedulable)
I0924 12:53:15.831198    6058 eventhandlers.go:308] delete event for scheduled pod system/default/mizar-operator-6985d77546-2nd82 
I0924 12:53:18.387569    6058 scheduler.go:576] Attempting to schedule pod: system/kube-system/coredns-default-6cfd6c6766-cqfm7
I0924 12:53:18.402264    6058 generic_scheduler.go:1052] Node master is a potential node for preemption.
I0924 12:53:18.402566    6058 factory.go:470] Unable to schedule system/kube-system/coredns-default-6cfd6c6766-cqfm7: no fit: 0/1 nodes are available: 1 node(s) runtime is not ready.; waiting
I0924 12:53:18.402646    6058 scheduler.go:787] Updating pod condition for system/kube-system/coredns-default-6cfd6c6766-cqfm7 to (PodScheduled==False, Reason=Unschedulable)
I0924 12:53:18.406298    6058 scheduler.go:576] Attempting to schedule pod: system/kube-system/kube-dns-7f4bf79dc-pvldq
I0924 12:53:18.472383    6058 generic_scheduler.go:1052] Node master is a potential node for preemption.
I0924 12:53:18.472931    6058 factory.go:470] Unable to schedule system/kube-system/kube-dns-7f4bf79dc-pvldq: no fit: 0/1 nodes are available: 1 node(s) runtime is not ready.; waiting
I0924 12:53:18.825129    6058 scheduler.go:787] Updating pod condition for system/kube-system/kube-dns-7f4bf79dc-pvldq to (PodScheduled==False, Reason=Unschedulable)
I0924 12:53:21.776622    6058 scheduler.go:576] Attempting to schedule pod: system/kube-system/coredns-default-6cfd6c6766-cqfm7
I0924 12:53:21.906544    6058 generic_scheduler.go:1052] Node master is a potential node for preemption.
I0924 12:53:21.907398    6058 factory.go:470] Unable to schedule system/kube-system/coredns-default-6cfd6c6766-cqfm7: no fit: 0/1 nodes are available: 1 node(s) runtime is not ready.; waiting
I0924 12:53:21.907640    6058 scheduler.go:787] Updating pod condition for system/kube-system/coredns-default-6cfd6c6766-cqfm7 to (PodScheduled==False, Reason=Unschedulable)
I0924 12:53:21.910266    6058 scheduler.go:576] Attempting to schedule pod: system/kube-system/kube-dns-7f4bf79dc-pvldq
I0924 12:53:22.010812    6058 generic_scheduler.go:1052] Node master is a potential node for preemption.
I0924 12:53:22.011260    6058 factory.go:470] Unable to schedule system/kube-system/kube-dns-7f4bf79dc-pvldq: no fit: 0/1 nodes are available: 1 node(s) runtime is not ready.; waiting
I0924 12:53:22.011330    6058 scheduler.go:787] Updating pod condition for system/kube-system/kube-dns-7f4bf79dc-pvldq to (PodScheduled==False, Reason=Unschedulable)
I0924 12:53:33.207615    6058 scheduler.go:576] Attempting to schedule pod: system/kube-system/coredns-default-6cfd6c6766-cqfm7
I0924 12:53:33.952924    6058 generic_scheduler.go:1052] Node master is a potential node for preemption.
I0924 12:53:33.953277    6058 factory.go:470] Unable to schedule system/kube-system/coredns-default-6cfd6c6766-cqfm7: no fit: 0/1 nodes are available: 1 node(s) runtime is not ready.; waiting
I0924 12:53:33.953331    6058 scheduler.go:787] Updating pod condition for system/kube-system/coredns-default-6cfd6c6766-cqfm7 to (PodScheduled==False, Reason=Unschedulable)
I0924 12:53:33.962986    6058 scheduler.go:576] Attempting to schedule pod: system/kube-system/kube-dns-7f4bf79dc-pvldq
I0924 12:53:34.064906    6058 generic_scheduler.go:1052] Node master is a potential node for preemption.
I0924 12:53:34.065233    6058 factory.go:470] Unable to schedule system/kube-system/kube-dns-7f4bf79dc-pvldq: no fit: 0/1 nodes are available: 1 node(s) runtime is not ready.; waiting
I0924 12:53:34.065306    6058 scheduler.go:787] Updating pod condition for system/kube-system/kube-dns-7f4bf79dc-pvldq to (PodScheduled==False, Reason=Unschedulable)
I0924 12:53:34.066481    6058 scheduler.go:576] Attempting to schedule pod: system/kube-system/coredns-default-6cfd6c6766-cqfm7
I0924 12:53:34.636650    6058 generic_scheduler.go:1052] Node master is a potential node for preemption.
I0924 12:53:34.638802    6058 factory.go:470] Unable to schedule system/kube-system/coredns-default-6cfd6c6766-cqfm7: no fit: 0/1 nodes are available: 1 node(s) runtime is not ready.; waiting
I0924 12:53:34.638912    6058 scheduler.go:787] Updating pod condition for system/kube-system/coredns-default-6cfd6c6766-cqfm7 to (PodScheduled==False, Reason=Unschedulable)
E0924 12:53:34.652293    6058 factory.go:512] pod system/kube-system/coredns-default-6cfd6c6766-cqfm7 is already present in the backoff queue
I0924 12:53:34.737779    6058 scheduler.go:576] Attempting to schedule pod: system/kube-system/kube-dns-7f4bf79dc-pvldq
I0924 12:53:34.817900    6058 generic_scheduler.go:1052] Node master is a potential node for preemption.
I0924 12:53:34.818462    6058 factory.go:470] Unable to schedule system/kube-system/kube-dns-7f4bf79dc-pvldq: no fit: 0/1 nodes are available: 1 node(s) runtime is not ready.; waiting
I0924 12:53:34.818611    6058 scheduler.go:787] Updating pod condition for system/kube-system/kube-dns-7f4bf79dc-pvldq to (PodScheduled==False, Reason=Unschedulable)
I0924 12:53:37.385372    6058 scheduler.go:576] Attempting to schedule pod: system/kube-system/coredns-default-6cfd6c6766-cqfm7
I0924 12:53:37.647734    6058 generic_scheduler.go:1052] Node master is a potential node for preemption.
I0924 12:53:37.648017    6058 factory.go:470] Unable to schedule system/kube-system/coredns-default-6cfd6c6766-cqfm7: no fit: 0/1 nodes are available: 1 node(s) runtime is not ready.; waiting
I0924 12:53:37.648102    6058 scheduler.go:787] Updating pod condition for system/kube-system/coredns-default-6cfd6c6766-cqfm7 to (PodScheduled==False, Reason=Unschedulable)
I0924 12:53:39.008733    6058 scheduler.go:576] Attempting to schedule pod: system/kube-system/kube-dns-7f4bf79dc-pvldq
I0924 12:53:39.308671    6058 generic_scheduler.go:1052] Node master is a potential node for preemption.
I0924 12:53:39.309976    6058 factory.go:470] Unable to schedule system/kube-system/kube-dns-7f4bf79dc-pvldq: no fit: 0/1 nodes are available: 1 node(s) runtime is not ready.; waiting
I0924 12:53:39.313982    6058 scheduler.go:787] Updating pod condition for system/kube-system/kube-dns-7f4bf79dc-pvldq to (PodScheduled==False, Reason=Unschedulable)
I0924 12:53:48.162402    6058 scheduler.go:576] Attempting to schedule pod: system/kube-system/coredns-default-6cfd6c6766-cqfm7
I0924 12:53:48.298911    6058 generic_scheduler.go:1052] Node master is a potential node for preemption.
I0924 12:53:48.299427    6058 factory.go:470] Unable to schedule system/kube-system/coredns-default-6cfd6c6766-cqfm7: no fit: 0/1 nodes are available: 1 node(s) runtime is not ready.; waiting
I0924 12:53:48.299499    6058 scheduler.go:787] Updating pod condition for system/kube-system/coredns-default-6cfd6c6766-cqfm7 to (PodScheduled==False, Reason=Unschedulable)
I0924 12:53:50.402271    6058 scheduler.go:576] Attempting to schedule pod: system/kube-system/kube-dns-7f4bf79dc-pvldq
I0924 12:53:50.625930    6058 generic_scheduler.go:1052] Node master is a potential node for preemption.
I0924 12:53:50.626278    6058 factory.go:470] Unable to schedule system/kube-system/kube-dns-7f4bf79dc-pvldq: no fit: 0/1 nodes are available: 1 node(s) runtime is not ready.; waiting
I0924 12:53:50.626389    6058 scheduler.go:787] Updating pod condition for system/kube-system/kube-dns-7f4bf79dc-pvldq to (PodScheduled==False, Reason=Unschedulable)
I0924 12:53:57.720385    6058 scheduler.go:576] Attempting to schedule pod: system/kube-system/coredns-default-6cfd6c6766-cqfm7
I0924 12:53:57.929359    6058 generic_scheduler.go:1052] Node master is a potential node for preemption.
I0924 12:53:57.929653    6058 factory.go:470] Unable to schedule system/kube-system/coredns-default-6cfd6c6766-cqfm7: no fit: 0/1 nodes are available: 1 node(s) runtime is not ready.; waiting
I0924 12:53:57.929771    6058 scheduler.go:787] Updating pod condition for system/kube-system/coredns-default-6cfd6c6766-cqfm7 to (PodScheduled==False, Reason=Unschedulable)
I0924 12:53:58.854340    6058 scheduler.go:576] Attempting to schedule pod: system/kube-system/coredns-default-6cfd6c6766-cqfm7
I0924 12:53:58.882074    6058 generic_scheduler.go:1052] Node master is a potential node for preemption.
I0924 12:53:58.882392    6058 factory.go:470] Unable to schedule system/kube-system/coredns-default-6cfd6c6766-cqfm7: no fit: 0/1 nodes are available: 1 node(s) runtime is not ready.; waiting
I0924 12:53:58.882457    6058 scheduler.go:787] Updating pod condition for system/kube-system/coredns-default-6cfd6c6766-cqfm7 to (PodScheduled==False, Reason=Unschedulable)
I0924 12:53:58.901926    6058 scheduler.go:576] Attempting to schedule pod: system/kube-system/kube-dns-7f4bf79dc-pvldq
I0924 12:53:58.958137    6058 generic_scheduler.go:1052] Node master is a potential node for preemption.
I0924 12:53:58.958434    6058 factory.go:470] Unable to schedule system/kube-system/kube-dns-7f4bf79dc-pvldq: no fit: 0/1 nodes are available: 1 node(s) runtime is not ready.; waiting
I0924 12:53:58.958725    6058 scheduler.go:787] Updating pod condition for system/kube-system/kube-dns-7f4bf79dc-pvldq to (PodScheduled==False, Reason=Unschedulable)
I0924 12:54:00.413433    6058 scheduler.go:576] Attempting to schedule pod: system/kube-system/kube-dns-7f4bf79dc-pvldq
I0924 12:54:00.477578    6058 generic_scheduler.go:1052] Node master is a potential node for preemption.
I0924 12:54:00.477937    6058 factory.go:470] Unable to schedule system/kube-system/kube-dns-7f4bf79dc-pvldq: no fit: 0/1 nodes are available: 1 node(s) runtime is not ready.; waiting
I0924 12:54:00.478025    6058 scheduler.go:787] Updating pod condition for system/kube-system/kube-dns-7f4bf79dc-pvldq to (PodScheduled==False, Reason=Unschedulable)
I0924 12:54:09.938811    6058 scheduler.go:576] Attempting to schedule pod: system/kube-system/coredns-default-6cfd6c6766-cqfm7
I0924 12:54:09.953924    6058 generic_scheduler.go:1052] Node master is a potential node for preemption.
I0924 12:54:09.954222    6058 factory.go:470] Unable to schedule system/kube-system/coredns-default-6cfd6c6766-cqfm7: no fit: 0/1 nodes are available: 1 node(s) runtime is not ready.; waiting
I0924 12:54:09.954288    6058 scheduler.go:787] Updating pod condition for system/kube-system/coredns-default-6cfd6c6766-cqfm7 to (PodScheduled==False, Reason=Unschedulable)
I0924 12:54:10.939173    6058 scheduler.go:576] Attempting to schedule pod: system/kube-system/kube-dns-7f4bf79dc-pvldq
I0924 12:54:10.960982    6058 generic_scheduler.go:1052] Node master is a potential node for preemption.
I0924 12:54:10.961275    6058 factory.go:470] Unable to schedule system/kube-system/kube-dns-7f4bf79dc-pvldq: no fit: 0/1 nodes are available: 1 node(s) runtime is not ready.; waiting
I0924 12:54:10.961374    6058 scheduler.go:787] Updating pod condition for system/kube-system/kube-dns-7f4bf79dc-pvldq to (PodScheduled==False, Reason=Unschedulable)
I0924 12:54:18.834607    6058 scheduler.go:576] Attempting to schedule pod: system/kube-system/coredns-default-6cfd6c6766-cqfm7
I0924 12:54:18.850718    6058 generic_scheduler.go:1052] Node master is a potential node for preemption.
I0924 12:54:18.851114    6058 factory.go:470] Unable to schedule system/kube-system/coredns-default-6cfd6c6766-cqfm7: no fit: 0/1 nodes are available: 1 node(s) runtime is not ready.; waiting
I0924 12:54:18.851190    6058 scheduler.go:787] Updating pod condition for system/kube-system/coredns-default-6cfd6c6766-cqfm7 to (PodScheduled==False, Reason=Unschedulable)
I0924 12:54:19.341025    6058 scheduler.go:576] Attempting to schedule pod: system/kube-system/coredns-default-6cfd6c6766-cqfm7
I0924 12:54:19.351984    6058 generic_scheduler.go:1052] Node master is a potential node for preemption.
I0924 12:54:19.352289    6058 factory.go:470] Unable to schedule system/kube-system/coredns-default-6cfd6c6766-cqfm7: no fit: 0/1 nodes are available: 1 node(s) runtime is not ready.; waiting
I0924 12:54:19.352359    6058 scheduler.go:787] Updating pod condition for system/kube-system/coredns-default-6cfd6c6766-cqfm7 to (PodScheduled==False, Reason=Unschedulable)
I0924 12:54:20.369359    6058 scheduler.go:576] Attempting to schedule pod: system/kube-system/kube-dns-7f4bf79dc-pvldq
I0924 12:54:20.653375    6058 generic_scheduler.go:1052] Node master is a potential node for preemption.
I0924 12:54:20.654244    6058 factory.go:470] Unable to schedule system/kube-system/kube-dns-7f4bf79dc-pvldq: no fit: 0/1 nodes are available: 1 node(s) runtime is not ready.; waiting
I0924 12:54:20.654435    6058 scheduler.go:787] Updating pod condition for system/kube-system/kube-dns-7f4bf79dc-pvldq to (PodScheduled==False, Reason=Unschedulable)
I0924 12:54:22.430450    6058 scheduler.go:576] Attempting to schedule pod: system/kube-system/kube-dns-7f4bf79dc-pvldq
I0924 12:54:22.557621    6058 generic_scheduler.go:1052] Node master is a potential node for preemption.
I0924 12:54:22.558376    6058 factory.go:470] Unable to schedule system/kube-system/kube-dns-7f4bf79dc-pvldq: no fit: 0/1 nodes are available: 1 node(s) runtime is not ready.; waiting
I0924 12:54:22.558502    6058 scheduler.go:787] Updating pod condition for system/kube-system/kube-dns-7f4bf79dc-pvldq to (PodScheduled==False, Reason=Unschedulable)
I0924 12:54:29.868505    6058 scheduler.go:576] Attempting to schedule pod: system/kube-system/coredns-default-6cfd6c6766-cqfm7
I0924 12:54:29.877164    6058 generic_scheduler.go:1052] Node master is a potential node for preemption.
I0924 12:54:29.878041    6058 factory.go:470] Unable to schedule system/kube-system/coredns-default-6cfd6c6766-cqfm7: no fit: 0/1 nodes are available: 1 node(s) runtime is not ready.; waiting
I0924 12:54:29.878171    6058 scheduler.go:787] Updating pod condition for system/kube-system/coredns-default-6cfd6c6766-cqfm7 to (PodScheduled==False, Reason=Unschedulable)
I0924 12:54:33.280833    6058 scheduler.go:576] Attempting to schedule pod: system/kube-system/kube-dns-7f4bf79dc-pvldq
I0924 12:54:33.291516    6058 generic_scheduler.go:1052] Node master is a potential node for preemption.
I0924 12:54:33.291997    6058 factory.go:470] Unable to schedule system/kube-system/kube-dns-7f4bf79dc-pvldq: no fit: 0/1 nodes are available: 1 node(s) runtime is not ready.; waiting
I0924 12:54:33.292065    6058 scheduler.go:787] Updating pod condition for system/kube-system/kube-dns-7f4bf79dc-pvldq to (PodScheduled==False, Reason=Unschedulable)
I0924 12:54:39.563958    6058 scheduler.go:576] Attempting to schedule pod: system/kube-system/coredns-default-6cfd6c6766-cqfm7
I0924 12:54:39.609285    6058 generic_scheduler.go:1052] Node master is a potential node for preemption.
I0924 12:54:39.609526    6058 factory.go:470] Unable to schedule system/kube-system/coredns-default-6cfd6c6766-cqfm7: no fit: 0/1 nodes are available: 1 node(s) runtime is not ready.; waiting
I0924 12:54:39.609585    6058 scheduler.go:787] Updating pod condition for system/kube-system/coredns-default-6cfd6c6766-cqfm7 to (PodScheduled==False, Reason=Unschedulable)
I0924 12:54:40.082881    6058 scheduler.go:576] Attempting to schedule pod: system/kube-system/coredns-default-6cfd6c6766-cqfm7
I0924 12:54:40.091624    6058 generic_scheduler.go:1052] Node master is a potential node for preemption.
I0924 12:54:40.091923    6058 factory.go:470] Unable to schedule system/kube-system/coredns-default-6cfd6c6766-cqfm7: no fit: 0/1 nodes are available: 1 node(s) runtime is not ready.; waiting
I0924 12:54:40.091979    6058 scheduler.go:787] Updating pod condition for system/kube-system/coredns-default-6cfd6c6766-cqfm7 to (PodScheduled==False, Reason=Unschedulable)
I0924 12:54:42.220896    6058 scheduler.go:576] Attempting to schedule pod: system/kube-system/kube-dns-7f4bf79dc-pvldq
I0924 12:54:42.227480    6058 generic_scheduler.go:1052] Node master is a potential node for preemption.
I0924 12:54:42.227743    6058 factory.go:470] Unable to schedule system/kube-system/kube-dns-7f4bf79dc-pvldq: no fit: 0/1 nodes are available: 1 node(s) runtime is not ready.; waiting
I0924 12:54:42.227817    6058 scheduler.go:787] Updating pod condition for system/kube-system/kube-dns-7f4bf79dc-pvldq to (PodScheduled==False, Reason=Unschedulable)
I0924 12:54:42.556664    6058 scheduler.go:576] Attempting to schedule pod: system/kube-system/kube-dns-7f4bf79dc-pvldq
I0924 12:54:42.612088    6058 generic_scheduler.go:1052] Node master is a potential node for preemption.
I0924 12:54:42.612971    6058 factory.go:470] Unable to schedule system/kube-system/kube-dns-7f4bf79dc-pvldq: no fit: 0/1 nodes are available: 1 node(s) runtime is not ready.; waiting
I0924 12:54:42.613235    6058 scheduler.go:787] Updating pod condition for system/kube-system/kube-dns-7f4bf79dc-pvldq to (PodScheduled==False, Reason=Unschedulable)
I0924 12:54:50.879182    6058 scheduler.go:576] Attempting to schedule pod: system/kube-system/coredns-default-6cfd6c6766-cqfm7
I0924 12:54:50.891189    6058 generic_scheduler.go:1052] Node master is a potential node for preemption.
I0924 12:54:50.891574    6058 factory.go:470] Unable to schedule system/kube-system/coredns-default-6cfd6c6766-cqfm7: no fit: 0/1 nodes are available: 1 node(s) runtime is not ready.; waiting
I0924 12:54:50.891821    6058 scheduler.go:787] Updating pod condition for system/kube-system/coredns-default-6cfd6c6766-cqfm7 to (PodScheduled==False, Reason=Unschedulable)
I0924 12:54:52.879839    6058 scheduler.go:576] Attempting to schedule pod: system/kube-system/kube-dns-7f4bf79dc-pvldq
I0924 12:54:52.891342    6058 generic_scheduler.go:1052] Node master is a potential node for preemption.
I0924 12:54:52.891953    6058 factory.go:470] Unable to schedule system/kube-system/kube-dns-7f4bf79dc-pvldq: no fit: 0/1 nodes are available: 1 node(s) runtime is not ready.; waiting
I0924 12:54:52.892090    6058 scheduler.go:787] Updating pod condition for system/kube-system/kube-dns-7f4bf79dc-pvldq to (PodScheduled==False, Reason=Unschedulable)
I0924 12:55:00.060144    6058 scheduler.go:576] Attempting to schedule pod: system/kube-system/coredns-default-6cfd6c6766-cqfm7
I0924 12:55:00.071044    6058 generic_scheduler.go:1052] Node master is a potential node for preemption.
I0924 12:55:00.071276    6058 factory.go:470] Unable to schedule system/kube-system/coredns-default-6cfd6c6766-cqfm7: no fit: 0/1 nodes are available: 1 node(s) runtime is not ready.; waiting
I0924 12:55:00.071323    6058 scheduler.go:787] Updating pod condition for system/kube-system/coredns-default-6cfd6c6766-cqfm7 to (PodScheduled==False, Reason=Unschedulable)
I0924 12:55:00.284688    6058 scheduler.go:576] Attempting to schedule pod: system/kube-system/coredns-default-6cfd6c6766-cqfm7
I0924 12:55:00.291508    6058 generic_scheduler.go:1052] Node master is a potential node for preemption.
I0924 12:55:00.291730    6058 factory.go:470] Unable to schedule system/kube-system/coredns-default-6cfd6c6766-cqfm7: no fit: 0/1 nodes are available: 1 node(s) runtime is not ready.; waiting
I0924 12:55:00.291777    6058 scheduler.go:787] Updating pod condition for system/kube-system/coredns-default-6cfd6c6766-cqfm7 to (PodScheduled==False, Reason=Unschedulable)
I0924 12:55:02.553622    6058 scheduler.go:576] Attempting to schedule pod: system/kube-system/kube-dns-7f4bf79dc-pvldq
I0924 12:55:02.562013    6058 generic_scheduler.go:1052] Node master is a potential node for preemption.
I0924 12:55:02.562260    6058 factory.go:470] Unable to schedule system/kube-system/kube-dns-7f4bf79dc-pvldq: no fit: 0/1 nodes are available: 1 node(s) runtime is not ready.; waiting
I0924 12:55:02.562306    6058 scheduler.go:787] Updating pod condition for system/kube-system/kube-dns-7f4bf79dc-pvldq to (PodScheduled==False, Reason=Unschedulable)
I0924 12:55:02.801233    6058 scheduler.go:576] Attempting to schedule pod: system/kube-system/kube-dns-7f4bf79dc-pvldq
I0924 12:55:02.807602    6058 generic_scheduler.go:1052] Node master is a potential node for preemption.
I0924 12:55:02.807894    6058 factory.go:470] Unable to schedule system/kube-system/kube-dns-7f4bf79dc-pvldq: no fit: 0/1 nodes are available: 1 node(s) runtime is not ready.; waiting
I0924 12:55:02.807952    6058 scheduler.go:787] Updating pod condition for system/kube-system/kube-dns-7f4bf79dc-pvldq to (PodScheduled==False, Reason=Unschedulable)
I0924 12:55:11.158733    6058 scheduler.go:576] Attempting to schedule pod: system/kube-system/coredns-default-6cfd6c6766-cqfm7
I0924 12:55:11.167928    6058 generic_scheduler.go:1052] Node master is a potential node for preemption.
I0924 12:55:11.168315    6058 factory.go:470] Unable to schedule system/kube-system/coredns-default-6cfd6c6766-cqfm7: no fit: 0/1 nodes are available: 1 node(s) runtime is not ready.; waiting
I0924 12:55:11.168386    6058 scheduler.go:787] Updating pod condition for system/kube-system/coredns-default-6cfd6c6766-cqfm7 to (PodScheduled==False, Reason=Unschedulable)
I0924 12:55:13.159265    6058 scheduler.go:576] Attempting to schedule pod: system/kube-system/kube-dns-7f4bf79dc-pvldq
I0924 12:55:13.169322    6058 generic_scheduler.go:1052] Node master is a potential node for preemption.
I0924 12:55:13.170084    6058 factory.go:470] Unable to schedule system/kube-system/kube-dns-7f4bf79dc-pvldq: no fit: 0/1 nodes are available: 1 node(s) runtime is not ready.; waiting
I0924 12:55:13.170239    6058 scheduler.go:787] Updating pod condition for system/kube-system/kube-dns-7f4bf79dc-pvldq to (PodScheduled==False, Reason=Unschedulable)
I0924 12:55:20.281375    6058 scheduler.go:576] Attempting to schedule pod: system/kube-system/coredns-default-6cfd6c6766-cqfm7
I0924 12:55:20.290640    6058 generic_scheduler.go:1052] Node master is a potential node for preemption.
I0924 12:55:20.290926    6058 factory.go:470] Unable to schedule system/kube-system/coredns-default-6cfd6c6766-cqfm7: no fit: 0/1 nodes are available: 1 node(s) runtime is not ready.; waiting
I0924 12:55:20.291013    6058 scheduler.go:787] Updating pod condition for system/kube-system/coredns-default-6cfd6c6766-cqfm7 to (PodScheduled==False, Reason=Unschedulable)
I0924 12:55:20.492291    6058 scheduler.go:576] Attempting to schedule pod: system/kube-system/coredns-default-6cfd6c6766-cqfm7
I0924 12:55:20.559663    6058 generic_scheduler.go:1052] Node master is a potential node for preemption.
I0924 12:55:20.559989    6058 factory.go:470] Unable to schedule system/kube-system/coredns-default-6cfd6c6766-cqfm7: no fit: 0/1 nodes are available: 1 node(s) runtime is not ready.; waiting
I0924 12:55:20.560072    6058 scheduler.go:787] Updating pod condition for system/kube-system/coredns-default-6cfd6c6766-cqfm7 to (PodScheduled==False, Reason=Unschedulable)
I0924 12:55:22.803154    6058 scheduler.go:576] Attempting to schedule pod: system/kube-system/kube-dns-7f4bf79dc-pvldq
I0924 12:55:22.810527    6058 generic_scheduler.go:1052] Node master is a potential node for preemption.
I0924 12:55:22.810765    6058 factory.go:470] Unable to schedule system/kube-system/kube-dns-7f4bf79dc-pvldq: no fit: 0/1 nodes are available: 1 node(s) runtime is not ready.; waiting
I0924 12:55:22.810835    6058 scheduler.go:787] Updating pod condition for system/kube-system/kube-dns-7f4bf79dc-pvldq to (PodScheduled==False, Reason=Unschedulable)
I0924 12:55:23.054824    6058 scheduler.go:576] Attempting to schedule pod: system/kube-system/kube-dns-7f4bf79dc-pvldq
I0924 12:55:23.090362    6058 generic_scheduler.go:1052] Node master is a potential node for preemption.
I0924 12:55:23.091107    6058 factory.go:470] Unable to schedule system/kube-system/kube-dns-7f4bf79dc-pvldq: no fit: 0/1 nodes are available: 1 node(s) runtime is not ready.; waiting
I0924 12:55:23.091253    6058 scheduler.go:787] Updating pod condition for system/kube-system/kube-dns-7f4bf79dc-pvldq to (PodScheduled==False, Reason=Unschedulable)
I0924 12:55:31.166633    6058 scheduler.go:576] Attempting to schedule pod: system/kube-system/coredns-default-6cfd6c6766-cqfm7
I0924 12:55:31.736950    6058 generic_scheduler.go:1052] Node master is a potential node for preemption.
I0924 12:55:31.737230    6058 factory.go:470] Unable to schedule system/kube-system/coredns-default-6cfd6c6766-cqfm7: no fit: 0/1 nodes are available: 1 node(s) runtime is not ready.; waiting
I0924 12:55:31.737288    6058 scheduler.go:787] Updating pod condition for system/kube-system/coredns-default-6cfd6c6766-cqfm7 to (PodScheduled==False, Reason=Unschedulable)
I0924 12:55:33.167100    6058 scheduler.go:576] Attempting to schedule pod: system/kube-system/kube-dns-7f4bf79dc-pvldq
I0924 12:55:33.175277    6058 generic_scheduler.go:1052] Node master is a potential node for preemption.
I0924 12:55:33.175655    6058 factory.go:470] Unable to schedule system/kube-system/kube-dns-7f4bf79dc-pvldq: no fit: 0/1 nodes are available: 1 node(s) runtime is not ready.; waiting
I0924 12:55:33.175725    6058 scheduler.go:787] Updating pod condition for system/kube-system/kube-dns-7f4bf79dc-pvldq to (PodScheduled==False, Reason=Unschedulable)
I0924 12:55:40.499647    6058 scheduler.go:576] Attempting to schedule pod: system/kube-system/coredns-default-6cfd6c6766-cqfm7
I0924 12:55:40.510229    6058 generic_scheduler.go:1052] Node master is a potential node for preemption.
I0924 12:55:40.510535    6058 factory.go:470] Unable to schedule system/kube-system/coredns-default-6cfd6c6766-cqfm7: no fit: 0/1 nodes are available: 1 node(s) runtime is not ready.; waiting
I0924 12:55:40.510606    6058 scheduler.go:787] Updating pod condition for system/kube-system/coredns-default-6cfd6c6766-cqfm7 to (PodScheduled==False, Reason=Unschedulable)
I0924 12:55:40.710238    6058 scheduler.go:576] Attempting to schedule pod: system/kube-system/coredns-default-6cfd6c6766-cqfm7
I0924 12:55:40.718326    6058 generic_scheduler.go:1052] Node master is a potential node for preemption.
I0924 12:55:40.718597    6058 factory.go:470] Unable to schedule system/kube-system/coredns-default-6cfd6c6766-cqfm7: no fit: 0/1 nodes are available: 1 node(s) runtime is not ready.; waiting
I0924 12:55:40.718650    6058 scheduler.go:787] Updating pod condition for system/kube-system/coredns-default-6cfd6c6766-cqfm7 to (PodScheduled==False, Reason=Unschedulable)
I0924 12:55:43.055436    6058 scheduler.go:576] Attempting to schedule pod: system/kube-system/kube-dns-7f4bf79dc-pvldq
I0924 12:55:44.098592    6058 generic_scheduler.go:1052] Node master is a potential node for preemption.
I0924 12:55:44.099564    6058 factory.go:470] Unable to schedule system/kube-system/kube-dns-7f4bf79dc-pvldq: no fit: 0/1 nodes are available: 1 node(s) runtime is not ready.; waiting
I0924 12:55:44.099750    6058 scheduler.go:787] Updating pod condition for system/kube-system/kube-dns-7f4bf79dc-pvldq to (PodScheduled==False, Reason=Unschedulable)
I0924 12:55:44.411988    6058 scheduler.go:576] Attempting to schedule pod: system/kube-system/kube-dns-7f4bf79dc-pvldq
I0924 12:55:44.428629    6058 generic_scheduler.go:1052] Node master is a potential node for preemption.
I0924 12:55:44.428929    6058 factory.go:470] Unable to schedule system/kube-system/kube-dns-7f4bf79dc-pvldq: no fit: 0/1 nodes are available: 1 node(s) runtime is not ready.; waiting
I0924 12:55:44.428995    6058 scheduler.go:787] Updating pod condition for system/kube-system/kube-dns-7f4bf79dc-pvldq to (PodScheduled==False, Reason=Unschedulable)
I0924 12:55:51.180247    6058 scheduler.go:576] Attempting to schedule pod: system/kube-system/coredns-default-6cfd6c6766-cqfm7
I0924 12:55:51.188338    6058 generic_scheduler.go:1052] Node master is a potential node for preemption.
I0924 12:55:51.188753    6058 factory.go:470] Unable to schedule system/kube-system/coredns-default-6cfd6c6766-cqfm7: no fit: 0/1 nodes are available: 1 node(s) runtime is not ready.; waiting
I0924 12:55:51.188835    6058 scheduler.go:787] Updating pod condition for system/kube-system/coredns-default-6cfd6c6766-cqfm7 to (PodScheduled==False, Reason=Unschedulable)
I0924 12:55:55.181638    6058 scheduler.go:576] Attempting to schedule pod: system/kube-system/kube-dns-7f4bf79dc-pvldq
I0924 12:55:55.188243    6058 generic_scheduler.go:1052] Node master is a potential node for preemption.
I0924 12:55:55.188602    6058 factory.go:470] Unable to schedule system/kube-system/kube-dns-7f4bf79dc-pvldq: no fit: 0/1 nodes are available: 1 node(s) runtime is not ready.; waiting
I0924 12:55:55.188669    6058 scheduler.go:787] Updating pod condition for system/kube-system/kube-dns-7f4bf79dc-pvldq to (PodScheduled==False, Reason=Unschedulable)
I0924 12:56:00.742389    6058 scheduler.go:576] Attempting to schedule pod: system/kube-system/coredns-default-6cfd6c6766-cqfm7
I0924 12:56:00.813607    6058 generic_scheduler.go:1052] Node master is a potential node for preemption.
I0924 12:56:00.813952    6058 factory.go:470] Unable to schedule system/kube-system/coredns-default-6cfd6c6766-cqfm7: no fit: 0/1 nodes are available: 1 node(s) runtime is not ready.; waiting
I0924 12:56:00.814014    6058 scheduler.go:787] Updating pod condition for system/kube-system/coredns-default-6cfd6c6766-cqfm7 to (PodScheduled==False, Reason=Unschedulable)
I0924 12:56:01.264371    6058 scheduler.go:576] Attempting to schedule pod: system/kube-system/coredns-default-6cfd6c6766-cqfm7
I0924 12:56:01.310211    6058 generic_scheduler.go:1052] Node master is a potential node for preemption.
I0924 12:56:01.310522    6058 factory.go:470] Unable to schedule system/kube-system/coredns-default-6cfd6c6766-cqfm7: no fit: 0/1 nodes are available: 1 node(s) runtime is not ready.; waiting
I0924 12:56:01.310788    6058 scheduler.go:787] Updating pod condition for system/kube-system/coredns-default-6cfd6c6766-cqfm7 to (PodScheduled==False, Reason=Unschedulable)
I0924 12:56:04.533940    6058 scheduler.go:576] Attempting to schedule pod: system/kube-system/kube-dns-7f4bf79dc-pvldq
I0924 12:56:04.819357    6058 generic_scheduler.go:1052] Node master is a potential node for preemption.
I0924 12:56:04.825633    6058 factory.go:470] Unable to schedule system/kube-system/kube-dns-7f4bf79dc-pvldq: no fit: 0/1 nodes are available: 1 node(s) runtime is not ready.; waiting
I0924 12:56:04.825804    6058 scheduler.go:787] Updating pod condition for system/kube-system/kube-dns-7f4bf79dc-pvldq to (PodScheduled==False, Reason=Unschedulable)
I0924 12:56:06.809974    6058 scheduler.go:576] Attempting to schedule pod: system/kube-system/kube-dns-7f4bf79dc-pvldq
I0924 12:56:08.529533    6058 generic_scheduler.go:1052] Node master is a potential node for preemption.
I0924 12:56:08.602248    6058 factory.go:470] Unable to schedule system/kube-system/kube-dns-7f4bf79dc-pvldq: no fit: 0/1 nodes are available: 1 node(s) runtime is not ready.; waiting
I0924 12:56:08.603346    6058 scheduler.go:787] Updating pod condition for system/kube-system/kube-dns-7f4bf79dc-pvldq to (PodScheduled==False, Reason=Unschedulable)
I0924 12:56:11.624600    6058 scheduler.go:576] Attempting to schedule pod: system/kube-system/coredns-default-6cfd6c6766-cqfm7
I0924 12:56:11.837688    6058 generic_scheduler.go:1052] Node master is a potential node for preemption.
I0924 12:56:11.839153    6058 factory.go:470] Unable to schedule system/kube-system/coredns-default-6cfd6c6766-cqfm7: no fit: 0/1 nodes are available: 1 node(s) runtime is not ready.; waiting
I0924 12:56:11.839271    6058 scheduler.go:787] Updating pod condition for system/kube-system/coredns-default-6cfd6c6766-cqfm7 to (PodScheduled==False, Reason=Unschedulable)
I0924 12:56:18.827018    6058 scheduler.go:576] Attempting to schedule pod: system/kube-system/kube-dns-7f4bf79dc-pvldq
I0924 12:56:18.867851    6058 generic_scheduler.go:1052] Node master is a potential node for preemption.
I0924 12:56:18.868122    6058 factory.go:470] Unable to schedule system/kube-system/kube-dns-7f4bf79dc-pvldq: no fit: 0/1 nodes are available: 1 node(s) runtime is not ready.; waiting
I0924 12:56:18.868171    6058 scheduler.go:787] Updating pod condition for system/kube-system/kube-dns-7f4bf79dc-pvldq to (PodScheduled==False, Reason=Unschedulable)
I0924 12:56:21.452253    6058 scheduler.go:576] Attempting to schedule pod: system/kube-system/coredns-default-6cfd6c6766-cqfm7
I0924 12:56:21.760923    6058 generic_scheduler.go:1052] Node master is a potential node for preemption.
I0924 12:56:21.761418    6058 factory.go:470] Unable to schedule system/kube-system/coredns-default-6cfd6c6766-cqfm7: no fit: 0/1 nodes are available: 1 node(s) runtime is not ready.; waiting
I0924 12:56:22.198405    6058 scheduler.go:787] Updating pod condition for system/kube-system/coredns-default-6cfd6c6766-cqfm7 to (PodScheduled==False, Reason=Unschedulable)
I0924 12:56:24.908124    6058 scheduler.go:576] Attempting to schedule pod: system/kube-system/coredns-default-6cfd6c6766-cqfm7
I0924 12:56:25.131296    6058 generic_scheduler.go:1052] Node master is a potential node for preemption.
I0924 12:56:25.131592    6058 factory.go:470] Unable to schedule system/kube-system/coredns-default-6cfd6c6766-cqfm7: no fit: 0/1 nodes are available: 1 node(s) runtime is not ready.; waiting
I0924 12:56:25.131646    6058 scheduler.go:787] Updating pod condition for system/kube-system/coredns-default-6cfd6c6766-cqfm7 to (PodScheduled==False, Reason=Unschedulable)
I0924 12:56:27.530824    6058 scheduler.go:576] Attempting to schedule pod: system/kube-system/kube-dns-7f4bf79dc-pvldq
I0924 12:56:27.770868    6058 generic_scheduler.go:1052] Node master is a potential node for preemption.
I0924 12:56:27.771234    6058 factory.go:470] Unable to schedule system/kube-system/kube-dns-7f4bf79dc-pvldq: no fit: 0/1 nodes are available: 1 node(s) runtime is not ready.; waiting
I0924 12:56:27.771293    6058 scheduler.go:787] Updating pod condition for system/kube-system/kube-dns-7f4bf79dc-pvldq to (PodScheduled==False, Reason=Unschedulable)
I0924 12:56:32.108727    6058 scheduler.go:576] Attempting to schedule pod: system/kube-system/kube-dns-7f4bf79dc-pvldq
I0924 12:56:32.423591    6058 generic_scheduler.go:1052] Node master is a potential node for preemption.
I0924 12:56:32.423906    6058 factory.go:470] Unable to schedule system/kube-system/kube-dns-7f4bf79dc-pvldq: no fit: 0/1 nodes are available: 1 node(s) runtime is not ready.; waiting
I0924 12:56:32.423956    6058 scheduler.go:787] Updating pod condition for system/kube-system/kube-dns-7f4bf79dc-pvldq to (PodScheduled==False, Reason=Unschedulable)
I0924 12:56:36.226165    6058 scheduler.go:576] Attempting to schedule pod: system/kube-system/coredns-default-6cfd6c6766-cqfm7
I0924 12:56:36.988527    6058 generic_scheduler.go:1052] Node master is a potential node for preemption.
I0924 12:56:36.988817    6058 factory.go:470] Unable to schedule system/kube-system/coredns-default-6cfd6c6766-cqfm7: no fit: 0/1 nodes are available: 1 node(s) runtime is not ready.; waiting
I0924 12:56:36.988866    6058 scheduler.go:787] Updating pod condition for system/kube-system/coredns-default-6cfd6c6766-cqfm7 to (PodScheduled==False, Reason=Unschedulable)
I0924 12:56:42.554005    6058 scheduler.go:576] Attempting to schedule pod: system/kube-system/kube-dns-7f4bf79dc-pvldq
I0924 12:56:43.938994    6058 generic_scheduler.go:1052] Node master is a potential node for preemption.
I0924 12:56:43.941033    6058 factory.go:470] Unable to schedule system/kube-system/kube-dns-7f4bf79dc-pvldq: no fit: 0/1 nodes are available: 1 node(s) runtime is not ready.; waiting
I0924 12:56:43.941148    6058 scheduler.go:787] Updating pod condition for system/kube-system/kube-dns-7f4bf79dc-pvldq to (PodScheduled==False, Reason=Unschedulable)
I0924 12:56:48.454350    6058 scheduler.go:576] Attempting to schedule pod: system/kube-system/coredns-default-6cfd6c6766-cqfm7
I0924 12:57:01.944382    6058 generic_scheduler.go:1052] Node master is a potential node for preemption.
I0924 12:57:01.944743    6058 factory.go:470] Unable to schedule system/kube-system/coredns-default-6cfd6c6766-cqfm7: no fit: 0/1 nodes are available: 1 node(s) runtime is not ready.; waiting
I0924 12:57:01.944830    6058 scheduler.go:787] Updating pod condition for system/kube-system/coredns-default-6cfd6c6766-cqfm7 to (PodScheduled==False, Reason=Unschedulable)
I0924 12:57:01.946156    6058 scheduler.go:576] Attempting to schedule pod: system/kube-system/kube-dns-7f4bf79dc-pvldq
E0924 12:57:03.069261    6058 factory.go:512] pod: system/kube-system/coredns-default-6cfd6c6766-cqfm7 is already present in the active queue
I0924 12:57:03.122754    6058 generic_scheduler.go:1052] Node master is a potential node for preemption.
I0924 12:57:03.135040    6058 factory.go:470] Unable to schedule system/kube-system/kube-dns-7f4bf79dc-pvldq: no fit: 0/1 nodes are available: 1 node(s) runtime is not ready.; waiting
I0924 12:57:03.135161    6058 scheduler.go:787] Updating pod condition for system/kube-system/kube-dns-7f4bf79dc-pvldq to (PodScheduled==False, Reason=Unschedulable)
I0924 12:57:03.137396    6058 scheduler.go:576] Attempting to schedule pod: system/kube-system/coredns-default-6cfd6c6766-cqfm7
I0924 12:57:04.603269    6058 generic_scheduler.go:1052] Node master is a potential node for preemption.
I0924 12:57:04.669939    6058 factory.go:470] Unable to schedule system/kube-system/coredns-default-6cfd6c6766-cqfm7: no fit: 0/1 nodes are available: 1 node(s) runtime is not ready.; waiting
I0924 12:57:04.604275    6058 eventhandlers.go:183] add event for unscheduled pod system/default/mizar-operator-6985d77546-596pp
I0924 12:57:04.670016    6058 scheduler.go:787] Updating pod condition for system/kube-system/coredns-default-6cfd6c6766-cqfm7 to (PodScheduled==False, Reason=Unschedulable)
I0924 12:57:04.672224    6058 scheduler.go:576] Attempting to schedule pod: system/default/mizar-operator-6985d77546-596pp
I0924 12:57:04.672775    6058 default_binder.go:53] Attempting to bind system/default/mizar-operator-6985d77546-596pp to master
I0924 12:57:04.729671    6058 cache.go:757] Couldn't expire cache for pod system/default/mizar-operator-6985d77546-596pp. Binding is still in progress.
I0924 12:57:05.745275    6058 cache.go:757] Couldn't expire cache for pod system/default/mizar-operator-6985d77546-596pp. Binding is still in progress.
I0924 12:57:06.110971    6058 eventhandlers.go:215] delete event for unscheduled pod system/default/mizar-operator-6985d77546-596pp
I0924 12:57:06.111019    6058 eventhandlers.go:239] add event for scheduled pod system/default/mizar-operator-6985d77546-596pp 
I0924 12:57:06.112304    6058 scheduler.go:741] pod system/default/mizar-operator-6985d77546-596pp is bound successfully on node "master", 1 nodes evaluated, 1 nodes were found feasible.
I0924 12:57:06.753683    6058 scheduler.go:576] Attempting to schedule pod: system/kube-system/coredns-default-6cfd6c6766-cqfm7
I0924 12:57:07.230962    6058 generic_scheduler.go:1052] Node master is a potential node for preemption.
I0924 12:57:07.231292    6058 factory.go:470] Unable to schedule system/kube-system/coredns-default-6cfd6c6766-cqfm7: no fit: 0/1 nodes are available: 1 node(s) runtime is not ready.; waiting
I0924 12:57:07.231353    6058 scheduler.go:787] Updating pod condition for system/kube-system/coredns-default-6cfd6c6766-cqfm7 to (PodScheduled==False, Reason=Unschedulable)
I0924 12:57:10.480628    6058 scheduler.go:576] Attempting to schedule pod: system/kube-system/coredns-default-6cfd6c6766-cqfm7
I0924 12:57:10.964171    6058 generic_scheduler.go:1052] Node master is a potential node for preemption.
I0924 12:57:10.964491    6058 factory.go:470] Unable to schedule system/kube-system/coredns-default-6cfd6c6766-cqfm7: no fit: 0/1 nodes are available: 1 node(s) runtime is not ready.; waiting
I0924 12:57:10.964550    6058 scheduler.go:787] Updating pod condition for system/kube-system/coredns-default-6cfd6c6766-cqfm7 to (PodScheduled==False, Reason=Unschedulable)
I0924 12:57:13.863836    6058 scheduler.go:576] Attempting to schedule pod: system/kube-system/kube-dns-7f4bf79dc-pvldq
I0924 12:57:13.876175    6058 generic_scheduler.go:1052] Node master is a potential node for preemption.
I0924 12:57:13.876451    6058 factory.go:470] Unable to schedule system/kube-system/kube-dns-7f4bf79dc-pvldq: no fit: 0/1 nodes are available: 1 node(s) runtime is not ready.; waiting
I0924 12:57:13.876522    6058 scheduler.go:787] Updating pod condition for system/kube-system/kube-dns-7f4bf79dc-pvldq to (PodScheduled==False, Reason=Unschedulable)
I0924 12:57:16.027579    6058 scheduler.go:576] Attempting to schedule pod: system/kube-system/coredns-default-6cfd6c6766-cqfm7
I0924 12:57:16.550569    6058 generic_scheduler.go:1052] Node master is a potential node for preemption.
I0924 12:57:16.550910    6058 factory.go:470] Unable to schedule system/kube-system/coredns-default-6cfd6c6766-cqfm7: no fit: 0/1 nodes are available: 1 node(s) runtime is not ready.; waiting
I0924 12:57:16.550962    6058 scheduler.go:787] Updating pod condition for system/kube-system/coredns-default-6cfd6c6766-cqfm7 to (PodScheduled==False, Reason=Unschedulable)
I0924 12:57:24.623233    6058 scheduler.go:576] Attempting to schedule pod: system/kube-system/kube-dns-7f4bf79dc-pvldq
I0924 12:57:25.026960    6058 generic_scheduler.go:1052] Node master is a potential node for preemption.
I0924 12:57:25.027351    6058 factory.go:470] Unable to schedule system/kube-system/kube-dns-7f4bf79dc-pvldq: no fit: 0/1 nodes are available: 1 node(s) runtime is not ready.; waiting
I0924 12:57:25.027413    6058 scheduler.go:787] Updating pod condition for system/kube-system/kube-dns-7f4bf79dc-pvldq to (PodScheduled==False, Reason=Unschedulable)
I0924 12:57:25.852412    6058 scheduler.go:576] Attempting to schedule pod: system/kube-system/coredns-default-6cfd6c6766-cqfm7
I0924 12:57:26.295553    6058 generic_scheduler.go:1052] Node master is a potential node for preemption.
I0924 12:57:26.295826    6058 factory.go:470] Unable to schedule system/kube-system/coredns-default-6cfd6c6766-cqfm7: no fit: 0/1 nodes are available: 1 node(s) runtime is not ready.; waiting
I0924 12:57:26.295882    6058 scheduler.go:787] Updating pod condition for system/kube-system/coredns-default-6cfd6c6766-cqfm7 to (PodScheduled==False, Reason=Unschedulable)
I0924 12:57:35.304263    6058 scheduler.go:576] Attempting to schedule pod: system/kube-system/kube-dns-7f4bf79dc-pvldq
I0924 12:57:35.391593    6058 generic_scheduler.go:1052] Node master is a potential node for preemption.
I0924 12:57:35.392252    6058 factory.go:470] Unable to schedule system/kube-system/kube-dns-7f4bf79dc-pvldq: no fit: 0/1 nodes are available: 1 node(s) runtime is not ready.; waiting
I0924 12:57:35.392413    6058 scheduler.go:787] Updating pod condition for system/kube-system/kube-dns-7f4bf79dc-pvldq to (PodScheduled==False, Reason=Unschedulable)
I0924 12:57:37.379571    6058 scheduler.go:576] Attempting to schedule pod: system/kube-system/coredns-default-6cfd6c6766-cqfm7
I0924 12:57:37.666759    6058 generic_scheduler.go:1052] Node master is a potential node for preemption.
I0924 12:57:37.667038    6058 factory.go:470] Unable to schedule system/kube-system/coredns-default-6cfd6c6766-cqfm7: no fit: 0/1 nodes are available: 1 node(s) runtime is not ready.; waiting
I0924 12:57:37.667085    6058 scheduler.go:787] Updating pod condition for system/kube-system/coredns-default-6cfd6c6766-cqfm7 to (PodScheduled==False, Reason=Unschedulable)
I0924 12:57:46.186157    6058 scheduler.go:576] Attempting to schedule pod: system/kube-system/kube-dns-7f4bf79dc-pvldq
I0924 12:57:46.284647    6058 generic_scheduler.go:1052] Node master is a potential node for preemption.
I0924 12:57:46.285074    6058 factory.go:470] Unable to schedule system/kube-system/kube-dns-7f4bf79dc-pvldq: no fit: 0/1 nodes are available: 1 node(s) runtime is not ready.; waiting
I0924 12:57:46.285275    6058 scheduler.go:787] Updating pod condition for system/kube-system/kube-dns-7f4bf79dc-pvldq to (PodScheduled==False, Reason=Unschedulable)
I0924 12:57:48.293079    6058 scheduler.go:576] Attempting to schedule pod: system/kube-system/coredns-default-6cfd6c6766-cqfm7
I0924 12:57:48.605559    6058 generic_scheduler.go:1052] Node master is a potential node for preemption.
I0924 12:57:48.605859    6058 factory.go:470] Unable to schedule system/kube-system/coredns-default-6cfd6c6766-cqfm7: no fit: 0/1 nodes are available: 1 node(s) runtime is not ready.; waiting
I0924 12:57:48.605915    6058 scheduler.go:787] Updating pod condition for system/kube-system/coredns-default-6cfd6c6766-cqfm7 to (PodScheduled==False, Reason=Unschedulable)
I0924 12:57:56.786655    6058 scheduler.go:576] Attempting to schedule pod: system/kube-system/kube-dns-7f4bf79dc-pvldq
I0924 12:57:56.864179    6058 generic_scheduler.go:1052] Node master is a potential node for preemption.
I0924 12:57:56.864509    6058 factory.go:470] Unable to schedule system/kube-system/kube-dns-7f4bf79dc-pvldq: no fit: 0/1 nodes are available: 1 node(s) runtime is not ready.; waiting
I0924 12:57:56.864569    6058 scheduler.go:787] Updating pod condition for system/kube-system/kube-dns-7f4bf79dc-pvldq to (PodScheduled==False, Reason=Unschedulable)
I0924 12:57:58.809634    6058 scheduler.go:576] Attempting to schedule pod: system/kube-system/coredns-default-6cfd6c6766-cqfm7
I0924 12:57:59.025861    6058 generic_scheduler.go:1052] Node master is a potential node for preemption.
I0924 12:57:59.026160    6058 factory.go:470] Unable to schedule system/kube-system/coredns-default-6cfd6c6766-cqfm7: no fit: 0/1 nodes are available: 1 node(s) runtime is not ready.; waiting
I0924 12:57:59.026217    6058 scheduler.go:787] Updating pod condition for system/kube-system/coredns-default-6cfd6c6766-cqfm7 to (PodScheduled==False, Reason=Unschedulable)
I0924 12:58:07.733254    6058 scheduler.go:576] Attempting to schedule pod: system/kube-system/kube-dns-7f4bf79dc-pvldq
I0924 12:58:07.940339    6058 generic_scheduler.go:1052] Node master is a potential node for preemption.
I0924 12:58:07.940668    6058 factory.go:470] Unable to schedule system/kube-system/kube-dns-7f4bf79dc-pvldq: no fit: 0/1 nodes are available: 1 node(s) runtime is not ready.; waiting
I0924 12:58:07.940721    6058 scheduler.go:787] Updating pod condition for system/kube-system/kube-dns-7f4bf79dc-pvldq to (PodScheduled==False, Reason=Unschedulable)
I0924 12:58:09.825963    6058 scheduler.go:576] Attempting to schedule pod: system/kube-system/coredns-default-6cfd6c6766-cqfm7
I0924 12:58:10.027033    6058 generic_scheduler.go:1052] Node master is a potential node for preemption.
I0924 12:58:10.027314    6058 factory.go:470] Unable to schedule system/kube-system/coredns-default-6cfd6c6766-cqfm7: no fit: 0/1 nodes are available: 1 node(s) runtime is not ready.; waiting
I0924 12:58:10.027379    6058 scheduler.go:787] Updating pod condition for system/kube-system/coredns-default-6cfd6c6766-cqfm7 to (PodScheduled==False, Reason=Unschedulable)
I0924 12:58:18.610007    6058 scheduler.go:576] Attempting to schedule pod: system/kube-system/kube-dns-7f4bf79dc-pvldq
I0924 12:58:19.316445    6058 generic_scheduler.go:1052] Node master is a potential node for preemption.
I0924 12:58:19.316897    6058 factory.go:470] Unable to schedule system/kube-system/kube-dns-7f4bf79dc-pvldq: no fit: 0/1 nodes are available: 1 node(s) runtime is not ready.; waiting
I0924 12:58:19.316970    6058 scheduler.go:787] Updating pod condition for system/kube-system/kube-dns-7f4bf79dc-pvldq to (PodScheduled==False, Reason=Unschedulable)
I0924 12:58:20.941895    6058 scheduler.go:576] Attempting to schedule pod: system/kube-system/coredns-default-6cfd6c6766-cqfm7
I0924 12:58:21.099342    6058 generic_scheduler.go:1052] Node master is a potential node for preemption.
I0924 12:58:22.108846    6058 factory.go:470] Unable to schedule system/kube-system/coredns-default-6cfd6c6766-cqfm7: no fit: 0/1 nodes are available: 1 node(s) runtime is not ready.; waiting
I0924 12:58:22.108943    6058 scheduler.go:787] Updating pod condition for system/kube-system/coredns-default-6cfd6c6766-cqfm7 to (PodScheduled==False, Reason=Unschedulable)
I0924 12:58:30.043497    6058 scheduler.go:576] Attempting to schedule pod: system/kube-system/kube-dns-7f4bf79dc-pvldq
I0924 12:58:30.054678    6058 generic_scheduler.go:1052] Node master is a potential node for preemption.
I0924 12:58:30.054950    6058 factory.go:470] Unable to schedule system/kube-system/kube-dns-7f4bf79dc-pvldq: no fit: 0/1 nodes are available: 1 node(s) runtime is not ready.; waiting
I0924 12:58:30.055002    6058 scheduler.go:787] Updating pod condition for system/kube-system/kube-dns-7f4bf79dc-pvldq to (PodScheduled==False, Reason=Unschedulable)
I0924 12:58:33.161032    6058 scheduler.go:576] Attempting to schedule pod: system/kube-system/coredns-default-6cfd6c6766-cqfm7
I0924 12:58:33.397082    6058 generic_scheduler.go:1052] Node master is a potential node for preemption.
I0924 12:58:33.397848    6058 factory.go:470] Unable to schedule system/kube-system/coredns-default-6cfd6c6766-cqfm7: no fit: 0/1 nodes are available: 1 node(s) runtime is not ready.; waiting
I0924 12:58:33.398801    6058 scheduler.go:787] Updating pod condition for system/kube-system/coredns-default-6cfd6c6766-cqfm7 to (PodScheduled==False, Reason=Unschedulable)
I0924 12:58:36.013242    6058 scheduler.go:576] Attempting to schedule pod: system/kube-system/coredns-default-6cfd6c6766-cqfm7
I0924 12:58:37.022441    6058 generic_scheduler.go:1052] Node master is a potential node for preemption.
I0924 12:58:37.022728    6058 factory.go:470] Unable to schedule system/kube-system/coredns-default-6cfd6c6766-cqfm7: no fit: 0/1 nodes are available: 1 node(s) runtime is not ready.; waiting
I0924 12:58:37.022798    6058 scheduler.go:787] Updating pod condition for system/kube-system/coredns-default-6cfd6c6766-cqfm7 to (PodScheduled==False, Reason=Unschedulable)
I0924 12:58:37.043184    6058 scheduler.go:576] Attempting to schedule pod: system/kube-system/kube-dns-7f4bf79dc-pvldq
I0924 12:58:37.139132    6058 eventhandlers.go:308] delete event for scheduled pod system/default/mizar-operator-6985d77546-n8jsm 
I0924 12:58:37.383815    6058 generic_scheduler.go:1052] Node master is a potential node for preemption.
I0924 12:58:37.384124    6058 factory.go:470] Unable to schedule system/kube-system/kube-dns-7f4bf79dc-pvldq: no fit: 0/1 nodes are available: 1 node(s) runtime is not ready.; waiting
I0924 12:58:37.384180    6058 scheduler.go:787] Updating pod condition for system/kube-system/kube-dns-7f4bf79dc-pvldq to (PodScheduled==False, Reason=Unschedulable)
I0924 12:58:47.714232    6058 scheduler.go:576] Attempting to schedule pod: system/kube-system/coredns-default-6cfd6c6766-cqfm7
I0924 12:58:47.741999    6058 generic_scheduler.go:1052] Node master is a potential node for preemption.
I0924 12:58:47.742753    6058 factory.go:470] Unable to schedule system/kube-system/coredns-default-6cfd6c6766-cqfm7: no fit: 0/1 nodes are available: 1 node(s) runtime is not ready.; waiting
I0924 12:58:47.742911    6058 scheduler.go:787] Updating pod condition for system/kube-system/coredns-default-6cfd6c6766-cqfm7 to (PodScheduled==False, Reason=Unschedulable)
I0924 12:58:48.750916    6058 scheduler.go:576] Attempting to schedule pod: system/kube-system/kube-dns-7f4bf79dc-pvldq
I0924 12:58:48.972536    6058 generic_scheduler.go:1052] Node master is a potential node for preemption.
I0924 12:58:49.122012    6058 factory.go:470] Unable to schedule system/kube-system/kube-dns-7f4bf79dc-pvldq: no fit: 0/1 nodes are available: 1 node(s) runtime is not ready.; waiting
I0924 12:58:49.122211    6058 scheduler.go:787] Updating pod condition for system/kube-system/kube-dns-7f4bf79dc-pvldq to (PodScheduled==False, Reason=Unschedulable)
I0924 12:58:54.632857    6058 scheduler.go:576] Attempting to schedule pod: system/kube-system/coredns-default-6cfd6c6766-cqfm7
I0924 12:58:54.723509    6058 generic_scheduler.go:1052] Node master is a potential node for preemption.
I0924 12:58:54.723859    6058 factory.go:470] Unable to schedule system/kube-system/coredns-default-6cfd6c6766-cqfm7: no fit: 0/1 nodes are available: 1 node(s) runtime is not ready.; waiting
I0924 12:58:54.723920    6058 scheduler.go:787] Updating pod condition for system/kube-system/coredns-default-6cfd6c6766-cqfm7 to (PodScheduled==False, Reason=Unschedulable)
I0924 12:58:55.422142    6058 scheduler.go:576] Attempting to schedule pod: system/kube-system/kube-dns-7f4bf79dc-pvldq
I0924 12:58:55.800593    6058 generic_scheduler.go:1052] Node master is a potential node for preemption.
I0924 12:58:55.800960    6058 factory.go:470] Unable to schedule system/kube-system/kube-dns-7f4bf79dc-pvldq: no fit: 0/1 nodes are available: 1 node(s) runtime is not ready.; waiting
I0924 12:58:55.801024    6058 scheduler.go:787] Updating pod condition for system/kube-system/kube-dns-7f4bf79dc-pvldq to (PodScheduled==False, Reason=Unschedulable)
I0924 12:59:00.909326    6058 scheduler.go:576] Attempting to schedule pod: system/kube-system/kube-dns-7f4bf79dc-pvldq
I0924 12:59:01.167796    6058 generic_scheduler.go:1052] Node master is a potential node for preemption.
I0924 12:59:01.168185    6058 factory.go:470] Unable to schedule system/kube-system/kube-dns-7f4bf79dc-pvldq: no fit: 0/1 nodes are available: 1 node(s) runtime is not ready.; waiting
I0924 12:59:01.168327    6058 scheduler.go:787] Updating pod condition for system/kube-system/kube-dns-7f4bf79dc-pvldq to (PodScheduled==False, Reason=Unschedulable)
I0924 12:59:06.017869    6058 scheduler.go:576] Attempting to schedule pod: system/kube-system/coredns-default-6cfd6c6766-cqfm7
I0924 12:59:06.141646    6058 generic_scheduler.go:1052] Node master is a potential node for preemption.
I0924 12:59:06.143503    6058 factory.go:470] Unable to schedule system/kube-system/coredns-default-6cfd6c6766-cqfm7: no fit: 0/1 nodes are available: 1 node(s) runtime is not ready.; waiting
I0924 12:59:06.143564    6058 scheduler.go:787] Updating pod condition for system/kube-system/coredns-default-6cfd6c6766-cqfm7 to (PodScheduled==False, Reason=Unschedulable)
I0924 12:59:12.516687    6058 scheduler.go:576] Attempting to schedule pod: system/kube-system/kube-dns-7f4bf79dc-pvldq
I0924 12:59:12.677900    6058 generic_scheduler.go:1052] Node master is a potential node for preemption.
I0924 12:59:12.678166    6058 factory.go:470] Unable to schedule system/kube-system/kube-dns-7f4bf79dc-pvldq: no fit: 0/1 nodes are available: 1 node(s) runtime is not ready.; waiting
I0924 12:59:12.678218    6058 scheduler.go:787] Updating pod condition for system/kube-system/kube-dns-7f4bf79dc-pvldq to (PodScheduled==False, Reason=Unschedulable)
I0924 12:59:13.276204    6058 scheduler.go:576] Attempting to schedule pod: system/kube-system/coredns-default-6cfd6c6766-cqfm7
I0924 12:59:13.350271    6058 generic_scheduler.go:1052] Node master is a potential node for preemption.
I0924 12:59:13.350539    6058 factory.go:470] Unable to schedule system/kube-system/coredns-default-6cfd6c6766-cqfm7: no fit: 0/1 nodes are available: 1 node(s) runtime is not ready.; waiting
I0924 12:59:13.350590    6058 scheduler.go:787] Updating pod condition for system/kube-system/coredns-default-6cfd6c6766-cqfm7 to (PodScheduled==False, Reason=Unschedulable)
I0924 12:59:19.122834    6058 scheduler.go:576] Attempting to schedule pod: system/kube-system/coredns-default-6cfd6c6766-cqfm7
I0924 12:59:19.350383    6058 generic_scheduler.go:1052] Node master is a potential node for preemption.
I0924 12:59:19.350856    6058 factory.go:470] Unable to schedule system/kube-system/coredns-default-6cfd6c6766-cqfm7: no fit: 0/1 nodes are available: 1 node(s) runtime is not ready.; waiting
I0924 12:59:19.350927    6058 scheduler.go:787] Updating pod condition for system/kube-system/coredns-default-6cfd6c6766-cqfm7 to (PodScheduled==False, Reason=Unschedulable)
I0924 12:59:20.622111    6058 scheduler.go:576] Attempting to schedule pod: system/kube-system/kube-dns-7f4bf79dc-pvldq
I0924 12:59:20.890583    6058 generic_scheduler.go:1052] Node master is a potential node for preemption.
I0924 12:59:20.891128    6058 factory.go:470] Unable to schedule system/kube-system/kube-dns-7f4bf79dc-pvldq: no fit: 0/1 nodes are available: 1 node(s) runtime is not ready.; waiting
I0924 12:59:20.891197    6058 scheduler.go:787] Updating pod condition for system/kube-system/kube-dns-7f4bf79dc-pvldq to (PodScheduled==False, Reason=Unschedulable)
I0924 12:59:23.023823    6058 scheduler.go:576] Attempting to schedule pod: system/kube-system/kube-dns-7f4bf79dc-pvldq
I0924 12:59:23.585856    6058 generic_scheduler.go:1052] Node master is a potential node for preemption.
I0924 12:59:23.586741    6058 factory.go:470] Unable to schedule system/kube-system/kube-dns-7f4bf79dc-pvldq: no fit: 0/1 nodes are available: 1 node(s) runtime is not ready.; waiting
I0924 12:59:23.586862    6058 scheduler.go:787] Updating pod condition for system/kube-system/kube-dns-7f4bf79dc-pvldq to (PodScheduled==False, Reason=Unschedulable)
I0924 12:59:30.403480    6058 scheduler.go:576] Attempting to schedule pod: system/kube-system/coredns-default-6cfd6c6766-cqfm7
I0924 12:59:30.433782    6058 generic_scheduler.go:1052] Node master is a potential node for preemption.
I0924 12:59:30.434122    6058 factory.go:470] Unable to schedule system/kube-system/coredns-default-6cfd6c6766-cqfm7: no fit: 0/1 nodes are available: 1 node(s) runtime is not ready.; waiting
I0924 12:59:30.434204    6058 scheduler.go:787] Updating pod condition for system/kube-system/coredns-default-6cfd6c6766-cqfm7 to (PodScheduled==False, Reason=Unschedulable)
I0924 12:59:34.481795    6058 scheduler.go:576] Attempting to schedule pod: system/kube-system/kube-dns-7f4bf79dc-pvldq
I0924 12:59:34.498526    6058 generic_scheduler.go:1052] Node master is a potential node for preemption.
I0924 12:59:34.498794    6058 factory.go:470] Unable to schedule system/kube-system/kube-dns-7f4bf79dc-pvldq: no fit: 0/1 nodes are available: 1 node(s) runtime is not ready.; waiting
I0924 12:59:34.498845    6058 scheduler.go:787] Updating pod condition for system/kube-system/kube-dns-7f4bf79dc-pvldq to (PodScheduled==False, Reason=Unschedulable)
I0924 12:59:37.907686    6058 scheduler.go:576] Attempting to schedule pod: system/kube-system/coredns-default-6cfd6c6766-cqfm7
I0924 12:59:38.100439    6058 generic_scheduler.go:1052] Node master is a potential node for preemption.
I0924 12:59:38.100769    6058 factory.go:470] Unable to schedule system/kube-system/coredns-default-6cfd6c6766-cqfm7: no fit: 0/1 nodes are available: 1 node(s) runtime is not ready.; waiting
I0924 12:59:38.100823    6058 scheduler.go:787] Updating pod condition for system/kube-system/coredns-default-6cfd6c6766-cqfm7 to (PodScheduled==False, Reason=Unschedulable)
I0924 12:59:45.256322    6058 scheduler.go:576] Attempting to schedule pod: system/kube-system/kube-dns-7f4bf79dc-pvldq
I0924 12:59:45.375897    6058 generic_scheduler.go:1052] Node master is a potential node for preemption.
I0924 12:59:45.376222    6058 factory.go:470] Unable to schedule system/kube-system/kube-dns-7f4bf79dc-pvldq: no fit: 0/1 nodes are available: 1 node(s) runtime is not ready.; waiting
I0924 12:59:45.376281    6058 scheduler.go:787] Updating pod condition for system/kube-system/kube-dns-7f4bf79dc-pvldq to (PodScheduled==False, Reason=Unschedulable)
I0924 12:59:45.922520    6058 scheduler.go:576] Attempting to schedule pod: system/kube-system/kube-dns-7f4bf79dc-pvldq
I0924 12:59:47.393835    6058 generic_scheduler.go:1052] Node master is a potential node for preemption.
I0924 12:59:47.394258    6058 factory.go:470] Unable to schedule system/kube-system/kube-dns-7f4bf79dc-pvldq: no fit: 0/1 nodes are available: 1 node(s) runtime is not ready.; waiting
I0924 12:59:47.394320    6058 scheduler.go:787] Updating pod condition for system/kube-system/kube-dns-7f4bf79dc-pvldq to (PodScheduled==False, Reason=Unschedulable)
I0924 12:59:47.405970    6058 scheduler.go:576] Attempting to schedule pod: system/kube-system/coredns-default-6cfd6c6766-cqfm7
I0924 12:59:48.306208    6058 generic_scheduler.go:1052] Node master is a potential node for preemption.
I0924 12:59:48.306847    6058 factory.go:470] Unable to schedule system/kube-system/coredns-default-6cfd6c6766-cqfm7: no fit: 0/1 nodes are available: 1 node(s) runtime is not ready.; waiting
I0924 12:59:48.306951    6058 scheduler.go:787] Updating pod condition for system/kube-system/coredns-default-6cfd6c6766-cqfm7 to (PodScheduled==False, Reason=Unschedulable)
I0924 12:59:49.384270    6058 scheduler.go:576] Attempting to schedule pod: system/kube-system/kube-dns-7f4bf79dc-pvldq
I0924 12:59:49.487809    6058 generic_scheduler.go:1052] Node master is a potential node for preemption.
I0924 12:59:49.488283    6058 factory.go:470] Unable to schedule system/kube-system/kube-dns-7f4bf79dc-pvldq: no fit: 0/1 nodes are available: 1 node(s) runtime is not ready.; waiting
I0924 12:59:49.488349    6058 scheduler.go:787] Updating pod condition for system/kube-system/kube-dns-7f4bf79dc-pvldq to (PodScheduled==False, Reason=Unschedulable)
I0924 12:59:59.497526    6058 scheduler.go:576] Attempting to schedule pod: system/kube-system/coredns-default-6cfd6c6766-cqfm7
I0924 12:59:59.681330    6058 generic_scheduler.go:1052] Node master is a potential node for preemption.
I0924 12:59:59.681633    6058 factory.go:470] Unable to schedule system/kube-system/coredns-default-6cfd6c6766-cqfm7: no fit: 0/1 nodes are available: 1 node(s) runtime is not ready.; waiting
I0924 12:59:59.681686    6058 scheduler.go:787] Updating pod condition for system/kube-system/coredns-default-6cfd6c6766-cqfm7 to (PodScheduled==False, Reason=Unschedulable)
I0924 13:00:00.521140    6058 scheduler.go:576] Attempting to schedule pod: system/kube-system/kube-dns-7f4bf79dc-pvldq
I0924 13:00:00.651417    6058 generic_scheduler.go:1052] Node master is a potential node for preemption.
I0924 13:00:00.651701    6058 factory.go:470] Unable to schedule system/kube-system/kube-dns-7f4bf79dc-pvldq: no fit: 0/1 nodes are available: 1 node(s) runtime is not ready.; waiting
I0924 13:00:00.651757    6058 scheduler.go:787] Updating pod condition for system/kube-system/kube-dns-7f4bf79dc-pvldq to (PodScheduled==False, Reason=Unschedulable)
I0924 13:00:05.709216    6058 scheduler.go:576] Attempting to schedule pod: system/kube-system/coredns-default-6cfd6c6766-cqfm7
I0924 13:00:06.175697    6058 generic_scheduler.go:1052] Node master is a potential node for preemption.
I0924 13:00:06.176183    6058 factory.go:470] Unable to schedule system/kube-system/coredns-default-6cfd6c6766-cqfm7: no fit: 0/1 nodes are available: 1 node(s) runtime is not ready.; waiting
I0924 13:00:06.176291    6058 scheduler.go:787] Updating pod condition for system/kube-system/coredns-default-6cfd6c6766-cqfm7 to (PodScheduled==False, Reason=Unschedulable)
I0924 13:00:08.294513    6058 scheduler.go:576] Attempting to schedule pod: system/kube-system/coredns-default-6cfd6c6766-cqfm7
I0924 13:00:08.678017    6058 generic_scheduler.go:1052] Node master is a potential node for preemption.
I0924 13:00:08.678347    6058 factory.go:470] Unable to schedule system/kube-system/coredns-default-6cfd6c6766-cqfm7: no fit: 0/1 nodes are available: 1 node(s) runtime is not ready.; waiting
I0924 13:00:08.678417    6058 scheduler.go:787] Updating pod condition for system/kube-system/coredns-default-6cfd6c6766-cqfm7 to (PodScheduled==False, Reason=Unschedulable)
I0924 13:00:08.701865    6058 scheduler.go:576] Attempting to schedule pod: system/kube-system/kube-dns-7f4bf79dc-pvldq
I0924 13:00:08.828240    6058 generic_scheduler.go:1052] Node master is a potential node for preemption.
I0924 13:00:08.828607    6058 factory.go:470] Unable to schedule system/kube-system/kube-dns-7f4bf79dc-pvldq: no fit: 0/1 nodes are available: 1 node(s) runtime is not ready.; waiting
I0924 13:00:08.828664    6058 scheduler.go:787] Updating pod condition for system/kube-system/kube-dns-7f4bf79dc-pvldq to (PodScheduled==False, Reason=Unschedulable)
I0924 13:00:11.313491    6058 scheduler.go:576] Attempting to schedule pod: system/kube-system/kube-dns-7f4bf79dc-pvldq
I0924 13:00:11.432773    6058 generic_scheduler.go:1052] Node master is a potential node for preemption.
I0924 13:00:11.433567    6058 factory.go:470] Unable to schedule system/kube-system/kube-dns-7f4bf79dc-pvldq: no fit: 0/1 nodes are available: 1 node(s) runtime is not ready.; waiting
I0924 13:00:11.433636    6058 scheduler.go:787] Updating pod condition for system/kube-system/kube-dns-7f4bf79dc-pvldq to (PodScheduled==False, Reason=Unschedulable)
I0924 13:00:19.508562    6058 scheduler.go:576] Attempting to schedule pod: system/kube-system/coredns-default-6cfd6c6766-cqfm7
I0924 13:00:20.252249    6058 generic_scheduler.go:1052] Node master is a potential node for preemption.
I0924 13:00:20.252529    6058 factory.go:470] Unable to schedule system/kube-system/coredns-default-6cfd6c6766-cqfm7: no fit: 0/1 nodes are available: 1 node(s) runtime is not ready.; waiting
I0924 13:00:20.252584    6058 scheduler.go:787] Updating pod condition for system/kube-system/coredns-default-6cfd6c6766-cqfm7 to (PodScheduled==False, Reason=Unschedulable)
I0924 13:00:22.752102    6058 scheduler.go:576] Attempting to schedule pod: system/kube-system/kube-dns-7f4bf79dc-pvldq
I0924 13:00:22.959729    6058 generic_scheduler.go:1052] Node master is a potential node for preemption.
I0924 13:00:22.964275    6058 factory.go:470] Unable to schedule system/kube-system/kube-dns-7f4bf79dc-pvldq: no fit: 0/1 nodes are available: 1 node(s) runtime is not ready.; waiting
I0924 13:00:22.966895    6058 scheduler.go:787] Updating pod condition for system/kube-system/kube-dns-7f4bf79dc-pvldq to (PodScheduled==False, Reason=Unschedulable)
I0924 13:00:28.970387    6058 scheduler.go:576] Attempting to schedule pod: system/kube-system/coredns-default-6cfd6c6766-cqfm7
I0924 13:00:29.137794    6058 generic_scheduler.go:1052] Node master is a potential node for preemption.
I0924 13:00:29.138549    6058 factory.go:470] Unable to schedule system/kube-system/coredns-default-6cfd6c6766-cqfm7: no fit: 0/1 nodes are available: 1 node(s) runtime is not ready.; waiting
I0924 13:00:29.138658    6058 scheduler.go:787] Updating pod condition for system/kube-system/coredns-default-6cfd6c6766-cqfm7 to (PodScheduled==False, Reason=Unschedulable)
I0924 13:00:30.006321    6058 scheduler.go:576] Attempting to schedule pod: system/kube-system/coredns-default-6cfd6c6766-cqfm7
I0924 13:00:30.628168    6058 generic_scheduler.go:1052] Node master is a potential node for preemption.
I0924 13:00:30.628661    6058 factory.go:470] Unable to schedule system/kube-system/coredns-default-6cfd6c6766-cqfm7: no fit: 0/1 nodes are available: 1 node(s) runtime is not ready.; waiting
I0924 13:00:30.628767    6058 scheduler.go:787] Updating pod condition for system/kube-system/coredns-default-6cfd6c6766-cqfm7 to (PodScheduled==False, Reason=Unschedulable)
I0924 13:00:31.307741    6058 scheduler.go:576] Attempting to schedule pod: system/kube-system/kube-dns-7f4bf79dc-pvldq
I0924 13:00:32.557289    6058 generic_scheduler.go:1052] Node master is a potential node for preemption.
I0924 13:00:32.558213    6058 factory.go:470] Unable to schedule system/kube-system/kube-dns-7f4bf79dc-pvldq: no fit: 0/1 nodes are available: 1 node(s) runtime is not ready.; waiting
I0924 13:00:32.558375    6058 scheduler.go:787] Updating pod condition for system/kube-system/kube-dns-7f4bf79dc-pvldq to (PodScheduled==False, Reason=Unschedulable)
I0924 13:00:34.529485    6058 scheduler.go:576] Attempting to schedule pod: system/kube-system/kube-dns-7f4bf79dc-pvldq
I0924 13:00:34.744415    6058 generic_scheduler.go:1052] Node master is a potential node for preemption.
I0924 13:00:34.745036    6058 factory.go:470] Unable to schedule system/kube-system/kube-dns-7f4bf79dc-pvldq: no fit: 0/1 nodes are available: 1 node(s) runtime is not ready.; waiting
I0924 13:00:34.745095    6058 scheduler.go:787] Updating pod condition for system/kube-system/kube-dns-7f4bf79dc-pvldq to (PodScheduled==False, Reason=Unschedulable)
I0924 13:00:41.632594    6058 scheduler.go:576] Attempting to schedule pod: system/kube-system/coredns-default-6cfd6c6766-cqfm7
I0924 13:00:41.799132    6058 generic_scheduler.go:1052] Node master is a potential node for preemption.
I0924 13:00:41.799550    6058 factory.go:470] Unable to schedule system/kube-system/coredns-default-6cfd6c6766-cqfm7: no fit: 0/1 nodes are available: 1 node(s) runtime is not ready.; waiting
I0924 13:00:41.799610    6058 scheduler.go:787] Updating pod condition for system/kube-system/coredns-default-6cfd6c6766-cqfm7 to (PodScheduled==False, Reason=Unschedulable)
I0924 13:00:45.150512    6058 scheduler.go:576] Attempting to schedule pod: system/kube-system/kube-dns-7f4bf79dc-pvldq
I0924 13:00:45.665542    6058 generic_scheduler.go:1052] Node master is a potential node for preemption.
I0924 13:00:45.915794    6058 factory.go:470] Unable to schedule system/kube-system/kube-dns-7f4bf79dc-pvldq: no fit: 0/1 nodes are available: 1 node(s) runtime is not ready.; waiting
I0924 13:00:45.915980    6058 scheduler.go:787] Updating pod condition for system/kube-system/kube-dns-7f4bf79dc-pvldq to (PodScheduled==False, Reason=Unschedulable)
I0924 13:00:52.719687    6058 scheduler.go:576] Attempting to schedule pod: system/kube-system/coredns-default-6cfd6c6766-cqfm7
I0924 13:00:52.825906    6058 generic_scheduler.go:1052] Node master is a potential node for preemption.
I0924 13:00:52.826199    6058 factory.go:470] Unable to schedule system/kube-system/coredns-default-6cfd6c6766-cqfm7: no fit: 0/1 nodes are available: 1 node(s) runtime is not ready.; waiting
I0924 13:00:52.826259    6058 scheduler.go:787] Updating pod condition for system/kube-system/coredns-default-6cfd6c6766-cqfm7 to (PodScheduled==False, Reason=Unschedulable)
I0924 13:00:56.871543    6058 scheduler.go:576] Attempting to schedule pod: system/kube-system/kube-dns-7f4bf79dc-pvldq
I0924 13:00:57.083490    6058 generic_scheduler.go:1052] Node master is a potential node for preemption.
I0924 13:00:57.084143    6058 factory.go:470] Unable to schedule system/kube-system/kube-dns-7f4bf79dc-pvldq: no fit: 0/1 nodes are available: 1 node(s) runtime is not ready.; waiting
I0924 13:00:57.084295    6058 scheduler.go:787] Updating pod condition for system/kube-system/kube-dns-7f4bf79dc-pvldq to (PodScheduled==False, Reason=Unschedulable)
I0924 13:01:03.317821    6058 scheduler.go:576] Attempting to schedule pod: system/kube-system/coredns-default-6cfd6c6766-cqfm7
I0924 13:01:03.639807    6058 generic_scheduler.go:1052] Node master is a potential node for preemption.
I0924 13:01:03.640285    6058 factory.go:470] Unable to schedule system/kube-system/coredns-default-6cfd6c6766-cqfm7: no fit: 0/1 nodes are available: 1 node(s) runtime is not ready.; waiting
I0924 13:01:03.640497    6058 scheduler.go:787] Updating pod condition for system/kube-system/coredns-default-6cfd6c6766-cqfm7 to (PodScheduled==False, Reason=Unschedulable)
I0924 13:01:07.389540    6058 scheduler.go:576] Attempting to schedule pod: system/kube-system/kube-dns-7f4bf79dc-pvldq
I0924 13:01:07.644317    6058 generic_scheduler.go:1052] Node master is a potential node for preemption.
I0924 13:01:07.644760    6058 factory.go:470] Unable to schedule system/kube-system/kube-dns-7f4bf79dc-pvldq: no fit: 0/1 nodes are available: 1 node(s) runtime is not ready.; waiting
I0924 13:01:07.644876    6058 scheduler.go:787] Updating pod condition for system/kube-system/kube-dns-7f4bf79dc-pvldq to (PodScheduled==False, Reason=Unschedulable)
I0924 13:01:14.130028    6058 scheduler.go:576] Attempting to schedule pod: system/kube-system/coredns-default-6cfd6c6766-cqfm7
I0924 13:01:14.250761    6058 generic_scheduler.go:1052] Node master is a potential node for preemption.
I0924 13:01:14.251461    6058 factory.go:470] Unable to schedule system/kube-system/coredns-default-6cfd6c6766-cqfm7: no fit: 0/1 nodes are available: 1 node(s) runtime is not ready.; waiting
I0924 13:01:14.251554    6058 scheduler.go:787] Updating pod condition for system/kube-system/coredns-default-6cfd6c6766-cqfm7 to (PodScheduled==False, Reason=Unschedulable)
I0924 13:01:18.261946    6058 scheduler.go:576] Attempting to schedule pod: system/kube-system/kube-dns-7f4bf79dc-pvldq
I0924 13:01:18.638317    6058 generic_scheduler.go:1052] Node master is a potential node for preemption.
I0924 13:01:18.639013    6058 factory.go:470] Unable to schedule system/kube-system/kube-dns-7f4bf79dc-pvldq: no fit: 0/1 nodes are available: 1 node(s) runtime is not ready.; waiting
I0924 13:01:18.639137    6058 scheduler.go:787] Updating pod condition for system/kube-system/kube-dns-7f4bf79dc-pvldq to (PodScheduled==False, Reason=Unschedulable)
I0924 13:01:25.402523    6058 scheduler.go:576] Attempting to schedule pod: system/kube-system/coredns-default-6cfd6c6766-cqfm7
I0924 13:01:26.383776    6058 generic_scheduler.go:1052] Node master is a potential node for preemption.
I0924 13:01:26.384023    6058 factory.go:470] Unable to schedule system/kube-system/coredns-default-6cfd6c6766-cqfm7: no fit: 0/1 nodes are available: 1 node(s) runtime is not ready.; waiting
I0924 13:01:26.384085    6058 scheduler.go:787] Updating pod condition for system/kube-system/coredns-default-6cfd6c6766-cqfm7 to (PodScheduled==False, Reason=Unschedulable)
I0924 13:01:29.600270    6058 scheduler.go:576] Attempting to schedule pod: system/kube-system/kube-dns-7f4bf79dc-pvldq
I0924 13:01:29.928344    6058 generic_scheduler.go:1052] Node master is a potential node for preemption.
I0924 13:01:29.930726    6058 factory.go:470] Unable to schedule system/kube-system/kube-dns-7f4bf79dc-pvldq: no fit: 0/1 nodes are available: 1 node(s) runtime is not ready.; waiting
I0924 13:01:29.930812    6058 scheduler.go:787] Updating pod condition for system/kube-system/kube-dns-7f4bf79dc-pvldq to (PodScheduled==False, Reason=Unschedulable)
I0924 13:01:37.128657    6058 scheduler.go:576] Attempting to schedule pod: system/kube-system/coredns-default-6cfd6c6766-cqfm7
I0924 13:01:37.338041    6058 generic_scheduler.go:1052] Node master is a potential node for preemption.
I0924 13:01:37.338559    6058 factory.go:470] Unable to schedule system/kube-system/coredns-default-6cfd6c6766-cqfm7: no fit: 0/1 nodes are available: 1 node(s) runtime is not ready.; waiting
I0924 13:01:37.338687    6058 scheduler.go:787] Updating pod condition for system/kube-system/coredns-default-6cfd6c6766-cqfm7 to (PodScheduled==False, Reason=Unschedulable)
I0924 13:01:40.309970    6058 scheduler.go:576] Attempting to schedule pod: system/kube-system/kube-dns-7f4bf79dc-pvldq
I0924 13:01:40.379287    6058 generic_scheduler.go:1052] Node master is a potential node for preemption.
I0924 13:01:40.379629    6058 factory.go:470] Unable to schedule system/kube-system/kube-dns-7f4bf79dc-pvldq: no fit: 0/1 nodes are available: 1 node(s) runtime is not ready.; waiting
I0924 13:01:40.379725    6058 scheduler.go:787] Updating pod condition for system/kube-system/kube-dns-7f4bf79dc-pvldq to (PodScheduled==False, Reason=Unschedulable)
I0924 13:01:47.967231    6058 scheduler.go:576] Attempting to schedule pod: system/kube-system/coredns-default-6cfd6c6766-cqfm7
I0924 13:01:48.216632    6058 trace.go:81] Trace[1303428270]: "Scheduling system/kube-system/coredns-default-6cfd6c6766-cqfm7" (started: 2021-09-24 13:01:47.967362311 +0000 UTC m=+1232.100801659) (total time: 249.172622ms):
Trace[1303428270]: [249.167442ms] [248.996411ms] Computing predicates done
I0924 13:01:48.318705    6058 generic_scheduler.go:1052] Node master is a potential node for preemption.
I0924 13:01:48.318990    6058 factory.go:470] Unable to schedule system/kube-system/coredns-default-6cfd6c6766-cqfm7: no fit: 0/1 nodes are available: 1 node(s) runtime is not ready.; waiting
I0924 13:01:48.319045    6058 scheduler.go:787] Updating pod condition for system/kube-system/coredns-default-6cfd6c6766-cqfm7 to (PodScheduled==False, Reason=Unschedulable)
I0924 13:01:51.184912    6058 scheduler.go:576] Attempting to schedule pod: system/kube-system/kube-dns-7f4bf79dc-pvldq
I0924 13:01:51.851218    6058 generic_scheduler.go:1052] Node master is a potential node for preemption.
I0924 13:01:51.851501    6058 factory.go:470] Unable to schedule system/kube-system/kube-dns-7f4bf79dc-pvldq: no fit: 0/1 nodes are available: 1 node(s) runtime is not ready.; waiting
I0924 13:01:51.851551    6058 scheduler.go:787] Updating pod condition for system/kube-system/kube-dns-7f4bf79dc-pvldq to (PodScheduled==False, Reason=Unschedulable)
I0924 13:01:58.747689    6058 scheduler.go:576] Attempting to schedule pod: system/kube-system/coredns-default-6cfd6c6766-cqfm7
I0924 13:01:58.765929    6058 generic_scheduler.go:1052] Node master is a potential node for preemption.
I0924 13:01:58.766274    6058 factory.go:470] Unable to schedule system/kube-system/coredns-default-6cfd6c6766-cqfm7: no fit: 0/1 nodes are available: 1 node(s) runtime is not ready.; waiting
I0924 13:01:58.766341    6058 scheduler.go:787] Updating pod condition for system/kube-system/coredns-default-6cfd6c6766-cqfm7 to (PodScheduled==False, Reason=Unschedulable)
I0924 13:02:03.159954    6058 scheduler.go:576] Attempting to schedule pod: system/kube-system/kube-dns-7f4bf79dc-pvldq
I0924 13:02:03.311463    6058 generic_scheduler.go:1052] Node master is a potential node for preemption.
I0924 13:02:03.311863    6058 factory.go:470] Unable to schedule system/kube-system/kube-dns-7f4bf79dc-pvldq: no fit: 0/1 nodes are available: 1 node(s) runtime is not ready.; waiting
I0924 13:02:03.311961    6058 scheduler.go:787] Updating pod condition for system/kube-system/kube-dns-7f4bf79dc-pvldq to (PodScheduled==False, Reason=Unschedulable)
I0924 13:02:06.836588    6058 eventhandlers.go:183] add event for unscheduled pod system/default/mizar-operator-6985d77546-4bw2g
I0924 13:02:06.836827    6058 scheduler.go:576] Attempting to schedule pod: system/default/mizar-operator-6985d77546-4bw2g
I0924 13:02:06.837646    6058 default_binder.go:53] Attempting to bind system/default/mizar-operator-6985d77546-4bw2g to master
I0924 13:02:07.666610    6058 cache.go:757] Couldn't expire cache for pod system/default/mizar-operator-6985d77546-4bw2g. Binding is still in progress.
I0924 13:02:07.690316    6058 eventhandlers.go:215] delete event for unscheduled pod system/default/mizar-operator-6985d77546-4bw2g
I0924 13:02:07.690415    6058 eventhandlers.go:239] add event for scheduled pod system/default/mizar-operator-6985d77546-4bw2g 
I0924 13:02:07.706932    6058 scheduler.go:741] pod system/default/mizar-operator-6985d77546-4bw2g is bound successfully on node "master", 1 nodes evaluated, 1 nodes were found feasible.
I0924 13:02:09.669221    6058 eventhandlers.go:308] delete event for scheduled pod system/default/mizar-operator-6985d77546-596pp 
I0924 13:02:10.113035    6058 scheduler.go:576] Attempting to schedule pod: system/kube-system/coredns-default-6cfd6c6766-cqfm7
I0924 13:02:12.448950    6058 generic_scheduler.go:1052] Node master is a potential node for preemption.
I0924 13:02:12.449296    6058 factory.go:470] Unable to schedule system/kube-system/coredns-default-6cfd6c6766-cqfm7: no fit: 0/1 nodes are available: 1 node(s) runtime is not ready.; waiting
I0924 13:02:12.449358    6058 scheduler.go:787] Updating pod condition for system/kube-system/coredns-default-6cfd6c6766-cqfm7 to (PodScheduled==False, Reason=Unschedulable)
I0924 13:02:14.058353    6058 scheduler.go:576] Attempting to schedule pod: system/kube-system/kube-dns-7f4bf79dc-pvldq
I0924 13:02:14.903821    6058 generic_scheduler.go:1052] Node master is a potential node for preemption.
I0924 13:02:14.904117    6058 factory.go:470] Unable to schedule system/kube-system/kube-dns-7f4bf79dc-pvldq: no fit: 0/1 nodes are available: 1 node(s) runtime is not ready.; waiting
I0924 13:02:14.904172    6058 scheduler.go:787] Updating pod condition for system/kube-system/kube-dns-7f4bf79dc-pvldq to (PodScheduled==False, Reason=Unschedulable)
I0924 13:02:22.952036    6058 scheduler.go:576] Attempting to schedule pod: system/kube-system/coredns-default-6cfd6c6766-cqfm7
I0924 13:02:24.625462    6058 generic_scheduler.go:1052] Node master is a potential node for preemption.
I0924 13:02:24.812463    6058 factory.go:470] Unable to schedule system/kube-system/coredns-default-6cfd6c6766-cqfm7: no fit: 0/1 nodes are available: 1 node(s) runtime is not ready.; waiting
I0924 13:02:24.812594    6058 scheduler.go:787] Updating pod condition for system/kube-system/coredns-default-6cfd6c6766-cqfm7 to (PodScheduled==False, Reason=Unschedulable)
I0924 13:02:26.048042    6058 scheduler.go:576] Attempting to schedule pod: system/kube-system/kube-dns-7f4bf79dc-pvldq
I0924 13:02:26.082601    6058 generic_scheduler.go:1052] Node master is a potential node for preemption.
I0924 13:02:26.107267    6058 factory.go:470] Unable to schedule system/kube-system/kube-dns-7f4bf79dc-pvldq: no fit: 0/1 nodes are available: 1 node(s) runtime is not ready.; waiting
I0924 13:02:26.107414    6058 scheduler.go:787] Updating pod condition for system/kube-system/kube-dns-7f4bf79dc-pvldq to (PodScheduled==False, Reason=Unschedulable)
I0924 13:02:35.317990    6058 scheduler.go:576] Attempting to schedule pod: system/kube-system/coredns-default-6cfd6c6766-cqfm7
I0924 13:02:35.418487    6058 generic_scheduler.go:1052] Node master is a potential node for preemption.
I0924 13:02:36.276671    6058 factory.go:470] Unable to schedule system/kube-system/coredns-default-6cfd6c6766-cqfm7: no fit: 0/1 nodes are available: 1 node(s) runtime is not ready.; waiting
I0924 13:02:36.276818    6058 scheduler.go:787] Updating pod condition for system/kube-system/coredns-default-6cfd6c6766-cqfm7 to (PodScheduled==False, Reason=Unschedulable)
I0924 13:02:38.300357    6058 scheduler.go:576] Attempting to schedule pod: system/kube-system/kube-dns-7f4bf79dc-pvldq
I0924 13:02:38.469519    6058 generic_scheduler.go:1052] Node master is a potential node for preemption.
I0924 13:02:38.470307    6058 factory.go:470] Unable to schedule system/kube-system/kube-dns-7f4bf79dc-pvldq: no fit: 0/1 nodes are available: 1 node(s) runtime is not ready.; waiting
I0924 13:02:38.470404    6058 scheduler.go:787] Updating pod condition for system/kube-system/kube-dns-7f4bf79dc-pvldq to (PodScheduled==False, Reason=Unschedulable)
I0924 13:02:46.669895    6058 scheduler.go:576] Attempting to schedule pod: system/kube-system/coredns-default-6cfd6c6766-cqfm7
I0924 13:02:46.876070    6058 trace.go:81] Trace[1267564538]: "Scheduling system/kube-system/coredns-default-6cfd6c6766-cqfm7" (started: 2021-09-24 13:02:46.671977716 +0000 UTC m=+1290.805417021) (total time: 203.996307ms):
Trace[1267564538]: [203.877222ms] [203.826559ms] Running prefilter plugins done
I0924 13:02:47.924937    6058 generic_scheduler.go:1052] Node master is a potential node for preemption.
I0924 13:02:47.925188    6058 factory.go:470] Unable to schedule system/kube-system/coredns-default-6cfd6c6766-cqfm7: no fit: 0/1 nodes are available: 1 node(s) runtime is not ready.; waiting
I0924 13:02:47.925250    6058 scheduler.go:787] Updating pod condition for system/kube-system/coredns-default-6cfd6c6766-cqfm7 to (PodScheduled==False, Reason=Unschedulable)
I0924 13:02:48.947405    6058 scheduler.go:576] Attempting to schedule pod: system/kube-system/kube-dns-7f4bf79dc-pvldq
I0924 13:02:49.952342    6058 generic_scheduler.go:1052] Node master is a potential node for preemption.
I0924 13:02:49.952792    6058 factory.go:470] Unable to schedule system/kube-system/kube-dns-7f4bf79dc-pvldq: no fit: 0/1 nodes are available: 1 node(s) runtime is not ready.; waiting
I0924 13:02:49.952866    6058 scheduler.go:787] Updating pod condition for system/kube-system/kube-dns-7f4bf79dc-pvldq to (PodScheduled==False, Reason=Unschedulable)
I0924 13:02:58.392621    6058 scheduler.go:576] Attempting to schedule pod: system/kube-system/coredns-default-6cfd6c6766-cqfm7
I0924 13:02:58.531779    6058 generic_scheduler.go:1052] Node master is a potential node for preemption.
I0924 13:02:58.532060    6058 factory.go:470] Unable to schedule system/kube-system/coredns-default-6cfd6c6766-cqfm7: no fit: 0/1 nodes are available: 1 node(s) runtime is not ready.; waiting
I0924 13:02:58.532120    6058 scheduler.go:787] Updating pod condition for system/kube-system/coredns-default-6cfd6c6766-cqfm7 to (PodScheduled==False, Reason=Unschedulable)
I0924 13:03:01.138649    6058 scheduler.go:576] Attempting to schedule pod: system/kube-system/kube-dns-7f4bf79dc-pvldq
I0924 13:03:01.777000    6058 generic_scheduler.go:1052] Node master is a potential node for preemption.
I0924 13:03:01.777350    6058 factory.go:470] Unable to schedule system/kube-system/kube-dns-7f4bf79dc-pvldq: no fit: 0/1 nodes are available: 1 node(s) runtime is not ready.; waiting
I0924 13:03:01.777414    6058 scheduler.go:787] Updating pod condition for system/kube-system/kube-dns-7f4bf79dc-pvldq to (PodScheduled==False, Reason=Unschedulable)
I0924 13:03:09.931608    6058 scheduler.go:576] Attempting to schedule pod: system/kube-system/coredns-default-6cfd6c6766-cqfm7
I0924 13:03:10.004706    6058 generic_scheduler.go:1052] Node master is a potential node for preemption.
I0924 13:03:10.005006    6058 factory.go:470] Unable to schedule system/kube-system/coredns-default-6cfd6c6766-cqfm7: no fit: 0/1 nodes are available: 1 node(s) runtime is not ready.; waiting
I0924 13:03:10.005060    6058 scheduler.go:787] Updating pod condition for system/kube-system/coredns-default-6cfd6c6766-cqfm7 to (PodScheduled==False, Reason=Unschedulable)
I0924 13:03:12.108427    6058 scheduler.go:576] Attempting to schedule pod: system/kube-system/kube-dns-7f4bf79dc-pvldq
I0924 13:03:12.137375    6058 generic_scheduler.go:1052] Node master is a potential node for preemption.
I0924 13:03:12.137679    6058 factory.go:470] Unable to schedule system/kube-system/kube-dns-7f4bf79dc-pvldq: no fit: 0/1 nodes are available: 1 node(s) runtime is not ready.; waiting
I0924 13:03:12.137774    6058 scheduler.go:787] Updating pod condition for system/kube-system/kube-dns-7f4bf79dc-pvldq to (PodScheduled==False, Reason=Unschedulable)
I0924 13:03:20.272237    6058 scheduler.go:576] Attempting to schedule pod: system/kube-system/coredns-default-6cfd6c6766-cqfm7
I0924 13:03:20.466789    6058 generic_scheduler.go:1052] Node master is a potential node for preemption.
I0924 13:03:20.467294    6058 factory.go:470] Unable to schedule system/kube-system/coredns-default-6cfd6c6766-cqfm7: no fit: 0/1 nodes are available: 1 node(s) runtime is not ready.; waiting
I0924 13:03:20.467576    6058 scheduler.go:787] Updating pod condition for system/kube-system/coredns-default-6cfd6c6766-cqfm7 to (PodScheduled==False, Reason=Unschedulable)
I0924 13:03:22.448359    6058 scheduler.go:576] Attempting to schedule pod: system/kube-system/kube-dns-7f4bf79dc-pvldq
I0924 13:03:22.478547    6058 generic_scheduler.go:1052] Node master is a potential node for preemption.
I0924 13:03:22.478931    6058 factory.go:470] Unable to schedule system/kube-system/kube-dns-7f4bf79dc-pvldq: no fit: 0/1 nodes are available: 1 node(s) runtime is not ready.; waiting
I0924 13:03:22.479023    6058 scheduler.go:787] Updating pod condition for system/kube-system/kube-dns-7f4bf79dc-pvldq to (PodScheduled==False, Reason=Unschedulable)
I0924 13:03:30.751177    6058 scheduler.go:576] Attempting to schedule pod: system/kube-system/coredns-default-6cfd6c6766-cqfm7
I0924 13:03:31.237803    6058 generic_scheduler.go:1052] Node master is a potential node for preemption.
I0924 13:03:31.238097    6058 factory.go:470] Unable to schedule system/kube-system/coredns-default-6cfd6c6766-cqfm7: no fit: 0/1 nodes are available: 1 node(s) runtime is not ready.; waiting
I0924 13:03:31.238156    6058 scheduler.go:787] Updating pod condition for system/kube-system/coredns-default-6cfd6c6766-cqfm7 to (PodScheduled==False, Reason=Unschedulable)
I0924 13:03:32.754410    6058 scheduler.go:576] Attempting to schedule pod: system/kube-system/kube-dns-7f4bf79dc-pvldq
I0924 13:03:32.833379    6058 generic_scheduler.go:1052] Node master is a potential node for preemption.
I0924 13:03:32.833662    6058 factory.go:470] Unable to schedule system/kube-system/kube-dns-7f4bf79dc-pvldq: no fit: 0/1 nodes are available: 1 node(s) runtime is not ready.; waiting
I0924 13:03:32.833713    6058 scheduler.go:787] Updating pod condition for system/kube-system/kube-dns-7f4bf79dc-pvldq to (PodScheduled==False, Reason=Unschedulable)
I0924 13:03:41.802628    6058 scheduler.go:576] Attempting to schedule pod: system/kube-system/coredns-default-6cfd6c6766-cqfm7
I0924 13:03:41.837566    6058 generic_scheduler.go:1052] Node master is a potential node for preemption.
I0924 13:03:41.837866    6058 factory.go:470] Unable to schedule system/kube-system/coredns-default-6cfd6c6766-cqfm7: no fit: 0/1 nodes are available: 1 node(s) runtime is not ready.; waiting
I0924 13:03:41.837922    6058 scheduler.go:787] Updating pod condition for system/kube-system/coredns-default-6cfd6c6766-cqfm7 to (PodScheduled==False, Reason=Unschedulable)
I0924 13:03:43.959224    6058 scheduler.go:576] Attempting to schedule pod: system/kube-system/kube-dns-7f4bf79dc-pvldq
I0924 13:03:44.115782    6058 generic_scheduler.go:1052] Node master is a potential node for preemption.
I0924 13:03:44.116116    6058 factory.go:470] Unable to schedule system/kube-system/kube-dns-7f4bf79dc-pvldq: no fit: 0/1 nodes are available: 1 node(s) runtime is not ready.; waiting
I0924 13:03:44.116170    6058 scheduler.go:787] Updating pod condition for system/kube-system/kube-dns-7f4bf79dc-pvldq to (PodScheduled==False, Reason=Unschedulable)
I0924 13:03:48.660018    6058 scheduler.go:576] Attempting to schedule pod: system/kube-system/coredns-default-6cfd6c6766-cqfm7
I0924 13:03:49.089380    6058 generic_scheduler.go:1052] Node master is a potential node for preemption.
I0924 13:03:49.145916    6058 factory.go:470] Unable to schedule system/kube-system/coredns-default-6cfd6c6766-cqfm7: no fit: 0/1 nodes are available: 1 node(s) runtime is not ready.; waiting
I0924 13:03:49.146227    6058 scheduler.go:787] Updating pod condition for system/kube-system/coredns-default-6cfd6c6766-cqfm7 to (PodScheduled==False, Reason=Unschedulable)
I0924 13:03:49.148368    6058 scheduler.go:576] Attempting to schedule pod: system/kube-system/kube-dns-7f4bf79dc-pvldq
I0924 13:03:49.697572    6058 generic_scheduler.go:1052] Node master is a potential node for preemption.
I0924 13:03:49.698087    6058 factory.go:470] Unable to schedule system/kube-system/kube-dns-7f4bf79dc-pvldq: no fit: 0/1 nodes are available: 1 node(s) runtime is not ready.; waiting
I0924 13:03:49.698155    6058 scheduler.go:787] Updating pod condition for system/kube-system/kube-dns-7f4bf79dc-pvldq to (PodScheduled==False, Reason=Unschedulable)
I0924 13:03:55.423294    6058 scheduler.go:576] Attempting to schedule pod: system/kube-system/coredns-default-6cfd6c6766-cqfm7
I0924 13:03:55.735888    6058 generic_scheduler.go:1052] Node master is a potential node for preemption.
I0924 13:03:55.740131    6058 factory.go:470] Unable to schedule system/kube-system/coredns-default-6cfd6c6766-cqfm7: no fit: 0/1 nodes are available: 1 node(s) runtime is not ready.; waiting
I0924 13:03:55.740300    6058 scheduler.go:787] Updating pod condition for system/kube-system/coredns-default-6cfd6c6766-cqfm7 to (PodScheduled==False, Reason=Unschedulable)
I0924 13:03:59.158809    6058 scheduler.go:576] Attempting to schedule pod: system/kube-system/kube-dns-7f4bf79dc-pvldq
I0924 13:03:59.474335    6058 generic_scheduler.go:1052] Node master is a potential node for preemption.
I0924 13:03:59.474684    6058 factory.go:470] Unable to schedule system/kube-system/kube-dns-7f4bf79dc-pvldq: no fit: 0/1 nodes are available: 1 node(s) runtime is not ready.; waiting
I0924 13:03:59.474741    6058 scheduler.go:787] Updating pod condition for system/kube-system/kube-dns-7f4bf79dc-pvldq to (PodScheduled==False, Reason=Unschedulable)
I0924 13:04:06.302024    6058 scheduler.go:576] Attempting to schedule pod: system/kube-system/coredns-default-6cfd6c6766-cqfm7
I0924 13:04:06.576172    6058 generic_scheduler.go:1052] Node master is a potential node for preemption.
I0924 13:04:06.576594    6058 factory.go:470] Unable to schedule system/kube-system/coredns-default-6cfd6c6766-cqfm7: no fit: 0/1 nodes are available: 1 node(s) runtime is not ready.; waiting
I0924 13:04:06.576660    6058 scheduler.go:787] Updating pod condition for system/kube-system/coredns-default-6cfd6c6766-cqfm7 to (PodScheduled==False, Reason=Unschedulable)
I0924 13:04:10.950102    6058 scheduler.go:576] Attempting to schedule pod: system/kube-system/kube-dns-7f4bf79dc-pvldq
I0924 13:04:11.605048    6058 generic_scheduler.go:1052] Node master is a potential node for preemption.
I0924 13:04:11.650717    6058 factory.go:470] Unable to schedule system/kube-system/kube-dns-7f4bf79dc-pvldq: no fit: 0/1 nodes are available: 1 node(s) runtime is not ready.; waiting
I0924 13:04:11.650864    6058 scheduler.go:787] Updating pod condition for system/kube-system/kube-dns-7f4bf79dc-pvldq to (PodScheduled==False, Reason=Unschedulable)
I0924 13:04:16.002091    6058 scheduler.go:576] Attempting to schedule pod: system/kube-system/coredns-default-6cfd6c6766-cqfm7
I0924 13:04:16.262036    6058 generic_scheduler.go:1052] Node master is a potential node for preemption.
I0924 13:04:16.262316    6058 factory.go:470] Unable to schedule system/kube-system/coredns-default-6cfd6c6766-cqfm7: no fit: 0/1 nodes are available: 1 node(s) runtime is not ready.; waiting
I0924 13:04:16.262367    6058 scheduler.go:787] Updating pod condition for system/kube-system/coredns-default-6cfd6c6766-cqfm7 to (PodScheduled==False, Reason=Unschedulable)
I0924 13:04:20.176394    6058 scheduler.go:576] Attempting to schedule pod: system/kube-system/coredns-default-6cfd6c6766-cqfm7
I0924 13:04:20.609781    6058 generic_scheduler.go:1052] Node master is a potential node for preemption.
I0924 13:04:20.610236    6058 factory.go:470] Unable to schedule system/kube-system/coredns-default-6cfd6c6766-cqfm7: no fit: 0/1 nodes are available: 1 node(s) runtime is not ready.; waiting
I0924 13:04:20.610298    6058 scheduler.go:787] Updating pod condition for system/kube-system/coredns-default-6cfd6c6766-cqfm7 to (PodScheduled==False, Reason=Unschedulable)
I0924 13:04:20.612792    6058 scheduler.go:576] Attempting to schedule pod: system/kube-system/kube-dns-7f4bf79dc-pvldq
I0924 13:04:21.095992    6058 generic_scheduler.go:1052] Node master is a potential node for preemption.
I0924 13:04:21.096531    6058 factory.go:470] Unable to schedule system/kube-system/kube-dns-7f4bf79dc-pvldq: no fit: 0/1 nodes are available: 1 node(s) runtime is not ready.; waiting
I0924 13:04:21.096614    6058 scheduler.go:787] Updating pod condition for system/kube-system/kube-dns-7f4bf79dc-pvldq to (PodScheduled==False, Reason=Unschedulable)
I0924 13:04:24.312293    6058 scheduler.go:576] Attempting to schedule pod: system/kube-system/kube-dns-7f4bf79dc-pvldq
I0924 13:04:24.892601    6058 generic_scheduler.go:1052] Node master is a potential node for preemption.
I0924 13:04:24.892917    6058 factory.go:470] Unable to schedule system/kube-system/kube-dns-7f4bf79dc-pvldq: no fit: 0/1 nodes are available: 1 node(s) runtime is not ready.; waiting
I0924 13:04:24.892998    6058 scheduler.go:787] Updating pod condition for system/kube-system/kube-dns-7f4bf79dc-pvldq to (PodScheduled==False, Reason=Unschedulable)
I0924 13:04:31.864461    6058 scheduler.go:576] Attempting to schedule pod: system/kube-system/coredns-default-6cfd6c6766-cqfm7
I0924 13:04:31.975305    6058 generic_scheduler.go:1052] Node master is a potential node for preemption.
I0924 13:04:31.975594    6058 factory.go:470] Unable to schedule system/kube-system/coredns-default-6cfd6c6766-cqfm7: no fit: 0/1 nodes are available: 1 node(s) runtime is not ready.; waiting
I0924 13:04:31.975651    6058 scheduler.go:787] Updating pod condition for system/kube-system/coredns-default-6cfd6c6766-cqfm7 to (PodScheduled==False, Reason=Unschedulable)
I0924 13:04:36.114805    6058 scheduler.go:576] Attempting to schedule pod: system/kube-system/kube-dns-7f4bf79dc-pvldq
I0924 13:04:36.320850    6058 generic_scheduler.go:1052] Node master is a potential node for preemption.
I0924 13:04:36.321178    6058 factory.go:470] Unable to schedule system/kube-system/kube-dns-7f4bf79dc-pvldq: no fit: 0/1 nodes are available: 1 node(s) runtime is not ready.; waiting
I0924 13:04:36.321241    6058 scheduler.go:787] Updating pod condition for system/kube-system/kube-dns-7f4bf79dc-pvldq to (PodScheduled==False, Reason=Unschedulable)
I0924 13:04:40.929697    6058 scheduler.go:576] Attempting to schedule pod: system/kube-system/coredns-default-6cfd6c6766-cqfm7
I0924 13:04:41.795718    6058 generic_scheduler.go:1052] Node master is a potential node for preemption.
I0924 13:04:41.796007    6058 factory.go:470] Unable to schedule system/kube-system/coredns-default-6cfd6c6766-cqfm7: no fit: 0/1 nodes are available: 1 node(s) runtime is not ready.; waiting
I0924 13:04:41.796062    6058 scheduler.go:787] Updating pod condition for system/kube-system/coredns-default-6cfd6c6766-cqfm7 to (PodScheduled==False, Reason=Unschedulable)
I0924 13:04:43.739228    6058 scheduler.go:576] Attempting to schedule pod: system/kube-system/coredns-default-6cfd6c6766-cqfm7
I0924 13:04:44.017519    6058 generic_scheduler.go:1052] Node master is a potential node for preemption.
I0924 13:04:44.035247    6058 factory.go:470] Unable to schedule system/kube-system/coredns-default-6cfd6c6766-cqfm7: no fit: 0/1 nodes are available: 1 node(s) runtime is not ready.; waiting
I0924 13:04:44.035357    6058 scheduler.go:787] Updating pod condition for system/kube-system/coredns-default-6cfd6c6766-cqfm7 to (PodScheduled==False, Reason=Unschedulable)
I0924 13:04:44.457832    6058 scheduler.go:576] Attempting to schedule pod: system/kube-system/kube-dns-7f4bf79dc-pvldq
I0924 13:04:44.583190    6058 generic_scheduler.go:1052] Node master is a potential node for preemption.
I0924 13:04:44.583703    6058 factory.go:470] Unable to schedule system/kube-system/kube-dns-7f4bf79dc-pvldq: no fit: 0/1 nodes are available: 1 node(s) runtime is not ready.; waiting
I0924 13:04:44.583766    6058 scheduler.go:787] Updating pod condition for system/kube-system/kube-dns-7f4bf79dc-pvldq to (PodScheduled==False, Reason=Unschedulable)
I0924 13:04:47.070647    6058 scheduler.go:576] Attempting to schedule pod: system/kube-system/kube-dns-7f4bf79dc-pvldq
I0924 13:04:47.112335    6058 generic_scheduler.go:1052] Node master is a potential node for preemption.
I0924 13:04:47.112640    6058 factory.go:470] Unable to schedule system/kube-system/kube-dns-7f4bf79dc-pvldq: no fit: 0/1 nodes are available: 1 node(s) runtime is not ready.; waiting
I0924 13:04:47.112698    6058 scheduler.go:787] Updating pod condition for system/kube-system/kube-dns-7f4bf79dc-pvldq to (PodScheduled==False, Reason=Unschedulable)
I0924 13:04:55.448377    6058 scheduler.go:576] Attempting to schedule pod: system/kube-system/coredns-default-6cfd6c6766-cqfm7
I0924 13:04:55.843105    6058 generic_scheduler.go:1052] Node master is a potential node for preemption.
I0924 13:04:55.972091    6058 factory.go:470] Unable to schedule system/kube-system/coredns-default-6cfd6c6766-cqfm7: no fit: 0/1 nodes are available: 1 node(s) runtime is not ready.; waiting
I0924 13:04:55.972206    6058 scheduler.go:787] Updating pod condition for system/kube-system/coredns-default-6cfd6c6766-cqfm7 to (PodScheduled==False, Reason=Unschedulable)
I0924 13:04:57.913130    6058 scheduler.go:576] Attempting to schedule pod: system/kube-system/kube-dns-7f4bf79dc-pvldq
I0924 13:04:58.501313    6058 generic_scheduler.go:1052] Node master is a potential node for preemption.
I0924 13:04:58.501632    6058 factory.go:470] Unable to schedule system/kube-system/kube-dns-7f4bf79dc-pvldq: no fit: 0/1 nodes are available: 1 node(s) runtime is not ready.; waiting
I0924 13:04:58.501880    6058 scheduler.go:787] Updating pod condition for system/kube-system/kube-dns-7f4bf79dc-pvldq to (PodScheduled==False, Reason=Unschedulable)
I0924 13:05:03.780659    6058 scheduler.go:576] Attempting to schedule pod: system/kube-system/coredns-default-6cfd6c6766-cqfm7
I0924 13:05:04.414609    6058 generic_scheduler.go:1052] Node master is a potential node for preemption.
I0924 13:05:04.414891    6058 factory.go:470] Unable to schedule system/kube-system/coredns-default-6cfd6c6766-cqfm7: no fit: 0/1 nodes are available: 1 node(s) runtime is not ready.; waiting
I0924 13:05:05.215289    6058 scheduler.go:787] Updating pod condition for system/kube-system/coredns-default-6cfd6c6766-cqfm7 to (PodScheduled==False, Reason=Unschedulable)
I0924 13:05:07.986764    6058 scheduler.go:576] Attempting to schedule pod: system/kube-system/kube-dns-7f4bf79dc-pvldq
I0924 13:05:08.369879    6058 generic_scheduler.go:1052] Node master is a potential node for preemption.
I0924 13:05:08.370171    6058 factory.go:470] Unable to schedule system/kube-system/kube-dns-7f4bf79dc-pvldq: no fit: 0/1 nodes are available: 1 node(s) runtime is not ready.; waiting
I0924 13:05:08.370225    6058 scheduler.go:787] Updating pod condition for system/kube-system/kube-dns-7f4bf79dc-pvldq to (PodScheduled==False, Reason=Unschedulable)
I0924 13:05:09.564628    6058 scheduler.go:576] Attempting to schedule pod: system/kube-system/coredns-default-6cfd6c6766-cqfm7
I0924 13:05:10.322601    6058 generic_scheduler.go:1052] Node master is a potential node for preemption.
I0924 13:05:10.322872    6058 factory.go:470] Unable to schedule system/kube-system/coredns-default-6cfd6c6766-cqfm7: no fit: 0/1 nodes are available: 1 node(s) runtime is not ready.; waiting
I0924 13:05:10.322923    6058 scheduler.go:787] Updating pod condition for system/kube-system/coredns-default-6cfd6c6766-cqfm7 to (PodScheduled==False, Reason=Unschedulable)
I0924 13:05:11.445425    6058 scheduler.go:576] Attempting to schedule pod: system/kube-system/kube-dns-7f4bf79dc-pvldq
I0924 13:05:11.831000    6058 generic_scheduler.go:1052] Node master is a potential node for preemption.
I0924 13:05:11.831300    6058 factory.go:470] Unable to schedule system/kube-system/kube-dns-7f4bf79dc-pvldq: no fit: 0/1 nodes are available: 1 node(s) runtime is not ready.; waiting
I0924 13:05:11.831356    6058 scheduler.go:787] Updating pod condition for system/kube-system/kube-dns-7f4bf79dc-pvldq to (PodScheduled==False, Reason=Unschedulable)
I0924 13:05:21.391097    6058 scheduler.go:576] Attempting to schedule pod: system/kube-system/coredns-default-6cfd6c6766-cqfm7
I0924 13:05:21.536334    6058 generic_scheduler.go:1052] Node master is a potential node for preemption.
I0924 13:05:21.536721    6058 factory.go:470] Unable to schedule system/kube-system/coredns-default-6cfd6c6766-cqfm7: no fit: 0/1 nodes are available: 1 node(s) runtime is not ready.; waiting
I0924 13:05:21.536807    6058 scheduler.go:787] Updating pod condition for system/kube-system/coredns-default-6cfd6c6766-cqfm7 to (PodScheduled==False, Reason=Unschedulable)
I0924 13:05:22.469321    6058 scheduler.go:576] Attempting to schedule pod: system/kube-system/kube-dns-7f4bf79dc-pvldq
I0924 13:05:22.479839    6058 generic_scheduler.go:1052] Node master is a potential node for preemption.
I0924 13:05:22.480253    6058 factory.go:470] Unable to schedule system/kube-system/kube-dns-7f4bf79dc-pvldq: no fit: 0/1 nodes are available: 1 node(s) runtime is not ready.; waiting
I0924 13:05:22.480362    6058 scheduler.go:787] Updating pod condition for system/kube-system/kube-dns-7f4bf79dc-pvldq to (PodScheduled==False, Reason=Unschedulable)
I0924 13:05:28.325079    6058 scheduler.go:576] Attempting to schedule pod: system/kube-system/coredns-default-6cfd6c6766-cqfm7
I0924 13:05:28.521132    6058 generic_scheduler.go:1052] Node master is a potential node for preemption.
I0924 13:05:28.521407    6058 factory.go:470] Unable to schedule system/kube-system/coredns-default-6cfd6c6766-cqfm7: no fit: 0/1 nodes are available: 1 node(s) runtime is not ready.; waiting
I0924 13:05:28.521455    6058 scheduler.go:787] Updating pod condition for system/kube-system/coredns-default-6cfd6c6766-cqfm7 to (PodScheduled==False, Reason=Unschedulable)
I0924 13:05:30.556050    6058 scheduler.go:576] Attempting to schedule pod: system/kube-system/coredns-default-6cfd6c6766-cqfm7
I0924 13:05:30.760341    6058 generic_scheduler.go:1052] Node master is a potential node for preemption.
I0924 13:05:30.760652    6058 factory.go:470] Unable to schedule system/kube-system/coredns-default-6cfd6c6766-cqfm7: no fit: 0/1 nodes are available: 1 node(s) runtime is not ready.; waiting
I0924 13:05:30.760710    6058 scheduler.go:787] Updating pod condition for system/kube-system/coredns-default-6cfd6c6766-cqfm7 to (PodScheduled==False, Reason=Unschedulable)
I0924 13:05:31.556317    6058 scheduler.go:576] Attempting to schedule pod: system/kube-system/kube-dns-7f4bf79dc-pvldq
I0924 13:05:31.778898    6058 generic_scheduler.go:1052] Node master is a potential node for preemption.
I0924 13:05:31.779172    6058 factory.go:470] Unable to schedule system/kube-system/kube-dns-7f4bf79dc-pvldq: no fit: 0/1 nodes are available: 1 node(s) runtime is not ready.; waiting
I0924 13:05:31.779228    6058 scheduler.go:787] Updating pod condition for system/kube-system/kube-dns-7f4bf79dc-pvldq to (PodScheduled==False, Reason=Unschedulable)
I0924 13:05:33.035313    6058 scheduler.go:576] Attempting to schedule pod: system/kube-system/kube-dns-7f4bf79dc-pvldq
I0924 13:05:33.227280    6058 generic_scheduler.go:1052] Node master is a potential node for preemption.
I0924 13:05:33.228541    6058 factory.go:470] Unable to schedule system/kube-system/kube-dns-7f4bf79dc-pvldq: no fit: 0/1 nodes are available: 1 node(s) runtime is not ready.; waiting
I0924 13:05:33.228657    6058 scheduler.go:787] Updating pod condition for system/kube-system/kube-dns-7f4bf79dc-pvldq to (PodScheduled==False, Reason=Unschedulable)
I0924 13:05:41.567522    6058 scheduler.go:576] Attempting to schedule pod: system/kube-system/coredns-default-6cfd6c6766-cqfm7
I0924 13:05:41.583447    6058 generic_scheduler.go:1052] Node master is a potential node for preemption.
I0924 13:05:41.584164    6058 factory.go:470] Unable to schedule system/kube-system/coredns-default-6cfd6c6766-cqfm7: no fit: 0/1 nodes are available: 1 node(s) runtime is not ready.; waiting
I0924 13:05:41.584239    6058 scheduler.go:787] Updating pod condition for system/kube-system/coredns-default-6cfd6c6766-cqfm7 to (PodScheduled==False, Reason=Unschedulable)
I0924 13:05:43.786182    6058 scheduler.go:576] Attempting to schedule pod: system/kube-system/kube-dns-7f4bf79dc-pvldq
I0924 13:05:44.246710    6058 generic_scheduler.go:1052] Node master is a potential node for preemption.
I0924 13:05:44.320666    6058 factory.go:470] Unable to schedule system/kube-system/kube-dns-7f4bf79dc-pvldq: no fit: 0/1 nodes are available: 1 node(s) runtime is not ready.; waiting
I0924 13:05:44.321018    6058 scheduler.go:787] Updating pod condition for system/kube-system/kube-dns-7f4bf79dc-pvldq to (PodScheduled==False, Reason=Unschedulable)
I0924 13:05:50.269470    6058 scheduler.go:576] Attempting to schedule pod: system/kube-system/coredns-default-6cfd6c6766-cqfm7
I0924 13:05:50.278637    6058 generic_scheduler.go:1052] Node master is a potential node for preemption.
I0924 13:05:50.278888    6058 factory.go:470] Unable to schedule system/kube-system/coredns-default-6cfd6c6766-cqfm7: no fit: 0/1 nodes are available: 1 node(s) runtime is not ready.; waiting
I0924 13:05:50.279013    6058 scheduler.go:787] Updating pod condition for system/kube-system/coredns-default-6cfd6c6766-cqfm7 to (PodScheduled==False, Reason=Unschedulable)
I0924 13:05:51.158866    6058 scheduler.go:576] Attempting to schedule pod: system/kube-system/coredns-default-6cfd6c6766-cqfm7
I0924 13:05:51.219857    6058 generic_scheduler.go:1052] Node master is a potential node for preemption.
I0924 13:05:51.220424    6058 factory.go:470] Unable to schedule system/kube-system/coredns-default-6cfd6c6766-cqfm7: no fit: 0/1 nodes are available: 1 node(s) runtime is not ready.; waiting
I0924 13:05:51.220615    6058 scheduler.go:787] Updating pod condition for system/kube-system/coredns-default-6cfd6c6766-cqfm7 to (PodScheduled==False, Reason=Unschedulable)
I0924 13:05:53.060698    6058 scheduler.go:576] Attempting to schedule pod: system/kube-system/kube-dns-7f4bf79dc-pvldq
I0924 13:05:53.167133    6058 generic_scheduler.go:1052] Node master is a potential node for preemption.
I0924 13:05:53.168044    6058 factory.go:470] Unable to schedule system/kube-system/kube-dns-7f4bf79dc-pvldq: no fit: 0/1 nodes are available: 1 node(s) runtime is not ready.; waiting
I0924 13:05:53.168109    6058 scheduler.go:787] Updating pod condition for system/kube-system/kube-dns-7f4bf79dc-pvldq to (PodScheduled==False, Reason=Unschedulable)
I0924 13:05:53.775694    6058 scheduler.go:576] Attempting to schedule pod: system/kube-system/kube-dns-7f4bf79dc-pvldq
I0924 13:05:53.833505    6058 generic_scheduler.go:1052] Node master is a potential node for preemption.
I0924 13:05:53.833933    6058 factory.go:470] Unable to schedule system/kube-system/kube-dns-7f4bf79dc-pvldq: no fit: 0/1 nodes are available: 1 node(s) runtime is not ready.; waiting
I0924 13:05:53.834014    6058 scheduler.go:787] Updating pod condition for system/kube-system/kube-dns-7f4bf79dc-pvldq to (PodScheduled==False, Reason=Unschedulable)
I0924 13:06:02.210837    6058 scheduler.go:576] Attempting to schedule pod: system/kube-system/coredns-default-6cfd6c6766-cqfm7
I0924 13:06:02.663708    6058 generic_scheduler.go:1052] Node master is a potential node for preemption.
I0924 13:06:02.664195    6058 factory.go:470] Unable to schedule system/kube-system/coredns-default-6cfd6c6766-cqfm7: no fit: 0/1 nodes are available: 1 node(s) runtime is not ready.; waiting
I0924 13:06:02.664284    6058 scheduler.go:787] Updating pod condition for system/kube-system/coredns-default-6cfd6c6766-cqfm7 to (PodScheduled==False, Reason=Unschedulable)
I0924 13:06:04.362590    6058 scheduler.go:576] Attempting to schedule pod: system/kube-system/kube-dns-7f4bf79dc-pvldq
I0924 13:06:04.377298    6058 generic_scheduler.go:1052] Node master is a potential node for preemption.
I0924 13:06:04.377584    6058 factory.go:470] Unable to schedule system/kube-system/kube-dns-7f4bf79dc-pvldq: no fit: 0/1 nodes are available: 1 node(s) runtime is not ready.; waiting
I0924 13:06:04.377643    6058 scheduler.go:787] Updating pod condition for system/kube-system/kube-dns-7f4bf79dc-pvldq to (PodScheduled==False, Reason=Unschedulable)
I0924 13:06:11.175826    6058 scheduler.go:576] Attempting to schedule pod: system/kube-system/coredns-default-6cfd6c6766-cqfm7
I0924 13:06:11.314285    6058 generic_scheduler.go:1052] Node master is a potential node for preemption.
I0924 13:06:11.314909    6058 factory.go:470] Unable to schedule system/kube-system/coredns-default-6cfd6c6766-cqfm7: no fit: 0/1 nodes are available: 1 node(s) runtime is not ready.; waiting
I0924 13:06:11.314981    6058 scheduler.go:787] Updating pod condition for system/kube-system/coredns-default-6cfd6c6766-cqfm7 to (PodScheduled==False, Reason=Unschedulable)
I0924 13:06:12.689593    6058 scheduler.go:576] Attempting to schedule pod: system/kube-system/coredns-default-6cfd6c6766-cqfm7
I0924 13:06:12.699843    6058 generic_scheduler.go:1052] Node master is a potential node for preemption.
I0924 13:06:12.700159    6058 factory.go:470] Unable to schedule system/kube-system/coredns-default-6cfd6c6766-cqfm7: no fit: 0/1 nodes are available: 1 node(s) runtime is not ready.; waiting
I0924 13:06:12.700235    6058 scheduler.go:787] Updating pod condition for system/kube-system/coredns-default-6cfd6c6766-cqfm7 to (PodScheduled==False, Reason=Unschedulable)
I0924 13:06:13.880297    6058 scheduler.go:576] Attempting to schedule pod: system/kube-system/kube-dns-7f4bf79dc-pvldq
I0924 13:06:13.891984    6058 generic_scheduler.go:1052] Node master is a potential node for preemption.
I0924 13:06:13.892333    6058 factory.go:470] Unable to schedule system/kube-system/kube-dns-7f4bf79dc-pvldq: no fit: 0/1 nodes are available: 1 node(s) runtime is not ready.; waiting
I0924 13:06:13.892408    6058 scheduler.go:787] Updating pod condition for system/kube-system/kube-dns-7f4bf79dc-pvldq to (PodScheduled==False, Reason=Unschedulable)
I0924 13:06:15.503494    6058 scheduler.go:576] Attempting to schedule pod: system/kube-system/kube-dns-7f4bf79dc-pvldq
I0924 13:06:15.513884    6058 generic_scheduler.go:1052] Node master is a potential node for preemption.
I0924 13:06:15.514170    6058 factory.go:470] Unable to schedule system/kube-system/kube-dns-7f4bf79dc-pvldq: no fit: 0/1 nodes are available: 1 node(s) runtime is not ready.; waiting
I0924 13:06:15.514220    6058 scheduler.go:787] Updating pod condition for system/kube-system/kube-dns-7f4bf79dc-pvldq to (PodScheduled==False, Reason=Unschedulable)
I0924 13:06:23.295058    6058 scheduler.go:576] Attempting to schedule pod: system/kube-system/coredns-default-6cfd6c6766-cqfm7
I0924 13:06:23.514507    6058 generic_scheduler.go:1052] Node master is a potential node for preemption.
I0924 13:06:23.514776    6058 factory.go:470] Unable to schedule system/kube-system/coredns-default-6cfd6c6766-cqfm7: no fit: 0/1 nodes are available: 1 node(s) runtime is not ready.; waiting
I0924 13:06:23.514831    6058 scheduler.go:787] Updating pod condition for system/kube-system/coredns-default-6cfd6c6766-cqfm7 to (PodScheduled==False, Reason=Unschedulable)
I0924 13:06:26.298151    6058 scheduler.go:576] Attempting to schedule pod: system/kube-system/kube-dns-7f4bf79dc-pvldq
I0924 13:06:26.305262    6058 generic_scheduler.go:1052] Node master is a potential node for preemption.
I0924 13:06:26.305513    6058 factory.go:470] Unable to schedule system/kube-system/kube-dns-7f4bf79dc-pvldq: no fit: 0/1 nodes are available: 1 node(s) runtime is not ready.; waiting
I0924 13:06:26.305562    6058 scheduler.go:787] Updating pod condition for system/kube-system/kube-dns-7f4bf79dc-pvldq to (PodScheduled==False, Reason=Unschedulable)
I0924 13:06:32.574852    6058 scheduler.go:576] Attempting to schedule pod: system/kube-system/coredns-default-6cfd6c6766-cqfm7
I0924 13:06:32.582661    6058 generic_scheduler.go:1052] Node master is a potential node for preemption.
I0924 13:06:32.582934    6058 factory.go:470] Unable to schedule system/kube-system/coredns-default-6cfd6c6766-cqfm7: no fit: 0/1 nodes are available: 1 node(s) runtime is not ready.; waiting
I0924 13:06:32.583003    6058 scheduler.go:787] Updating pod condition for system/kube-system/coredns-default-6cfd6c6766-cqfm7 to (PodScheduled==False, Reason=Unschedulable)
I0924 13:06:33.211727    6058 scheduler.go:576] Attempting to schedule pod: system/kube-system/coredns-default-6cfd6c6766-cqfm7
I0924 13:06:33.830677    6058 generic_scheduler.go:1052] Node master is a potential node for preemption.
I0924 13:06:33.830930    6058 factory.go:470] Unable to schedule system/kube-system/coredns-default-6cfd6c6766-cqfm7: no fit: 0/1 nodes are available: 1 node(s) runtime is not ready.; waiting
I0924 13:06:33.830983    6058 scheduler.go:787] Updating pod condition for system/kube-system/coredns-default-6cfd6c6766-cqfm7 to (PodScheduled==False, Reason=Unschedulable)
I0924 13:06:35.612602    6058 scheduler.go:576] Attempting to schedule pod: system/kube-system/kube-dns-7f4bf79dc-pvldq
I0924 13:06:35.842259    6058 generic_scheduler.go:1052] Node master is a potential node for preemption.
I0924 13:06:35.842522    6058 factory.go:470] Unable to schedule system/kube-system/kube-dns-7f4bf79dc-pvldq: no fit: 0/1 nodes are available: 1 node(s) runtime is not ready.; waiting
I0924 13:06:35.842606    6058 scheduler.go:787] Updating pod condition for system/kube-system/kube-dns-7f4bf79dc-pvldq to (PodScheduled==False, Reason=Unschedulable)
I0924 13:06:37.723953    6058 scheduler.go:576] Attempting to schedule pod: system/kube-system/kube-dns-7f4bf79dc-pvldq
I0924 13:06:37.763698    6058 generic_scheduler.go:1052] Node master is a potential node for preemption.
I0924 13:06:37.763947    6058 factory.go:470] Unable to schedule system/kube-system/kube-dns-7f4bf79dc-pvldq: no fit: 0/1 nodes are available: 1 node(s) runtime is not ready.; waiting
I0924 13:06:37.763997    6058 scheduler.go:787] Updating pod condition for system/kube-system/kube-dns-7f4bf79dc-pvldq to (PodScheduled==False, Reason=Unschedulable)
I0924 13:06:44.327259    6058 scheduler.go:576] Attempting to schedule pod: system/kube-system/coredns-default-6cfd6c6766-cqfm7
I0924 13:06:44.345714    6058 generic_scheduler.go:1052] Node master is a potential node for preemption.
I0924 13:06:44.346027    6058 factory.go:470] Unable to schedule system/kube-system/coredns-default-6cfd6c6766-cqfm7: no fit: 0/1 nodes are available: 1 node(s) runtime is not ready.; waiting
I0924 13:06:44.346083    6058 scheduler.go:787] Updating pod condition for system/kube-system/coredns-default-6cfd6c6766-cqfm7 to (PodScheduled==False, Reason=Unschedulable)
I0924 13:06:48.409872    6058 scheduler.go:576] Attempting to schedule pod: system/kube-system/kube-dns-7f4bf79dc-pvldq
I0924 13:06:48.424263    6058 generic_scheduler.go:1052] Node master is a potential node for preemption.
I0924 13:06:48.424533    6058 factory.go:470] Unable to schedule system/kube-system/kube-dns-7f4bf79dc-pvldq: no fit: 0/1 nodes are available: 1 node(s) runtime is not ready.; waiting
I0924 13:06:48.424580    6058 scheduler.go:787] Updating pod condition for system/kube-system/kube-dns-7f4bf79dc-pvldq to (PodScheduled==False, Reason=Unschedulable)
I0924 13:06:53.893819    6058 scheduler.go:576] Attempting to schedule pod: system/kube-system/coredns-default-6cfd6c6766-cqfm7
I0924 13:06:53.917234    6058 generic_scheduler.go:1052] Node master is a potential node for preemption.
I0924 13:06:53.917501    6058 factory.go:470] Unable to schedule system/kube-system/coredns-default-6cfd6c6766-cqfm7: no fit: 0/1 nodes are available: 1 node(s) runtime is not ready.; waiting
I0924 13:06:53.917558    6058 scheduler.go:787] Updating pod condition for system/kube-system/coredns-default-6cfd6c6766-cqfm7 to (PodScheduled==False, Reason=Unschedulable)
I0924 13:06:54.170021    6058 scheduler.go:576] Attempting to schedule pod: system/kube-system/coredns-default-6cfd6c6766-cqfm7
I0924 13:06:54.177240    6058 generic_scheduler.go:1052] Node master is a potential node for preemption.
I0924 13:06:54.177481    6058 factory.go:470] Unable to schedule system/kube-system/coredns-default-6cfd6c6766-cqfm7: no fit: 0/1 nodes are available: 1 node(s) runtime is not ready.; waiting
I0924 13:06:54.177534    6058 scheduler.go:787] Updating pod condition for system/kube-system/coredns-default-6cfd6c6766-cqfm7 to (PodScheduled==False, Reason=Unschedulable)
I0924 13:06:57.801844    6058 scheduler.go:576] Attempting to schedule pod: system/kube-system/kube-dns-7f4bf79dc-pvldq
I0924 13:06:57.812715    6058 generic_scheduler.go:1052] Node master is a potential node for preemption.
I0924 13:06:57.812975    6058 factory.go:470] Unable to schedule system/kube-system/kube-dns-7f4bf79dc-pvldq: no fit: 0/1 nodes are available: 1 node(s) runtime is not ready.; waiting
I0924 13:06:57.813022    6058 scheduler.go:787] Updating pod condition for system/kube-system/kube-dns-7f4bf79dc-pvldq to (PodScheduled==False, Reason=Unschedulable)
I0924 13:06:58.831584    6058 scheduler.go:576] Attempting to schedule pod: system/kube-system/kube-dns-7f4bf79dc-pvldq
I0924 13:06:59.576516    6058 generic_scheduler.go:1052] Node master is a potential node for preemption.
I0924 13:06:59.577002    6058 factory.go:470] Unable to schedule system/kube-system/kube-dns-7f4bf79dc-pvldq: no fit: 0/1 nodes are available: 1 node(s) runtime is not ready.; waiting
I0924 13:06:59.577379    6058 scheduler.go:787] Updating pod condition for system/kube-system/kube-dns-7f4bf79dc-pvldq to (PodScheduled==False, Reason=Unschedulable)
I0924 13:07:04.301437    6058 scheduler.go:576] Attempting to schedule pod: system/kube-system/coredns-default-6cfd6c6766-cqfm7
I0924 13:07:04.310864    6058 generic_scheduler.go:1052] Node master is a potential node for preemption.
I0924 13:07:04.311195    6058 factory.go:470] Unable to schedule system/kube-system/coredns-default-6cfd6c6766-cqfm7: no fit: 0/1 nodes are available: 1 node(s) runtime is not ready.; waiting
I0924 13:07:04.311257    6058 scheduler.go:787] Updating pod condition for system/kube-system/coredns-default-6cfd6c6766-cqfm7 to (PodScheduled==False, Reason=Unschedulable)
I0924 13:07:07.781758    6058 eventhandlers.go:183] add event for unscheduled pod system/default/mizar-operator-6985d77546-gqn7g
I0924 13:07:07.781875    6058 scheduler.go:576] Attempting to schedule pod: system/default/mizar-operator-6985d77546-gqn7g
I0924 13:07:07.782351    6058 default_binder.go:53] Attempting to bind system/default/mizar-operator-6985d77546-gqn7g to master
I0924 13:07:07.796100    6058 eventhandlers.go:215] delete event for unscheduled pod system/default/mizar-operator-6985d77546-gqn7g
I0924 13:07:07.796204    6058 eventhandlers.go:239] add event for scheduled pod system/default/mizar-operator-6985d77546-gqn7g 
I0924 13:07:07.798953    6058 scheduler.go:741] pod system/default/mizar-operator-6985d77546-gqn7g is bound successfully on node "master", 1 nodes evaluated, 1 nodes were found feasible.
I0924 13:07:08.703358    6058 eventhandlers.go:308] delete event for scheduled pod system/default/mizar-operator-6985d77546-4bw2g 
I0924 13:07:10.441706    6058 scheduler.go:576] Attempting to schedule pod: system/kube-system/kube-dns-7f4bf79dc-pvldq
I0924 13:07:10.452142    6058 generic_scheduler.go:1052] Node master is a potential node for preemption.
I0924 13:07:10.452452    6058 factory.go:470] Unable to schedule system/kube-system/kube-dns-7f4bf79dc-pvldq: no fit: 0/1 nodes are available: 1 node(s) runtime is not ready.; waiting
I0924 13:07:10.452514    6058 scheduler.go:787] Updating pod condition for system/kube-system/kube-dns-7f4bf79dc-pvldq to (PodScheduled==False, Reason=Unschedulable)
I0924 13:07:14.807995    6058 scheduler.go:576] Attempting to schedule pod: system/kube-system/coredns-default-6cfd6c6766-cqfm7
I0924 13:07:14.827714    6058 generic_scheduler.go:1052] Node master is a potential node for preemption.
I0924 13:07:14.827989    6058 factory.go:470] Unable to schedule system/kube-system/coredns-default-6cfd6c6766-cqfm7: no fit: 0/1 nodes are available: 1 node(s) runtime is not ready.; waiting
I0924 13:07:14.828046    6058 scheduler.go:787] Updating pod condition for system/kube-system/coredns-default-6cfd6c6766-cqfm7 to (PodScheduled==False, Reason=Unschedulable)
I0924 13:07:21.142274    6058 scheduler.go:576] Attempting to schedule pod: system/kube-system/kube-dns-7f4bf79dc-pvldq
I0924 13:07:21.152579    6058 generic_scheduler.go:1052] Node master is a potential node for preemption.
I0924 13:07:21.152946    6058 factory.go:470] Unable to schedule system/kube-system/kube-dns-7f4bf79dc-pvldq: no fit: 0/1 nodes are available: 1 node(s) runtime is not ready.; waiting
I0924 13:07:21.153081    6058 scheduler.go:787] Updating pod condition for system/kube-system/kube-dns-7f4bf79dc-pvldq to (PodScheduled==False, Reason=Unschedulable)
I0924 13:07:25.182238    6058 scheduler.go:576] Attempting to schedule pod: system/kube-system/coredns-default-6cfd6c6766-cqfm7
I0924 13:07:25.191993    6058 generic_scheduler.go:1052] Node master is a potential node for preemption.
I0924 13:07:25.192265    6058 factory.go:470] Unable to schedule system/kube-system/coredns-default-6cfd6c6766-cqfm7: no fit: 0/1 nodes are available: 1 node(s) runtime is not ready.; waiting
I0924 13:07:25.192318    6058 scheduler.go:787] Updating pod condition for system/kube-system/coredns-default-6cfd6c6766-cqfm7 to (PodScheduled==False, Reason=Unschedulable)
I0924 13:07:25.425211    6058 scheduler.go:576] Attempting to schedule pod: system/kube-system/coredns-default-6cfd6c6766-cqfm7
I0924 13:07:25.467671    6058 generic_scheduler.go:1052] Node master is a potential node for preemption.
I0924 13:07:25.468033    6058 factory.go:470] Unable to schedule system/kube-system/coredns-default-6cfd6c6766-cqfm7: no fit: 0/1 nodes are available: 1 node(s) runtime is not ready.; waiting
I0924 13:07:25.468107    6058 scheduler.go:787] Updating pod condition for system/kube-system/coredns-default-6cfd6c6766-cqfm7 to (PodScheduled==False, Reason=Unschedulable)
I0924 13:07:25.468343    6058 scheduler.go:576] Attempting to schedule pod: system/kube-system/kube-dns-7f4bf79dc-pvldq
I0924 13:07:25.482105    6058 generic_scheduler.go:1052] Node master is a potential node for preemption.
I0924 13:07:25.482480    6058 factory.go:470] Unable to schedule system/kube-system/kube-dns-7f4bf79dc-pvldq: no fit: 0/1 nodes are available: 1 node(s) runtime is not ready.; waiting
I0924 13:07:25.482569    6058 scheduler.go:787] Updating pod condition for system/kube-system/kube-dns-7f4bf79dc-pvldq to (PodScheduled==False, Reason=Unschedulable)
I0924 13:07:36.185358    6058 scheduler.go:576] Attempting to schedule pod: system/kube-system/coredns-default-6cfd6c6766-cqfm7
I0924 13:07:36.197181    6058 generic_scheduler.go:1052] Node master is a potential node for preemption.
I0924 13:07:36.197426    6058 factory.go:470] Unable to schedule system/kube-system/coredns-default-6cfd6c6766-cqfm7: no fit: 0/1 nodes are available: 1 node(s) runtime is not ready.; waiting
I0924 13:07:36.197482    6058 scheduler.go:787] Updating pod condition for system/kube-system/coredns-default-6cfd6c6766-cqfm7 to (PodScheduled==False, Reason=Unschedulable)
I0924 13:07:36.197904    6058 scheduler.go:576] Attempting to schedule pod: system/kube-system/kube-dns-7f4bf79dc-pvldq
I0924 13:07:36.208492    6058 generic_scheduler.go:1052] Node master is a potential node for preemption.
I0924 13:07:36.208960    6058 factory.go:470] Unable to schedule system/kube-system/kube-dns-7f4bf79dc-pvldq: no fit: 0/1 nodes are available: 1 node(s) runtime is not ready.; waiting
I0924 13:07:36.209105    6058 scheduler.go:787] Updating pod condition for system/kube-system/kube-dns-7f4bf79dc-pvldq to (PodScheduled==False, Reason=Unschedulable)
I0924 13:07:44.245515    6058 scheduler.go:576] Attempting to schedule pod: system/kube-system/coredns-default-6cfd6c6766-cqfm7
I0924 13:07:44.303723    6058 generic_scheduler.go:1052] Node master is a potential node for preemption.
I0924 13:07:44.304014    6058 factory.go:470] Unable to schedule system/kube-system/coredns-default-6cfd6c6766-cqfm7: no fit: 0/1 nodes are available: 1 node(s) runtime is not ready.; waiting
I0924 13:07:44.304084    6058 scheduler.go:787] Updating pod condition for system/kube-system/coredns-default-6cfd6c6766-cqfm7 to (PodScheduled==False, Reason=Unschedulable)
I0924 13:07:44.304242    6058 scheduler.go:576] Attempting to schedule pod: system/kube-system/kube-dns-7f4bf79dc-pvldq
I0924 13:07:44.327698    6058 generic_scheduler.go:1052] Node master is a potential node for preemption.
I0924 13:07:44.328562    6058 factory.go:470] Unable to schedule system/kube-system/kube-dns-7f4bf79dc-pvldq: no fit: 0/1 nodes are available: 1 node(s) runtime is not ready.; waiting
I0924 13:07:44.329527    6058 scheduler.go:787] Updating pod condition for system/kube-system/kube-dns-7f4bf79dc-pvldq to (PodScheduled==False, Reason=Unschedulable)
I0924 13:07:44.726016    6058 scheduler.go:576] Attempting to schedule pod: system/kube-system/kube-dns-7f4bf79dc-pvldq
I0924 13:07:44.735352    6058 generic_scheduler.go:1052] Node master is a potential node for preemption.
I0924 13:07:44.735806    6058 factory.go:470] Unable to schedule system/kube-system/kube-dns-7f4bf79dc-pvldq: no fit: 0/1 nodes are available: 1 node(s) runtime is not ready.; waiting
I0924 13:07:44.735885    6058 scheduler.go:787] Updating pod condition for system/kube-system/kube-dns-7f4bf79dc-pvldq to (PodScheduled==False, Reason=Unschedulable)
I0924 13:07:45.175230    6058 scheduler.go:576] Attempting to schedule pod: system/kube-system/coredns-default-6cfd6c6766-cqfm7
I0924 13:07:45.186242    6058 generic_scheduler.go:1052] Node master is a potential node for preemption.
I0924 13:07:45.186519    6058 factory.go:470] Unable to schedule system/kube-system/coredns-default-6cfd6c6766-cqfm7: no fit: 0/1 nodes are available: 1 node(s) runtime is not ready.; waiting
I0924 13:07:45.186579    6058 scheduler.go:787] Updating pod condition for system/kube-system/coredns-default-6cfd6c6766-cqfm7 to (PodScheduled==False, Reason=Unschedulable)
I0924 13:07:55.319627    6058 scheduler.go:576] Attempting to schedule pod: system/kube-system/kube-dns-7f4bf79dc-pvldq
I0924 13:07:55.329960    6058 generic_scheduler.go:1052] Node master is a potential node for preemption.
I0924 13:07:55.330264    6058 factory.go:470] Unable to schedule system/kube-system/kube-dns-7f4bf79dc-pvldq: no fit: 0/1 nodes are available: 1 node(s) runtime is not ready.; waiting
I0924 13:07:55.330317    6058 scheduler.go:787] Updating pod condition for system/kube-system/kube-dns-7f4bf79dc-pvldq to (PodScheduled==False, Reason=Unschedulable)
I0924 13:07:55.330376    6058 scheduler.go:576] Attempting to schedule pod: system/kube-system/coredns-default-6cfd6c6766-cqfm7
I0924 13:07:55.342907    6058 generic_scheduler.go:1052] Node master is a potential node for preemption.
I0924 13:07:55.343160    6058 factory.go:470] Unable to schedule system/kube-system/coredns-default-6cfd6c6766-cqfm7: no fit: 0/1 nodes are available: 1 node(s) runtime is not ready.; waiting
I0924 13:07:55.343208    6058 scheduler.go:787] Updating pod condition for system/kube-system/coredns-default-6cfd6c6766-cqfm7 to (PodScheduled==False, Reason=Unschedulable)
I0924 13:08:04.718843    6058 scheduler.go:576] Attempting to schedule pod: system/kube-system/kube-dns-7f4bf79dc-pvldq
I0924 13:08:04.732303    6058 generic_scheduler.go:1052] Node master is a potential node for preemption.
I0924 13:08:04.732579    6058 factory.go:470] Unable to schedule system/kube-system/kube-dns-7f4bf79dc-pvldq: no fit: 0/1 nodes are available: 1 node(s) runtime is not ready.; waiting
I0924 13:08:04.732629    6058 scheduler.go:787] Updating pod condition for system/kube-system/kube-dns-7f4bf79dc-pvldq to (PodScheduled==False, Reason=Unschedulable)
I0924 13:08:04.957335    6058 scheduler.go:576] Attempting to schedule pod: system/kube-system/kube-dns-7f4bf79dc-pvldq
I0924 13:08:04.966519    6058 generic_scheduler.go:1052] Node master is a potential node for preemption.
I0924 13:08:04.967138    6058 factory.go:470] Unable to schedule system/kube-system/kube-dns-7f4bf79dc-pvldq: no fit: 0/1 nodes are available: 1 node(s) runtime is not ready.; waiting
I0924 13:08:04.967269    6058 scheduler.go:787] Updating pod condition for system/kube-system/kube-dns-7f4bf79dc-pvldq to (PodScheduled==False, Reason=Unschedulable)
I0924 13:08:05.338729    6058 scheduler.go:576] Attempting to schedule pod: system/kube-system/coredns-default-6cfd6c6766-cqfm7
I0924 13:08:05.346886    6058 generic_scheduler.go:1052] Node master is a potential node for preemption.
I0924 13:08:05.347186    6058 factory.go:470] Unable to schedule system/kube-system/coredns-default-6cfd6c6766-cqfm7: no fit: 0/1 nodes are available: 1 node(s) runtime is not ready.; waiting
I0924 13:08:05.347295    6058 scheduler.go:787] Updating pod condition for system/kube-system/coredns-default-6cfd6c6766-cqfm7 to (PodScheduled==False, Reason=Unschedulable)
I0924 13:08:05.983327    6058 scheduler.go:576] Attempting to schedule pod: system/kube-system/coredns-default-6cfd6c6766-cqfm7
I0924 13:08:05.995745    6058 generic_scheduler.go:1052] Node master is a potential node for preemption.
I0924 13:08:05.996276    6058 factory.go:470] Unable to schedule system/kube-system/coredns-default-6cfd6c6766-cqfm7: no fit: 0/1 nodes are available: 1 node(s) runtime is not ready.; waiting
I0924 13:08:05.996388    6058 scheduler.go:787] Updating pod condition for system/kube-system/coredns-default-6cfd6c6766-cqfm7 to (PodScheduled==False, Reason=Unschedulable)
I0924 13:08:15.354880    6058 scheduler.go:576] Attempting to schedule pod: system/kube-system/kube-dns-7f4bf79dc-pvldq
I0924 13:08:15.365451    6058 generic_scheduler.go:1052] Node master is a potential node for preemption.
I0924 13:08:15.365783    6058 factory.go:470] Unable to schedule system/kube-system/kube-dns-7f4bf79dc-pvldq: no fit: 0/1 nodes are available: 1 node(s) runtime is not ready.; waiting
I0924 13:08:15.365848    6058 scheduler.go:787] Updating pod condition for system/kube-system/kube-dns-7f4bf79dc-pvldq to (PodScheduled==False, Reason=Unschedulable)
I0924 13:08:16.355059    6058 scheduler.go:576] Attempting to schedule pod: system/kube-system/coredns-default-6cfd6c6766-cqfm7
I0924 13:08:16.364782    6058 generic_scheduler.go:1052] Node master is a potential node for preemption.
I0924 13:08:16.365867    6058 factory.go:470] Unable to schedule system/kube-system/coredns-default-6cfd6c6766-cqfm7: no fit: 0/1 nodes are available: 1 node(s) runtime is not ready.; waiting
I0924 13:08:16.365940    6058 scheduler.go:787] Updating pod condition for system/kube-system/coredns-default-6cfd6c6766-cqfm7 to (PodScheduled==False, Reason=Unschedulable)
I0924 13:08:24.953788    6058 scheduler.go:576] Attempting to schedule pod: system/kube-system/kube-dns-7f4bf79dc-pvldq
I0924 13:08:24.963023    6058 generic_scheduler.go:1052] Node master is a potential node for preemption.
I0924 13:08:24.963276    6058 factory.go:470] Unable to schedule system/kube-system/kube-dns-7f4bf79dc-pvldq: no fit: 0/1 nodes are available: 1 node(s) runtime is not ready.; waiting
I0924 13:08:24.963342    6058 scheduler.go:787] Updating pod condition for system/kube-system/kube-dns-7f4bf79dc-pvldq to (PodScheduled==False, Reason=Unschedulable)
I0924 13:08:25.174798    6058 scheduler.go:576] Attempting to schedule pod: system/kube-system/kube-dns-7f4bf79dc-pvldq
I0924 13:08:25.181891    6058 generic_scheduler.go:1052] Node master is a potential node for preemption.
I0924 13:08:25.182202    6058 factory.go:470] Unable to schedule system/kube-system/kube-dns-7f4bf79dc-pvldq: no fit: 0/1 nodes are available: 1 node(s) runtime is not ready.; waiting
I0924 13:08:25.182278    6058 scheduler.go:787] Updating pod condition for system/kube-system/kube-dns-7f4bf79dc-pvldq to (PodScheduled==False, Reason=Unschedulable)
I0924 13:08:25.978053    6058 scheduler.go:576] Attempting to schedule pod: system/kube-system/coredns-default-6cfd6c6766-cqfm7
I0924 13:08:25.986942    6058 generic_scheduler.go:1052] Node master is a potential node for preemption.
I0924 13:08:25.987200    6058 factory.go:470] Unable to schedule system/kube-system/coredns-default-6cfd6c6766-cqfm7: no fit: 0/1 nodes are available: 1 node(s) runtime is not ready.; waiting
I0924 13:08:25.987262    6058 scheduler.go:787] Updating pod condition for system/kube-system/coredns-default-6cfd6c6766-cqfm7 to (PodScheduled==False, Reason=Unschedulable)
I0924 13:08:26.187470    6058 scheduler.go:576] Attempting to schedule pod: system/kube-system/coredns-default-6cfd6c6766-cqfm7
I0924 13:08:26.195459    6058 generic_scheduler.go:1052] Node master is a potential node for preemption.
I0924 13:08:26.195960    6058 factory.go:470] Unable to schedule system/kube-system/coredns-default-6cfd6c6766-cqfm7: no fit: 0/1 nodes are available: 1 node(s) runtime is not ready.; waiting
I0924 13:08:26.196086    6058 scheduler.go:787] Updating pod condition for system/kube-system/coredns-default-6cfd6c6766-cqfm7 to (PodScheduled==False, Reason=Unschedulable)
I0924 13:08:35.361689    6058 scheduler.go:576] Attempting to schedule pod: system/kube-system/kube-dns-7f4bf79dc-pvldq
I0924 13:08:37.593961    6058 generic_scheduler.go:1052] Node master is a potential node for preemption.
I0924 13:08:37.594315    6058 factory.go:470] Unable to schedule system/kube-system/kube-dns-7f4bf79dc-pvldq: no fit: 0/1 nodes are available: 1 node(s) runtime is not ready.; waiting
I0924 13:08:37.594392    6058 scheduler.go:787] Updating pod condition for system/kube-system/kube-dns-7f4bf79dc-pvldq to (PodScheduled==False, Reason=Unschedulable)
I0924 13:08:37.595131    6058 scheduler.go:576] Attempting to schedule pod: system/kube-system/coredns-default-6cfd6c6766-cqfm7
I0924 13:08:37.604439    6058 generic_scheduler.go:1052] Node master is a potential node for preemption.
I0924 13:08:37.604864    6058 factory.go:470] Unable to schedule system/kube-system/coredns-default-6cfd6c6766-cqfm7: no fit: 0/1 nodes are available: 1 node(s) runtime is not ready.; waiting
I0924 13:08:37.604933    6058 scheduler.go:787] Updating pod condition for system/kube-system/coredns-default-6cfd6c6766-cqfm7 to (PodScheduled==False, Reason=Unschedulable)
I0924 13:08:45.181945    6058 scheduler.go:576] Attempting to schedule pod: system/kube-system/kube-dns-7f4bf79dc-pvldq
I0924 13:08:45.189122    6058 generic_scheduler.go:1052] Node master is a potential node for preemption.
I0924 13:08:45.189657    6058 factory.go:470] Unable to schedule system/kube-system/kube-dns-7f4bf79dc-pvldq: no fit: 0/1 nodes are available: 1 node(s) runtime is not ready.; waiting
I0924 13:08:45.189871    6058 scheduler.go:787] Updating pod condition for system/kube-system/kube-dns-7f4bf79dc-pvldq to (PodScheduled==False, Reason=Unschedulable)
I0924 13:08:45.436293    6058 scheduler.go:576] Attempting to schedule pod: system/kube-system/kube-dns-7f4bf79dc-pvldq
I0924 13:08:45.446701    6058 generic_scheduler.go:1052] Node master is a potential node for preemption.
I0924 13:08:45.447025    6058 factory.go:470] Unable to schedule system/kube-system/kube-dns-7f4bf79dc-pvldq: no fit: 0/1 nodes are available: 1 node(s) runtime is not ready.; waiting
I0924 13:08:45.447279    6058 scheduler.go:787] Updating pod condition for system/kube-system/kube-dns-7f4bf79dc-pvldq to (PodScheduled==False, Reason=Unschedulable)
I0924 13:08:46.185604    6058 scheduler.go:576] Attempting to schedule pod: system/kube-system/coredns-default-6cfd6c6766-cqfm7
I0924 13:08:46.199882    6058 generic_scheduler.go:1052] Node master is a potential node for preemption.
I0924 13:08:46.200466    6058 factory.go:470] Unable to schedule system/kube-system/coredns-default-6cfd6c6766-cqfm7: no fit: 0/1 nodes are available: 1 node(s) runtime is not ready.; waiting
I0924 13:08:46.200610    6058 scheduler.go:787] Updating pod condition for system/kube-system/coredns-default-6cfd6c6766-cqfm7 to (PodScheduled==False, Reason=Unschedulable)
I0924 13:08:46.415571    6058 scheduler.go:576] Attempting to schedule pod: system/kube-system/coredns-default-6cfd6c6766-cqfm7
I0924 13:08:46.425793    6058 generic_scheduler.go:1052] Node master is a potential node for preemption.
I0924 13:08:46.426110    6058 factory.go:470] Unable to schedule system/kube-system/coredns-default-6cfd6c6766-cqfm7: no fit: 0/1 nodes are available: 1 node(s) runtime is not ready.; waiting
I0924 13:08:46.426175    6058 scheduler.go:787] Updating pod condition for system/kube-system/coredns-default-6cfd6c6766-cqfm7 to (PodScheduled==False, Reason=Unschedulable)
I0924 13:08:56.368331    6058 scheduler.go:576] Attempting to schedule pod: system/kube-system/kube-dns-7f4bf79dc-pvldq
I0924 13:08:56.377091    6058 generic_scheduler.go:1052] Node master is a potential node for preemption.
I0924 13:08:56.377476    6058 factory.go:470] Unable to schedule system/kube-system/kube-dns-7f4bf79dc-pvldq: no fit: 0/1 nodes are available: 1 node(s) runtime is not ready.; waiting
I0924 13:08:56.377562    6058 scheduler.go:787] Updating pod condition for system/kube-system/kube-dns-7f4bf79dc-pvldq to (PodScheduled==False, Reason=Unschedulable)
I0924 13:08:57.368692    6058 scheduler.go:576] Attempting to schedule pod: system/kube-system/coredns-default-6cfd6c6766-cqfm7
I0924 13:08:57.377151    6058 generic_scheduler.go:1052] Node master is a potential node for preemption.
I0924 13:08:57.377655    6058 factory.go:470] Unable to schedule system/kube-system/coredns-default-6cfd6c6766-cqfm7: no fit: 0/1 nodes are available: 1 node(s) runtime is not ready.; waiting
I0924 13:08:57.377891    6058 scheduler.go:787] Updating pod condition for system/kube-system/coredns-default-6cfd6c6766-cqfm7 to (PodScheduled==False, Reason=Unschedulable)
I0924 13:09:05.439912    6058 scheduler.go:576] Attempting to schedule pod: system/kube-system/kube-dns-7f4bf79dc-pvldq
I0924 13:09:05.446707    6058 generic_scheduler.go:1052] Node master is a potential node for preemption.
I0924 13:09:05.446971    6058 factory.go:470] Unable to schedule system/kube-system/kube-dns-7f4bf79dc-pvldq: no fit: 0/1 nodes are available: 1 node(s) runtime is not ready.; waiting
I0924 13:09:05.447133    6058 scheduler.go:787] Updating pod condition for system/kube-system/kube-dns-7f4bf79dc-pvldq to (PodScheduled==False, Reason=Unschedulable)
I0924 13:09:05.653778    6058 scheduler.go:576] Attempting to schedule pod: system/kube-system/kube-dns-7f4bf79dc-pvldq
I0924 13:09:05.677772    6058 generic_scheduler.go:1052] Node master is a potential node for preemption.
I0924 13:09:05.678242    6058 factory.go:470] Unable to schedule system/kube-system/kube-dns-7f4bf79dc-pvldq: no fit: 0/1 nodes are available: 1 node(s) runtime is not ready.; waiting
I0924 13:09:05.678355    6058 scheduler.go:787] Updating pod condition for system/kube-system/kube-dns-7f4bf79dc-pvldq to (PodScheduled==False, Reason=Unschedulable)
I0924 13:09:06.415855    6058 scheduler.go:576] Attempting to schedule pod: system/kube-system/coredns-default-6cfd6c6766-cqfm7
E0924 13:09:13.422099    6058 scheduler.go:405] Error getting the updated preemptor pod object: etcdserver: request timed out
I0924 13:09:13.422239    6058 factory.go:470] Unable to schedule system/kube-system/coredns-default-6cfd6c6766-cqfm7: no fit: 0/1 nodes are available: 1 node(s) runtime is not ready.; waiting
I0924 13:09:13.422292    6058 scheduler.go:787] Updating pod condition for system/kube-system/coredns-default-6cfd6c6766-cqfm7 to (PodScheduled==False, Reason=Unschedulable)
E0924 13:09:20.430236    6058 event_broadcaster.go:234] Server rejected event '&v1beta1.Event{TypeMeta:v1.TypeMeta{Kind:"", APIVersion:""}, ObjectMeta:v1.ObjectMeta{Name:"coredns-default-6cfd6c6766-cqfm7.16a7c40dc87bed4f", GenerateName:"", Tenant:"system", Namespace:"kube-system", SelfLink:"", UID:"", HashKey:0, ResourceVersion:"", Generation:0, CreationTimestamp:v1.Time{Time:time.Time{wall:0x0, ext:0, loc:(*time.Location)(nil)}}, DeletionTimestamp:(*v1.Time)(nil), DeletionGracePeriodSeconds:(*int64)(nil), Labels:map[string]string(nil), Annotations:map[string]string(nil), OwnerReferences:[]v1.OwnerReference(nil), Initializers:(*v1.Initializers)(nil), Finalizers:[]string(nil), ClusterName:"", ManagedFields:[]v1.ManagedFieldsEntry(nil)}, EventTime:v1.MicroTime{Time:time.Time{wall:0xc04b915e592b3dc5, ext:1677555703531, loc:(*time.Location)(0x99ed840)}}, Series:(*v1beta1.EventSeries)(nil), ReportingController:"default-scheduler", ReportingInstance:"default-scheduler-master", Action:"Scheduling", Reason:"FailedScheduling", Regarding:v1.ObjectReference{Kind:"Pod", Namespace:"kube-system", Name:"coredns-default-6cfd6c6766-cqfm7", UID:"fdc1f70b-74bd-41ff-baf1-2177c0068343", APIVersion:"v1", ResourceVersion:"2793", FieldPath:"", Tenant:"system"}, Related:(*v1.ObjectReference)(nil), Note:"0/1 nodes are available: 1 node(s) runtime is not ready.", Type:"Warning", DeprecatedSource:v1.EventSource{Component:"default-scheduler", Host:""}, DeprecatedFirstTimestamp:v1.Time{Time:time.Time{wall:0x0, ext:0, loc:(*time.Location)(nil)}}, DeprecatedLastTimestamp:v1.Time{Time:time.Time{wall:0x0, ext:0, loc:(*time.Location)(nil)}}, DeprecatedCount:0}': 'etcdserver: request timed out' (will not retry!)
I0924 13:09:27.987453    6058 scheduler.go:576] Attempting to schedule pod: system/kube-system/kube-dns-7f4bf79dc-pvldq
E0924 13:09:27.988571    6058 factory.go:521] Error getting pod system/kube-system/coredns-default-6cfd6c6766-cqfm7 for retry: etcdserver: request timed out; retrying...
I0924 13:09:28.981984    6058 generic_scheduler.go:1052] Node master is a potential node for preemption.
I0924 13:09:28.982263    6058 factory.go:470] Unable to schedule system/kube-system/kube-dns-7f4bf79dc-pvldq: no fit: 0/1 nodes are available: 1 node(s) runtime is not ready.; waiting
I0924 13:09:28.982335    6058 scheduler.go:787] Updating pod condition for system/kube-system/kube-dns-7f4bf79dc-pvldq to (PodScheduled==False, Reason=Unschedulable)
I0924 13:09:29.259453    6058 scheduler.go:576] Attempting to schedule pod: system/kube-system/coredns-default-6cfd6c6766-cqfm7
I0924 13:09:29.724398    6058 generic_scheduler.go:1052] Node master is a potential node for preemption.
I0924 13:09:29.724690    6058 factory.go:470] Unable to schedule system/kube-system/coredns-default-6cfd6c6766-cqfm7: no fit: 0/1 nodes are available: 1 node(s) runtime is not ready.; waiting
I0924 13:09:29.724742    6058 scheduler.go:787] Updating pod condition for system/kube-system/coredns-default-6cfd6c6766-cqfm7 to (PodScheduled==False, Reason=Unschedulable)
E0924 13:09:30.240292    6058 factory.go:512] pod system/kube-system/coredns-default-6cfd6c6766-cqfm7 is already present in the backoff queue
I0924 13:09:40.112835    6058 scheduler.go:576] Attempting to schedule pod: system/kube-system/coredns-default-6cfd6c6766-cqfm7
I0924 13:09:40.457111    6058 generic_scheduler.go:1052] Node master is a potential node for preemption.
I0924 13:09:40.457375    6058 factory.go:470] Unable to schedule system/kube-system/coredns-default-6cfd6c6766-cqfm7: no fit: 0/1 nodes are available: 1 node(s) runtime is not ready.; waiting
I0924 13:09:40.457427    6058 scheduler.go:787] Updating pod condition for system/kube-system/coredns-default-6cfd6c6766-cqfm7 to (PodScheduled==False, Reason=Unschedulable)
I0924 13:09:40.495390    6058 scheduler.go:576] Attempting to schedule pod: system/kube-system/kube-dns-7f4bf79dc-pvldq
I0924 13:09:40.995164    6058 generic_scheduler.go:1052] Node master is a potential node for preemption.
I0924 13:09:40.995547    6058 factory.go:470] Unable to schedule system/kube-system/kube-dns-7f4bf79dc-pvldq: no fit: 0/1 nodes are available: 1 node(s) runtime is not ready.; waiting
I0924 13:09:40.995610    6058 scheduler.go:787] Updating pod condition for system/kube-system/kube-dns-7f4bf79dc-pvldq to (PodScheduled==False, Reason=Unschedulable)
I0924 13:09:52.899041    6058 scheduler.go:576] Attempting to schedule pod: system/kube-system/coredns-default-6cfd6c6766-cqfm7
I0924 13:09:53.182579    6058 generic_scheduler.go:1052] Node master is a potential node for preemption.
I0924 13:09:53.182917    6058 factory.go:470] Unable to schedule system/kube-system/coredns-default-6cfd6c6766-cqfm7: no fit: 0/1 nodes are available: 1 node(s) runtime is not ready.; waiting
I0924 13:09:53.182981    6058 scheduler.go:787] Updating pod condition for system/kube-system/coredns-default-6cfd6c6766-cqfm7 to (PodScheduled==False, Reason=Unschedulable)
I0924 13:09:54.017008    6058 scheduler.go:576] Attempting to schedule pod: system/kube-system/kube-dns-7f4bf79dc-pvldq
I0924 13:09:54.090727    6058 generic_scheduler.go:1052] Node master is a potential node for preemption.
I0924 13:09:54.091073    6058 factory.go:470] Unable to schedule system/kube-system/kube-dns-7f4bf79dc-pvldq: no fit: 0/1 nodes are available: 1 node(s) runtime is not ready.; waiting
I0924 13:09:54.091135    6058 scheduler.go:787] Updating pod condition for system/kube-system/kube-dns-7f4bf79dc-pvldq to (PodScheduled==False, Reason=Unschedulable)
I0924 13:10:04.492074    6058 scheduler.go:576] Attempting to schedule pod: system/kube-system/coredns-default-6cfd6c6766-cqfm7
I0924 13:10:04.738349    6058 generic_scheduler.go:1052] Node master is a potential node for preemption.
I0924 13:10:04.738632    6058 factory.go:470] Unable to schedule system/kube-system/coredns-default-6cfd6c6766-cqfm7: no fit: 0/1 nodes are available: 1 node(s) runtime is not ready.; waiting
I0924 13:10:04.738688    6058 scheduler.go:787] Updating pod condition for system/kube-system/coredns-default-6cfd6c6766-cqfm7 to (PodScheduled==False, Reason=Unschedulable)
I0924 13:10:04.745621    6058 scheduler.go:576] Attempting to schedule pod: system/kube-system/kube-dns-7f4bf79dc-pvldq
I0924 13:10:05.014373    6058 generic_scheduler.go:1052] Node master is a potential node for preemption.
I0924 13:10:05.014836    6058 factory.go:470] Unable to schedule system/kube-system/kube-dns-7f4bf79dc-pvldq: no fit: 0/1 nodes are available: 1 node(s) runtime is not ready.; waiting
I0924 13:10:05.014906    6058 scheduler.go:787] Updating pod condition for system/kube-system/kube-dns-7f4bf79dc-pvldq to (PodScheduled==False, Reason=Unschedulable)
I0924 13:10:15.981955    6058 scheduler.go:576] Attempting to schedule pod: system/kube-system/kube-dns-7f4bf79dc-pvldq
I0924 13:10:16.523586    6058 generic_scheduler.go:1052] Node master is a potential node for preemption.
I0924 13:10:16.523898    6058 factory.go:470] Unable to schedule system/kube-system/kube-dns-7f4bf79dc-pvldq: no fit: 0/1 nodes are available: 1 node(s) runtime is not ready.; waiting
I0924 13:10:16.523957    6058 scheduler.go:787] Updating pod condition for system/kube-system/kube-dns-7f4bf79dc-pvldq to (PodScheduled==False, Reason=Unschedulable)
I0924 13:10:16.524180    6058 scheduler.go:576] Attempting to schedule pod: system/kube-system/coredns-default-6cfd6c6766-cqfm7
I0924 13:10:16.621641    6058 generic_scheduler.go:1052] Node master is a potential node for preemption.
I0924 13:10:16.621964    6058 factory.go:470] Unable to schedule system/kube-system/coredns-default-6cfd6c6766-cqfm7: no fit: 0/1 nodes are available: 1 node(s) runtime is not ready.; waiting
I0924 13:10:16.622021    6058 scheduler.go:787] Updating pod condition for system/kube-system/coredns-default-6cfd6c6766-cqfm7 to (PodScheduled==False, Reason=Unschedulable)
I0924 13:10:27.395660    6058 scheduler.go:576] Attempting to schedule pod: system/kube-system/kube-dns-7f4bf79dc-pvldq
I0924 13:10:28.009352    6058 generic_scheduler.go:1052] Node master is a potential node for preemption.
I0924 13:10:28.009715    6058 factory.go:470] Unable to schedule system/kube-system/kube-dns-7f4bf79dc-pvldq: no fit: 0/1 nodes are available: 1 node(s) runtime is not ready.; waiting
I0924 13:10:28.685936    6058 scheduler.go:787] Updating pod condition for system/kube-system/kube-dns-7f4bf79dc-pvldq to (PodScheduled==False, Reason=Unschedulable)
I0924 13:10:28.688576    6058 scheduler.go:576] Attempting to schedule pod: system/kube-system/coredns-default-6cfd6c6766-cqfm7
I0924 13:10:28.744159    6058 generic_scheduler.go:1052] Node master is a potential node for preemption.
I0924 13:10:28.744427    6058 factory.go:470] Unable to schedule system/kube-system/coredns-default-6cfd6c6766-cqfm7: no fit: 0/1 nodes are available: 1 node(s) runtime is not ready.; waiting
I0924 13:10:28.744480    6058 scheduler.go:787] Updating pod condition for system/kube-system/coredns-default-6cfd6c6766-cqfm7 to (PodScheduled==False, Reason=Unschedulable)
I0924 13:10:39.395181    6058 scheduler.go:576] Attempting to schedule pod: system/kube-system/kube-dns-7f4bf79dc-pvldq
I0924 13:10:39.748567    6058 generic_scheduler.go:1052] Node master is a potential node for preemption.
I0924 13:10:39.748982    6058 factory.go:470] Unable to schedule system/kube-system/kube-dns-7f4bf79dc-pvldq: no fit: 0/1 nodes are available: 1 node(s) runtime is not ready.; waiting
I0924 13:10:39.749051    6058 scheduler.go:787] Updating pod condition for system/kube-system/kube-dns-7f4bf79dc-pvldq to (PodScheduled==False, Reason=Unschedulable)
I0924 13:10:39.766279    6058 scheduler.go:576] Attempting to schedule pod: system/kube-system/coredns-default-6cfd6c6766-cqfm7
I0924 13:10:39.840846    6058 generic_scheduler.go:1052] Node master is a potential node for preemption.
I0924 13:10:39.841142    6058 factory.go:470] Unable to schedule system/kube-system/coredns-default-6cfd6c6766-cqfm7: no fit: 0/1 nodes are available: 1 node(s) runtime is not ready.; waiting
I0924 13:10:39.841198    6058 scheduler.go:787] Updating pod condition for system/kube-system/coredns-default-6cfd6c6766-cqfm7 to (PodScheduled==False, Reason=Unschedulable)
I0924 13:10:50.299271    6058 scheduler.go:576] Attempting to schedule pod: system/kube-system/kube-dns-7f4bf79dc-pvldq
I0924 13:10:51.353267    6058 generic_scheduler.go:1052] Node master is a potential node for preemption.
I0924 13:10:51.353599    6058 factory.go:470] Unable to schedule system/kube-system/kube-dns-7f4bf79dc-pvldq: no fit: 0/1 nodes are available: 1 node(s) runtime is not ready.; waiting
I0924 13:10:51.353660    6058 scheduler.go:787] Updating pod condition for system/kube-system/kube-dns-7f4bf79dc-pvldq to (PodScheduled==False, Reason=Unschedulable)
I0924 13:10:51.354908    6058 scheduler.go:576] Attempting to schedule pod: system/kube-system/coredns-default-6cfd6c6766-cqfm7
I0924 13:10:51.379701    6058 generic_scheduler.go:1052] Node master is a potential node for preemption.
I0924 13:10:51.384035    6058 factory.go:470] Unable to schedule system/kube-system/coredns-default-6cfd6c6766-cqfm7: no fit: 0/1 nodes are available: 1 node(s) runtime is not ready.; waiting
I0924 13:10:51.384125    6058 scheduler.go:787] Updating pod condition for system/kube-system/coredns-default-6cfd6c6766-cqfm7 to (PodScheduled==False, Reason=Unschedulable)
I0924 13:11:03.157077    6058 scheduler.go:576] Attempting to schedule pod: system/kube-system/kube-dns-7f4bf79dc-pvldq
I0924 13:11:03.386735    6058 generic_scheduler.go:1052] Node master is a potential node for preemption.
I0924 13:11:03.387002    6058 factory.go:470] Unable to schedule system/kube-system/kube-dns-7f4bf79dc-pvldq: no fit: 0/1 nodes are available: 1 node(s) runtime is not ready.; waiting
I0924 13:11:03.387054    6058 scheduler.go:787] Updating pod condition for system/kube-system/kube-dns-7f4bf79dc-pvldq to (PodScheduled==False, Reason=Unschedulable)
I0924 13:11:03.387543    6058 scheduler.go:576] Attempting to schedule pod: system/kube-system/coredns-default-6cfd6c6766-cqfm7
I0924 13:11:03.600923    6058 generic_scheduler.go:1052] Node master is a potential node for preemption.
I0924 13:11:03.601211    6058 factory.go:470] Unable to schedule system/kube-system/coredns-default-6cfd6c6766-cqfm7: no fit: 0/1 nodes are available: 1 node(s) runtime is not ready.; waiting
I0924 13:11:03.601654    6058 scheduler.go:787] Updating pod condition for system/kube-system/coredns-default-6cfd6c6766-cqfm7 to (PodScheduled==False, Reason=Unschedulable)
I0924 13:11:13.674939    6058 scheduler.go:576] Attempting to schedule pod: system/kube-system/kube-dns-7f4bf79dc-pvldq
I0924 13:11:14.083117    6058 generic_scheduler.go:1052] Node master is a potential node for preemption.
I0924 13:11:14.083420    6058 factory.go:470] Unable to schedule system/kube-system/kube-dns-7f4bf79dc-pvldq: no fit: 0/1 nodes are available: 1 node(s) runtime is not ready.; waiting
I0924 13:11:14.083469    6058 scheduler.go:787] Updating pod condition for system/kube-system/kube-dns-7f4bf79dc-pvldq to (PodScheduled==False, Reason=Unschedulable)
I0924 13:11:14.690906    6058 scheduler.go:576] Attempting to schedule pod: system/kube-system/coredns-default-6cfd6c6766-cqfm7
I0924 13:11:15.050503    6058 generic_scheduler.go:1052] Node master is a potential node for preemption.
I0924 13:11:15.050783    6058 factory.go:470] Unable to schedule system/kube-system/coredns-default-6cfd6c6766-cqfm7: no fit: 0/1 nodes are available: 1 node(s) runtime is not ready.; waiting
I0924 13:11:15.050836    6058 scheduler.go:787] Updating pod condition for system/kube-system/coredns-default-6cfd6c6766-cqfm7 to (PodScheduled==False, Reason=Unschedulable)
I0924 13:11:24.729770    6058 scheduler.go:576] Attempting to schedule pod: system/kube-system/kube-dns-7f4bf79dc-pvldq
I0924 13:11:25.339649    6058 generic_scheduler.go:1052] Node master is a potential node for preemption.
I0924 13:11:25.339973    6058 factory.go:470] Unable to schedule system/kube-system/kube-dns-7f4bf79dc-pvldq: no fit: 0/1 nodes are available: 1 node(s) runtime is not ready.; waiting
I0924 13:11:25.340035    6058 scheduler.go:787] Updating pod condition for system/kube-system/kube-dns-7f4bf79dc-pvldq to (PodScheduled==False, Reason=Unschedulable)
I0924 13:11:25.738950    6058 scheduler.go:576] Attempting to schedule pod: system/kube-system/coredns-default-6cfd6c6766-cqfm7
I0924 13:11:25.938621    6058 generic_scheduler.go:1052] Node master is a potential node for preemption.
I0924 13:11:25.938955    6058 factory.go:470] Unable to schedule system/kube-system/coredns-default-6cfd6c6766-cqfm7: no fit: 0/1 nodes are available: 1 node(s) runtime is not ready.; waiting
I0924 13:11:25.939020    6058 scheduler.go:787] Updating pod condition for system/kube-system/coredns-default-6cfd6c6766-cqfm7 to (PodScheduled==False, Reason=Unschedulable)
I0924 13:11:36.360960    6058 scheduler.go:576] Attempting to schedule pod: system/kube-system/kube-dns-7f4bf79dc-pvldq
I0924 13:11:36.678652    6058 generic_scheduler.go:1052] Node master is a potential node for preemption.
I0924 13:11:36.678963    6058 factory.go:470] Unable to schedule system/kube-system/kube-dns-7f4bf79dc-pvldq: no fit: 0/1 nodes are available: 1 node(s) runtime is not ready.; waiting
I0924 13:11:36.679015    6058 scheduler.go:787] Updating pod condition for system/kube-system/kube-dns-7f4bf79dc-pvldq to (PodScheduled==False, Reason=Unschedulable)
I0924 13:11:36.681845    6058 scheduler.go:576] Attempting to schedule pod: system/kube-system/coredns-default-6cfd6c6766-cqfm7
I0924 13:11:37.179507    6058 generic_scheduler.go:1052] Node master is a potential node for preemption.
I0924 13:11:37.179759    6058 factory.go:470] Unable to schedule system/kube-system/coredns-default-6cfd6c6766-cqfm7: no fit: 0/1 nodes are available: 1 node(s) runtime is not ready.; waiting
I0924 13:11:37.179822    6058 scheduler.go:787] Updating pod condition for system/kube-system/coredns-default-6cfd6c6766-cqfm7 to (PodScheduled==False, Reason=Unschedulable)
I0924 13:11:47.347817    6058 scheduler.go:576] Attempting to schedule pod: system/kube-system/kube-dns-7f4bf79dc-pvldq
I0924 13:11:47.456149    6058 generic_scheduler.go:1052] Node master is a potential node for preemption.
I0924 13:11:47.456753    6058 factory.go:470] Unable to schedule system/kube-system/kube-dns-7f4bf79dc-pvldq: no fit: 0/1 nodes are available: 1 node(s) runtime is not ready.; waiting
I0924 13:11:47.456845    6058 scheduler.go:787] Updating pod condition for system/kube-system/kube-dns-7f4bf79dc-pvldq to (PodScheduled==False, Reason=Unschedulable)
I0924 13:11:47.508851    6058 scheduler.go:576] Attempting to schedule pod: system/kube-system/coredns-default-6cfd6c6766-cqfm7
I0924 13:11:47.677184    6058 generic_scheduler.go:1052] Node master is a potential node for preemption.
I0924 13:11:47.677442    6058 factory.go:470] Unable to schedule system/kube-system/coredns-default-6cfd6c6766-cqfm7: no fit: 0/1 nodes are available: 1 node(s) runtime is not ready.; waiting
I0924 13:11:47.677493    6058 scheduler.go:787] Updating pod condition for system/kube-system/coredns-default-6cfd6c6766-cqfm7 to (PodScheduled==False, Reason=Unschedulable)
I0924 13:11:57.850102    6058 scheduler.go:576] Attempting to schedule pod: system/kube-system/kube-dns-7f4bf79dc-pvldq
I0924 13:11:58.281520    6058 generic_scheduler.go:1052] Node master is a potential node for preemption.
I0924 13:11:58.281838    6058 factory.go:470] Unable to schedule system/kube-system/kube-dns-7f4bf79dc-pvldq: no fit: 0/1 nodes are available: 1 node(s) runtime is not ready.; waiting
I0924 13:11:58.281905    6058 scheduler.go:787] Updating pod condition for system/kube-system/kube-dns-7f4bf79dc-pvldq to (PodScheduled==False, Reason=Unschedulable)
I0924 13:11:58.283919    6058 scheduler.go:576] Attempting to schedule pod: system/kube-system/coredns-default-6cfd6c6766-cqfm7
I0924 13:11:58.644097    6058 generic_scheduler.go:1052] Node master is a potential node for preemption.
I0924 13:11:58.644925    6058 factory.go:470] Unable to schedule system/kube-system/coredns-default-6cfd6c6766-cqfm7: no fit: 0/1 nodes are available: 1 node(s) runtime is not ready.; waiting
I0924 13:11:58.645042    6058 scheduler.go:787] Updating pod condition for system/kube-system/coredns-default-6cfd6c6766-cqfm7 to (PodScheduled==False, Reason=Unschedulable)
I0924 13:12:08.469057    6058 scheduler.go:576] Attempting to schedule pod: system/kube-system/kube-dns-7f4bf79dc-pvldq
I0924 13:12:08.695971    6058 generic_scheduler.go:1052] Node master is a potential node for preemption.
I0924 13:12:08.823996    6058 factory.go:470] Unable to schedule system/kube-system/kube-dns-7f4bf79dc-pvldq: no fit: 0/1 nodes are available: 1 node(s) runtime is not ready.; waiting
I0924 13:12:08.824183    6058 scheduler.go:787] Updating pod condition for system/kube-system/kube-dns-7f4bf79dc-pvldq to (PodScheduled==False, Reason=Unschedulable)
I0924 13:12:08.845037    6058 eventhandlers.go:183] add event for unscheduled pod system/default/mizar-operator-6985d77546-ttkxg
I0924 13:12:08.845162    6058 scheduler.go:576] Attempting to schedule pod: system/default/mizar-operator-6985d77546-ttkxg
I0924 13:12:08.845617    6058 default_binder.go:53] Attempting to bind system/default/mizar-operator-6985d77546-ttkxg to master
I0924 13:12:09.000695    6058 eventhandlers.go:215] delete event for unscheduled pod system/default/mizar-operator-6985d77546-ttkxg
I0924 13:12:09.000860    6058 eventhandlers.go:239] add event for scheduled pod system/default/mizar-operator-6985d77546-ttkxg 
I0924 13:12:09.198325    6058 scheduler.go:741] pod system/default/mizar-operator-6985d77546-ttkxg is bound successfully on node "master", 1 nodes evaluated, 1 nodes were found feasible.
I0924 13:12:09.506082    6058 scheduler.go:576] Attempting to schedule pod: system/kube-system/coredns-default-6cfd6c6766-cqfm7
I0924 13:12:09.944151    6058 generic_scheduler.go:1052] Node master is a potential node for preemption.
I0924 13:12:09.981215    6058 factory.go:470] Unable to schedule system/kube-system/coredns-default-6cfd6c6766-cqfm7: no fit: 0/1 nodes are available: 1 node(s) runtime is not ready.; waiting
I0924 13:12:09.981305    6058 scheduler.go:787] Updating pod condition for system/kube-system/coredns-default-6cfd6c6766-cqfm7 to (PodScheduled==False, Reason=Unschedulable)
I0924 13:12:12.395283    6058 eventhandlers.go:308] delete event for scheduled pod system/default/mizar-operator-6985d77546-gqn7g 
I0924 13:12:19.210866    6058 scheduler.go:576] Attempting to schedule pod: system/kube-system/kube-dns-7f4bf79dc-pvldq
I0924 13:12:19.555246    6058 generic_scheduler.go:1052] Node master is a potential node for preemption.
I0924 13:12:19.555620    6058 factory.go:470] Unable to schedule system/kube-system/kube-dns-7f4bf79dc-pvldq: no fit: 0/1 nodes are available: 1 node(s) runtime is not ready.; waiting
I0924 13:12:19.555685    6058 scheduler.go:787] Updating pod condition for system/kube-system/kube-dns-7f4bf79dc-pvldq to (PodScheduled==False, Reason=Unschedulable)
I0924 13:12:22.488893    6058 scheduler.go:576] Attempting to schedule pod: system/kube-system/coredns-default-6cfd6c6766-cqfm7
I0924 13:12:22.953164    6058 generic_scheduler.go:1052] Node master is a potential node for preemption.
I0924 13:12:22.953438    6058 factory.go:470] Unable to schedule system/kube-system/coredns-default-6cfd6c6766-cqfm7: no fit: 0/1 nodes are available: 1 node(s) runtime is not ready.; waiting
I0924 13:12:22.953492    6058 scheduler.go:787] Updating pod condition for system/kube-system/coredns-default-6cfd6c6766-cqfm7 to (PodScheduled==False, Reason=Unschedulable)
I0924 13:12:31.854712    6058 scheduler.go:576] Attempting to schedule pod: system/kube-system/kube-dns-7f4bf79dc-pvldq
I0924 13:12:32.175253    6058 generic_scheduler.go:1052] Node master is a potential node for preemption.
I0924 13:12:32.175581    6058 factory.go:470] Unable to schedule system/kube-system/kube-dns-7f4bf79dc-pvldq: no fit: 0/1 nodes are available: 1 node(s) runtime is not ready.; waiting
I0924 13:12:32.175635    6058 scheduler.go:787] Updating pod condition for system/kube-system/kube-dns-7f4bf79dc-pvldq to (PodScheduled==False, Reason=Unschedulable)
I0924 13:12:33.865480    6058 scheduler.go:576] Attempting to schedule pod: system/kube-system/coredns-default-6cfd6c6766-cqfm7
I0924 13:12:34.332916    6058 generic_scheduler.go:1052] Node master is a potential node for preemption.
I0924 13:12:34.738324    6058 factory.go:470] Unable to schedule system/kube-system/coredns-default-6cfd6c6766-cqfm7: no fit: 0/1 nodes are available: 1 node(s) runtime is not ready.; waiting
I0924 13:12:34.738585    6058 scheduler.go:787] Updating pod condition for system/kube-system/coredns-default-6cfd6c6766-cqfm7 to (PodScheduled==False, Reason=Unschedulable)
I0924 13:12:42.707645    6058 scheduler.go:576] Attempting to schedule pod: system/kube-system/kube-dns-7f4bf79dc-pvldq
I0924 13:12:42.798486    6058 generic_scheduler.go:1052] Node master is a potential node for preemption.
I0924 13:12:42.798806    6058 factory.go:470] Unable to schedule system/kube-system/kube-dns-7f4bf79dc-pvldq: no fit: 0/1 nodes are available: 1 node(s) runtime is not ready.; waiting
I0924 13:12:42.798859    6058 scheduler.go:787] Updating pod condition for system/kube-system/kube-dns-7f4bf79dc-pvldq to (PodScheduled==False, Reason=Unschedulable)
I0924 13:12:46.064026    6058 scheduler.go:576] Attempting to schedule pod: system/kube-system/coredns-default-6cfd6c6766-cqfm7
I0924 13:12:46.171101    6058 generic_scheduler.go:1052] Node master is a potential node for preemption.
I0924 13:12:46.171435    6058 factory.go:470] Unable to schedule system/kube-system/coredns-default-6cfd6c6766-cqfm7: no fit: 0/1 nodes are available: 1 node(s) runtime is not ready.; waiting
I0924 13:12:46.171504    6058 scheduler.go:787] Updating pod condition for system/kube-system/coredns-default-6cfd6c6766-cqfm7 to (PodScheduled==False, Reason=Unschedulable)
I0924 13:12:53.380984    6058 scheduler.go:576] Attempting to schedule pod: system/kube-system/kube-dns-7f4bf79dc-pvldq
I0924 13:12:53.794377    6058 generic_scheduler.go:1052] Node master is a potential node for preemption.
I0924 13:12:53.794769    6058 factory.go:470] Unable to schedule system/kube-system/kube-dns-7f4bf79dc-pvldq: no fit: 0/1 nodes are available: 1 node(s) runtime is not ready.; waiting
I0924 13:12:53.794832    6058 scheduler.go:787] Updating pod condition for system/kube-system/kube-dns-7f4bf79dc-pvldq to (PodScheduled==False, Reason=Unschedulable)
I0924 13:12:57.122198    6058 scheduler.go:576] Attempting to schedule pod: system/kube-system/coredns-default-6cfd6c6766-cqfm7
I0924 13:12:57.183872    6058 generic_scheduler.go:1052] Node master is a potential node for preemption.
I0924 13:12:57.184708    6058 factory.go:470] Unable to schedule system/kube-system/coredns-default-6cfd6c6766-cqfm7: no fit: 0/1 nodes are available: 1 node(s) runtime is not ready.; waiting
I0924 13:12:57.185113    6058 scheduler.go:787] Updating pod condition for system/kube-system/coredns-default-6cfd6c6766-cqfm7 to (PodScheduled==False, Reason=Unschedulable)
I0924 13:13:04.568359    6058 scheduler.go:576] Attempting to schedule pod: system/kube-system/kube-dns-7f4bf79dc-pvldq
I0924 13:13:04.902773    6058 generic_scheduler.go:1052] Node master is a potential node for preemption.
I0924 13:13:04.903045    6058 factory.go:470] Unable to schedule system/kube-system/kube-dns-7f4bf79dc-pvldq: no fit: 0/1 nodes are available: 1 node(s) runtime is not ready.; waiting
I0924 13:13:04.903101    6058 scheduler.go:787] Updating pod condition for system/kube-system/kube-dns-7f4bf79dc-pvldq to (PodScheduled==False, Reason=Unschedulable)
I0924 13:13:08.700111    6058 scheduler.go:576] Attempting to schedule pod: system/kube-system/coredns-default-6cfd6c6766-cqfm7
I0924 13:13:09.077816    6058 generic_scheduler.go:1052] Node master is a potential node for preemption.
I0924 13:13:09.078318    6058 factory.go:470] Unable to schedule system/kube-system/coredns-default-6cfd6c6766-cqfm7: no fit: 0/1 nodes are available: 1 node(s) runtime is not ready.; waiting
I0924 13:13:09.078384    6058 scheduler.go:787] Updating pod condition for system/kube-system/coredns-default-6cfd6c6766-cqfm7 to (PodScheduled==False, Reason=Unschedulable)
I0924 13:13:15.362822    6058 scheduler.go:576] Attempting to schedule pod: system/kube-system/kube-dns-7f4bf79dc-pvldq
I0924 13:13:15.565780    6058 generic_scheduler.go:1052] Node master is a potential node for preemption.
I0924 13:13:15.566089    6058 factory.go:470] Unable to schedule system/kube-system/kube-dns-7f4bf79dc-pvldq: no fit: 0/1 nodes are available: 1 node(s) runtime is not ready.; waiting
I0924 13:13:15.566177    6058 scheduler.go:787] Updating pod condition for system/kube-system/kube-dns-7f4bf79dc-pvldq to (PodScheduled==False, Reason=Unschedulable)
I0924 13:13:19.858596    6058 scheduler.go:576] Attempting to schedule pod: system/kube-system/coredns-default-6cfd6c6766-cqfm7
I0924 13:13:20.312484    6058 generic_scheduler.go:1052] Node master is a potential node for preemption.
I0924 13:13:20.312833    6058 factory.go:470] Unable to schedule system/kube-system/coredns-default-6cfd6c6766-cqfm7: no fit: 0/1 nodes are available: 1 node(s) runtime is not ready.; waiting
I0924 13:13:20.312899    6058 scheduler.go:787] Updating pod condition for system/kube-system/coredns-default-6cfd6c6766-cqfm7 to (PodScheduled==False, Reason=Unschedulable)
I0924 13:13:26.064745    6058 scheduler.go:576] Attempting to schedule pod: system/kube-system/kube-dns-7f4bf79dc-pvldq
I0924 13:13:26.096869    6058 generic_scheduler.go:1052] Node master is a potential node for preemption.
I0924 13:13:26.097120    6058 factory.go:470] Unable to schedule system/kube-system/kube-dns-7f4bf79dc-pvldq: no fit: 0/1 nodes are available: 1 node(s) runtime is not ready.; waiting
I0924 13:13:26.097171    6058 scheduler.go:787] Updating pod condition for system/kube-system/kube-dns-7f4bf79dc-pvldq to (PodScheduled==False, Reason=Unschedulable)
I0924 13:13:31.183801    6058 scheduler.go:576] Attempting to schedule pod: system/kube-system/coredns-default-6cfd6c6766-cqfm7
I0924 13:13:31.311655    6058 generic_scheduler.go:1052] Node master is a potential node for preemption.
I0924 13:13:31.311926    6058 factory.go:470] Unable to schedule system/kube-system/coredns-default-6cfd6c6766-cqfm7: no fit: 0/1 nodes are available: 1 node(s) runtime is not ready.; waiting
I0924 13:13:31.311977    6058 scheduler.go:787] Updating pod condition for system/kube-system/coredns-default-6cfd6c6766-cqfm7 to (PodScheduled==False, Reason=Unschedulable)
I0924 13:13:36.612250    6058 scheduler.go:576] Attempting to schedule pod: system/kube-system/kube-dns-7f4bf79dc-pvldq
I0924 13:13:36.902453    6058 generic_scheduler.go:1052] Node master is a potential node for preemption.
I0924 13:13:36.902709    6058 factory.go:470] Unable to schedule system/kube-system/kube-dns-7f4bf79dc-pvldq: no fit: 0/1 nodes are available: 1 node(s) runtime is not ready.; waiting
I0924 13:13:36.902760    6058 scheduler.go:787] Updating pod condition for system/kube-system/kube-dns-7f4bf79dc-pvldq to (PodScheduled==False, Reason=Unschedulable)
I0924 13:13:41.974185    6058 scheduler.go:576] Attempting to schedule pod: system/kube-system/coredns-default-6cfd6c6766-cqfm7
I0924 13:13:42.207583    6058 generic_scheduler.go:1052] Node master is a potential node for preemption.
I0924 13:13:42.207908    6058 factory.go:470] Unable to schedule system/kube-system/coredns-default-6cfd6c6766-cqfm7: no fit: 0/1 nodes are available: 1 node(s) runtime is not ready.; waiting
I0924 13:13:42.207972    6058 scheduler.go:787] Updating pod condition for system/kube-system/coredns-default-6cfd6c6766-cqfm7 to (PodScheduled==False, Reason=Unschedulable)
I0924 13:13:42.756073    6058 scheduler.go:576] Attempting to schedule pod: system/kube-system/coredns-default-6cfd6c6766-cqfm7
I0924 13:13:43.105500    6058 generic_scheduler.go:1052] Node master is a potential node for preemption.
I0924 13:13:43.105802    6058 factory.go:470] Unable to schedule system/kube-system/coredns-default-6cfd6c6766-cqfm7: no fit: 0/1 nodes are available: 1 node(s) runtime is not ready.; waiting
I0924 13:13:43.105855    6058 scheduler.go:787] Updating pod condition for system/kube-system/coredns-default-6cfd6c6766-cqfm7 to (PodScheduled==False, Reason=Unschedulable)
I0924 13:13:43.315360    6058 scheduler.go:576] Attempting to schedule pod: system/kube-system/kube-dns-7f4bf79dc-pvldq
I0924 13:13:43.655915    6058 generic_scheduler.go:1052] Node master is a potential node for preemption.
I0924 13:13:43.656255    6058 factory.go:470] Unable to schedule system/kube-system/kube-dns-7f4bf79dc-pvldq: no fit: 0/1 nodes are available: 1 node(s) runtime is not ready.; waiting
I0924 13:13:43.656359    6058 scheduler.go:787] Updating pod condition for system/kube-system/kube-dns-7f4bf79dc-pvldq to (PodScheduled==False, Reason=Unschedulable)
I0924 13:13:53.385683    6058 scheduler.go:576] Attempting to schedule pod: system/kube-system/coredns-default-6cfd6c6766-cqfm7
I0924 13:13:53.417336    6058 generic_scheduler.go:1052] Node master is a potential node for preemption.
I0924 13:13:53.438585    6058 factory.go:470] Unable to schedule system/kube-system/coredns-default-6cfd6c6766-cqfm7: no fit: 0/1 nodes are available: 1 node(s) runtime is not ready.; waiting
I0924 13:13:53.438751    6058 scheduler.go:787] Updating pod condition for system/kube-system/coredns-default-6cfd6c6766-cqfm7 to (PodScheduled==False, Reason=Unschedulable)
I0924 13:13:54.448861    6058 scheduler.go:576] Attempting to schedule pod: system/kube-system/kube-dns-7f4bf79dc-pvldq
I0924 13:13:54.455292    6058 generic_scheduler.go:1052] Node master is a potential node for preemption.
I0924 13:13:54.455533    6058 factory.go:470] Unable to schedule system/kube-system/kube-dns-7f4bf79dc-pvldq: no fit: 0/1 nodes are available: 1 node(s) runtime is not ready.; waiting
I0924 13:13:54.455580    6058 scheduler.go:787] Updating pod condition for system/kube-system/kube-dns-7f4bf79dc-pvldq to (PodScheduled==False, Reason=Unschedulable)
I0924 13:13:59.713708    6058 scheduler.go:576] Attempting to schedule pod: system/kube-system/coredns-default-6cfd6c6766-cqfm7
I0924 13:13:59.789945    6058 generic_scheduler.go:1052] Node master is a potential node for preemption.
I0924 13:13:59.790390    6058 factory.go:470] Unable to schedule system/kube-system/coredns-default-6cfd6c6766-cqfm7: no fit: 0/1 nodes are available: 1 node(s) runtime is not ready.; waiting
I0924 13:13:59.790452    6058 scheduler.go:787] Updating pod condition for system/kube-system/coredns-default-6cfd6c6766-cqfm7 to (PodScheduled==False, Reason=Unschedulable)
I0924 13:14:01.575170    6058 scheduler.go:576] Attempting to schedule pod: system/kube-system/kube-dns-7f4bf79dc-pvldq
I0924 13:14:01.881563    6058 generic_scheduler.go:1052] Node master is a potential node for preemption.
I0924 13:14:01.881956    6058 factory.go:470] Unable to schedule system/kube-system/kube-dns-7f4bf79dc-pvldq: no fit: 0/1 nodes are available: 1 node(s) runtime is not ready.; waiting
I0924 13:14:01.882018    6058 scheduler.go:787] Updating pod condition for system/kube-system/kube-dns-7f4bf79dc-pvldq to (PodScheduled==False, Reason=Unschedulable)
I0924 13:14:02.123727    6058 scheduler.go:576] Attempting to schedule pod: system/kube-system/coredns-default-6cfd6c6766-cqfm7
I0924 13:14:02.242539    6058 trace.go:81] Trace[706800797]: "Scheduling system/kube-system/coredns-default-6cfd6c6766-cqfm7" (started: 2021-09-24 13:14:02.123806313 +0000 UTC m=+1966.257245564) (total time: 118.594339ms):
Trace[706800797]: [118.402307ms] [118.39349ms] Running prefilter plugins done
I0924 13:14:02.254505    6058 generic_scheduler.go:1052] Node master is a potential node for preemption.
I0924 13:14:02.255045    6058 factory.go:470] Unable to schedule system/kube-system/coredns-default-6cfd6c6766-cqfm7: no fit: 0/1 nodes are available: 1 node(s) runtime is not ready.; waiting
I0924 13:14:02.255125    6058 scheduler.go:787] Updating pod condition for system/kube-system/coredns-default-6cfd6c6766-cqfm7 to (PodScheduled==False, Reason=Unschedulable)
I0924 13:14:04.132321    6058 scheduler.go:576] Attempting to schedule pod: system/kube-system/kube-dns-7f4bf79dc-pvldq
I0924 13:14:04.266601    6058 generic_scheduler.go:1052] Node master is a potential node for preemption.
I0924 13:14:04.267988    6058 factory.go:470] Unable to schedule system/kube-system/kube-dns-7f4bf79dc-pvldq: no fit: 0/1 nodes are available: 1 node(s) runtime is not ready.; waiting
I0924 13:14:04.268065    6058 scheduler.go:787] Updating pod condition for system/kube-system/kube-dns-7f4bf79dc-pvldq to (PodScheduled==False, Reason=Unschedulable)
I0924 13:14:12.876938    6058 scheduler.go:576] Attempting to schedule pod: system/kube-system/coredns-default-6cfd6c6766-cqfm7
I0924 13:14:13.040197    6058 generic_scheduler.go:1052] Node master is a potential node for preemption.
I0924 13:14:13.040574    6058 factory.go:470] Unable to schedule system/kube-system/coredns-default-6cfd6c6766-cqfm7: no fit: 0/1 nodes are available: 1 node(s) runtime is not ready.; waiting
I0924 13:14:13.040634    6058 scheduler.go:787] Updating pod condition for system/kube-system/coredns-default-6cfd6c6766-cqfm7 to (PodScheduled==False, Reason=Unschedulable)
I0924 13:14:15.175030    6058 scheduler.go:576] Attempting to schedule pod: system/kube-system/kube-dns-7f4bf79dc-pvldq
I0924 13:14:15.338787    6058 generic_scheduler.go:1052] Node master is a potential node for preemption.
I0924 13:14:15.339330    6058 factory.go:470] Unable to schedule system/kube-system/kube-dns-7f4bf79dc-pvldq: no fit: 0/1 nodes are available: 1 node(s) runtime is not ready.; waiting
I0924 13:14:15.339484    6058 scheduler.go:787] Updating pod condition for system/kube-system/kube-dns-7f4bf79dc-pvldq to (PodScheduled==False, Reason=Unschedulable)
I0924 13:14:22.281666    6058 scheduler.go:576] Attempting to schedule pod: system/kube-system/coredns-default-6cfd6c6766-cqfm7
I0924 13:14:22.528404    6058 generic_scheduler.go:1052] Node master is a potential node for preemption.
I0924 13:14:22.529238    6058 factory.go:470] Unable to schedule system/kube-system/coredns-default-6cfd6c6766-cqfm7: no fit: 0/1 nodes are available: 1 node(s) runtime is not ready.; waiting
I0924 13:14:22.529296    6058 scheduler.go:787] Updating pod condition for system/kube-system/coredns-default-6cfd6c6766-cqfm7 to (PodScheduled==False, Reason=Unschedulable)
I0924 13:14:24.902588    6058 scheduler.go:576] Attempting to schedule pod: system/kube-system/coredns-default-6cfd6c6766-cqfm7
I0924 13:14:29.038275    6058 generic_scheduler.go:1052] Node master is a potential node for preemption.
I0924 13:14:29.038758    6058 factory.go:470] Unable to schedule system/kube-system/coredns-default-6cfd6c6766-cqfm7: no fit: 0/1 nodes are available: 1 node(s) runtime is not ready.; waiting
I0924 13:14:29.038833    6058 scheduler.go:787] Updating pod condition for system/kube-system/coredns-default-6cfd6c6766-cqfm7 to (PodScheduled==False, Reason=Unschedulable)
I0924 13:14:29.038902    6058 scheduler.go:576] Attempting to schedule pod: system/kube-system/kube-dns-7f4bf79dc-pvldq
I0924 13:14:29.938058    6058 generic_scheduler.go:1052] Node master is a potential node for preemption.
I0924 13:14:29.938339    6058 factory.go:470] Unable to schedule system/kube-system/kube-dns-7f4bf79dc-pvldq: no fit: 0/1 nodes are available: 1 node(s) runtime is not ready.; waiting
I0924 13:14:29.938389    6058 scheduler.go:787] Updating pod condition for system/kube-system/kube-dns-7f4bf79dc-pvldq to (PodScheduled==False, Reason=Unschedulable)
I0924 13:14:31.011413    6058 scheduler.go:576] Attempting to schedule pod: system/kube-system/kube-dns-7f4bf79dc-pvldq
I0924 13:14:31.122074    6058 generic_scheduler.go:1052] Node master is a potential node for preemption.
I0924 13:14:31.122429    6058 factory.go:470] Unable to schedule system/kube-system/kube-dns-7f4bf79dc-pvldq: no fit: 0/1 nodes are available: 1 node(s) runtime is not ready.; waiting
I0924 13:14:31.122491    6058 scheduler.go:787] Updating pod condition for system/kube-system/kube-dns-7f4bf79dc-pvldq to (PodScheduled==False, Reason=Unschedulable)
I0924 13:14:40.100632    6058 scheduler.go:576] Attempting to schedule pod: system/kube-system/coredns-default-6cfd6c6766-cqfm7
I0924 13:14:40.777107    6058 generic_scheduler.go:1052] Node master is a potential node for preemption.
I0924 13:14:40.777389    6058 factory.go:470] Unable to schedule system/kube-system/coredns-default-6cfd6c6766-cqfm7: no fit: 0/1 nodes are available: 1 node(s) runtime is not ready.; waiting
I0924 13:14:40.777447    6058 scheduler.go:787] Updating pod condition for system/kube-system/coredns-default-6cfd6c6766-cqfm7 to (PodScheduled==False, Reason=Unschedulable)
I0924 13:14:42.189137    6058 scheduler.go:576] Attempting to schedule pod: system/kube-system/kube-dns-7f4bf79dc-pvldq
I0924 13:14:42.319380    6058 generic_scheduler.go:1052] Node master is a potential node for preemption.
I0924 13:14:42.319691    6058 factory.go:470] Unable to schedule system/kube-system/kube-dns-7f4bf79dc-pvldq: no fit: 0/1 nodes are available: 1 node(s) runtime is not ready.; waiting
I0924 13:14:42.319745    6058 scheduler.go:787] Updating pod condition for system/kube-system/kube-dns-7f4bf79dc-pvldq to (PodScheduled==False, Reason=Unschedulable)
I0924 13:14:45.152699    6058 scheduler.go:576] Attempting to schedule pod: system/kube-system/coredns-default-6cfd6c6766-cqfm7
I0924 13:14:45.343957    6058 generic_scheduler.go:1052] Node master is a potential node for preemption.
I0924 13:14:45.344387    6058 factory.go:470] Unable to schedule system/kube-system/coredns-default-6cfd6c6766-cqfm7: no fit: 0/1 nodes are available: 1 node(s) runtime is not ready.; waiting
I0924 13:14:45.344451    6058 scheduler.go:787] Updating pod condition for system/kube-system/coredns-default-6cfd6c6766-cqfm7 to (PodScheduled==False, Reason=Unschedulable)
I0924 13:14:47.400326    6058 scheduler.go:576] Attempting to schedule pod: system/kube-system/coredns-default-6cfd6c6766-cqfm7
I0924 13:14:47.725286    6058 generic_scheduler.go:1052] Node master is a potential node for preemption.
I0924 13:14:47.725558    6058 factory.go:470] Unable to schedule system/kube-system/coredns-default-6cfd6c6766-cqfm7: no fit: 0/1 nodes are available: 1 node(s) runtime is not ready.; waiting
I0924 13:14:47.725611    6058 scheduler.go:787] Updating pod condition for system/kube-system/coredns-default-6cfd6c6766-cqfm7 to (PodScheduled==False, Reason=Unschedulable)
I0924 13:14:50.740154    6058 scheduler.go:576] Attempting to schedule pod: system/kube-system/kube-dns-7f4bf79dc-pvldq
I0924 13:14:51.383091    6058 generic_scheduler.go:1052] Node master is a potential node for preemption.
I0924 13:14:51.383429    6058 factory.go:470] Unable to schedule system/kube-system/kube-dns-7f4bf79dc-pvldq: no fit: 0/1 nodes are available: 1 node(s) runtime is not ready.; waiting
I0924 13:14:51.383520    6058 scheduler.go:787] Updating pod condition for system/kube-system/kube-dns-7f4bf79dc-pvldq to (PodScheduled==False, Reason=Unschedulable)
I0924 13:14:52.612534    6058 scheduler.go:576] Attempting to schedule pod: system/kube-system/kube-dns-7f4bf79dc-pvldq
I0924 13:14:52.721812    6058 generic_scheduler.go:1052] Node master is a potential node for preemption.
I0924 13:14:52.722383    6058 factory.go:470] Unable to schedule system/kube-system/kube-dns-7f4bf79dc-pvldq: no fit: 0/1 nodes are available: 1 node(s) runtime is not ready.; waiting
I0924 13:14:52.722461    6058 scheduler.go:787] Updating pod condition for system/kube-system/kube-dns-7f4bf79dc-pvldq to (PodScheduled==False, Reason=Unschedulable)
I0924 13:14:58.710923    6058 scheduler.go:576] Attempting to schedule pod: system/kube-system/coredns-default-6cfd6c6766-cqfm7
I0924 13:14:58.767753    6058 generic_scheduler.go:1052] Node master is a potential node for preemption.
I0924 13:14:58.768173    6058 factory.go:470] Unable to schedule system/kube-system/coredns-default-6cfd6c6766-cqfm7: no fit: 0/1 nodes are available: 1 node(s) runtime is not ready.; waiting
I0924 13:14:58.768231    6058 scheduler.go:787] Updating pod condition for system/kube-system/coredns-default-6cfd6c6766-cqfm7 to (PodScheduled==False, Reason=Unschedulable)
I0924 13:15:02.982279    6058 scheduler.go:576] Attempting to schedule pod: system/kube-system/kube-dns-7f4bf79dc-pvldq
I0924 13:15:03.401506    6058 generic_scheduler.go:1052] Node master is a potential node for preemption.
I0924 13:15:03.441146    6058 factory.go:470] Unable to schedule system/kube-system/kube-dns-7f4bf79dc-pvldq: no fit: 0/1 nodes are available: 1 node(s) runtime is not ready.; waiting
I0924 13:15:03.441381    6058 scheduler.go:787] Updating pod condition for system/kube-system/kube-dns-7f4bf79dc-pvldq to (PodScheduled==False, Reason=Unschedulable)
I0924 13:15:08.314146    6058 scheduler.go:576] Attempting to schedule pod: system/kube-system/coredns-default-6cfd6c6766-cqfm7
I0924 13:15:08.444115    6058 generic_scheduler.go:1052] Node master is a potential node for preemption.
I0924 13:15:08.444427    6058 factory.go:470] Unable to schedule system/kube-system/coredns-default-6cfd6c6766-cqfm7: no fit: 0/1 nodes are available: 1 node(s) runtime is not ready.; waiting
I0924 13:15:08.444490    6058 scheduler.go:787] Updating pod condition for system/kube-system/coredns-default-6cfd6c6766-cqfm7 to (PodScheduled==False, Reason=Unschedulable)
I0924 13:15:10.505054    6058 scheduler.go:576] Attempting to schedule pod: system/kube-system/coredns-default-6cfd6c6766-cqfm7
I0924 13:15:10.985605    6058 generic_scheduler.go:1052] Node master is a potential node for preemption.
I0924 13:15:10.985928    6058 factory.go:470] Unable to schedule system/kube-system/coredns-default-6cfd6c6766-cqfm7: no fit: 0/1 nodes are available: 1 node(s) runtime is not ready.; waiting
I0924 13:15:10.985992    6058 scheduler.go:787] Updating pod condition for system/kube-system/coredns-default-6cfd6c6766-cqfm7 to (PodScheduled==False, Reason=Unschedulable)
I0924 13:15:12.421588    6058 scheduler.go:576] Attempting to schedule pod: system/kube-system/kube-dns-7f4bf79dc-pvldq
I0924 13:15:12.529206    6058 generic_scheduler.go:1052] Node master is a potential node for preemption.
I0924 13:15:12.529592    6058 factory.go:470] Unable to schedule system/kube-system/kube-dns-7f4bf79dc-pvldq: no fit: 0/1 nodes are available: 1 node(s) runtime is not ready.; waiting
I0924 13:15:12.529643    6058 scheduler.go:787] Updating pod condition for system/kube-system/kube-dns-7f4bf79dc-pvldq to (PodScheduled==False, Reason=Unschedulable)
I0924 13:15:14.427636    6058 scheduler.go:576] Attempting to schedule pod: system/kube-system/kube-dns-7f4bf79dc-pvldq
I0924 13:15:14.620753    6058 generic_scheduler.go:1052] Node master is a potential node for preemption.
I0924 13:15:14.626852    6058 factory.go:470] Unable to schedule system/kube-system/kube-dns-7f4bf79dc-pvldq: no fit: 0/1 nodes are available: 1 node(s) runtime is not ready.; waiting
I0924 13:15:14.627019    6058 scheduler.go:787] Updating pod condition for system/kube-system/kube-dns-7f4bf79dc-pvldq to (PodScheduled==False, Reason=Unschedulable)
I0924 13:15:21.989542    6058 scheduler.go:576] Attempting to schedule pod: system/kube-system/coredns-default-6cfd6c6766-cqfm7
I0924 13:15:22.082588    6058 generic_scheduler.go:1052] Node master is a potential node for preemption.
I0924 13:15:22.082909    6058 factory.go:470] Unable to schedule system/kube-system/coredns-default-6cfd6c6766-cqfm7: no fit: 0/1 nodes are available: 1 node(s) runtime is not ready.; waiting
I0924 13:15:22.082961    6058 scheduler.go:787] Updating pod condition for system/kube-system/coredns-default-6cfd6c6766-cqfm7 to (PodScheduled==False, Reason=Unschedulable)
I0924 13:15:25.173786    6058 scheduler.go:576] Attempting to schedule pod: system/kube-system/kube-dns-7f4bf79dc-pvldq
I0924 13:15:25.410136    6058 generic_scheduler.go:1052] Node master is a potential node for preemption.
I0924 13:15:25.410483    6058 factory.go:470] Unable to schedule system/kube-system/kube-dns-7f4bf79dc-pvldq: no fit: 0/1 nodes are available: 1 node(s) runtime is not ready.; waiting
I0924 13:15:25.410537    6058 scheduler.go:787] Updating pod condition for system/kube-system/kube-dns-7f4bf79dc-pvldq to (PodScheduled==False, Reason=Unschedulable)
I0924 13:15:30.553185    6058 scheduler.go:576] Attempting to schedule pod: system/kube-system/coredns-default-6cfd6c6766-cqfm7
I0924 13:15:30.619470    6058 generic_scheduler.go:1052] Node master is a potential node for preemption.
I0924 13:15:30.837914    6058 factory.go:470] Unable to schedule system/kube-system/coredns-default-6cfd6c6766-cqfm7: no fit: 0/1 nodes are available: 1 node(s) runtime is not ready.; waiting
I0924 13:15:30.876962    6058 scheduler.go:787] Updating pod condition for system/kube-system/coredns-default-6cfd6c6766-cqfm7 to (PodScheduled==False, Reason=Unschedulable)
I0924 13:15:34.153932    6058 scheduler.go:576] Attempting to schedule pod: system/kube-system/coredns-default-6cfd6c6766-cqfm7
I0924 13:15:35.415051    6058 generic_scheduler.go:1052] Node master is a potential node for preemption.
I0924 13:15:35.415611    6058 factory.go:470] Unable to schedule system/kube-system/coredns-default-6cfd6c6766-cqfm7: no fit: 0/1 nodes are available: 1 node(s) runtime is not ready.; waiting
I0924 13:15:35.415752    6058 scheduler.go:787] Updating pod condition for system/kube-system/coredns-default-6cfd6c6766-cqfm7 to (PodScheduled==False, Reason=Unschedulable)
I0924 13:15:35.417354    6058 scheduler.go:576] Attempting to schedule pod: system/kube-system/kube-dns-7f4bf79dc-pvldq
I0924 13:15:35.566575    6058 generic_scheduler.go:1052] Node master is a potential node for preemption.
I0924 13:15:35.570229    6058 factory.go:470] Unable to schedule system/kube-system/kube-dns-7f4bf79dc-pvldq: no fit: 0/1 nodes are available: 1 node(s) runtime is not ready.; waiting
I0924 13:15:35.570351    6058 scheduler.go:787] Updating pod condition for system/kube-system/kube-dns-7f4bf79dc-pvldq to (PodScheduled==False, Reason=Unschedulable)
I0924 13:15:37.288847    6058 scheduler.go:576] Attempting to schedule pod: system/kube-system/kube-dns-7f4bf79dc-pvldq
I0924 13:15:37.354538    6058 generic_scheduler.go:1052] Node master is a potential node for preemption.
I0924 13:15:37.355081    6058 factory.go:470] Unable to schedule system/kube-system/kube-dns-7f4bf79dc-pvldq: no fit: 0/1 nodes are available: 1 node(s) runtime is not ready.; waiting
I0924 13:15:37.355153    6058 scheduler.go:787] Updating pod condition for system/kube-system/kube-dns-7f4bf79dc-pvldq to (PodScheduled==False, Reason=Unschedulable)
I0924 13:15:46.303044    6058 scheduler.go:576] Attempting to schedule pod: system/kube-system/coredns-default-6cfd6c6766-cqfm7
I0924 13:15:47.237621    6058 generic_scheduler.go:1052] Node master is a potential node for preemption.
I0924 13:15:47.239551    6058 factory.go:470] Unable to schedule system/kube-system/coredns-default-6cfd6c6766-cqfm7: no fit: 0/1 nodes are available: 1 node(s) runtime is not ready.; waiting
I0924 13:15:47.239957    6058 scheduler.go:787] Updating pod condition for system/kube-system/coredns-default-6cfd6c6766-cqfm7 to (PodScheduled==False, Reason=Unschedulable)
I0924 13:15:48.467711    6058 scheduler.go:576] Attempting to schedule pod: system/kube-system/kube-dns-7f4bf79dc-pvldq
I0924 13:15:48.703798    6058 generic_scheduler.go:1052] Node master is a potential node for preemption.
I0924 13:15:48.704391    6058 factory.go:470] Unable to schedule system/kube-system/kube-dns-7f4bf79dc-pvldq: no fit: 0/1 nodes are available: 1 node(s) runtime is not ready.; waiting
I0924 13:15:48.704522    6058 scheduler.go:787] Updating pod condition for system/kube-system/kube-dns-7f4bf79dc-pvldq to (PodScheduled==False, Reason=Unschedulable)
I0924 13:15:55.298037    6058 scheduler.go:576] Attempting to schedule pod: system/kube-system/coredns-default-6cfd6c6766-cqfm7
I0924 13:15:55.345102    6058 generic_scheduler.go:1052] Node master is a potential node for preemption.
I0924 13:15:55.345423    6058 factory.go:470] Unable to schedule system/kube-system/coredns-default-6cfd6c6766-cqfm7: no fit: 0/1 nodes are available: 1 node(s) runtime is not ready.; waiting
I0924 13:15:55.345632    6058 scheduler.go:787] Updating pod condition for system/kube-system/coredns-default-6cfd6c6766-cqfm7 to (PodScheduled==False, Reason=Unschedulable)
I0924 13:15:58.663955    6058 scheduler.go:576] Attempting to schedule pod: system/kube-system/kube-dns-7f4bf79dc-pvldq
I0924 13:15:58.893170    6058 generic_scheduler.go:1052] Node master is a potential node for preemption.
I0924 13:15:58.893454    6058 factory.go:470] Unable to schedule system/kube-system/kube-dns-7f4bf79dc-pvldq: no fit: 0/1 nodes are available: 1 node(s) runtime is not ready.; waiting
I0924 13:15:58.893507    6058 scheduler.go:787] Updating pod condition for system/kube-system/kube-dns-7f4bf79dc-pvldq to (PodScheduled==False, Reason=Unschedulable)
I0924 13:15:58.916413    6058 scheduler.go:576] Attempting to schedule pod: system/kube-system/coredns-default-6cfd6c6766-cqfm7
I0924 13:15:59.118082    6058 generic_scheduler.go:1052] Node master is a potential node for preemption.
I0924 13:15:59.118636    6058 factory.go:470] Unable to schedule system/kube-system/coredns-default-6cfd6c6766-cqfm7: no fit: 0/1 nodes are available: 1 node(s) runtime is not ready.; waiting
I0924 13:15:59.118702    6058 scheduler.go:787] Updating pod condition for system/kube-system/coredns-default-6cfd6c6766-cqfm7 to (PodScheduled==False, Reason=Unschedulable)
I0924 13:16:01.011205    6058 scheduler.go:576] Attempting to schedule pod: system/kube-system/kube-dns-7f4bf79dc-pvldq
I0924 13:16:01.518591    6058 generic_scheduler.go:1052] Node master is a potential node for preemption.
I0924 13:16:01.518876    6058 factory.go:470] Unable to schedule system/kube-system/kube-dns-7f4bf79dc-pvldq: no fit: 0/1 nodes are available: 1 node(s) runtime is not ready.; waiting
I0924 13:16:01.518928    6058 scheduler.go:787] Updating pod condition for system/kube-system/kube-dns-7f4bf79dc-pvldq to (PodScheduled==False, Reason=Unschedulable)
I0924 13:16:09.616969    6058 scheduler.go:576] Attempting to schedule pod: system/kube-system/coredns-default-6cfd6c6766-cqfm7
I0924 13:16:09.639786    6058 generic_scheduler.go:1052] Node master is a potential node for preemption.
I0924 13:16:09.640054    6058 factory.go:470] Unable to schedule system/kube-system/coredns-default-6cfd6c6766-cqfm7: no fit: 0/1 nodes are available: 1 node(s) runtime is not ready.; waiting
I0924 13:16:09.640108    6058 scheduler.go:787] Updating pod condition for system/kube-system/coredns-default-6cfd6c6766-cqfm7 to (PodScheduled==False, Reason=Unschedulable)
I0924 13:16:12.640154    6058 scheduler.go:576] Attempting to schedule pod: system/kube-system/kube-dns-7f4bf79dc-pvldq
I0924 13:16:12.751687    6058 generic_scheduler.go:1052] Node master is a potential node for preemption.
I0924 13:16:12.752030    6058 factory.go:470] Unable to schedule system/kube-system/kube-dns-7f4bf79dc-pvldq: no fit: 0/1 nodes are available: 1 node(s) runtime is not ready.; waiting
I0924 13:16:12.752099    6058 scheduler.go:787] Updating pod condition for system/kube-system/kube-dns-7f4bf79dc-pvldq to (PodScheduled==False, Reason=Unschedulable)
I0924 13:16:18.925650    6058 scheduler.go:576] Attempting to schedule pod: system/kube-system/coredns-default-6cfd6c6766-cqfm7
I0924 13:16:19.055252    6058 generic_scheduler.go:1052] Node master is a potential node for preemption.
I0924 13:16:19.055544    6058 factory.go:470] Unable to schedule system/kube-system/coredns-default-6cfd6c6766-cqfm7: no fit: 0/1 nodes are available: 1 node(s) runtime is not ready.; waiting
I0924 13:16:19.055594    6058 scheduler.go:787] Updating pod condition for system/kube-system/coredns-default-6cfd6c6766-cqfm7 to (PodScheduled==False, Reason=Unschedulable)
I0924 13:16:20.505341    6058 scheduler.go:576] Attempting to schedule pod: system/kube-system/coredns-default-6cfd6c6766-cqfm7
I0924 13:16:20.637419    6058 generic_scheduler.go:1052] Node master is a potential node for preemption.
I0924 13:16:20.638413    6058 factory.go:470] Unable to schedule system/kube-system/coredns-default-6cfd6c6766-cqfm7: no fit: 0/1 nodes are available: 1 node(s) runtime is not ready.; waiting
I0924 13:16:20.638497    6058 scheduler.go:787] Updating pod condition for system/kube-system/coredns-default-6cfd6c6766-cqfm7 to (PodScheduled==False, Reason=Unschedulable)
I0924 13:16:21.582765    6058 scheduler.go:576] Attempting to schedule pod: system/kube-system/kube-dns-7f4bf79dc-pvldq
I0924 13:16:22.342077    6058 generic_scheduler.go:1052] Node master is a potential node for preemption.
I0924 13:16:22.376086    6058 factory.go:470] Unable to schedule system/kube-system/kube-dns-7f4bf79dc-pvldq: no fit: 0/1 nodes are available: 1 node(s) runtime is not ready.; waiting
I0924 13:16:22.590761    6058 scheduler.go:787] Updating pod condition for system/kube-system/kube-dns-7f4bf79dc-pvldq to (PodScheduled==False, Reason=Unschedulable)
I0924 13:16:24.950159    6058 scheduler.go:576] Attempting to schedule pod: system/kube-system/kube-dns-7f4bf79dc-pvldq
I0924 13:16:25.091484    6058 generic_scheduler.go:1052] Node master is a potential node for preemption.
I0924 13:16:25.091766    6058 factory.go:470] Unable to schedule system/kube-system/kube-dns-7f4bf79dc-pvldq: no fit: 0/1 nodes are available: 1 node(s) runtime is not ready.; waiting
I0924 13:16:25.091827    6058 scheduler.go:787] Updating pod condition for system/kube-system/kube-dns-7f4bf79dc-pvldq to (PodScheduled==False, Reason=Unschedulable)
I0924 13:16:32.304852    6058 scheduler.go:576] Attempting to schedule pod: system/kube-system/coredns-default-6cfd6c6766-cqfm7
I0924 13:16:32.326535    6058 generic_scheduler.go:1052] Node master is a potential node for preemption.
I0924 13:16:32.326776    6058 factory.go:470] Unable to schedule system/kube-system/coredns-default-6cfd6c6766-cqfm7: no fit: 0/1 nodes are available: 1 node(s) runtime is not ready.; waiting
I0924 13:16:32.326834    6058 scheduler.go:787] Updating pod condition for system/kube-system/coredns-default-6cfd6c6766-cqfm7 to (PodScheduled==False, Reason=Unschedulable)
I0924 13:16:36.428586    6058 scheduler.go:576] Attempting to schedule pod: system/kube-system/kube-dns-7f4bf79dc-pvldq
I0924 13:16:36.442552    6058 generic_scheduler.go:1052] Node master is a potential node for preemption.
I0924 13:16:36.442838    6058 factory.go:470] Unable to schedule system/kube-system/kube-dns-7f4bf79dc-pvldq: no fit: 0/1 nodes are available: 1 node(s) runtime is not ready.; waiting
I0924 13:16:36.442888    6058 scheduler.go:787] Updating pod condition for system/kube-system/kube-dns-7f4bf79dc-pvldq to (PodScheduled==False, Reason=Unschedulable)
I0924 13:16:42.434535    6058 scheduler.go:576] Attempting to schedule pod: system/kube-system/coredns-default-6cfd6c6766-cqfm7
I0924 13:16:42.978651    6058 generic_scheduler.go:1052] Node master is a potential node for preemption.
I0924 13:16:42.978942    6058 factory.go:470] Unable to schedule system/kube-system/coredns-default-6cfd6c6766-cqfm7: no fit: 0/1 nodes are available: 1 node(s) runtime is not ready.; waiting
I0924 13:16:42.979014    6058 scheduler.go:787] Updating pod condition for system/kube-system/coredns-default-6cfd6c6766-cqfm7 to (PodScheduled==False, Reason=Unschedulable)
I0924 13:16:43.008499    6058 scheduler.go:576] Attempting to schedule pod: system/kube-system/coredns-default-6cfd6c6766-cqfm7
I0924 13:16:43.648780    6058 generic_scheduler.go:1052] Node master is a potential node for preemption.
I0924 13:16:43.649376    6058 factory.go:470] Unable to schedule system/kube-system/coredns-default-6cfd6c6766-cqfm7: no fit: 0/1 nodes are available: 1 node(s) runtime is not ready.; waiting
I0924 13:16:43.649461    6058 scheduler.go:787] Updating pod condition for system/kube-system/coredns-default-6cfd6c6766-cqfm7 to (PodScheduled==False, Reason=Unschedulable)
E0924 13:16:44.309629    6058 factory.go:512] pod system/kube-system/coredns-default-6cfd6c6766-cqfm7 is already present in the backoff queue
I0924 13:16:46.718101    6058 scheduler.go:576] Attempting to schedule pod: system/kube-system/kube-dns-7f4bf79dc-pvldq
I0924 13:16:46.739030    6058 generic_scheduler.go:1052] Node master is a potential node for preemption.
I0924 13:16:46.739326    6058 factory.go:470] Unable to schedule system/kube-system/kube-dns-7f4bf79dc-pvldq: no fit: 0/1 nodes are available: 1 node(s) runtime is not ready.; waiting
I0924 13:16:46.739380    6058 scheduler.go:787] Updating pod condition for system/kube-system/kube-dns-7f4bf79dc-pvldq to (PodScheduled==False, Reason=Unschedulable)
I0924 13:16:47.327082    6058 scheduler.go:576] Attempting to schedule pod: system/kube-system/coredns-default-6cfd6c6766-cqfm7
I0924 13:16:47.621483    6058 generic_scheduler.go:1052] Node master is a potential node for preemption.
I0924 13:16:47.622014    6058 factory.go:470] Unable to schedule system/kube-system/coredns-default-6cfd6c6766-cqfm7: no fit: 0/1 nodes are available: 1 node(s) runtime is not ready.; waiting
I0924 13:16:47.622120    6058 scheduler.go:787] Updating pod condition for system/kube-system/coredns-default-6cfd6c6766-cqfm7 to (PodScheduled==False, Reason=Unschedulable)
I0924 13:16:47.622982    6058 scheduler.go:576] Attempting to schedule pod: system/kube-system/kube-dns-7f4bf79dc-pvldq
I0924 13:16:48.437199    6058 generic_scheduler.go:1052] Node master is a potential node for preemption.
I0924 13:16:48.488154    6058 factory.go:470] Unable to schedule system/kube-system/kube-dns-7f4bf79dc-pvldq: no fit: 0/1 nodes are available: 1 node(s) runtime is not ready.; waiting
I0924 13:16:48.488246    6058 scheduler.go:787] Updating pod condition for system/kube-system/kube-dns-7f4bf79dc-pvldq to (PodScheduled==False, Reason=Unschedulable)
I0924 13:16:50.213374    6058 scheduler.go:576] Attempting to schedule pod: system/kube-system/kube-dns-7f4bf79dc-pvldq
I0924 13:16:51.478392    6058 generic_scheduler.go:1052] Node master is a potential node for preemption.
I0924 13:16:51.493243    6058 factory.go:470] Unable to schedule system/kube-system/kube-dns-7f4bf79dc-pvldq: no fit: 0/1 nodes are available: 1 node(s) runtime is not ready.; waiting
I0924 13:16:51.493434    6058 scheduler.go:787] Updating pod condition for system/kube-system/kube-dns-7f4bf79dc-pvldq to (PodScheduled==False, Reason=Unschedulable)
I0924 13:16:58.390263    6058 scheduler.go:576] Attempting to schedule pod: system/kube-system/coredns-default-6cfd6c6766-cqfm7
I0924 13:16:58.570602    6058 generic_scheduler.go:1052] Node master is a potential node for preemption.
I0924 13:16:58.570884    6058 factory.go:470] Unable to schedule system/kube-system/coredns-default-6cfd6c6766-cqfm7: no fit: 0/1 nodes are available: 1 node(s) runtime is not ready.; waiting
I0924 13:16:58.570939    6058 scheduler.go:787] Updating pod condition for system/kube-system/coredns-default-6cfd6c6766-cqfm7 to (PodScheduled==False, Reason=Unschedulable)
I0924 13:17:03.099603    6058 scheduler.go:576] Attempting to schedule pod: system/kube-system/kube-dns-7f4bf79dc-pvldq
I0924 13:17:03.398209    6058 generic_scheduler.go:1052] Node master is a potential node for preemption.
I0924 13:17:03.398794    6058 factory.go:470] Unable to schedule system/kube-system/kube-dns-7f4bf79dc-pvldq: no fit: 0/1 nodes are available: 1 node(s) runtime is not ready.; waiting
I0924 13:17:03.399378    6058 scheduler.go:787] Updating pod condition for system/kube-system/kube-dns-7f4bf79dc-pvldq to (PodScheduled==False, Reason=Unschedulable)
I0924 13:17:07.301177    6058 scheduler.go:576] Attempting to schedule pod: system/kube-system/coredns-default-6cfd6c6766-cqfm7
I0924 13:17:07.400223    6058 generic_scheduler.go:1052] Node master is a potential node for preemption.
I0924 13:17:07.400680    6058 factory.go:470] Unable to schedule system/kube-system/coredns-default-6cfd6c6766-cqfm7: no fit: 0/1 nodes are available: 1 node(s) runtime is not ready.; waiting
I0924 13:17:07.400746    6058 scheduler.go:787] Updating pod condition for system/kube-system/coredns-default-6cfd6c6766-cqfm7 to (PodScheduled==False, Reason=Unschedulable)
I0924 13:17:10.962737    6058 eventhandlers.go:183] add event for unscheduled pod system/default/mizar-operator-6985d77546-9tc8d
I0924 13:17:10.962854    6058 scheduler.go:576] Attempting to schedule pod: system/default/mizar-operator-6985d77546-9tc8d
I0924 13:17:10.963318    6058 default_binder.go:53] Attempting to bind system/default/mizar-operator-6985d77546-9tc8d to master
I0924 13:17:11.532135    6058 scheduler.go:576] Attempting to schedule pod: system/kube-system/coredns-default-6cfd6c6766-cqfm7
I0924 13:17:11.540118    6058 eventhandlers.go:215] delete event for unscheduled pod system/default/mizar-operator-6985d77546-9tc8d
I0924 13:17:11.540165    6058 eventhandlers.go:239] add event for scheduled pod system/default/mizar-operator-6985d77546-9tc8d 
I0924 13:17:11.770220    6058 scheduler.go:741] pod system/default/mizar-operator-6985d77546-9tc8d is bound successfully on node "master", 1 nodes evaluated, 1 nodes were found feasible.
I0924 13:17:13.494138    6058 generic_scheduler.go:1052] Node master is a potential node for preemption.
I0924 13:17:13.530293    6058 factory.go:470] Unable to schedule system/kube-system/coredns-default-6cfd6c6766-cqfm7: no fit: 0/1 nodes are available: 1 node(s) runtime is not ready.; waiting
I0924 13:17:13.530385    6058 scheduler.go:787] Updating pod condition for system/kube-system/coredns-default-6cfd6c6766-cqfm7 to (PodScheduled==False, Reason=Unschedulable)
I0924 13:17:13.555185    6058 scheduler.go:576] Attempting to schedule pod: system/kube-system/kube-dns-7f4bf79dc-pvldq
I0924 13:17:13.874634    6058 generic_scheduler.go:1052] Node master is a potential node for preemption.
I0924 13:17:13.874934    6058 factory.go:470] Unable to schedule system/kube-system/kube-dns-7f4bf79dc-pvldq: no fit: 0/1 nodes are available: 1 node(s) runtime is not ready.; waiting
I0924 13:17:13.874993    6058 scheduler.go:787] Updating pod condition for system/kube-system/kube-dns-7f4bf79dc-pvldq to (PodScheduled==False, Reason=Unschedulable)
I0924 13:17:23.989990    6058 scheduler.go:576] Attempting to schedule pod: system/kube-system/coredns-default-6cfd6c6766-cqfm7
I0924 13:17:24.158214    6058 generic_scheduler.go:1052] Node master is a potential node for preemption.
I0924 13:17:24.158482    6058 factory.go:470] Unable to schedule system/kube-system/coredns-default-6cfd6c6766-cqfm7: no fit: 0/1 nodes are available: 1 node(s) runtime is not ready.; waiting
I0924 13:17:24.158541    6058 scheduler.go:787] Updating pod condition for system/kube-system/coredns-default-6cfd6c6766-cqfm7 to (PodScheduled==False, Reason=Unschedulable)
I0924 13:17:24.993996    6058 scheduler.go:576] Attempting to schedule pod: system/kube-system/kube-dns-7f4bf79dc-pvldq
I0924 13:17:25.311268    6058 generic_scheduler.go:1052] Node master is a potential node for preemption.
I0924 13:17:25.328908    6058 factory.go:470] Unable to schedule system/kube-system/kube-dns-7f4bf79dc-pvldq: no fit: 0/1 nodes are available: 1 node(s) runtime is not ready.; waiting
I0924 13:17:25.328988    6058 scheduler.go:787] Updating pod condition for system/kube-system/kube-dns-7f4bf79dc-pvldq to (PodScheduled==False, Reason=Unschedulable)
I0924 13:17:34.380677    6058 scheduler.go:576] Attempting to schedule pod: system/kube-system/coredns-default-6cfd6c6766-cqfm7
I0924 13:17:34.559451    6058 generic_scheduler.go:1052] Node master is a potential node for preemption.
I0924 13:17:34.559763    6058 factory.go:470] Unable to schedule system/kube-system/coredns-default-6cfd6c6766-cqfm7: no fit: 0/1 nodes are available: 1 node(s) runtime is not ready.; waiting
I0924 13:17:34.559821    6058 scheduler.go:787] Updating pod condition for system/kube-system/coredns-default-6cfd6c6766-cqfm7 to (PodScheduled==False, Reason=Unschedulable)
I0924 13:17:36.511545    6058 scheduler.go:576] Attempting to schedule pod: system/kube-system/kube-dns-7f4bf79dc-pvldq
I0924 13:17:36.672171    6058 generic_scheduler.go:1052] Node master is a potential node for preemption.
I0924 13:17:36.672486    6058 factory.go:470] Unable to schedule system/kube-system/kube-dns-7f4bf79dc-pvldq: no fit: 0/1 nodes are available: 1 node(s) runtime is not ready.; waiting
I0924 13:17:36.672546    6058 scheduler.go:787] Updating pod condition for system/kube-system/kube-dns-7f4bf79dc-pvldq to (PodScheduled==False, Reason=Unschedulable)
I0924 13:17:45.111894    6058 scheduler.go:576] Attempting to schedule pod: system/kube-system/coredns-default-6cfd6c6766-cqfm7
I0924 13:17:45.306945    6058 generic_scheduler.go:1052] Node master is a potential node for preemption.
I0924 13:17:45.307248    6058 factory.go:470] Unable to schedule system/kube-system/coredns-default-6cfd6c6766-cqfm7: no fit: 0/1 nodes are available: 1 node(s) runtime is not ready.; waiting
I0924 13:17:45.307302    6058 scheduler.go:787] Updating pod condition for system/kube-system/coredns-default-6cfd6c6766-cqfm7 to (PodScheduled==False, Reason=Unschedulable)
I0924 13:17:47.362683    6058 scheduler.go:576] Attempting to schedule pod: system/kube-system/kube-dns-7f4bf79dc-pvldq
I0924 13:17:47.506185    6058 generic_scheduler.go:1052] Node master is a potential node for preemption.
I0924 13:17:47.506496    6058 factory.go:470] Unable to schedule system/kube-system/kube-dns-7f4bf79dc-pvldq: no fit: 0/1 nodes are available: 1 node(s) runtime is not ready.; waiting
I0924 13:17:47.506563    6058 scheduler.go:787] Updating pod condition for system/kube-system/kube-dns-7f4bf79dc-pvldq to (PodScheduled==False, Reason=Unschedulable)
I0924 13:17:55.913924    6058 scheduler.go:576] Attempting to schedule pod: system/kube-system/coredns-default-6cfd6c6766-cqfm7
I0924 13:17:55.946573    6058 generic_scheduler.go:1052] Node master is a potential node for preemption.
I0924 13:17:55.946876    6058 factory.go:470] Unable to schedule system/kube-system/coredns-default-6cfd6c6766-cqfm7: no fit: 0/1 nodes are available: 1 node(s) runtime is not ready.; waiting
I0924 13:17:55.946931    6058 scheduler.go:787] Updating pod condition for system/kube-system/coredns-default-6cfd6c6766-cqfm7 to (PodScheduled==False, Reason=Unschedulable)
I0924 13:17:58.283983    6058 scheduler.go:576] Attempting to schedule pod: system/kube-system/kube-dns-7f4bf79dc-pvldq
I0924 13:17:58.440244    6058 generic_scheduler.go:1052] Node master is a potential node for preemption.
I0924 13:17:58.595083    6058 factory.go:470] Unable to schedule system/kube-system/kube-dns-7f4bf79dc-pvldq: no fit: 0/1 nodes are available: 1 node(s) runtime is not ready.; waiting
I0924 13:17:58.595177    6058 scheduler.go:787] Updating pod condition for system/kube-system/kube-dns-7f4bf79dc-pvldq to (PodScheduled==False, Reason=Unschedulable)
I0924 13:18:06.773990    6058 scheduler.go:576] Attempting to schedule pod: system/kube-system/coredns-default-6cfd6c6766-cqfm7
I0924 13:18:06.822715    6058 generic_scheduler.go:1052] Node master is a potential node for preemption.
I0924 13:18:06.823004    6058 factory.go:470] Unable to schedule system/kube-system/coredns-default-6cfd6c6766-cqfm7: no fit: 0/1 nodes are available: 1 node(s) runtime is not ready.; waiting
I0924 13:18:06.823052    6058 scheduler.go:787] Updating pod condition for system/kube-system/coredns-default-6cfd6c6766-cqfm7 to (PodScheduled==False, Reason=Unschedulable)
I0924 13:18:08.951657    6058 scheduler.go:576] Attempting to schedule pod: system/kube-system/kube-dns-7f4bf79dc-pvldq
I0924 13:18:08.967328    6058 generic_scheduler.go:1052] Node master is a potential node for preemption.
I0924 13:18:08.998101    6058 factory.go:470] Unable to schedule system/kube-system/kube-dns-7f4bf79dc-pvldq: no fit: 0/1 nodes are available: 1 node(s) runtime is not ready.; waiting
I0924 13:18:08.999284    6058 scheduler.go:787] Updating pod condition for system/kube-system/kube-dns-7f4bf79dc-pvldq to (PodScheduled==False, Reason=Unschedulable)
I0924 13:18:17.154993    6058 scheduler.go:576] Attempting to schedule pod: system/kube-system/coredns-default-6cfd6c6766-cqfm7
I0924 13:18:17.197895    6058 generic_scheduler.go:1052] Node master is a potential node for preemption.
I0924 13:18:17.198213    6058 factory.go:470] Unable to schedule system/kube-system/coredns-default-6cfd6c6766-cqfm7: no fit: 0/1 nodes are available: 1 node(s) runtime is not ready.; waiting
I0924 13:18:17.198266    6058 scheduler.go:787] Updating pod condition for system/kube-system/coredns-default-6cfd6c6766-cqfm7 to (PodScheduled==False, Reason=Unschedulable)
I0924 13:18:19.336553    6058 scheduler.go:576] Attempting to schedule pod: system/kube-system/kube-dns-7f4bf79dc-pvldq
I0924 13:18:19.406221    6058 generic_scheduler.go:1052] Node master is a potential node for preemption.
I0924 13:18:19.406542    6058 factory.go:470] Unable to schedule system/kube-system/kube-dns-7f4bf79dc-pvldq: no fit: 0/1 nodes are available: 1 node(s) runtime is not ready.; waiting
I0924 13:18:19.406594    6058 scheduler.go:787] Updating pod condition for system/kube-system/kube-dns-7f4bf79dc-pvldq to (PodScheduled==False, Reason=Unschedulable)
I0924 13:18:28.602451    6058 scheduler.go:576] Attempting to schedule pod: system/kube-system/coredns-default-6cfd6c6766-cqfm7
I0924 13:18:28.635857    6058 generic_scheduler.go:1052] Node master is a potential node for preemption.
I0924 13:18:28.636243    6058 factory.go:470] Unable to schedule system/kube-system/coredns-default-6cfd6c6766-cqfm7: no fit: 0/1 nodes are available: 1 node(s) runtime is not ready.; waiting
I0924 13:18:28.636308    6058 scheduler.go:787] Updating pod condition for system/kube-system/coredns-default-6cfd6c6766-cqfm7 to (PodScheduled==False, Reason=Unschedulable)
I0924 13:18:29.849444    6058 scheduler.go:576] Attempting to schedule pod: system/kube-system/kube-dns-7f4bf79dc-pvldq
I0924 13:18:29.924220    6058 generic_scheduler.go:1052] Node master is a potential node for preemption.
I0924 13:18:29.924501    6058 factory.go:470] Unable to schedule system/kube-system/kube-dns-7f4bf79dc-pvldq: no fit: 0/1 nodes are available: 1 node(s) runtime is not ready.; waiting
I0924 13:18:29.924563    6058 scheduler.go:787] Updating pod condition for system/kube-system/kube-dns-7f4bf79dc-pvldq to (PodScheduled==False, Reason=Unschedulable)
I0924 13:18:39.859731    6058 scheduler.go:576] Attempting to schedule pod: system/kube-system/coredns-default-6cfd6c6766-cqfm7
I0924 13:18:40.052546    6058 generic_scheduler.go:1052] Node master is a potential node for preemption.
I0924 13:18:40.052812    6058 factory.go:470] Unable to schedule system/kube-system/coredns-default-6cfd6c6766-cqfm7: no fit: 0/1 nodes are available: 1 node(s) runtime is not ready.; waiting
I0924 13:18:40.052861    6058 scheduler.go:787] Updating pod condition for system/kube-system/coredns-default-6cfd6c6766-cqfm7 to (PodScheduled==False, Reason=Unschedulable)
I0924 13:18:40.866657    6058 scheduler.go:576] Attempting to schedule pod: system/kube-system/kube-dns-7f4bf79dc-pvldq
I0924 13:18:40.923825    6058 generic_scheduler.go:1052] Node master is a potential node for preemption.
I0924 13:18:40.924776    6058 factory.go:470] Unable to schedule system/kube-system/kube-dns-7f4bf79dc-pvldq: no fit: 0/1 nodes are available: 1 node(s) runtime is not ready.; waiting
I0924 13:18:40.924859    6058 scheduler.go:787] Updating pod condition for system/kube-system/kube-dns-7f4bf79dc-pvldq to (PodScheduled==False, Reason=Unschedulable)
I0924 13:18:50.431794    6058 scheduler.go:576] Attempting to schedule pod: system/kube-system/coredns-default-6cfd6c6766-cqfm7
I0924 13:18:50.526529    6058 generic_scheduler.go:1052] Node master is a potential node for preemption.
I0924 13:18:50.532145    6058 factory.go:470] Unable to schedule system/kube-system/coredns-default-6cfd6c6766-cqfm7: no fit: 0/1 nodes are available: 1 node(s) runtime is not ready.; waiting
I0924 13:18:50.532312    6058 scheduler.go:787] Updating pod condition for system/kube-system/coredns-default-6cfd6c6766-cqfm7 to (PodScheduled==False, Reason=Unschedulable)
I0924 13:18:50.910876    6058 eventhandlers.go:308] delete event for scheduled pod system/default/mizar-operator-6985d77546-ttkxg 
I0924 13:18:51.468657    6058 scheduler.go:576] Attempting to schedule pod: system/kube-system/kube-dns-7f4bf79dc-pvldq
I0924 13:18:51.554251    6058 generic_scheduler.go:1052] Node master is a potential node for preemption.
I0924 13:18:51.554800    6058 factory.go:470] Unable to schedule system/kube-system/kube-dns-7f4bf79dc-pvldq: no fit: 0/1 nodes are available: 1 node(s) runtime is not ready.; waiting
I0924 13:18:51.554940    6058 scheduler.go:787] Updating pod condition for system/kube-system/kube-dns-7f4bf79dc-pvldq to (PodScheduled==False, Reason=Unschedulable)
I0924 13:18:52.550200    6058 scheduler.go:576] Attempting to schedule pod: system/kube-system/coredns-default-6cfd6c6766-cqfm7
I0924 13:18:53.775468    6058 generic_scheduler.go:1052] Node master is a potential node for preemption.
I0924 13:18:53.775957    6058 factory.go:470] Unable to schedule system/kube-system/coredns-default-6cfd6c6766-cqfm7: no fit: 0/1 nodes are available: 1 node(s) runtime is not ready.; waiting
I0924 13:18:53.776084    6058 scheduler.go:787] Updating pod condition for system/kube-system/coredns-default-6cfd6c6766-cqfm7 to (PodScheduled==False, Reason=Unschedulable)
I0924 13:18:53.777932    6058 scheduler.go:576] Attempting to schedule pod: system/kube-system/kube-dns-7f4bf79dc-pvldq
I0924 13:18:53.940862    6058 generic_scheduler.go:1052] Node master is a potential node for preemption.
I0924 13:18:53.941180    6058 factory.go:470] Unable to schedule system/kube-system/kube-dns-7f4bf79dc-pvldq: no fit: 0/1 nodes are available: 1 node(s) runtime is not ready.; waiting
I0924 13:18:53.941238    6058 scheduler.go:787] Updating pod condition for system/kube-system/kube-dns-7f4bf79dc-pvldq to (PodScheduled==False, Reason=Unschedulable)
I0924 13:18:57.943558    6058 scheduler.go:576] Attempting to schedule pod: system/kube-system/coredns-default-6cfd6c6766-cqfm7
I0924 13:18:58.184213    6058 generic_scheduler.go:1052] Node master is a potential node for preemption.
I0924 13:18:58.184726    6058 factory.go:470] Unable to schedule system/kube-system/coredns-default-6cfd6c6766-cqfm7: no fit: 0/1 nodes are available: 1 node(s) runtime is not ready.; waiting
I0924 13:18:58.184792    6058 scheduler.go:787] Updating pod condition for system/kube-system/coredns-default-6cfd6c6766-cqfm7 to (PodScheduled==False, Reason=Unschedulable)
I0924 13:18:59.195689    6058 scheduler.go:576] Attempting to schedule pod: system/kube-system/kube-dns-7f4bf79dc-pvldq
I0924 13:18:59.443232    6058 generic_scheduler.go:1052] Node master is a potential node for preemption.
I0924 13:18:59.443956    6058 factory.go:470] Unable to schedule system/kube-system/kube-dns-7f4bf79dc-pvldq: no fit: 0/1 nodes are available: 1 node(s) runtime is not ready.; waiting
I0924 13:18:59.444033    6058 scheduler.go:787] Updating pod condition for system/kube-system/kube-dns-7f4bf79dc-pvldq to (PodScheduled==False, Reason=Unschedulable)
I0924 13:19:00.989221    6058 scheduler.go:576] Attempting to schedule pod: system/kube-system/coredns-default-6cfd6c6766-cqfm7
I0924 13:19:01.120508    6058 generic_scheduler.go:1052] Node master is a potential node for preemption.
I0924 13:19:01.120927    6058 factory.go:470] Unable to schedule system/kube-system/coredns-default-6cfd6c6766-cqfm7: no fit: 0/1 nodes are available: 1 node(s) runtime is not ready.; waiting
I0924 13:19:01.123819    6058 scheduler.go:787] Updating pod condition for system/kube-system/coredns-default-6cfd6c6766-cqfm7 to (PodScheduled==False, Reason=Unschedulable)
I0924 13:19:01.674277    6058 scheduler.go:576] Attempting to schedule pod: system/kube-system/kube-dns-7f4bf79dc-pvldq
I0924 13:19:01.682315    6058 generic_scheduler.go:1052] Node master is a potential node for preemption.
I0924 13:19:01.683902    6058 factory.go:470] Unable to schedule system/kube-system/kube-dns-7f4bf79dc-pvldq: no fit: 0/1 nodes are available: 1 node(s) runtime is not ready.; waiting
I0924 13:19:01.683997    6058 scheduler.go:787] Updating pod condition for system/kube-system/kube-dns-7f4bf79dc-pvldq to (PodScheduled==False, Reason=Unschedulable)
I0924 13:19:11.362274    6058 scheduler.go:576] Attempting to schedule pod: system/kube-system/coredns-default-6cfd6c6766-cqfm7
I0924 13:19:11.371920    6058 generic_scheduler.go:1052] Node master is a potential node for preemption.
I0924 13:19:11.372199    6058 factory.go:470] Unable to schedule system/kube-system/coredns-default-6cfd6c6766-cqfm7: no fit: 0/1 nodes are available: 1 node(s) runtime is not ready.; waiting
I0924 13:19:11.372251    6058 scheduler.go:787] Updating pod condition for system/kube-system/coredns-default-6cfd6c6766-cqfm7 to (PodScheduled==False, Reason=Unschedulable)
I0924 13:19:12.362440    6058 scheduler.go:576] Attempting to schedule pod: system/kube-system/kube-dns-7f4bf79dc-pvldq
I0924 13:19:12.589261    6058 generic_scheduler.go:1052] Node master is a potential node for preemption.
I0924 13:19:12.589683    6058 factory.go:470] Unable to schedule system/kube-system/kube-dns-7f4bf79dc-pvldq: no fit: 0/1 nodes are available: 1 node(s) runtime is not ready.; waiting
I0924 13:19:12.589787    6058 scheduler.go:787] Updating pod condition for system/kube-system/kube-dns-7f4bf79dc-pvldq to (PodScheduled==False, Reason=Unschedulable)
I0924 13:19:21.007009    6058 scheduler.go:576] Attempting to schedule pod: system/kube-system/coredns-default-6cfd6c6766-cqfm7
I0924 13:19:21.034832    6058 generic_scheduler.go:1052] Node master is a potential node for preemption.
I0924 13:19:21.035118    6058 factory.go:470] Unable to schedule system/kube-system/coredns-default-6cfd6c6766-cqfm7: no fit: 0/1 nodes are available: 1 node(s) runtime is not ready.; waiting
I0924 13:19:21.035167    6058 scheduler.go:787] Updating pod condition for system/kube-system/coredns-default-6cfd6c6766-cqfm7 to (PodScheduled==False, Reason=Unschedulable)
I0924 13:19:22.076775    6058 scheduler.go:576] Attempting to schedule pod: system/kube-system/coredns-default-6cfd6c6766-cqfm7
I0924 13:19:22.174814    6058 generic_scheduler.go:1052] Node master is a potential node for preemption.
I0924 13:19:22.175098    6058 factory.go:470] Unable to schedule system/kube-system/coredns-default-6cfd6c6766-cqfm7: no fit: 0/1 nodes are available: 1 node(s) runtime is not ready.; waiting
I0924 13:19:22.175149    6058 scheduler.go:787] Updating pod condition for system/kube-system/coredns-default-6cfd6c6766-cqfm7 to (PodScheduled==False, Reason=Unschedulable)
I0924 13:19:22.177578    6058 scheduler.go:576] Attempting to schedule pod: system/kube-system/kube-dns-7f4bf79dc-pvldq
I0924 13:19:22.249324    6058 generic_scheduler.go:1052] Node master is a potential node for preemption.
I0924 13:19:22.252928    6058 factory.go:470] Unable to schedule system/kube-system/kube-dns-7f4bf79dc-pvldq: no fit: 0/1 nodes are available: 1 node(s) runtime is not ready.; waiting
I0924 13:19:22.265082    6058 scheduler.go:787] Updating pod condition for system/kube-system/kube-dns-7f4bf79dc-pvldq to (PodScheduled==False, Reason=Unschedulable)
I0924 13:19:23.379785    6058 scheduler.go:576] Attempting to schedule pod: system/kube-system/kube-dns-7f4bf79dc-pvldq
I0924 13:19:23.510937    6058 generic_scheduler.go:1052] Node master is a potential node for preemption.
I0924 13:19:23.511249    6058 factory.go:470] Unable to schedule system/kube-system/kube-dns-7f4bf79dc-pvldq: no fit: 0/1 nodes are available: 1 node(s) runtime is not ready.; waiting
I0924 13:19:23.511299    6058 scheduler.go:787] Updating pod condition for system/kube-system/kube-dns-7f4bf79dc-pvldq to (PodScheduled==False, Reason=Unschedulable)
I0924 13:19:32.513756    6058 scheduler.go:576] Attempting to schedule pod: system/kube-system/coredns-default-6cfd6c6766-cqfm7
I0924 13:19:32.626095    6058 generic_scheduler.go:1052] Node master is a potential node for preemption.
I0924 13:19:32.626371    6058 factory.go:470] Unable to schedule system/kube-system/coredns-default-6cfd6c6766-cqfm7: no fit: 0/1 nodes are available: 1 node(s) runtime is not ready.; waiting
I0924 13:19:32.626425    6058 scheduler.go:787] Updating pod condition for system/kube-system/coredns-default-6cfd6c6766-cqfm7 to (PodScheduled==False, Reason=Unschedulable)
I0924 13:19:34.591725    6058 scheduler.go:576] Attempting to schedule pod: system/kube-system/kube-dns-7f4bf79dc-pvldq
I0924 13:19:34.812051    6058 generic_scheduler.go:1052] Node master is a potential node for preemption.
I0924 13:19:34.813097    6058 factory.go:470] Unable to schedule system/kube-system/kube-dns-7f4bf79dc-pvldq: no fit: 0/1 nodes are available: 1 node(s) runtime is not ready.; waiting
I0924 13:19:34.813185    6058 scheduler.go:787] Updating pod condition for system/kube-system/kube-dns-7f4bf79dc-pvldq to (PodScheduled==False, Reason=Unschedulable)
I0924 13:19:41.863093    6058 scheduler.go:576] Attempting to schedule pod: system/kube-system/coredns-default-6cfd6c6766-cqfm7
I0924 13:19:41.878391    6058 generic_scheduler.go:1052] Node master is a potential node for preemption.
I0924 13:19:41.878960    6058 factory.go:470] Unable to schedule system/kube-system/coredns-default-6cfd6c6766-cqfm7: no fit: 0/1 nodes are available: 1 node(s) runtime is not ready.; waiting
I0924 13:19:41.879042    6058 scheduler.go:787] Updating pod condition for system/kube-system/coredns-default-6cfd6c6766-cqfm7 to (PodScheduled==False, Reason=Unschedulable)
I0924 13:19:43.799415    6058 scheduler.go:576] Attempting to schedule pod: system/kube-system/coredns-default-6cfd6c6766-cqfm7
I0924 13:19:43.980969    6058 generic_scheduler.go:1052] Node master is a potential node for preemption.
I0924 13:19:43.981497    6058 factory.go:470] Unable to schedule system/kube-system/coredns-default-6cfd6c6766-cqfm7: no fit: 0/1 nodes are available: 1 node(s) runtime is not ready.; waiting
I0924 13:19:43.981619    6058 scheduler.go:787] Updating pod condition for system/kube-system/coredns-default-6cfd6c6766-cqfm7 to (PodScheduled==False, Reason=Unschedulable)
I0924 13:19:43.983223    6058 scheduler.go:576] Attempting to schedule pod: system/kube-system/kube-dns-7f4bf79dc-pvldq
I0924 13:19:44.050150    6058 generic_scheduler.go:1052] Node master is a potential node for preemption.
I0924 13:19:44.050415    6058 factory.go:470] Unable to schedule system/kube-system/kube-dns-7f4bf79dc-pvldq: no fit: 0/1 nodes are available: 1 node(s) runtime is not ready.; waiting
I0924 13:19:44.050465    6058 scheduler.go:787] Updating pod condition for system/kube-system/kube-dns-7f4bf79dc-pvldq to (PodScheduled==False, Reason=Unschedulable)
I0924 13:19:44.558079    6058 scheduler.go:576] Attempting to schedule pod: system/kube-system/kube-dns-7f4bf79dc-pvldq
I0924 13:19:44.566884    6058 generic_scheduler.go:1052] Node master is a potential node for preemption.
I0924 13:19:44.567177    6058 factory.go:470] Unable to schedule system/kube-system/kube-dns-7f4bf79dc-pvldq: no fit: 0/1 nodes are available: 1 node(s) runtime is not ready.; waiting
I0924 13:19:44.567238    6058 scheduler.go:787] Updating pod condition for system/kube-system/kube-dns-7f4bf79dc-pvldq to (PodScheduled==False, Reason=Unschedulable)
I0924 13:19:54.441707    6058 scheduler.go:576] Attempting to schedule pod: system/kube-system/coredns-default-6cfd6c6766-cqfm7
I0924 13:19:54.456045    6058 generic_scheduler.go:1052] Node master is a potential node for preemption.
I0924 13:19:54.456360    6058 factory.go:470] Unable to schedule system/kube-system/coredns-default-6cfd6c6766-cqfm7: no fit: 0/1 nodes are available: 1 node(s) runtime is not ready.; waiting
I0924 13:19:54.456413    6058 scheduler.go:787] Updating pod condition for system/kube-system/coredns-default-6cfd6c6766-cqfm7 to (PodScheduled==False, Reason=Unschedulable)
I0924 13:19:55.901697    6058 scheduler.go:576] Attempting to schedule pod: system/kube-system/kube-dns-7f4bf79dc-pvldq
I0924 13:19:55.923105    6058 generic_scheduler.go:1052] Node master is a potential node for preemption.
I0924 13:19:55.923663    6058 factory.go:470] Unable to schedule system/kube-system/kube-dns-7f4bf79dc-pvldq: no fit: 0/1 nodes are available: 1 node(s) runtime is not ready.; waiting
I0924 13:19:55.923730    6058 scheduler.go:787] Updating pod condition for system/kube-system/kube-dns-7f4bf79dc-pvldq to (PodScheduled==False, Reason=Unschedulable)
I0924 13:20:03.780605    6058 scheduler.go:576] Attempting to schedule pod: system/kube-system/coredns-default-6cfd6c6766-cqfm7
I0924 13:20:03.787711    6058 generic_scheduler.go:1052] Node master is a potential node for preemption.
I0924 13:20:03.787970    6058 factory.go:470] Unable to schedule system/kube-system/coredns-default-6cfd6c6766-cqfm7: no fit: 0/1 nodes are available: 1 node(s) runtime is not ready.; waiting
I0924 13:20:03.788032    6058 scheduler.go:787] Updating pod condition for system/kube-system/coredns-default-6cfd6c6766-cqfm7 to (PodScheduled==False, Reason=Unschedulable)
I0924 13:20:04.667687    6058 scheduler.go:576] Attempting to schedule pod: system/kube-system/coredns-default-6cfd6c6766-cqfm7
I0924 13:20:04.838914    6058 generic_scheduler.go:1052] Node master is a potential node for preemption.
I0924 13:20:04.839174    6058 factory.go:470] Unable to schedule system/kube-system/coredns-default-6cfd6c6766-cqfm7: no fit: 0/1 nodes are available: 1 node(s) runtime is not ready.; waiting
I0924 13:20:04.839236    6058 scheduler.go:787] Updating pod condition for system/kube-system/coredns-default-6cfd6c6766-cqfm7 to (PodScheduled==False, Reason=Unschedulable)
I0924 13:20:04.852677    6058 scheduler.go:576] Attempting to schedule pod: system/kube-system/kube-dns-7f4bf79dc-pvldq
I0924 13:20:04.860410    6058 generic_scheduler.go:1052] Node master is a potential node for preemption.
I0924 13:20:04.860674    6058 factory.go:470] Unable to schedule system/kube-system/kube-dns-7f4bf79dc-pvldq: no fit: 0/1 nodes are available: 1 node(s) runtime is not ready.; waiting
I0924 13:20:04.860720    6058 scheduler.go:787] Updating pod condition for system/kube-system/kube-dns-7f4bf79dc-pvldq to (PodScheduled==False, Reason=Unschedulable)
I0924 13:20:05.529908    6058 scheduler.go:576] Attempting to schedule pod: system/kube-system/kube-dns-7f4bf79dc-pvldq
I0924 13:20:05.592801    6058 generic_scheduler.go:1052] Node master is a potential node for preemption.
I0924 13:20:05.593129    6058 factory.go:470] Unable to schedule system/kube-system/kube-dns-7f4bf79dc-pvldq: no fit: 0/1 nodes are available: 1 node(s) runtime is not ready.; waiting
I0924 13:20:05.593201    6058 scheduler.go:787] Updating pod condition for system/kube-system/kube-dns-7f4bf79dc-pvldq to (PodScheduled==False, Reason=Unschedulable)
I0924 13:20:15.485314    6058 scheduler.go:576] Attempting to schedule pod: system/kube-system/coredns-default-6cfd6c6766-cqfm7
I0924 13:20:15.500709    6058 generic_scheduler.go:1052] Node master is a potential node for preemption.
I0924 13:20:15.500950    6058 factory.go:470] Unable to schedule system/kube-system/coredns-default-6cfd6c6766-cqfm7: no fit: 0/1 nodes are available: 1 node(s) runtime is not ready.; waiting
I0924 13:20:15.500997    6058 scheduler.go:787] Updating pod condition for system/kube-system/coredns-default-6cfd6c6766-cqfm7 to (PodScheduled==False, Reason=Unschedulable)
I0924 13:20:16.652077    6058 scheduler.go:576] Attempting to schedule pod: system/kube-system/kube-dns-7f4bf79dc-pvldq
I0924 13:20:16.665517    6058 generic_scheduler.go:1052] Node master is a potential node for preemption.
I0924 13:20:16.666165    6058 factory.go:470] Unable to schedule system/kube-system/kube-dns-7f4bf79dc-pvldq: no fit: 0/1 nodes are available: 1 node(s) runtime is not ready.; waiting
I0924 13:20:16.666249    6058 scheduler.go:787] Updating pod condition for system/kube-system/kube-dns-7f4bf79dc-pvldq to (PodScheduled==False, Reason=Unschedulable)
I0924 13:20:24.654478    6058 scheduler.go:576] Attempting to schedule pod: system/kube-system/coredns-default-6cfd6c6766-cqfm7
I0924 13:20:24.660750    6058 generic_scheduler.go:1052] Node master is a potential node for preemption.
I0924 13:20:24.660989    6058 factory.go:470] Unable to schedule system/kube-system/coredns-default-6cfd6c6766-cqfm7: no fit: 0/1 nodes are available: 1 node(s) runtime is not ready.; waiting
I0924 13:20:24.661039    6058 scheduler.go:787] Updating pod condition for system/kube-system/coredns-default-6cfd6c6766-cqfm7 to (PodScheduled==False, Reason=Unschedulable)
I0924 13:20:24.824570    6058 scheduler.go:576] Attempting to schedule pod: system/kube-system/coredns-default-6cfd6c6766-cqfm7
I0924 13:20:24.830508    6058 generic_scheduler.go:1052] Node master is a potential node for preemption.
I0924 13:20:24.830948    6058 factory.go:470] Unable to schedule system/kube-system/coredns-default-6cfd6c6766-cqfm7: no fit: 0/1 nodes are available: 1 node(s) runtime is not ready.; waiting
I0924 13:20:24.831015    6058 scheduler.go:787] Updating pod condition for system/kube-system/coredns-default-6cfd6c6766-cqfm7 to (PodScheduled==False, Reason=Unschedulable)
I0924 13:20:25.529954    6058 scheduler.go:576] Attempting to schedule pod: system/kube-system/kube-dns-7f4bf79dc-pvldq
I0924 13:20:25.603871    6058 generic_scheduler.go:1052] Node master is a potential node for preemption.
I0924 13:20:25.604193    6058 factory.go:470] Unable to schedule system/kube-system/kube-dns-7f4bf79dc-pvldq: no fit: 0/1 nodes are available: 1 node(s) runtime is not ready.; waiting
I0924 13:20:25.604249    6058 scheduler.go:787] Updating pod condition for system/kube-system/kube-dns-7f4bf79dc-pvldq to (PodScheduled==False, Reason=Unschedulable)
I0924 13:20:25.846240    6058 scheduler.go:576] Attempting to schedule pod: system/kube-system/kube-dns-7f4bf79dc-pvldq
I0924 13:20:25.851765    6058 generic_scheduler.go:1052] Node master is a potential node for preemption.
I0924 13:20:25.852018    6058 factory.go:470] Unable to schedule system/kube-system/kube-dns-7f4bf79dc-pvldq: no fit: 0/1 nodes are available: 1 node(s) runtime is not ready.; waiting
I0924 13:20:25.852063    6058 scheduler.go:787] Updating pod condition for system/kube-system/kube-dns-7f4bf79dc-pvldq to (PodScheduled==False, Reason=Unschedulable)
I0924 13:20:35.727088    6058 scheduler.go:576] Attempting to schedule pod: system/kube-system/coredns-default-6cfd6c6766-cqfm7
I0924 13:20:35.737212    6058 generic_scheduler.go:1052] Node master is a potential node for preemption.
I0924 13:20:35.737676    6058 factory.go:470] Unable to schedule system/kube-system/coredns-default-6cfd6c6766-cqfm7: no fit: 0/1 nodes are available: 1 node(s) runtime is not ready.; waiting
I0924 13:20:35.737840    6058 scheduler.go:787] Updating pod condition for system/kube-system/coredns-default-6cfd6c6766-cqfm7 to (PodScheduled==False, Reason=Unschedulable)
I0924 13:20:36.727328    6058 scheduler.go:576] Attempting to schedule pod: system/kube-system/kube-dns-7f4bf79dc-pvldq
I0924 13:20:36.738469    6058 generic_scheduler.go:1052] Node master is a potential node for preemption.
I0924 13:20:36.738833    6058 factory.go:470] Unable to schedule system/kube-system/kube-dns-7f4bf79dc-pvldq: no fit: 0/1 nodes are available: 1 node(s) runtime is not ready.; waiting
I0924 13:20:36.738903    6058 scheduler.go:787] Updating pod condition for system/kube-system/kube-dns-7f4bf79dc-pvldq to (PodScheduled==False, Reason=Unschedulable)
I0924 13:20:45.754291    6058 scheduler.go:576] Attempting to schedule pod: system/kube-system/coredns-default-6cfd6c6766-cqfm7
I0924 13:20:45.764087    6058 generic_scheduler.go:1052] Node master is a potential node for preemption.
I0924 13:20:45.764496    6058 factory.go:470] Unable to schedule system/kube-system/coredns-default-6cfd6c6766-cqfm7: no fit: 0/1 nodes are available: 1 node(s) runtime is not ready.; waiting
I0924 13:20:45.764569    6058 scheduler.go:787] Updating pod condition for system/kube-system/coredns-default-6cfd6c6766-cqfm7 to (PodScheduled==False, Reason=Unschedulable)
I0924 13:20:45.853783    6058 scheduler.go:576] Attempting to schedule pod: system/kube-system/kube-dns-7f4bf79dc-pvldq
I0924 13:20:45.868930    6058 generic_scheduler.go:1052] Node master is a potential node for preemption.
I0924 13:20:45.869214    6058 factory.go:470] Unable to schedule system/kube-system/kube-dns-7f4bf79dc-pvldq: no fit: 0/1 nodes are available: 1 node(s) runtime is not ready.; waiting
I0924 13:20:45.869267    6058 scheduler.go:787] Updating pod condition for system/kube-system/kube-dns-7f4bf79dc-pvldq to (PodScheduled==False, Reason=Unschedulable)
I0924 13:20:46.007996    6058 scheduler.go:576] Attempting to schedule pod: system/kube-system/kube-dns-7f4bf79dc-pvldq
I0924 13:20:46.056305    6058 generic_scheduler.go:1052] Node master is a potential node for preemption.
I0924 13:20:46.056577    6058 factory.go:470] Unable to schedule system/kube-system/kube-dns-7f4bf79dc-pvldq: no fit: 0/1 nodes are available: 1 node(s) runtime is not ready.; waiting
I0924 13:20:46.056637    6058 scheduler.go:787] Updating pod condition for system/kube-system/kube-dns-7f4bf79dc-pvldq to (PodScheduled==False, Reason=Unschedulable)
I0924 13:20:56.760300    6058 scheduler.go:576] Attempting to schedule pod: system/kube-system/coredns-default-6cfd6c6766-cqfm7
I0924 13:20:56.768814    6058 generic_scheduler.go:1052] Node master is a potential node for preemption.
I0924 13:20:56.769085    6058 factory.go:470] Unable to schedule system/kube-system/coredns-default-6cfd6c6766-cqfm7: no fit: 0/1 nodes are available: 1 node(s) runtime is not ready.; waiting
I0924 13:20:56.769154    6058 scheduler.go:787] Updating pod condition for system/kube-system/coredns-default-6cfd6c6766-cqfm7 to (PodScheduled==False, Reason=Unschedulable)
I0924 13:20:56.770373    6058 scheduler.go:576] Attempting to schedule pod: system/kube-system/kube-dns-7f4bf79dc-pvldq
I0924 13:20:56.778432    6058 generic_scheduler.go:1052] Node master is a potential node for preemption.
I0924 13:20:56.778658    6058 factory.go:470] Unable to schedule system/kube-system/kube-dns-7f4bf79dc-pvldq: no fit: 0/1 nodes are available: 1 node(s) runtime is not ready.; waiting
I0924 13:20:56.778702    6058 scheduler.go:787] Updating pod condition for system/kube-system/kube-dns-7f4bf79dc-pvldq to (PodScheduled==False, Reason=Unschedulable)
I0924 13:21:07.764431    6058 scheduler.go:576] Attempting to schedule pod: system/kube-system/coredns-default-6cfd6c6766-cqfm7
I0924 13:21:07.770277    6058 generic_scheduler.go:1052] Node master is a potential node for preemption.
I0924 13:21:07.770532    6058 factory.go:470] Unable to schedule system/kube-system/coredns-default-6cfd6c6766-cqfm7: no fit: 0/1 nodes are available: 1 node(s) runtime is not ready.; waiting
I0924 13:21:07.770588    6058 scheduler.go:787] Updating pod condition for system/kube-system/coredns-default-6cfd6c6766-cqfm7 to (PodScheduled==False, Reason=Unschedulable)
I0924 13:21:07.770853    6058 scheduler.go:576] Attempting to schedule pod: system/kube-system/kube-dns-7f4bf79dc-pvldq
I0924 13:21:07.777223    6058 generic_scheduler.go:1052] Node master is a potential node for preemption.
I0924 13:21:07.777463    6058 factory.go:470] Unable to schedule system/kube-system/kube-dns-7f4bf79dc-pvldq: no fit: 0/1 nodes are available: 1 node(s) runtime is not ready.; waiting
I0924 13:21:07.777507    6058 scheduler.go:787] Updating pod condition for system/kube-system/kube-dns-7f4bf79dc-pvldq to (PodScheduled==False, Reason=Unschedulable)
I0924 13:21:17.866654    6058 scheduler.go:576] Attempting to schedule pod: system/kube-system/coredns-default-6cfd6c6766-cqfm7
I0924 13:21:17.875732    6058 generic_scheduler.go:1052] Node master is a potential node for preemption.
I0924 13:21:17.876089    6058 factory.go:470] Unable to schedule system/kube-system/coredns-default-6cfd6c6766-cqfm7: no fit: 0/1 nodes are available: 1 node(s) runtime is not ready.; waiting
I0924 13:21:17.876163    6058 scheduler.go:787] Updating pod condition for system/kube-system/coredns-default-6cfd6c6766-cqfm7 to (PodScheduled==False, Reason=Unschedulable)
I0924 13:21:17.876399    6058 scheduler.go:576] Attempting to schedule pod: system/kube-system/kube-dns-7f4bf79dc-pvldq
I0924 13:21:17.884875    6058 generic_scheduler.go:1052] Node master is a potential node for preemption.
I0924 13:21:17.885200    6058 factory.go:470] Unable to schedule system/kube-system/kube-dns-7f4bf79dc-pvldq: no fit: 0/1 nodes are available: 1 node(s) runtime is not ready.; waiting
I0924 13:21:17.885262    6058 scheduler.go:787] Updating pod condition for system/kube-system/kube-dns-7f4bf79dc-pvldq to (PodScheduled==False, Reason=Unschedulable)
I0924 13:21:28.308980    6058 scheduler.go:576] Attempting to schedule pod: system/kube-system/coredns-default-6cfd6c6766-cqfm7
I0924 13:21:28.318224    6058 generic_scheduler.go:1052] Node master is a potential node for preemption.
I0924 13:21:28.318504    6058 factory.go:470] Unable to schedule system/kube-system/coredns-default-6cfd6c6766-cqfm7: no fit: 0/1 nodes are available: 1 node(s) runtime is not ready.; waiting
I0924 13:21:28.318569    6058 scheduler.go:787] Updating pod condition for system/kube-system/coredns-default-6cfd6c6766-cqfm7 to (PodScheduled==False, Reason=Unschedulable)
I0924 13:21:28.318982    6058 scheduler.go:576] Attempting to schedule pod: system/kube-system/kube-dns-7f4bf79dc-pvldq
I0924 13:21:28.328295    6058 generic_scheduler.go:1052] Node master is a potential node for preemption.
I0924 13:21:28.328587    6058 factory.go:470] Unable to schedule system/kube-system/kube-dns-7f4bf79dc-pvldq: no fit: 0/1 nodes are available: 1 node(s) runtime is not ready.; waiting
I0924 13:21:28.328650    6058 scheduler.go:787] Updating pod condition for system/kube-system/kube-dns-7f4bf79dc-pvldq to (PodScheduled==False, Reason=Unschedulable)
I0924 13:21:39.327919    6058 scheduler.go:576] Attempting to schedule pod: system/kube-system/coredns-default-6cfd6c6766-cqfm7
I0924 13:21:39.337003    6058 generic_scheduler.go:1052] Node master is a potential node for preemption.
I0924 13:21:39.337301    6058 factory.go:470] Unable to schedule system/kube-system/coredns-default-6cfd6c6766-cqfm7: no fit: 0/1 nodes are available: 1 node(s) runtime is not ready.; waiting
I0924 13:21:39.337367    6058 scheduler.go:787] Updating pod condition for system/kube-system/coredns-default-6cfd6c6766-cqfm7 to (PodScheduled==False, Reason=Unschedulable)
I0924 13:21:39.337648    6058 scheduler.go:576] Attempting to schedule pod: system/kube-system/kube-dns-7f4bf79dc-pvldq
I0924 13:21:39.346362    6058 generic_scheduler.go:1052] Node master is a potential node for preemption.
I0924 13:21:39.346785    6058 factory.go:470] Unable to schedule system/kube-system/kube-dns-7f4bf79dc-pvldq: no fit: 0/1 nodes are available: 1 node(s) runtime is not ready.; waiting
I0924 13:21:39.346854    6058 scheduler.go:787] Updating pod condition for system/kube-system/kube-dns-7f4bf79dc-pvldq to (PodScheduled==False, Reason=Unschedulable)
I0924 13:21:50.332306    6058 scheduler.go:576] Attempting to schedule pod: system/kube-system/coredns-default-6cfd6c6766-cqfm7
I0924 13:21:50.345063    6058 generic_scheduler.go:1052] Node master is a potential node for preemption.
I0924 13:21:50.345588    6058 factory.go:470] Unable to schedule system/kube-system/coredns-default-6cfd6c6766-cqfm7: no fit: 0/1 nodes are available: 1 node(s) runtime is not ready.; waiting
I0924 13:21:50.345653    6058 scheduler.go:787] Updating pod condition for system/kube-system/coredns-default-6cfd6c6766-cqfm7 to (PodScheduled==False, Reason=Unschedulable)
I0924 13:21:50.345824    6058 scheduler.go:576] Attempting to schedule pod: system/kube-system/kube-dns-7f4bf79dc-pvldq
I0924 13:21:50.356808    6058 generic_scheduler.go:1052] Node master is a potential node for preemption.
I0924 13:21:50.357089    6058 factory.go:470] Unable to schedule system/kube-system/kube-dns-7f4bf79dc-pvldq: no fit: 0/1 nodes are available: 1 node(s) runtime is not ready.; waiting
I0924 13:21:50.357150    6058 scheduler.go:787] Updating pod condition for system/kube-system/kube-dns-7f4bf79dc-pvldq to (PodScheduled==False, Reason=Unschedulable)
I0924 13:22:01.337110    6058 scheduler.go:576] Attempting to schedule pod: system/kube-system/coredns-default-6cfd6c6766-cqfm7
I0924 13:22:01.353052    6058 generic_scheduler.go:1052] Node master is a potential node for preemption.
I0924 13:22:01.353339    6058 factory.go:470] Unable to schedule system/kube-system/coredns-default-6cfd6c6766-cqfm7: no fit: 0/1 nodes are available: 1 node(s) runtime is not ready.; waiting
I0924 13:22:01.353402    6058 scheduler.go:787] Updating pod condition for system/kube-system/coredns-default-6cfd6c6766-cqfm7 to (PodScheduled==False, Reason=Unschedulable)
I0924 13:22:01.353631    6058 scheduler.go:576] Attempting to schedule pod: system/kube-system/kube-dns-7f4bf79dc-pvldq
I0924 13:22:01.362762    6058 generic_scheduler.go:1052] Node master is a potential node for preemption.
I0924 13:22:01.363381    6058 factory.go:470] Unable to schedule system/kube-system/kube-dns-7f4bf79dc-pvldq: no fit: 0/1 nodes are available: 1 node(s) runtime is not ready.; waiting
I0924 13:22:01.363518    6058 scheduler.go:787] Updating pod condition for system/kube-system/kube-dns-7f4bf79dc-pvldq to (PodScheduled==False, Reason=Unschedulable)
I0924 13:22:11.710884    6058 scheduler.go:576] Attempting to schedule pod: system/kube-system/coredns-default-6cfd6c6766-cqfm7
I0924 13:22:11.771481    6058 generic_scheduler.go:1052] Node master is a potential node for preemption.
I0924 13:22:11.787798    6058 factory.go:470] Unable to schedule system/kube-system/coredns-default-6cfd6c6766-cqfm7: no fit: 0/1 nodes are available: 1 node(s) runtime is not ready.; waiting
I0924 13:22:11.787970    6058 scheduler.go:787] Updating pod condition for system/kube-system/coredns-default-6cfd6c6766-cqfm7 to (PodScheduled==False, Reason=Unschedulable)
I0924 13:22:11.793604    6058 scheduler.go:576] Attempting to schedule pod: system/kube-system/kube-dns-7f4bf79dc-pvldq
I0924 13:22:12.073198    6058 eventhandlers.go:183] add event for unscheduled pod system/default/mizar-operator-6985d77546-tvdlf
I0924 13:22:12.074165    6058 generic_scheduler.go:1052] Node master is a potential node for preemption.
I0924 13:22:12.075168    6058 factory.go:470] Unable to schedule system/kube-system/kube-dns-7f4bf79dc-pvldq: no fit: 0/1 nodes are available: 1 node(s) runtime is not ready.; waiting
I0924 13:22:12.075240    6058 scheduler.go:787] Updating pod condition for system/kube-system/kube-dns-7f4bf79dc-pvldq to (PodScheduled==False, Reason=Unschedulable)
I0924 13:22:12.075812    6058 scheduler.go:576] Attempting to schedule pod: system/default/mizar-operator-6985d77546-tvdlf
I0924 13:22:12.076253    6058 default_binder.go:53] Attempting to bind system/default/mizar-operator-6985d77546-tvdlf to master
I0924 13:22:12.228729    6058 eventhandlers.go:215] delete event for unscheduled pod system/default/mizar-operator-6985d77546-tvdlf
I0924 13:22:12.232614    6058 scheduler.go:741] pod system/default/mizar-operator-6985d77546-tvdlf is bound successfully on node "master", 1 nodes evaluated, 1 nodes were found feasible.
I0924 13:22:12.260811    6058 eventhandlers.go:239] add event for scheduled pod system/default/mizar-operator-6985d77546-tvdlf 
I0924 13:22:15.383274    6058 eventhandlers.go:308] delete event for scheduled pod system/default/mizar-operator-6985d77546-9tc8d 
I0924 13:22:22.132317    6058 scheduler.go:576] Attempting to schedule pod: system/kube-system/coredns-default-6cfd6c6766-cqfm7
I0924 13:22:23.743624    6058 generic_scheduler.go:1052] Node master is a potential node for preemption.
I0924 13:22:23.743917    6058 factory.go:470] Unable to schedule system/kube-system/coredns-default-6cfd6c6766-cqfm7: no fit: 0/1 nodes are available: 1 node(s) runtime is not ready.; waiting
I0924 13:22:23.743972    6058 scheduler.go:787] Updating pod condition for system/kube-system/coredns-default-6cfd6c6766-cqfm7 to (PodScheduled==False, Reason=Unschedulable)
I0924 13:22:23.918373    6058 scheduler.go:576] Attempting to schedule pod: system/kube-system/kube-dns-7f4bf79dc-pvldq
I0924 13:22:24.081150    6058 generic_scheduler.go:1052] Node master is a potential node for preemption.
I0924 13:22:24.081412    6058 factory.go:470] Unable to schedule system/kube-system/kube-dns-7f4bf79dc-pvldq: no fit: 0/1 nodes are available: 1 node(s) runtime is not ready.; waiting
I0924 13:22:24.081468    6058 scheduler.go:787] Updating pod condition for system/kube-system/kube-dns-7f4bf79dc-pvldq to (PodScheduled==False, Reason=Unschedulable)
I0924 13:22:35.175475    6058 scheduler.go:576] Attempting to schedule pod: system/kube-system/coredns-default-6cfd6c6766-cqfm7
I0924 13:22:35.288357    6058 generic_scheduler.go:1052] Node master is a potential node for preemption.
I0924 13:22:35.288659    6058 factory.go:470] Unable to schedule system/kube-system/coredns-default-6cfd6c6766-cqfm7: no fit: 0/1 nodes are available: 1 node(s) runtime is not ready.; waiting
I0924 13:22:35.288714    6058 scheduler.go:787] Updating pod condition for system/kube-system/coredns-default-6cfd6c6766-cqfm7 to (PodScheduled==False, Reason=Unschedulable)
I0924 13:22:35.288777    6058 scheduler.go:576] Attempting to schedule pod: system/kube-system/kube-dns-7f4bf79dc-pvldq
I0924 13:22:35.398957    6058 generic_scheduler.go:1052] Node master is a potential node for preemption.
I0924 13:22:35.399258    6058 factory.go:470] Unable to schedule system/kube-system/kube-dns-7f4bf79dc-pvldq: no fit: 0/1 nodes are available: 1 node(s) runtime is not ready.; waiting
I0924 13:22:35.399313    6058 scheduler.go:787] Updating pod condition for system/kube-system/kube-dns-7f4bf79dc-pvldq to (PodScheduled==False, Reason=Unschedulable)
I0924 13:22:45.858032    6058 scheduler.go:576] Attempting to schedule pod: system/kube-system/coredns-default-6cfd6c6766-cqfm7
I0924 13:22:47.303093    6058 generic_scheduler.go:1052] Node master is a potential node for preemption.
I0924 13:22:47.303869    6058 factory.go:470] Unable to schedule system/kube-system/coredns-default-6cfd6c6766-cqfm7: no fit: 0/1 nodes are available: 1 node(s) runtime is not ready.; waiting
I0924 13:22:47.303943    6058 scheduler.go:787] Updating pod condition for system/kube-system/coredns-default-6cfd6c6766-cqfm7 to (PodScheduled==False, Reason=Unschedulable)
I0924 13:22:47.304033    6058 scheduler.go:576] Attempting to schedule pod: system/kube-system/kube-dns-7f4bf79dc-pvldq
I0924 13:22:47.361269    6058 generic_scheduler.go:1052] Node master is a potential node for preemption.
I0924 13:22:47.361595    6058 factory.go:470] Unable to schedule system/kube-system/kube-dns-7f4bf79dc-pvldq: no fit: 0/1 nodes are available: 1 node(s) runtime is not ready.; waiting
I0924 13:22:47.361650    6058 scheduler.go:787] Updating pod condition for system/kube-system/kube-dns-7f4bf79dc-pvldq to (PodScheduled==False, Reason=Unschedulable)
I0924 13:22:58.022847    6058 scheduler.go:576] Attempting to schedule pod: system/kube-system/coredns-default-6cfd6c6766-cqfm7
I0924 13:22:58.186064    6058 generic_scheduler.go:1052] Node master is a potential node for preemption.
I0924 13:22:58.186357    6058 factory.go:470] Unable to schedule system/kube-system/coredns-default-6cfd6c6766-cqfm7: no fit: 0/1 nodes are available: 1 node(s) runtime is not ready.; waiting
I0924 13:22:58.186412    6058 scheduler.go:787] Updating pod condition for system/kube-system/coredns-default-6cfd6c6766-cqfm7 to (PodScheduled==False, Reason=Unschedulable)
I0924 13:22:58.187027    6058 scheduler.go:576] Attempting to schedule pod: system/kube-system/kube-dns-7f4bf79dc-pvldq
I0924 13:22:58.294154    6058 generic_scheduler.go:1052] Node master is a potential node for preemption.
I0924 13:22:58.294828    6058 factory.go:470] Unable to schedule system/kube-system/kube-dns-7f4bf79dc-pvldq: no fit: 0/1 nodes are available: 1 node(s) runtime is not ready.; waiting
I0924 13:22:58.294954    6058 scheduler.go:787] Updating pod condition for system/kube-system/kube-dns-7f4bf79dc-pvldq to (PodScheduled==False, Reason=Unschedulable)
I0924 13:23:08.631580    6058 scheduler.go:576] Attempting to schedule pod: system/kube-system/coredns-default-6cfd6c6766-cqfm7
I0924 13:23:08.702434    6058 generic_scheduler.go:1052] Node master is a potential node for preemption.
I0924 13:23:08.741627    6058 factory.go:470] Unable to schedule system/kube-system/coredns-default-6cfd6c6766-cqfm7: no fit: 0/1 nodes are available: 1 node(s) runtime is not ready.; waiting
I0924 13:23:08.741804    6058 scheduler.go:787] Updating pod condition for system/kube-system/coredns-default-6cfd6c6766-cqfm7 to (PodScheduled==False, Reason=Unschedulable)
I0924 13:23:08.783464    6058 scheduler.go:576] Attempting to schedule pod: system/kube-system/kube-dns-7f4bf79dc-pvldq
I0924 13:23:08.871272    6058 generic_scheduler.go:1052] Node master is a potential node for preemption.
I0924 13:23:08.871550    6058 factory.go:470] Unable to schedule system/kube-system/kube-dns-7f4bf79dc-pvldq: no fit: 0/1 nodes are available: 1 node(s) runtime is not ready.; waiting
I0924 13:23:08.871601    6058 scheduler.go:787] Updating pod condition for system/kube-system/kube-dns-7f4bf79dc-pvldq to (PodScheduled==False, Reason=Unschedulable)
I0924 13:23:19.207033    6058 scheduler.go:576] Attempting to schedule pod: system/kube-system/coredns-default-6cfd6c6766-cqfm7
I0924 13:23:19.426377    6058 generic_scheduler.go:1052] Node master is a potential node for preemption.
I0924 13:23:19.426659    6058 factory.go:470] Unable to schedule system/kube-system/coredns-default-6cfd6c6766-cqfm7: no fit: 0/1 nodes are available: 1 node(s) runtime is not ready.; waiting
I0924 13:23:19.426712    6058 scheduler.go:787] Updating pod condition for system/kube-system/coredns-default-6cfd6c6766-cqfm7 to (PodScheduled==False, Reason=Unschedulable)
I0924 13:23:19.426776    6058 scheduler.go:576] Attempting to schedule pod: system/kube-system/kube-dns-7f4bf79dc-pvldq
I0924 13:23:19.672333    6058 generic_scheduler.go:1052] Node master is a potential node for preemption.
I0924 13:23:19.672728    6058 factory.go:470] Unable to schedule system/kube-system/kube-dns-7f4bf79dc-pvldq: no fit: 0/1 nodes are available: 1 node(s) runtime is not ready.; waiting
I0924 13:23:19.672793    6058 scheduler.go:787] Updating pod condition for system/kube-system/kube-dns-7f4bf79dc-pvldq to (PodScheduled==False, Reason=Unschedulable)
I0924 13:23:30.004927    6058 scheduler.go:576] Attempting to schedule pod: system/kube-system/coredns-default-6cfd6c6766-cqfm7
I0924 13:23:30.268884    6058 generic_scheduler.go:1052] Node master is a potential node for preemption.
I0924 13:23:30.269174    6058 factory.go:470] Unable to schedule system/kube-system/coredns-default-6cfd6c6766-cqfm7: no fit: 0/1 nodes are available: 1 node(s) runtime is not ready.; waiting
I0924 13:23:30.269227    6058 scheduler.go:787] Updating pod condition for system/kube-system/coredns-default-6cfd6c6766-cqfm7 to (PodScheduled==False, Reason=Unschedulable)
I0924 13:23:30.281889    6058 scheduler.go:576] Attempting to schedule pod: system/kube-system/kube-dns-7f4bf79dc-pvldq
I0924 13:23:31.373684    6058 generic_scheduler.go:1052] Node master is a potential node for preemption.
I0924 13:23:31.374315    6058 factory.go:470] Unable to schedule system/kube-system/kube-dns-7f4bf79dc-pvldq: no fit: 0/1 nodes are available: 1 node(s) runtime is not ready.; waiting
I0924 13:23:31.374439    6058 scheduler.go:787] Updating pod condition for system/kube-system/kube-dns-7f4bf79dc-pvldq to (PodScheduled==False, Reason=Unschedulable)
I0924 13:23:40.928550    6058 scheduler.go:576] Attempting to schedule pod: system/kube-system/coredns-default-6cfd6c6766-cqfm7
I0924 13:23:41.053903    6058 generic_scheduler.go:1052] Node master is a potential node for preemption.
I0924 13:23:41.054188    6058 factory.go:470] Unable to schedule system/kube-system/coredns-default-6cfd6c6766-cqfm7: no fit: 0/1 nodes are available: 1 node(s) runtime is not ready.; waiting
I0924 13:23:41.054240    6058 scheduler.go:787] Updating pod condition for system/kube-system/coredns-default-6cfd6c6766-cqfm7 to (PodScheduled==False, Reason=Unschedulable)
I0924 13:23:41.954295    6058 scheduler.go:576] Attempting to schedule pod: system/kube-system/kube-dns-7f4bf79dc-pvldq
I0924 13:23:42.039857    6058 generic_scheduler.go:1052] Node master is a potential node for preemption.
I0924 13:23:42.040139    6058 factory.go:470] Unable to schedule system/kube-system/kube-dns-7f4bf79dc-pvldq: no fit: 0/1 nodes are available: 1 node(s) runtime is not ready.; waiting
I0924 13:23:42.040197    6058 scheduler.go:787] Updating pod condition for system/kube-system/kube-dns-7f4bf79dc-pvldq to (PodScheduled==False, Reason=Unschedulable)
I0924 13:23:45.939413    6058 scheduler.go:576] Attempting to schedule pod: system/kube-system/kube-dns-7f4bf79dc-pvldq
I0924 13:23:45.980617    6058 generic_scheduler.go:1052] Node master is a potential node for preemption.
I0924 13:23:45.980885    6058 factory.go:470] Unable to schedule system/kube-system/kube-dns-7f4bf79dc-pvldq: no fit: 0/1 nodes are available: 1 node(s) runtime is not ready.; waiting
I0924 13:23:45.980932    6058 scheduler.go:787] Updating pod condition for system/kube-system/kube-dns-7f4bf79dc-pvldq to (PodScheduled==False, Reason=Unschedulable)
I0924 13:23:46.003171    6058 scheduler.go:576] Attempting to schedule pod: system/kube-system/coredns-default-6cfd6c6766-cqfm7
I0924 13:23:46.265955    6058 generic_scheduler.go:1052] Node master is a potential node for preemption.
I0924 13:23:46.266228    6058 factory.go:470] Unable to schedule system/kube-system/coredns-default-6cfd6c6766-cqfm7: no fit: 0/1 nodes are available: 1 node(s) runtime is not ready.; waiting
I0924 13:23:46.266278    6058 scheduler.go:787] Updating pod condition for system/kube-system/coredns-default-6cfd6c6766-cqfm7 to (PodScheduled==False, Reason=Unschedulable)
I0924 13:23:55.106026    6058 scheduler.go:576] Attempting to schedule pod: system/kube-system/kube-dns-7f4bf79dc-pvldq
I0924 13:23:55.337109    6058 generic_scheduler.go:1052] Node master is a potential node for preemption.
I0924 13:23:55.337570    6058 factory.go:470] Unable to schedule system/kube-system/kube-dns-7f4bf79dc-pvldq: no fit: 0/1 nodes are available: 1 node(s) runtime is not ready.; waiting
I0924 13:23:55.338083    6058 scheduler.go:787] Updating pod condition for system/kube-system/kube-dns-7f4bf79dc-pvldq to (PodScheduled==False, Reason=Unschedulable)
I0924 13:23:55.338193    6058 scheduler.go:576] Attempting to schedule pod: system/kube-system/coredns-default-6cfd6c6766-cqfm7
I0924 13:23:55.766726    6058 generic_scheduler.go:1052] Node master is a potential node for preemption.
I0924 13:23:55.766995    6058 factory.go:470] Unable to schedule system/kube-system/coredns-default-6cfd6c6766-cqfm7: no fit: 0/1 nodes are available: 1 node(s) runtime is not ready.; waiting
I0924 13:23:55.767048    6058 scheduler.go:787] Updating pod condition for system/kube-system/coredns-default-6cfd6c6766-cqfm7 to (PodScheduled==False, Reason=Unschedulable)
I0924 13:23:56.437620    6058 scheduler.go:576] Attempting to schedule pod: system/kube-system/coredns-default-6cfd6c6766-cqfm7
I0924 13:23:56.798889    6058 generic_scheduler.go:1052] Node master is a potential node for preemption.
I0924 13:23:56.799202    6058 factory.go:470] Unable to schedule system/kube-system/coredns-default-6cfd6c6766-cqfm7: no fit: 0/1 nodes are available: 1 node(s) runtime is not ready.; waiting
I0924 13:23:56.799276    6058 scheduler.go:787] Updating pod condition for system/kube-system/coredns-default-6cfd6c6766-cqfm7 to (PodScheduled==False, Reason=Unschedulable)
I0924 13:23:58.119416    6058 scheduler.go:576] Attempting to schedule pod: system/kube-system/kube-dns-7f4bf79dc-pvldq
I0924 13:23:58.458929    6058 generic_scheduler.go:1052] Node master is a potential node for preemption.
I0924 13:23:58.459247    6058 factory.go:470] Unable to schedule system/kube-system/kube-dns-7f4bf79dc-pvldq: no fit: 0/1 nodes are available: 1 node(s) runtime is not ready.; waiting
I0924 13:23:58.459333    6058 scheduler.go:787] Updating pod condition for system/kube-system/kube-dns-7f4bf79dc-pvldq to (PodScheduled==False, Reason=Unschedulable)
I0924 13:24:07.443835    6058 scheduler.go:576] Attempting to schedule pod: system/kube-system/coredns-default-6cfd6c6766-cqfm7
I0924 13:24:07.459216    6058 generic_scheduler.go:1052] Node master is a potential node for preemption.
I0924 13:24:07.459505    6058 factory.go:470] Unable to schedule system/kube-system/coredns-default-6cfd6c6766-cqfm7: no fit: 0/1 nodes are available: 1 node(s) runtime is not ready.; waiting
I0924 13:24:07.459635    6058 scheduler.go:787] Updating pod condition for system/kube-system/coredns-default-6cfd6c6766-cqfm7 to (PodScheduled==False, Reason=Unschedulable)
I0924 13:24:09.496756    6058 scheduler.go:576] Attempting to schedule pod: system/kube-system/kube-dns-7f4bf79dc-pvldq
I0924 13:24:09.557659    6058 generic_scheduler.go:1052] Node master is a potential node for preemption.
I0924 13:24:09.558031    6058 factory.go:470] Unable to schedule system/kube-system/kube-dns-7f4bf79dc-pvldq: no fit: 0/1 nodes are available: 1 node(s) runtime is not ready.; waiting
I0924 13:24:09.558144    6058 scheduler.go:787] Updating pod condition for system/kube-system/kube-dns-7f4bf79dc-pvldq to (PodScheduled==False, Reason=Unschedulable)
I0924 13:24:17.124353    6058 scheduler.go:576] Attempting to schedule pod: system/kube-system/coredns-default-6cfd6c6766-cqfm7
I0924 13:24:17.355255    6058 generic_scheduler.go:1052] Node master is a potential node for preemption.
I0924 13:24:17.355585    6058 factory.go:470] Unable to schedule system/kube-system/coredns-default-6cfd6c6766-cqfm7: no fit: 0/1 nodes are available: 1 node(s) runtime is not ready.; waiting
I0924 13:24:17.355652    6058 scheduler.go:787] Updating pod condition for system/kube-system/coredns-default-6cfd6c6766-cqfm7 to (PodScheduled==False, Reason=Unschedulable)
I0924 13:24:18.758679    6058 scheduler.go:576] Attempting to schedule pod: system/kube-system/kube-dns-7f4bf79dc-pvldq
I0924 13:24:19.000690    6058 generic_scheduler.go:1052] Node master is a potential node for preemption.
I0924 13:24:19.001015    6058 factory.go:470] Unable to schedule system/kube-system/kube-dns-7f4bf79dc-pvldq: no fit: 0/1 nodes are available: 1 node(s) runtime is not ready.; waiting
I0924 13:24:19.001068    6058 scheduler.go:787] Updating pod condition for system/kube-system/kube-dns-7f4bf79dc-pvldq to (PodScheduled==False, Reason=Unschedulable)
I0924 13:24:19.130975    6058 scheduler.go:576] Attempting to schedule pod: system/kube-system/coredns-default-6cfd6c6766-cqfm7
I0924 13:24:19.575709    6058 generic_scheduler.go:1052] Node master is a potential node for preemption.
I0924 13:24:19.576013    6058 factory.go:470] Unable to schedule system/kube-system/coredns-default-6cfd6c6766-cqfm7: no fit: 0/1 nodes are available: 1 node(s) runtime is not ready.; waiting
I0924 13:24:19.576067    6058 scheduler.go:787] Updating pod condition for system/kube-system/coredns-default-6cfd6c6766-cqfm7 to (PodScheduled==False, Reason=Unschedulable)
I0924 13:24:21.337883    6058 scheduler.go:576] Attempting to schedule pod: system/kube-system/kube-dns-7f4bf79dc-pvldq
I0924 13:24:21.988738    6058 generic_scheduler.go:1052] Node master is a potential node for preemption.
I0924 13:24:21.989154    6058 factory.go:470] Unable to schedule system/kube-system/kube-dns-7f4bf79dc-pvldq: no fit: 0/1 nodes are available: 1 node(s) runtime is not ready.; waiting
I0924 13:24:21.989254    6058 scheduler.go:787] Updating pod condition for system/kube-system/kube-dns-7f4bf79dc-pvldq to (PodScheduled==False, Reason=Unschedulable)
I0924 13:24:30.882785    6058 scheduler.go:576] Attempting to schedule pod: system/kube-system/coredns-default-6cfd6c6766-cqfm7
I0924 13:24:31.005379    6058 generic_scheduler.go:1052] Node master is a potential node for preemption.
I0924 13:24:31.005639    6058 factory.go:470] Unable to schedule system/kube-system/coredns-default-6cfd6c6766-cqfm7: no fit: 0/1 nodes are available: 1 node(s) runtime is not ready.; waiting
I0924 13:24:31.005693    6058 scheduler.go:787] Updating pod condition for system/kube-system/coredns-default-6cfd6c6766-cqfm7 to (PodScheduled==False, Reason=Unschedulable)
I0924 13:24:33.018176    6058 scheduler.go:576] Attempting to schedule pod: system/kube-system/kube-dns-7f4bf79dc-pvldq
I0924 13:24:33.312115    6058 generic_scheduler.go:1052] Node master is a potential node for preemption.
I0924 13:24:33.312769    6058 factory.go:470] Unable to schedule system/kube-system/kube-dns-7f4bf79dc-pvldq: no fit: 0/1 nodes are available: 1 node(s) runtime is not ready.; waiting
I0924 13:24:33.314931    6058 scheduler.go:787] Updating pod condition for system/kube-system/kube-dns-7f4bf79dc-pvldq to (PodScheduled==False, Reason=Unschedulable)
I0924 13:24:40.591379    6058 scheduler.go:576] Attempting to schedule pod: system/kube-system/coredns-default-6cfd6c6766-cqfm7
I0924 13:24:40.686639    6058 generic_scheduler.go:1052] Node master is a potential node for preemption.
I0924 13:24:40.687248    6058 factory.go:470] Unable to schedule system/kube-system/coredns-default-6cfd6c6766-cqfm7: no fit: 0/1 nodes are available: 1 node(s) runtime is not ready.; waiting
I0924 13:24:40.687311    6058 scheduler.go:787] Updating pod condition for system/kube-system/coredns-default-6cfd6c6766-cqfm7 to (PodScheduled==False, Reason=Unschedulable)
I0924 13:24:43.399220    6058 scheduler.go:576] Attempting to schedule pod: system/kube-system/kube-dns-7f4bf79dc-pvldq
I0924 13:24:43.601782    6058 generic_scheduler.go:1052] Node master is a potential node for preemption.
I0924 13:24:43.602090    6058 factory.go:470] Unable to schedule system/kube-system/kube-dns-7f4bf79dc-pvldq: no fit: 0/1 nodes are available: 1 node(s) runtime is not ready.; waiting
I0924 13:24:43.602143    6058 scheduler.go:787] Updating pod condition for system/kube-system/kube-dns-7f4bf79dc-pvldq to (PodScheduled==False, Reason=Unschedulable)
I0924 13:24:43.602242    6058 scheduler.go:576] Attempting to schedule pod: system/kube-system/coredns-default-6cfd6c6766-cqfm7
I0924 13:24:43.875924    6058 generic_scheduler.go:1052] Node master is a potential node for preemption.
I0924 13:24:43.876214    6058 factory.go:470] Unable to schedule system/kube-system/coredns-default-6cfd6c6766-cqfm7: no fit: 0/1 nodes are available: 1 node(s) runtime is not ready.; waiting
I0924 13:24:43.876277    6058 scheduler.go:787] Updating pod condition for system/kube-system/coredns-default-6cfd6c6766-cqfm7 to (PodScheduled==False, Reason=Unschedulable)
E0924 13:24:43.877087    6058 factory.go:512] pod: system/kube-system/kube-dns-7f4bf79dc-pvldq is already present in the active queue
I0924 13:24:43.877452    6058 scheduler.go:576] Attempting to schedule pod: system/kube-system/kube-dns-7f4bf79dc-pvldq
I0924 13:24:44.119885    6058 generic_scheduler.go:1052] Node master is a potential node for preemption.
I0924 13:24:44.120447    6058 factory.go:470] Unable to schedule system/kube-system/kube-dns-7f4bf79dc-pvldq: no fit: 0/1 nodes are available: 1 node(s) runtime is not ready.; waiting
I0924 13:24:44.120509    6058 scheduler.go:787] Updating pod condition for system/kube-system/kube-dns-7f4bf79dc-pvldq to (PodScheduled==False, Reason=Unschedulable)
I0924 13:24:44.926878    6058 scheduler.go:576] Attempting to schedule pod: system/kube-system/kube-dns-7f4bf79dc-pvldq
I0924 13:24:45.343636    6058 generic_scheduler.go:1052] Node master is a potential node for preemption.
I0924 13:24:45.344093    6058 factory.go:470] Unable to schedule system/kube-system/kube-dns-7f4bf79dc-pvldq: no fit: 0/1 nodes are available: 1 node(s) runtime is not ready.; waiting
I0924 13:24:45.344160    6058 scheduler.go:787] Updating pod condition for system/kube-system/kube-dns-7f4bf79dc-pvldq to (PodScheduled==False, Reason=Unschedulable)
I0924 13:24:49.204607    6058 scheduler.go:576] Attempting to schedule pod: system/kube-system/kube-dns-7f4bf79dc-pvldq
I0924 13:24:49.596892    6058 generic_scheduler.go:1052] Node master is a potential node for preemption.
I0924 13:24:49.598414    6058 factory.go:470] Unable to schedule system/kube-system/kube-dns-7f4bf79dc-pvldq: no fit: 0/1 nodes are available: 1 node(s) runtime is not ready.; waiting
I0924 13:24:49.598557    6058 scheduler.go:787] Updating pod condition for system/kube-system/kube-dns-7f4bf79dc-pvldq to (PodScheduled==False, Reason=Unschedulable)
I0924 13:24:54.275111    6058 scheduler.go:576] Attempting to schedule pod: system/kube-system/kube-dns-7f4bf79dc-pvldq
I0924 13:24:54.403602    6058 generic_scheduler.go:1052] Node master is a potential node for preemption.
I0924 13:24:54.404073    6058 factory.go:470] Unable to schedule system/kube-system/kube-dns-7f4bf79dc-pvldq: no fit: 0/1 nodes are available: 1 node(s) runtime is not ready.; waiting
I0924 13:24:54.404165    6058 scheduler.go:787] Updating pod condition for system/kube-system/kube-dns-7f4bf79dc-pvldq to (PodScheduled==False, Reason=Unschedulable)
I0924 13:24:54.413398    6058 scheduler.go:576] Attempting to schedule pod: system/kube-system/coredns-default-6cfd6c6766-cqfm7
I0924 13:24:54.493558    6058 generic_scheduler.go:1052] Node master is a potential node for preemption.
I0924 13:24:54.493825    6058 factory.go:470] Unable to schedule system/kube-system/coredns-default-6cfd6c6766-cqfm7: no fit: 0/1 nodes are available: 1 node(s) runtime is not ready.; waiting
I0924 13:24:54.493876    6058 scheduler.go:787] Updating pod condition for system/kube-system/coredns-default-6cfd6c6766-cqfm7 to (PodScheduled==False, Reason=Unschedulable)
I0924 13:25:03.518311    6058 scheduler.go:576] Attempting to schedule pod: system/kube-system/kube-dns-7f4bf79dc-pvldq
I0924 13:25:03.986861    6058 generic_scheduler.go:1052] Node master is a potential node for preemption.
I0924 13:25:03.987343    6058 factory.go:470] Unable to schedule system/kube-system/kube-dns-7f4bf79dc-pvldq: no fit: 0/1 nodes are available: 1 node(s) runtime is not ready.; waiting
I0924 13:25:03.987408    6058 scheduler.go:787] Updating pod condition for system/kube-system/kube-dns-7f4bf79dc-pvldq to (PodScheduled==False, Reason=Unschedulable)
I0924 13:25:04.042639    6058 scheduler.go:576] Attempting to schedule pod: system/kube-system/coredns-default-6cfd6c6766-cqfm7
I0924 13:25:04.652851    6058 generic_scheduler.go:1052] Node master is a potential node for preemption.
I0924 13:25:04.653154    6058 factory.go:470] Unable to schedule system/kube-system/coredns-default-6cfd6c6766-cqfm7: no fit: 0/1 nodes are available: 1 node(s) runtime is not ready.; waiting
I0924 13:25:04.653208    6058 scheduler.go:787] Updating pod condition for system/kube-system/coredns-default-6cfd6c6766-cqfm7 to (PodScheduled==False, Reason=Unschedulable)
I0924 13:25:06.122053    6058 scheduler.go:576] Attempting to schedule pod: system/kube-system/coredns-default-6cfd6c6766-cqfm7
I0924 13:25:06.230788    6058 generic_scheduler.go:1052] Node master is a potential node for preemption.
I0924 13:25:06.231557    6058 factory.go:470] Unable to schedule system/kube-system/coredns-default-6cfd6c6766-cqfm7: no fit: 0/1 nodes are available: 1 node(s) runtime is not ready.; waiting
I0924 13:25:06.231682    6058 scheduler.go:787] Updating pod condition for system/kube-system/coredns-default-6cfd6c6766-cqfm7 to (PodScheduled==False, Reason=Unschedulable)
I0924 13:25:06.244173    6058 scheduler.go:576] Attempting to schedule pod: system/kube-system/kube-dns-7f4bf79dc-pvldq
I0924 13:25:06.388052    6058 generic_scheduler.go:1052] Node master is a potential node for preemption.
I0924 13:25:06.388353    6058 factory.go:470] Unable to schedule system/kube-system/kube-dns-7f4bf79dc-pvldq: no fit: 0/1 nodes are available: 1 node(s) runtime is not ready.; waiting
I0924 13:25:06.388404    6058 scheduler.go:787] Updating pod condition for system/kube-system/kube-dns-7f4bf79dc-pvldq to (PodScheduled==False, Reason=Unschedulable)
I0924 13:25:08.288587    6058 scheduler.go:576] Attempting to schedule pod: system/kube-system/kube-dns-7f4bf79dc-pvldq
I0924 13:25:08.392176    6058 generic_scheduler.go:1052] Node master is a potential node for preemption.
I0924 13:25:08.392485    6058 factory.go:470] Unable to schedule system/kube-system/kube-dns-7f4bf79dc-pvldq: no fit: 0/1 nodes are available: 1 node(s) runtime is not ready.; waiting
I0924 13:25:08.392541    6058 scheduler.go:787] Updating pod condition for system/kube-system/kube-dns-7f4bf79dc-pvldq to (PodScheduled==False, Reason=Unschedulable)
I0924 13:25:16.974000    6058 scheduler.go:576] Attempting to schedule pod: system/kube-system/coredns-default-6cfd6c6766-cqfm7
I0924 13:25:17.086686    6058 generic_scheduler.go:1052] Node master is a potential node for preemption.
I0924 13:25:17.086996    6058 factory.go:470] Unable to schedule system/kube-system/coredns-default-6cfd6c6766-cqfm7: no fit: 0/1 nodes are available: 1 node(s) runtime is not ready.; waiting
I0924 13:25:17.087051    6058 scheduler.go:787] Updating pod condition for system/kube-system/coredns-default-6cfd6c6766-cqfm7 to (PodScheduled==False, Reason=Unschedulable)
I0924 13:25:19.507943    6058 scheduler.go:576] Attempting to schedule pod: system/kube-system/kube-dns-7f4bf79dc-pvldq
I0924 13:25:19.873168    6058 generic_scheduler.go:1052] Node master is a potential node for preemption.
I0924 13:25:19.873499    6058 factory.go:470] Unable to schedule system/kube-system/kube-dns-7f4bf79dc-pvldq: no fit: 0/1 nodes are available: 1 node(s) runtime is not ready.; waiting
I0924 13:25:19.873553    6058 scheduler.go:787] Updating pod condition for system/kube-system/kube-dns-7f4bf79dc-pvldq to (PodScheduled==False, Reason=Unschedulable)
I0924 13:25:26.757484    6058 scheduler.go:576] Attempting to schedule pod: system/kube-system/coredns-default-6cfd6c6766-cqfm7
I0924 13:25:28.178740    6058 generic_scheduler.go:1052] Node master is a potential node for preemption.
I0924 13:25:28.179037    6058 factory.go:470] Unable to schedule system/kube-system/coredns-default-6cfd6c6766-cqfm7: no fit: 0/1 nodes are available: 1 node(s) runtime is not ready.; waiting
I0924 13:25:28.179094    6058 scheduler.go:787] Updating pod condition for system/kube-system/coredns-default-6cfd6c6766-cqfm7 to (PodScheduled==False, Reason=Unschedulable)
I0924 13:25:29.944600    6058 scheduler.go:576] Attempting to schedule pod: system/kube-system/kube-dns-7f4bf79dc-pvldq
I0924 13:25:30.192689    6058 generic_scheduler.go:1052] Node master is a potential node for preemption.
I0924 13:25:30.192980    6058 factory.go:470] Unable to schedule system/kube-system/kube-dns-7f4bf79dc-pvldq: no fit: 0/1 nodes are available: 1 node(s) runtime is not ready.; waiting
I0924 13:25:30.193039    6058 scheduler.go:787] Updating pod condition for system/kube-system/kube-dns-7f4bf79dc-pvldq to (PodScheduled==False, Reason=Unschedulable)
I0924 13:25:31.006006    6058 scheduler.go:576] Attempting to schedule pod: system/kube-system/coredns-default-6cfd6c6766-cqfm7
I0924 13:25:31.411669    6058 generic_scheduler.go:1052] Node master is a potential node for preemption.
I0924 13:25:31.411956    6058 factory.go:470] Unable to schedule system/kube-system/coredns-default-6cfd6c6766-cqfm7: no fit: 0/1 nodes are available: 1 node(s) runtime is not ready.; waiting
I0924 13:25:31.412019    6058 scheduler.go:787] Updating pod condition for system/kube-system/coredns-default-6cfd6c6766-cqfm7 to (PodScheduled==False, Reason=Unschedulable)
I0924 13:25:33.282401    6058 scheduler.go:576] Attempting to schedule pod: system/kube-system/kube-dns-7f4bf79dc-pvldq
I0924 13:25:33.324207    6058 generic_scheduler.go:1052] Node master is a potential node for preemption.
I0924 13:25:33.324775    6058 factory.go:470] Unable to schedule system/kube-system/kube-dns-7f4bf79dc-pvldq: no fit: 0/1 nodes are available: 1 node(s) runtime is not ready.; waiting
I0924 13:25:33.324884    6058 scheduler.go:787] Updating pod condition for system/kube-system/kube-dns-7f4bf79dc-pvldq to (PodScheduled==False, Reason=Unschedulable)
I0924 13:25:42.167903    6058 scheduler.go:576] Attempting to schedule pod: system/kube-system/coredns-default-6cfd6c6766-cqfm7
I0924 13:25:42.910916    6058 generic_scheduler.go:1052] Node master is a potential node for preemption.
I0924 13:25:42.911210    6058 factory.go:470] Unable to schedule system/kube-system/coredns-default-6cfd6c6766-cqfm7: no fit: 0/1 nodes are available: 1 node(s) runtime is not ready.; waiting
I0924 13:25:42.911265    6058 scheduler.go:787] Updating pod condition for system/kube-system/coredns-default-6cfd6c6766-cqfm7 to (PodScheduled==False, Reason=Unschedulable)
I0924 13:25:44.490792    6058 scheduler.go:576] Attempting to schedule pod: system/kube-system/kube-dns-7f4bf79dc-pvldq
I0924 13:25:44.684504    6058 generic_scheduler.go:1052] Node master is a potential node for preemption.
I0924 13:25:44.684827    6058 factory.go:470] Unable to schedule system/kube-system/kube-dns-7f4bf79dc-pvldq: no fit: 0/1 nodes are available: 1 node(s) runtime is not ready.; waiting
I0924 13:25:44.684887    6058 scheduler.go:787] Updating pod condition for system/kube-system/kube-dns-7f4bf79dc-pvldq to (PodScheduled==False, Reason=Unschedulable)
I0924 13:25:50.692131    6058 scheduler.go:576] Attempting to schedule pod: system/kube-system/coredns-default-6cfd6c6766-cqfm7
I0924 13:25:51.179388    6058 generic_scheduler.go:1052] Node master is a potential node for preemption.
I0924 13:25:51.179812    6058 factory.go:470] Unable to schedule system/kube-system/coredns-default-6cfd6c6766-cqfm7: no fit: 0/1 nodes are available: 1 node(s) runtime is not ready.; waiting
I0924 13:25:51.179867    6058 scheduler.go:787] Updating pod condition for system/kube-system/coredns-default-6cfd6c6766-cqfm7 to (PodScheduled==False, Reason=Unschedulable)
I0924 13:25:52.643126    6058 scheduler.go:576] Attempting to schedule pod: system/kube-system/coredns-default-6cfd6c6766-cqfm7
I0924 13:25:52.771857    6058 generic_scheduler.go:1052] Node master is a potential node for preemption.
I0924 13:25:52.772214    6058 factory.go:470] Unable to schedule system/kube-system/coredns-default-6cfd6c6766-cqfm7: no fit: 0/1 nodes are available: 1 node(s) runtime is not ready.; waiting
I0924 13:25:52.772288    6058 scheduler.go:787] Updating pod condition for system/kube-system/coredns-default-6cfd6c6766-cqfm7 to (PodScheduled==False, Reason=Unschedulable)
I0924 13:25:52.982717    6058 scheduler.go:576] Attempting to schedule pod: system/kube-system/kube-dns-7f4bf79dc-pvldq
I0924 13:25:53.455512    6058 generic_scheduler.go:1052] Node master is a potential node for preemption.
I0924 13:25:53.455802    6058 factory.go:470] Unable to schedule system/kube-system/kube-dns-7f4bf79dc-pvldq: no fit: 0/1 nodes are available: 1 node(s) runtime is not ready.; waiting
I0924 13:25:53.455854    6058 scheduler.go:787] Updating pod condition for system/kube-system/kube-dns-7f4bf79dc-pvldq to (PodScheduled==False, Reason=Unschedulable)
I0924 13:25:54.575395    6058 scheduler.go:576] Attempting to schedule pod: system/kube-system/kube-dns-7f4bf79dc-pvldq
I0924 13:25:54.776620    6058 generic_scheduler.go:1052] Node master is a potential node for preemption.
I0924 13:25:54.777226    6058 factory.go:470] Unable to schedule system/kube-system/kube-dns-7f4bf79dc-pvldq: no fit: 0/1 nodes are available: 1 node(s) runtime is not ready.; waiting
I0924 13:25:54.777355    6058 scheduler.go:787] Updating pod condition for system/kube-system/kube-dns-7f4bf79dc-pvldq to (PodScheduled==False, Reason=Unschedulable)
I0924 13:26:03.802417    6058 scheduler.go:576] Attempting to schedule pod: system/kube-system/coredns-default-6cfd6c6766-cqfm7
I0924 13:26:03.851180    6058 generic_scheduler.go:1052] Node master is a potential node for preemption.
I0924 13:26:03.851606    6058 factory.go:470] Unable to schedule system/kube-system/coredns-default-6cfd6c6766-cqfm7: no fit: 0/1 nodes are available: 1 node(s) runtime is not ready.; waiting
I0924 13:26:03.851704    6058 scheduler.go:787] Updating pod condition for system/kube-system/coredns-default-6cfd6c6766-cqfm7 to (PodScheduled==False, Reason=Unschedulable)
I0924 13:26:05.918634    6058 scheduler.go:576] Attempting to schedule pod: system/kube-system/kube-dns-7f4bf79dc-pvldq
I0924 13:26:06.122655    6058 generic_scheduler.go:1052] Node master is a potential node for preemption.
I0924 13:26:06.122957    6058 factory.go:470] Unable to schedule system/kube-system/kube-dns-7f4bf79dc-pvldq: no fit: 0/1 nodes are available: 1 node(s) runtime is not ready.; waiting
I0924 13:26:06.123010    6058 scheduler.go:787] Updating pod condition for system/kube-system/kube-dns-7f4bf79dc-pvldq to (PodScheduled==False, Reason=Unschedulable)
I0924 13:26:12.375990    6058 scheduler.go:576] Attempting to schedule pod: system/kube-system/coredns-default-6cfd6c6766-cqfm7
I0924 13:26:12.965859    6058 generic_scheduler.go:1052] Node master is a potential node for preemption.
I0924 13:26:12.966484    6058 factory.go:470] Unable to schedule system/kube-system/coredns-default-6cfd6c6766-cqfm7: no fit: 0/1 nodes are available: 1 node(s) runtime is not ready.; waiting
I0924 13:26:12.966557    6058 scheduler.go:787] Updating pod condition for system/kube-system/coredns-default-6cfd6c6766-cqfm7 to (PodScheduled==False, Reason=Unschedulable)
I0924 13:26:15.780628    6058 scheduler.go:576] Attempting to schedule pod: system/kube-system/coredns-default-6cfd6c6766-cqfm7
I0924 13:26:15.996068    6058 generic_scheduler.go:1052] Node master is a potential node for preemption.
I0924 13:26:15.996360    6058 factory.go:470] Unable to schedule system/kube-system/coredns-default-6cfd6c6766-cqfm7: no fit: 0/1 nodes are available: 1 node(s) runtime is not ready.; waiting
I0924 13:26:15.996418    6058 scheduler.go:787] Updating pod condition for system/kube-system/coredns-default-6cfd6c6766-cqfm7 to (PodScheduled==False, Reason=Unschedulable)
I0924 13:26:16.175993    6058 scheduler.go:576] Attempting to schedule pod: system/kube-system/kube-dns-7f4bf79dc-pvldq
I0924 13:26:16.250900    6058 generic_scheduler.go:1052] Node master is a potential node for preemption.
I0924 13:26:16.251162    6058 factory.go:470] Unable to schedule system/kube-system/kube-dns-7f4bf79dc-pvldq: no fit: 0/1 nodes are available: 1 node(s) runtime is not ready.; waiting
I0924 13:26:16.251248    6058 scheduler.go:787] Updating pod condition for system/kube-system/kube-dns-7f4bf79dc-pvldq to (PodScheduled==False, Reason=Unschedulable)
I0924 13:26:22.032451    6058 scheduler.go:576] Attempting to schedule pod: system/kube-system/kube-dns-7f4bf79dc-pvldq
I0924 13:26:22.279187    6058 generic_scheduler.go:1052] Node master is a potential node for preemption.
I0924 13:26:22.279534    6058 factory.go:470] Unable to schedule system/kube-system/kube-dns-7f4bf79dc-pvldq: no fit: 0/1 nodes are available: 1 node(s) runtime is not ready.; waiting
I0924 13:26:22.279592    6058 scheduler.go:787] Updating pod condition for system/kube-system/kube-dns-7f4bf79dc-pvldq to (PodScheduled==False, Reason=Unschedulable)
I0924 13:26:26.840745    6058 scheduler.go:576] Attempting to schedule pod: system/kube-system/coredns-default-6cfd6c6766-cqfm7
I0924 13:26:27.309531    6058 generic_scheduler.go:1052] Node master is a potential node for preemption.
I0924 13:26:27.309844    6058 factory.go:470] Unable to schedule system/kube-system/coredns-default-6cfd6c6766-cqfm7: no fit: 0/1 nodes are available: 1 node(s) runtime is not ready.; waiting
I0924 13:26:27.309915    6058 scheduler.go:787] Updating pod condition for system/kube-system/coredns-default-6cfd6c6766-cqfm7 to (PodScheduled==False, Reason=Unschedulable)
I0924 13:26:33.143158    6058 scheduler.go:576] Attempting to schedule pod: system/kube-system/kube-dns-7f4bf79dc-pvldq
I0924 13:26:33.691681    6058 generic_scheduler.go:1052] Node master is a potential node for preemption.
I0924 13:26:33.691975    6058 factory.go:470] Unable to schedule system/kube-system/kube-dns-7f4bf79dc-pvldq: no fit: 0/1 nodes are available: 1 node(s) runtime is not ready.; waiting
I0924 13:26:33.692027    6058 scheduler.go:787] Updating pod condition for system/kube-system/kube-dns-7f4bf79dc-pvldq to (PodScheduled==False, Reason=Unschedulable)
I0924 13:26:37.878387    6058 scheduler.go:576] Attempting to schedule pod: system/kube-system/coredns-default-6cfd6c6766-cqfm7
I0924 13:26:38.346671    6058 generic_scheduler.go:1052] Node master is a potential node for preemption.
I0924 13:26:38.347062    6058 factory.go:470] Unable to schedule system/kube-system/coredns-default-6cfd6c6766-cqfm7: no fit: 0/1 nodes are available: 1 node(s) runtime is not ready.; waiting
I0924 13:26:38.347130    6058 scheduler.go:787] Updating pod condition for system/kube-system/coredns-default-6cfd6c6766-cqfm7 to (PodScheduled==False, Reason=Unschedulable)
I0924 13:26:38.696391    6058 scheduler.go:576] Attempting to schedule pod: system/kube-system/coredns-default-6cfd6c6766-cqfm7
